return { { ["x"] = 0, ["meta"] = { ["fields"] = {  }, ["inventory"] = {  } }, ["param2"] = 0, ["y"] = 0, ["param1"] = 0, ["z"] = 0, ["name"] = "default:dirt_with_grass" }, { ["x"] = 0, ["meta"] = { ["fields"] = {  }, ["inventory"] = {  } }, ["param2"] = 0, ["y"] = 0, ["param1"] = 0, ["z"] = 1, ["name"] = "default:dirt_with_grass" }, { ["x"] = 0, ["meta"] = { ["fields"] = {  }, ["inventory"] = {  } }, ["param2"] = 0, ["y"] = 0, ["param1"] = 0, ["z"] = 2, ["name"] = "default:dirt_with_grass" }, { ["x"] = 0, ["meta"] = { ["fields"] = {  }, ["inventory"] = {  } }, ["param2"] = 0, ["y"] = 0, ["param1"] = 0, ["z"] = 3, ["name"] = "default:dirt_with_grass" }, { ["x"] = 0, ["meta"] = { ["fields"] = {  }, ["inventory"] = {  } }, ["param2"] = 0, ["y"] = 0, ["param1"] = 0, ["z"] = 4, ["name"] = "default:dirt_with_grass" }, { ["x"] = 0, ["meta"] = { ["fields"] = {  }, ["inventory"] = {  } }, ["param2"] = 0, ["y"] = 0, ["param1"] = 0, ["z"] = 5, ["name"] = "default:dirt_with_grass" }, { ["x"] = 0, ["meta"] = { ["fields"] = {  }, ["inventory"] = {  } }, ["param2"] = 0, ["y"] = 0, ["param1"] = 0, ["z"] = 6, ["name"] = "default:dirt_with_grass" }, { ["x"] = 0, ["meta"] = { ["fields"] = {  }, ["inventory"] = {  } }, ["param2"] = 0, ["y"] = 0, ["param1"] = 0, ["z"] = 7, ["name"] = "default:dirt_with_grass" }, { ["x"] = 0, ["meta"] = { ["fields"] = {  }, ["inventory"] = {  } }, ["param2"] = 0, ["y"] = 0, ["param1"] = 0, ["z"] = 8, ["name"] = "default:dirt_with_grass" }, { ["x"] = 0, ["meta"] = { ["fields"] = {  }, ["inventory"] = {  } }, ["param2"] = 0, ["y"] = 0, ["param1"] = 0, ["z"] = 9, ["name"] = "default:dirt_with_grass" }, { ["x"] = 0, ["meta"] = { ["fields"] = {  }, ["inventory"] = {  } }, ["param2"] = 0, ["y"] = 0, ["param1"] = 0, ["z"] = 10, ["name"] = "default:dirt_with_grass" }, { ["x"] = 0, ["meta"] = { ["fields"] = {  }, ["inventory"] = {  } }, ["param2"] = 0, ["y"] = 0, ["param1"] = 0, ["z"] = 11, ["name"] = "default:dirt_with_grass" }, { ["x"] = 0, ["meta"] = { ["fields"] = {  }, ["inventory"] = {  } }, ["param2"] = 0, ["y"] = 0, ["param1"] = 0, ["z"] = 12, ["name"] = "default:dirt_with_grass" }, { ["x"] = 0, ["meta"] = { ["fields"] = {  }, ["inventory"] = {  } }, ["param2"] = 0, ["y"] = 0, ["param1"] = 0, ["z"] = 13, ["name"] = "default:dirt_with_grass" }, { ["x"] = 0, ["meta"] = { ["fields"] = {  }, ["inventory"] = {  } }, ["param2"] = 0, ["y"] = 0, ["param1"] = 0, ["z"] = 14, ["name"] = "default:dirt_with_grass" }, { ["x"] = 0, ["meta"] = { ["fields"] = {  }, ["inventory"] = {  } }, ["param2"] = 0, ["y"] = 0, ["param1"] = 0, ["z"] = 15, ["name"] = "default:dirt_with_grass" }, { ["x"] = 0, ["meta"] = { ["fields"] = {  }, ["inventory"] = {  } }, ["param2"] = 0, ["y"] = 1, ["param1"] = 205, ["z"] = 0, ["name"] = "default:fence_wood" }, { ["x"] = 0, ["meta"] = { ["fields"] = {  }, ["inventory"] = {  } }, ["param2"] = 0, ["y"] = 1, ["param1"] = 189, ["z"] = 1, ["name"] = "default:fence_wood" }, { ["x"] = 0, ["meta"] = { ["fields"] = {  }, ["inventory"] = {  } }, ["param2"] = 0, ["y"] = 1, ["param1"] = 205, ["z"] = 2, ["name"] = "default:fence_wood" }, { ["x"] = 0, ["meta"] = { ["fields"] = {  }, ["inventory"] = {  } }, ["param2"] = 0, ["y"] = 1, ["param1"] = 189, ["z"] = 3, ["name"] = "default:fence_wood" }, { ["x"] = 0, ["meta"] = { ["fields"] = {  }, ["inventory"] = {  } }, ["param2"] = 0, ["y"] = 1, ["param1"] = 205, ["z"] = 4, ["name"] = "default:fence_wood" }, { ["x"] = 0, ["meta"] = { ["fields"] = {  }, ["inventory"] = {  } }, ["param2"] = 0, ["y"] = 1, ["param1"] = 189, ["z"] = 8, ["name"] = "cottages:bench" }, { ["x"] = 0, ["meta"] = { ["fields"] = {  }, ["inventory"] = {  } }, ["param2"] = 0, ["y"] = 1, ["param1"] = 205, ["z"] = 9, ["name"] = "default:fence_wood" }, { ["x"] = 0, ["meta"] = { ["fields"] = {  }, ["inventory"] = {  } }, ["param2"] = 0, ["y"] = 1, ["param1"] = 189, ["z"] = 10, ["name"] = "default:fence_wood" }, { ["x"] = 0, ["meta"] = { ["fields"] = {  }, ["inventory"] = {  } }, ["param2"] = 0, ["y"] = 1, ["param1"] = 205, ["z"] = 11, ["name"] = "default:fence_wood" }, { ["x"] = 0, ["meta"] = { ["fields"] = {  }, ["inventory"] = {  } }, ["param2"] = 0, ["y"] = 1, ["param1"] = 189, ["z"] = 12, ["name"] = "default:fence_wood" }, { ["x"] = 0, ["meta"] = { ["fields"] = {  }, ["inventory"] = {  } }, ["param2"] = 0, ["y"] = 1, ["param1"] = 205, ["z"] = 13, ["name"] = "default:fence_wood" }, { ["x"] = 0, ["meta"] = { ["fields"] = {  }, ["inventory"] = {  } }, ["param2"] = 0, ["y"] = 1, ["param1"] = 189, ["z"] = 14, ["name"] = "default:fence_wood" }, { ["x"] = 0, ["meta"] = { ["fields"] = {  }, ["inventory"] = {  } }, ["param2"] = 0, ["y"] = 1, ["param1"] = 205, ["z"] = 15, ["name"] = "default:fence_wood" }, { ["x"] = 0, ["meta"] = { ["fields"] = {  }, ["inventory"] = {  } }, ["param2"] = 1, ["y"] = 2, ["param1"] = 15, ["z"] = 0, ["name"] = "default:torch" }, { ["x"] = 0, ["meta"] = { ["fields"] = {  }, ["inventory"] = {  } }, ["param2"] = 1, ["y"] = 2, ["param1"] = 15, ["z"] = 2, ["name"] = "default:torch" }, { ["x"] = 0, ["meta"] = { ["fields"] = {  }, ["inventory"] = {  } }, ["param2"] = 1, ["y"] = 2, ["param1"] = 15, ["z"] = 4, ["name"] = "default:torch" }, { ["x"] = 0, ["meta"] = { ["fields"] = {  }, ["inventory"] = {  } }, ["param2"] = 1, ["y"] = 2, ["param1"] = 15, ["z"] = 9, ["name"] = "default:torch" }, { ["x"] = 0, ["meta"] = { ["fields"] = {  }, ["inventory"] = {  } }, ["param2"] = 1, ["y"] = 2, ["param1"] = 15, ["z"] = 11, ["name"] = "default:torch" }, { ["x"] = 0, ["meta"] = { ["fields"] = {  }, ["inventory"] = {  } }, ["param2"] = 1, ["y"] = 2, ["param1"] = 15, ["z"] = 13, ["name"] = "default:torch" }, { ["x"] = 0, ["meta"] = { ["fields"] = {  }, ["inventory"] = {  } }, ["param2"] = 1, ["y"] = 2, ["param1"] = 15, ["z"] = 15, ["name"] = "default:torch" }, { ["x"] = 1, ["meta"] = { ["fields"] = {  }, ["inventory"] = {  } }, ["param2"] = 0, ["y"] = 0, ["param1"] = 0, ["z"] = 0, ["name"] = "default:dirt_with_grass" }, { ["x"] = 1, ["meta"] = { ["fields"] = {  }, ["inventory"] = {  } }, ["param2"] = 0, ["y"] = 0, ["param1"] = 0, ["z"] = 1, ["name"] = "default:dirt_with_grass" }, { ["x"] = 1, ["meta"] = { ["fields"] = {  }, ["inventory"] = {  } }, ["param2"] = 0, ["y"] = 0, ["param1"] = 0, ["z"] = 2, ["name"] = "default:dirt_with_grass" }, { ["x"] = 1, ["meta"] = { ["fields"] = {  }, ["inventory"] = {  } }, ["param2"] = 0, ["y"] = 0, ["param1"] = 156, ["z"] = 3, ["name"] = "default:water_source" }, { ["x"] = 1, ["meta"] = { ["fields"] = {  }, ["inventory"] = {  } }, ["param2"] = 0, ["y"] = 0, ["param1"] = 0, ["z"] = 4, ["name"] = "default:dirt_with_grass" }, { ["x"] = 1, ["meta"] = { ["fields"] = {  }, ["inventory"] = {  } }, ["param2"] = 0, ["y"] = 0, ["param1"] = 0, ["z"] = 5, ["name"] = "default:dirt_with_grass" }, { ["x"] = 1, ["meta"] = { ["fields"] = {  }, ["inventory"] = {  } }, ["param2"] = 0, ["y"] = 0, ["param1"] = 0, ["z"] = 6, ["name"] = "default:dirt_with_grass" }, { ["x"] = 1, ["meta"] = { ["fields"] = {  }, ["inventory"] = {  } }, ["param2"] = 0, ["y"] = 0, ["param1"] = 0, ["z"] = 7, ["name"] = "default:dirt_with_grass" }, { ["x"] = 1, ["meta"] = { ["fields"] = {  }, ["inventory"] = {  } }, ["param2"] = 0, ["y"] = 0, ["param1"] = 0, ["z"] = 8, ["name"] = "default:dirt_with_grass" }, { ["x"] = 1, ["meta"] = { ["fields"] = {  }, ["inventory"] = {  } }, ["param2"] = 0, ["y"] = 0, ["param1"] = 0, ["z"] = 9, ["name"] = "default:dirt_with_grass" }, { ["x"] = 1, ["meta"] = { ["fields"] = {  }, ["inventory"] = {  } }, ["param2"] = 0, ["y"] = 0, ["param1"] = 0, ["z"] = 10, ["name"] = "farming:soil_wet" }, { ["x"] = 1, ["meta"] = { ["fields"] = {  }, ["inventory"] = {  } }, ["param2"] = 0, ["y"] = 0, ["param1"] = 0, ["z"] = 11, ["name"] = "farming:soil_wet" }, { ["x"] = 1, ["meta"] = { ["fields"] = {  }, ["inventory"] = {  } }, ["param2"] = 0, ["y"] = 0, ["param1"] = 0, ["z"] = 12, ["name"] = "farming:soil_wet" }, { ["x"] = 1, ["meta"] = { ["fields"] = {  }, ["inventory"] = {  } }, ["param2"] = 0, ["y"] = 0, ["param1"] = 0, ["z"] = 13, ["name"] = "farming:soil_wet" }, { ["x"] = 1, ["meta"] = { ["fields"] = {  }, ["inventory"] = {  } }, ["param2"] = 0, ["y"] = 0, ["param1"] = 0, ["z"] = 14, ["name"] = "farming:soil_wet" }, { ["x"] = 1, ["meta"] = { ["fields"] = {  }, ["inventory"] = {  } }, ["param2"] = 0, ["y"] = 0, ["param1"] = 0, ["z"] = 15, ["name"] = "default:dirt_with_grass" }, { ["x"] = 1, ["meta"] = { ["fields"] = {  }, ["inventory"] = {  } }, ["param2"] = 0, ["y"] = 1, ["param1"] = 189, ["z"] = 0, ["name"] = "default:fence_wood" }, { ["x"] = 1, ["meta"] = { ["fields"] = {  }, ["inventory"] = {  } }, ["param2"] = 3, ["y"] = 1, ["param1"] = 173, ["z"] = 3, ["name"] = "cottages:washing" }, { ["x"] = 1, ["meta"] = { ["fields"] = {  }, ["inventory"] = {  } }, ["param2"] = 0, ["y"] = 1, ["param1"] = 189, ["z"] = 4, ["name"] = "default:fence_wood" }, { ["x"] = 1, ["meta"] = { ["fields"] = {  }, ["inventory"] = {  } }, ["param2"] = 0, ["y"] = 1, ["param1"] = 173, ["z"] = 8, ["name"] = "cottages:bench" }, { ["x"] = 1, ["meta"] = { ["fields"] = {  }, ["inventory"] = {  } }, ["param2"] = 0, ["y"] = 1, ["param1"] = 189, ["z"] = 9, ["name"] = "default:fence_wood" }, { ["x"] = 1, ["meta"] = { ["fields"] = {  }, ["inventory"] = {  } }, ["param2"] = 0, ["y"] = 1, ["param1"] = 173, ["z"] = 10, ["name"] = "farming:cotton_3" }, { ["x"] = 1, ["meta"] = { ["fields"] = {  }, ["inventory"] = {  } }, ["param2"] = 0, ["y"] = 1, ["param1"] = 189, ["z"] = 11, ["name"] = "farming:cotton_3" }, { ["x"] = 1, ["meta"] = { ["fields"] = {  }, ["inventory"] = {  } }, ["param2"] = 0, ["y"] = 1, ["param1"] = 173, ["z"] = 12, ["name"] = "farming:cotton_4" }, { ["x"] = 1, ["meta"] = { ["fields"] = {  }, ["inventory"] = {  } }, ["param2"] = 0, ["y"] = 1, ["param1"] = 189, ["z"] = 13, ["name"] = "farming:cotton_4" }, { ["x"] = 1, ["meta"] = { ["fields"] = {  }, ["inventory"] = {  } }, ["param2"] = 0, ["y"] = 1, ["param1"] = 173, ["z"] = 14, ["name"] = "farming:cotton_3" }, { ["x"] = 1, ["meta"] = { ["fields"] = {  }, ["inventory"] = {  } }, ["param2"] = 0, ["y"] = 1, ["param1"] = 189, ["z"] = 15, ["name"] = "default:fence_wood" }, { ["x"] = 2, ["meta"] = { ["fields"] = {  }, ["inventory"] = {  } }, ["param2"] = 0, ["y"] = 0, ["param1"] = 0, ["z"] = 0, ["name"] = "default:dirt_with_grass" }, { ["x"] = 2, ["meta"] = { ["fields"] = {  }, ["inventory"] = {  } }, ["param2"] = 0, ["y"] = 0, ["param1"] = 0, ["z"] = 1, ["name"] = "default:dirt_with_grass" }, { ["x"] = 2, ["meta"] = { ["fields"] = {  }, ["inventory"] = {  } }, ["param2"] = 0, ["y"] = 0, ["param1"] = 0, ["z"] = 2, ["name"] = "default:dirt_with_grass" }, { ["x"] = 2, ["meta"] = { ["fields"] = {  }, ["inventory"] = {  } }, ["param2"] = 0, ["y"] = 0, ["param1"] = 0, ["z"] = 3, ["name"] = "default:dirt_with_grass" }, { ["x"] = 2, ["meta"] = { ["fields"] = {  }, ["inventory"] = {  } }, ["param2"] = 0, ["y"] = 0, ["param1"] = 0, ["z"] = 4, ["name"] = "default:dirt_with_grass" }, { ["x"] = 2, ["meta"] = { ["fields"] = {  }, ["inventory"] = {  } }, ["param2"] = 0, ["y"] = 0, ["param1"] = 0, ["z"] = 5, ["name"] = "default:dirt_with_grass" }, { ["x"] = 2, ["meta"] = { ["fields"] = {  }, ["inventory"] = {  } }, ["param2"] = 0, ["y"] = 0, ["param1"] = 0, ["z"] = 6, ["name"] = "default:dirt_with_grass" }, { ["x"] = 2, ["meta"] = { ["fields"] = {  }, ["inventory"] = {  } }, ["param2"] = 0, ["y"] = 0, ["param1"] = 0, ["z"] = 7, ["name"] = "default:dirt_with_grass" }, { ["x"] = 2, ["meta"] = { ["fields"] = {  }, ["inventory"] = {  } }, ["param2"] = 0, ["y"] = 0, ["param1"] = 0, ["z"] = 8, ["name"] = "default:dirt_with_grass" }, { ["x"] = 2, ["meta"] = { ["fields"] = {  }, ["inventory"] = {  } }, ["param2"] = 0, ["y"] = 0, ["param1"] = 0, ["z"] = 9, ["name"] = "default:dirt_with_grass" }, { ["x"] = 2, ["meta"] = { ["fields"] = {  }, ["inventory"] = {  } }, ["param2"] = 0, ["y"] = 0, ["param1"] = 0, ["z"] = 10, ["name"] = "farming:soil_wet" }, { ["x"] = 2, ["meta"] = { ["fields"] = {  }, ["inventory"] = {  } }, ["param2"] = 0, ["y"] = 0, ["param1"] = 0, ["z"] = 11, ["name"] = "farming:soil_wet" }, { ["x"] = 2, ["meta"] = { ["fields"] = {  }, ["inventory"] = {  } }, ["param2"] = 0, ["y"] = 0, ["param1"] = 0, ["z"] = 12, ["name"] = "farming:soil_wet" }, { ["x"] = 2, ["meta"] = { ["fields"] = {  }, ["inventory"] = {  } }, ["param2"] = 0, ["y"] = 0, ["param1"] = 0, ["z"] = 13, ["name"] = "farming:soil_wet" }, { ["x"] = 2, ["meta"] = { ["fields"] = {  }, ["inventory"] = {  } }, ["param2"] = 0, ["y"] = 0, ["param1"] = 0, ["z"] = 14, ["name"] = "farming:soil_wet" }, { ["x"] = 2, ["meta"] = { ["fields"] = {  }, ["inventory"] = {  } }, ["param2"] = 0, ["y"] = 0, ["param1"] = 0, ["z"] = 15, ["name"] = "default:dirt_with_grass" }, { ["x"] = 2, ["meta"] = { ["fields"] = {  }, ["inventory"] = {  } }, ["param2"] = 0, ["y"] = 1, ["param1"] = 205, ["z"] = 0, ["name"] = "default:fence_wood" }, { ["x"] = 2, ["meta"] = { ["fields"] = {  }, ["inventory"] = {  } }, ["param2"] = 0, ["y"] = 1, ["param1"] = 205, ["z"] = 4, ["name"] = "default:fence_wood" }, { ["x"] = 2, ["meta"] = { ["fields"] = {  }, ["inventory"] = {  } }, ["param2"] = 0, ["y"] = 1, ["param1"] = 189, ["z"] = 8, ["name"] = "cottages:bench" }, { ["x"] = 2, ["meta"] = { ["fields"] = {  }, ["inventory"] = {  } }, ["param2"] = 0, ["y"] = 1, ["param1"] = 205, ["z"] = 9, ["name"] = "default:fence_wood" }, { ["x"] = 2, ["meta"] = { ["fields"] = {  }, ["inventory"] = {  } }, ["param2"] = 0, ["y"] = 1, ["param1"] = 189, ["z"] = 10, ["name"] = "farming:cotton_3" }, { ["x"] = 2, ["meta"] = { ["fields"] = {  }, ["inventory"] = {  } }, ["param2"] = 0, ["y"] = 1, ["param1"] = 189, ["z"] = 11, ["name"] = "farming:cotton_3" }, { ["x"] = 2, ["meta"] = { ["fields"] = {  }, ["inventory"] = {  } }, ["param2"] = 0, ["y"] = 1, ["param1"] = 173, ["z"] = 12, ["name"] = "farming:cotton_4" }, { ["x"] = 2, ["meta"] = { ["fields"] = {  }, ["inventory"] = {  } }, ["param2"] = 0, ["y"] = 1, ["param1"] = 173, ["z"] = 13, ["name"] = "farming:cotton_3" }, { ["x"] = 2, ["meta"] = { ["fields"] = {  }, ["inventory"] = {  } }, ["param2"] = 0, ["y"] = 1, ["param1"] = 173, ["z"] = 14, ["name"] = "farming:cotton_3" }, { ["x"] = 2, ["meta"] = { ["fields"] = {  }, ["inventory"] = {  } }, ["param2"] = 0, ["y"] = 1, ["param1"] = 189, ["z"] = 15, ["name"] = "default:fence_wood" }, { ["x"] = 2, ["meta"] = { ["fields"] = {  }, ["inventory"] = {  } }, ["param2"] = 1, ["y"] = 2, ["param1"] = 15, ["z"] = 0, ["name"] = "default:torch" }, { ["x"] = 2, ["meta"] = { ["fields"] = {  }, ["inventory"] = {  } }, ["param2"] = 1, ["y"] = 2, ["param1"] = 15, ["z"] = 4, ["name"] = "default:torch" }, { ["x"] = 2, ["meta"] = { ["fields"] = {  }, ["inventory"] = {  } }, ["param2"] = 1, ["y"] = 2, ["param1"] = 15, ["z"] = 9, ["name"] = "default:torch" }, { ["x"] = 3, ["meta"] = { ["fields"] = {  }, ["inventory"] = {  } }, ["param2"] = 0, ["y"] = 0, ["param1"] = 0, ["z"] = 0, ["name"] = "default:dirt_with_grass" }, { ["x"] = 3, ["meta"] = { ["fields"] = {  }, ["inventory"] = {  } }, ["param2"] = 0, ["y"] = 0, ["param1"] = 0, ["z"] = 1, ["name"] = "default:dirt_with_grass" }, { ["x"] = 3, ["meta"] = { ["fields"] = {  }, ["inventory"] = {  } }, ["param2"] = 0, ["y"] = 0, ["param1"] = 0, ["z"] = 2, ["name"] = "default:dirt_with_grass" }, { ["x"] = 3, ["meta"] = { ["fields"] = {  }, ["inventory"] = {  } }, ["param2"] = 0, ["y"] = 0, ["param1"] = 0, ["z"] = 3, ["name"] = "default:dirt_with_grass" }, { ["x"] = 3, ["meta"] = { ["fields"] = {  }, ["inventory"] = {  } }, ["param2"] = 0, ["y"] = 0, ["param1"] = 0, ["z"] = 4, ["name"] = "default:dirt" }, { ["x"] = 3, ["meta"] = { ["fields"] = {  }, ["inventory"] = {  } }, ["param2"] = 0, ["y"] = 0, ["param1"] = 0, ["z"] = 5, ["name"] = "default:dirt_with_grass" }, { ["x"] = 3, ["meta"] = { ["fields"] = {  }, ["inventory"] = {  } }, ["param2"] = 0, ["y"] = 0, ["param1"] = 0, ["z"] = 6, ["name"] = "default:dirt_with_grass" }, { ["x"] = 3, ["meta"] = { ["fields"] = {  }, ["inventory"] = {  } }, ["param2"] = 0, ["y"] = 0, ["param1"] = 0, ["z"] = 7, ["name"] = "default:cobble" }, { ["x"] = 3, ["meta"] = { ["fields"] = {  }, ["inventory"] = {  } }, ["param2"] = 0, ["y"] = 0, ["param1"] = 0, ["z"] = 8, ["name"] = "default:dirt" }, { ["x"] = 3, ["meta"] = { ["fields"] = {  }, ["inventory"] = {  } }, ["param2"] = 0, ["y"] = 0, ["param1"] = 0, ["z"] = 9, ["name"] = "default:dirt" }, { ["x"] = 3, ["meta"] = { ["fields"] = {  }, ["inventory"] = {  } }, ["param2"] = 0, ["y"] = 0, ["param1"] = 0, ["z"] = 10, ["name"] = "farming:soil_wet" }, { ["x"] = 3, ["meta"] = { ["fields"] = {  }, ["inventory"] = {  } }, ["param2"] = 0, ["y"] = 0, ["param1"] = 0, ["z"] = 11, ["name"] = "farming:soil_wet" }, { ["x"] = 3, ["meta"] = { ["fields"] = {  }, ["inventory"] = {  } }, ["param2"] = 0, ["y"] = 0, ["param1"] = 0, ["z"] = 12, ["name"] = "farming:soil_wet" }, { ["x"] = 3, ["meta"] = { ["fields"] = {  }, ["inventory"] = {  } }, ["param2"] = 0, ["y"] = 0, ["param1"] = 155, ["z"] = 13, ["name"] = "default:water_source" }, { ["x"] = 3, ["meta"] = { ["fields"] = {  }, ["inventory"] = {  } }, ["param2"] = 0, ["y"] = 0, ["param1"] = 0, ["z"] = 14, ["name"] = "farming:soil_wet" }, { ["x"] = 3, ["meta"] = { ["fields"] = {  }, ["inventory"] = {  } }, ["param2"] = 0, ["y"] = 0, ["param1"] = 0, ["z"] = 15, ["name"] = "default:dirt_with_grass" }, { ["x"] = 3, ["meta"] = { ["fields"] = {  }, ["inventory"] = {  } }, ["param2"] = 0, ["y"] = 1, ["param1"] = 189, ["z"] = 0, ["name"] = "default:fence_wood" }, { ["x"] = 3, ["meta"] = { ["fields"] = {  }, ["inventory"] = {  } }, ["param2"] = 2, ["y"] = 1, ["param1"] = 188, ["z"] = 4, ["name"] = "cottages:gate_closed" }, { ["x"] = 3, ["meta"] = { ["fields"] = {  }, ["inventory"] = {  } }, ["param2"] = 2, ["y"] = 1, ["param1"] = 204, ["z"] = 8, ["name"] = "cottages:wagon_wheel" }, { ["x"] = 3, ["meta"] = { ["fields"] = {  }, ["inventory"] = {  } }, ["param2"] = 0, ["y"] = 1, ["param1"] = 188, ["z"] = 9, ["name"] = "cottages:gate_closed" }, { ["x"] = 3, ["meta"] = { ["fields"] = {  }, ["inventory"] = {  } }, ["param2"] = 0, ["y"] = 1, ["param1"] = 188, ["z"] = 10, ["name"] = "farming:cotton_3" }, { ["x"] = 3, ["meta"] = { ["fields"] = {  }, ["inventory"] = {  } }, ["param2"] = 0, ["y"] = 1, ["param1"] = 204, ["z"] = 11, ["name"] = "farming:cotton_3" }, { ["x"] = 3, ["meta"] = { ["fields"] = {  }, ["inventory"] = {  } }, ["param2"] = 0, ["y"] = 1, ["param1"] = 188, ["z"] = 12, ["name"] = "farming:cotton_3" }, { ["x"] = 3, ["meta"] = { ["fields"] = {  }, ["inventory"] = {  } }, ["param2"] = 0, ["y"] = 1, ["param1"] = 172, ["z"] = 13, ["name"] = "default:fence_wood" }, { ["x"] = 3, ["meta"] = { ["fields"] = {  }, ["inventory"] = {  } }, ["param2"] = 0, ["y"] = 1, ["param1"] = 189, ["z"] = 14, ["name"] = "farming:cotton_3" }, { ["x"] = 3, ["meta"] = { ["fields"] = {  }, ["inventory"] = {  } }, ["param2"] = 0, ["y"] = 1, ["param1"] = 205, ["z"] = 15, ["name"] = "default:fence_wood" }, { ["x"] = 3, ["meta"] = { ["fields"] = {  }, ["inventory"] = {  } }, ["param2"] = 1, ["y"] = 2, ["param1"] = 205, ["z"] = 4, ["name"] = "cottages:window_shutter_open" }, { ["x"] = 3, ["meta"] = { ["fields"] = {  }, ["inventory"] = {  } }, ["param2"] = 2, ["y"] = 2, ["param1"] = 0, ["z"] = 5, ["name"] = "default:torch" }, { ["x"] = 3, ["meta"] = { ["fields"] = {  }, ["inventory"] = {  } }, ["param2"] = 2, ["y"] = 2, ["param1"] = 205, ["z"] = 6, ["name"] = "default:sign_wall" }, { ["x"] = 3, ["meta"] = { ["fields"] = {  }, ["inventory"] = {  } }, ["param2"] = 2, ["y"] = 2, ["param1"] = 0, ["z"] = 8, ["name"] = "default:torch" }, { ["x"] = 3, ["meta"] = { ["fields"] = {  }, ["inventory"] = {  } }, ["param2"] = 1, ["y"] = 2, ["param1"] = 205, ["z"] = 10, ["name"] = "cottages:window_shutter_open" }, { ["x"] = 3, ["meta"] = { ["fields"] = {  }, ["inventory"] = {  } }, ["param2"] = 2, ["y"] = 2, ["param1"] = 0, ["z"] = 11, ["name"] = "default:torch" }, { ["x"] = 3, ["meta"] = { ["fields"] = {  }, ["inventory"] = {  } }, ["param2"] = 0, ["y"] = 2, ["param1"] = 189, ["z"] = 13, ["name"] = "default:fence_wood" }, { ["x"] = 3, ["meta"] = { ["fields"] = {  }, ["inventory"] = {  } }, ["param2"] = 1, ["y"] = 2, ["param1"] = 15, ["z"] = 15, ["name"] = "default:torch" }, { ["x"] = 3, ["meta"] = { ["fields"] = {  }, ["inventory"] = {  } }, ["param2"] = 1, ["y"] = 3, ["param1"] = 173, ["z"] = 2, ["name"] = "cottages:roof_straw" }, { ["x"] = 3, ["meta"] = { ["fields"] = {  }, ["inventory"] = {  } }, ["param2"] = 1, ["y"] = 3, ["param1"] = 173, ["z"] = 3, ["name"] = "cottages:roof_straw" }, { ["x"] = 3, ["meta"] = { ["fields"] = {  }, ["inventory"] = {  } }, ["param2"] = 1, ["y"] = 3, ["param1"] = 189, ["z"] = 4, ["name"] = "cottages:roof_straw" }, { ["x"] = 3, ["meta"] = { ["fields"] = {  }, ["inventory"] = {  } }, ["param2"] = 1, ["y"] = 3, ["param1"] = 205, ["z"] = 5, ["name"] = "cottages:roof_straw" }, { ["x"] = 3, ["meta"] = { ["fields"] = {  }, ["inventory"] = {  } }, ["param2"] = 1, ["y"] = 3, ["param1"] = 189, ["z"] = 6, ["name"] = "cottages:roof_straw" }, { ["x"] = 3, ["meta"] = { ["fields"] = {  }, ["inventory"] = {  } }, ["param2"] = 1, ["y"] = 3, ["param1"] = 189, ["z"] = 7, ["name"] = "cottages:roof_straw" }, { ["x"] = 3, ["meta"] = { ["fields"] = {  }, ["inventory"] = {  } }, ["param2"] = 1, ["y"] = 3, ["param1"] = 205, ["z"] = 8, ["name"] = "cottages:roof_straw" }, { ["x"] = 3, ["meta"] = { ["fields"] = {  }, ["inventory"] = {  } }, ["param2"] = 1, ["y"] = 3, ["param1"] = 189, ["z"] = 9, ["name"] = "cottages:roof_straw" }, { ["x"] = 3, ["meta"] = { ["fields"] = {  }, ["inventory"] = {  } }, ["param2"] = 1, ["y"] = 3, ["param1"] = 189, ["z"] = 10, ["name"] = "cottages:roof_straw" }, { ["x"] = 3, ["meta"] = { ["fields"] = {  }, ["inventory"] = {  } }, ["param2"] = 1, ["y"] = 3, ["param1"] = 205, ["z"] = 11, ["name"] = "cottages:roof_straw" }, { ["x"] = 3, ["meta"] = { ["fields"] = {  }, ["inventory"] = {  } }, ["param2"] = 1, ["y"] = 3, ["param1"] = 189, ["z"] = 12, ["name"] = "cottages:roof_straw" }, { ["x"] = 3, ["meta"] = { ["fields"] = {  }, ["inventory"] = {  } }, ["param2"] = 1, ["y"] = 3, ["param1"] = 173, ["z"] = 13, ["name"] = "cottages:roof_straw" }, { ["x"] = 4, ["meta"] = { ["fields"] = {  }, ["inventory"] = {  } }, ["param2"] = 0, ["y"] = 0, ["param1"] = 0, ["z"] = 0, ["name"] = "cottages:straw_ground" }, { ["x"] = 4, ["meta"] = { ["fields"] = {  }, ["inventory"] = {  } }, ["param2"] = 0, ["y"] = 0, ["param1"] = 0, ["z"] = 1, ["name"] = "cottages:straw_ground" }, { ["x"] = 4, ["meta"] = { ["fields"] = {  }, ["inventory"] = {  } }, ["param2"] = 0, ["y"] = 0, ["param1"] = 0, ["z"] = 2, ["name"] = "cottages:straw_ground" }, { ["x"] = 4, ["meta"] = { ["fields"] = {  }, ["inventory"] = {  } }, ["param2"] = 0, ["y"] = 0, ["param1"] = 0, ["z"] = 3, ["name"] = "default:cobble" }, { ["x"] = 4, ["meta"] = { ["fields"] = {  }, ["inventory"] = {  } }, ["param2"] = 0, ["y"] = 0, ["param1"] = 0, ["z"] = 4, ["name"] = "default:cobble" }, { ["x"] = 4, ["meta"] = { ["fields"] = {  }, ["inventory"] = {  } }, ["param2"] = 0, ["y"] = 0, ["param1"] = 0, ["z"] = 5, ["name"] = "default:cobble" }, { ["x"] = 4, ["meta"] = { ["fields"] = {  }, ["inventory"] = {  } }, ["param2"] = 0, ["y"] = 0, ["param1"] = 0, ["z"] = 6, ["name"] = "default:cobble" }, { ["x"] = 4, ["meta"] = { ["fields"] = {  }, ["inventory"] = {  } }, ["param2"] = 0, ["y"] = 0, ["param1"] = 0, ["z"] = 7, ["name"] = "default:cobble" }, { ["x"] = 4, ["meta"] = { ["fields"] = {  }, ["inventory"] = {  } }, ["param2"] = 0, ["y"] = 0, ["param1"] = 0, ["z"] = 8, ["name"] = "default:cobble" }, { ["x"] = 4, ["meta"] = { ["fields"] = {  }, ["inventory"] = {  } }, ["param2"] = 0, ["y"] = 0, ["param1"] = 0, ["z"] = 9, ["name"] = "default:cobble" }, { ["x"] = 4, ["meta"] = { ["fields"] = {  }, ["inventory"] = {  } }, ["param2"] = 0, ["y"] = 0, ["param1"] = 0, ["z"] = 10, ["name"] = "default:cobble" }, { ["x"] = 4, ["meta"] = { ["fields"] = {  }, ["inventory"] = {  } }, ["param2"] = 0, ["y"] = 0, ["param1"] = 0, ["z"] = 11, ["name"] = "default:cobble" }, { ["x"] = 4, ["meta"] = { ["fields"] = {  }, ["inventory"] = {  } }, ["param2"] = 0, ["y"] = 0, ["param1"] = 0, ["z"] = 12, ["name"] = "default:cobble" }, { ["x"] = 4, ["meta"] = { ["fields"] = {  }, ["inventory"] = {  } }, ["param2"] = 0, ["y"] = 0, ["param1"] = 0, ["z"] = 13, ["name"] = "farming:soil_wet" }, { ["x"] = 4, ["meta"] = { ["fields"] = {  }, ["inventory"] = {  } }, ["param2"] = 0, ["y"] = 0, ["param1"] = 0, ["z"] = 14, ["name"] = "farming:soil_wet" }, { ["x"] = 4, ["meta"] = { ["fields"] = {  }, ["inventory"] = {  } }, ["param2"] = 0, ["y"] = 0, ["param1"] = 0, ["z"] = 15, ["name"] = "default:dirt_with_grass" }, { ["x"] = 4, ["meta"] = { ["fields"] = {  }, ["inventory"] = {  } }, ["param2"] = 0, ["y"] = 1, ["param1"] = 173, ["z"] = 0, ["name"] = "default:fence_wood" }, { ["x"] = 4, ["meta"] = { ["fields"] = {  }, ["inventory"] = {  } }, ["param2"] = 0, ["y"] = 1, ["param1"] = 0, ["z"] = 1, ["name"] = "default:wood" }, { ["x"] = 4, ["meta"] = { ["fields"] = {  }, ["inventory"] = {  } }, ["param2"] = 3, ["y"] = 1, ["param1"] = 188, ["z"] = 2, ["name"] = "cottages:half_door" }, { ["x"] = 4, ["meta"] = { ["fields"] = {  }, ["inventory"] = {  } }, ["param2"] = 0, ["y"] = 1, ["param1"] = 0, ["z"] = 3, ["name"] = "default:tree" }, { ["x"] = 4, ["meta"] = { ["fields"] = {  }, ["inventory"] = {  } }, ["param2"] = 0, ["y"] = 1, ["param1"] = 0, ["z"] = 4, ["name"] = "default:clay" }, { ["x"] = 4, ["meta"] = { ["fields"] = {  }, ["inventory"] = {  } }, ["param2"] = 0, ["y"] = 1, ["param1"] = 0, ["z"] = 5, ["name"] = "default:clay" }, { ["x"] = 4, ["meta"] = { ["fields"] = {  }, ["inventory"] = {  } }, ["param2"] = 0, ["y"] = 1, ["param1"] = 0, ["z"] = 6, ["name"] = "default:tree" }, { ["x"] = 4, ["meta"] = { ["fields"] = {  }, ["inventory"] = {  } }, ["param2"] = 1, ["y"] = 1, ["param1"] = 188, ["z"] = 7, ["name"] = "doors:door_wood_b_1" }, { ["x"] = 4, ["meta"] = { ["fields"] = {  }, ["inventory"] = {  } }, ["param2"] = 0, ["y"] = 1, ["param1"] = 0, ["z"] = 8, ["name"] = "default:clay" }, { ["x"] = 4, ["meta"] = { ["fields"] = {  }, ["inventory"] = {  } }, ["param2"] = 0, ["y"] = 1, ["param1"] = 0, ["z"] = 9, ["name"] = "default:tree" }, { ["x"] = 4, ["meta"] = { ["fields"] = {  }, ["inventory"] = {  } }, ["param2"] = 0, ["y"] = 1, ["param1"] = 0, ["z"] = 10, ["name"] = "default:clay" }, { ["x"] = 4, ["meta"] = { ["fields"] = {  }, ["inventory"] = {  } }, ["param2"] = 0, ["y"] = 1, ["param1"] = 0, ["z"] = 11, ["name"] = "default:clay" }, { ["x"] = 4, ["meta"] = { ["fields"] = {  }, ["inventory"] = {  } }, ["param2"] = 0, ["y"] = 1, ["param1"] = 0, ["z"] = 12, ["name"] = "default:tree" }, { ["x"] = 4, ["meta"] = { ["fields"] = {  }, ["inventory"] = {  } }, ["param2"] = 0, ["y"] = 1, ["param1"] = 188, ["z"] = 13, ["name"] = "farming:cotton_3" }, { ["x"] = 4, ["meta"] = { ["fields"] = {  }, ["inventory"] = {  } }, ["param2"] = 0, ["y"] = 1, ["param1"] = 173, ["z"] = 14, ["name"] = "farming:cotton_4" }, { ["x"] = 4, ["meta"] = { ["fields"] = {  }, ["inventory"] = {  } }, ["param2"] = 2, ["y"] = 1, ["param1"] = 189, ["z"] = 15, ["name"] = "cottages:gate_closed" }, { ["x"] = 4, ["meta"] = { ["fields"] = {  }, ["inventory"] = {  } }, ["param2"] = 0, ["y"] = 2, ["param1"] = 189, ["z"] = 0, ["name"] = "cottages:roof_straw" }, { ["x"] = 4, ["meta"] = { ["fields"] = {  }, ["inventory"] = {  } }, ["param2"] = 0, ["y"] = 2, ["param1"] = 0, ["z"] = 1, ["name"] = "default:wood" }, { ["x"] = 4, ["meta"] = { ["fields"] = {  }, ["inventory"] = {  } }, ["param2"] = 3, ["y"] = 2, ["param1"] = 204, ["z"] = 2, ["name"] = "cottages:half_door" }, { ["x"] = 4, ["meta"] = { ["fields"] = {  }, ["inventory"] = {  } }, ["param2"] = 0, ["y"] = 2, ["param1"] = 0, ["z"] = 3, ["name"] = "default:tree" }, { ["x"] = 4, ["meta"] = { ["fields"] = {  }, ["inventory"] = {  } }, ["param2"] = 1, ["y"] = 2, ["param1"] = 188, ["z"] = 4, ["name"] = "cottages:glass_pane" }, { ["x"] = 4, ["meta"] = { ["fields"] = {  }, ["inventory"] = {  } }, ["param2"] = 0, ["y"] = 2, ["param1"] = 0, ["z"] = 5, ["name"] = "default:clay" }, { ["x"] = 4, ["meta"] = { ["fields"] = {  }, ["inventory"] = {  } }, ["param2"] = 0, ["y"] = 2, ["param1"] = 0, ["z"] = 6, ["name"] = "default:tree" }, { ["x"] = 4, ["meta"] = { ["fields"] = {  }, ["inventory"] = {  } }, ["param2"] = 1, ["y"] = 2, ["param1"] = 204, ["z"] = 7, ["name"] = "doors:door_wood_t_1" }, { ["x"] = 4, ["meta"] = { ["fields"] = {  }, ["inventory"] = {  } }, ["param2"] = 0, ["y"] = 2, ["param1"] = 0, ["z"] = 8, ["name"] = "default:clay" }, { ["x"] = 4, ["meta"] = { ["fields"] = {  }, ["inventory"] = {  } }, ["param2"] = 0, ["y"] = 2, ["param1"] = 0, ["z"] = 9, ["name"] = "default:tree" }, { ["x"] = 4, ["meta"] = { ["fields"] = {  }, ["inventory"] = {  } }, ["param2"] = 1, ["y"] = 2, ["param1"] = 188, ["z"] = 10, ["name"] = "cottages:glass_pane" }, { ["x"] = 4, ["meta"] = { ["fields"] = {  }, ["inventory"] = {  } }, ["param2"] = 0, ["y"] = 2, ["param1"] = 0, ["z"] = 11, ["name"] = "default:clay" }, { ["x"] = 4, ["meta"] = { ["fields"] = {  }, ["inventory"] = {  } }, ["param2"] = 0, ["y"] = 2, ["param1"] = 0, ["z"] = 12, ["name"] = "default:tree" }, { ["x"] = 4, ["meta"] = { ["fields"] = {  }, ["inventory"] = {  } }, ["param2"] = 0, ["y"] = 3, ["param1"] = 173, ["z"] = 1, ["name"] = "cottages:roof_straw" }, { ["x"] = 4, ["meta"] = { ["fields"] = {  }, ["inventory"] = {  } }, ["param2"] = 0, ["y"] = 3, ["param1"] = 0, ["z"] = 3, ["name"] = "default:tree" }, { ["x"] = 4, ["meta"] = { ["fields"] = {  }, ["inventory"] = {  } }, ["param2"] = 0, ["y"] = 3, ["param1"] = 0, ["z"] = 4, ["name"] = "cottages:loam" }, { ["x"] = 4, ["meta"] = { ["fields"] = {  }, ["inventory"] = {  } }, ["param2"] = 0, ["y"] = 3, ["param1"] = 0, ["z"] = 5, ["name"] = "cottages:loam" }, { ["x"] = 4, ["meta"] = { ["fields"] = {  }, ["inventory"] = {  } }, ["param2"] = 0, ["y"] = 3, ["param1"] = 0, ["z"] = 6, ["name"] = "default:tree" }, { ["x"] = 4, ["meta"] = { ["fields"] = {  }, ["inventory"] = {  } }, ["param2"] = 0, ["y"] = 3, ["param1"] = 0, ["z"] = 7, ["name"] = "cottages:loam" }, { ["x"] = 4, ["meta"] = { ["fields"] = {  }, ["inventory"] = {  } }, ["param2"] = 0, ["y"] = 3, ["param1"] = 0, ["z"] = 8, ["name"] = "cottages:loam" }, { ["x"] = 4, ["meta"] = { ["fields"] = {  }, ["inventory"] = {  } }, ["param2"] = 0, ["y"] = 3, ["param1"] = 0, ["z"] = 9, ["name"] = "default:tree" }, { ["x"] = 4, ["meta"] = { ["fields"] = {  }, ["inventory"] = {  } }, ["param2"] = 0, ["y"] = 3, ["param1"] = 0, ["z"] = 10, ["name"] = "cottages:loam" }, { ["x"] = 4, ["meta"] = { ["fields"] = {  }, ["inventory"] = {  } }, ["param2"] = 0, ["y"] = 3, ["param1"] = 0, ["z"] = 11, ["name"] = "cottages:loam" }, { ["x"] = 4, ["meta"] = { ["fields"] = {  }, ["inventory"] = {  } }, ["param2"] = 0, ["y"] = 3, ["param1"] = 0, ["z"] = 12, ["name"] = "default:tree" }, { ["x"] = 4, ["meta"] = { ["fields"] = {  }, ["inventory"] = {  } }, ["param2"] = 1, ["y"] = 4, ["param1"] = 173, ["z"] = 2, ["name"] = "cottages:roof_straw" }, { ["x"] = 4, ["meta"] = { ["fields"] = {  }, ["inventory"] = {  } }, ["param2"] = 1, ["y"] = 4, ["param1"] = 157, ["z"] = 3, ["name"] = "cottages:roof_connector_straw" }, { ["x"] = 4, ["meta"] = { ["fields"] = {  }, ["inventory"] = {  } }, ["param2"] = 1, ["y"] = 4, ["param1"] = 157, ["z"] = 4, ["name"] = "cottages:roof_straw" }, { ["x"] = 4, ["meta"] = { ["fields"] = {  }, ["inventory"] = {  } }, ["param2"] = 1, ["y"] = 4, ["param1"] = 173, ["z"] = 5, ["name"] = "cottages:roof_straw" }, { ["x"] = 4, ["meta"] = { ["fields"] = {  }, ["inventory"] = {  } }, ["param2"] = 1, ["y"] = 4, ["param1"] = 157, ["z"] = 6, ["name"] = "cottages:roof_straw" }, { ["x"] = 4, ["meta"] = { ["fields"] = {  }, ["inventory"] = {  } }, ["param2"] = 1, ["y"] = 4, ["param1"] = 157, ["z"] = 7, ["name"] = "cottages:roof_straw" }, { ["x"] = 4, ["meta"] = { ["fields"] = {  }, ["inventory"] = {  } }, ["param2"] = 1, ["y"] = 4, ["param1"] = 173, ["z"] = 8, ["name"] = "cottages:roof_straw" }, { ["x"] = 4, ["meta"] = { ["fields"] = {  }, ["inventory"] = {  } }, ["param2"] = 1, ["y"] = 4, ["param1"] = 157, ["z"] = 9, ["name"] = "cottages:roof_straw" }, { ["x"] = 4, ["meta"] = { ["fields"] = {  }, ["inventory"] = {  } }, ["param2"] = 1, ["y"] = 4, ["param1"] = 157, ["z"] = 10, ["name"] = "cottages:roof_straw" }, { ["x"] = 4, ["meta"] = { ["fields"] = {  }, ["inventory"] = {  } }, ["param2"] = 1, ["y"] = 4, ["param1"] = 173, ["z"] = 11, ["name"] = "cottages:roof_straw" }, { ["x"] = 4, ["meta"] = { ["fields"] = {  }, ["inventory"] = {  } }, ["param2"] = 1, ["y"] = 4, ["param1"] = 157, ["z"] = 12, ["name"] = "cottages:roof_connector_straw" }, { ["x"] = 4, ["meta"] = { ["fields"] = {  }, ["inventory"] = {  } }, ["param2"] = 1, ["y"] = 4, ["param1"] = 173, ["z"] = 13, ["name"] = "cottages:roof_straw" }, { ["x"] = 5, ["meta"] = { ["fields"] = {  }, ["inventory"] = {  } }, ["param2"] = 0, ["y"] = 0, ["param1"] = 0, ["z"] = 0, ["name"] = "cottages:straw_ground" }, { ["x"] = 5, ["meta"] = { ["fields"] = {  }, ["inventory"] = {  } }, ["param2"] = 0, ["y"] = 0, ["param1"] = 0, ["z"] = 1, ["name"] = "cottages:straw_ground" }, { ["x"] = 5, ["meta"] = { ["fields"] = {  }, ["inventory"] = {  } }, ["param2"] = 0, ["y"] = 0, ["param1"] = 0, ["z"] = 2, ["name"] = "cottages:straw_ground" }, { ["x"] = 5, ["meta"] = { ["fields"] = {  }, ["inventory"] = {  } }, ["param2"] = 0, ["y"] = 0, ["param1"] = 0, ["z"] = 3, ["name"] = "default:cobble" }, { ["x"] = 5, ["meta"] = { ["fields"] = {  }, ["inventory"] = {  } }, ["param2"] = 0, ["y"] = 0, ["param1"] = 0, ["z"] = 4, ["name"] = "default:sandstone" }, { ["x"] = 5, ["meta"] = { ["fields"] = {  }, ["inventory"] = {  } }, ["param2"] = 0, ["y"] = 0, ["param1"] = 0, ["z"] = 5, ["name"] = "default:sandstone" }, { ["x"] = 5, ["meta"] = { ["fields"] = {  }, ["inventory"] = {  } }, ["param2"] = 0, ["y"] = 0, ["param1"] = 0, ["z"] = 6, ["name"] = "default:sandstone" }, { ["x"] = 5, ["meta"] = { ["fields"] = {  }, ["inventory"] = {  } }, ["param2"] = 0, ["y"] = 0, ["param1"] = 0, ["z"] = 7, ["name"] = "default:sandstone" }, { ["x"] = 5, ["meta"] = { ["fields"] = {  }, ["inventory"] = {  } }, ["param2"] = 0, ["y"] = 0, ["param1"] = 0, ["z"] = 8, ["name"] = "default:sandstone" }, { ["x"] = 5, ["meta"] = { ["fields"] = {  }, ["inventory"] = {  } }, ["param2"] = 0, ["y"] = 0, ["param1"] = 0, ["z"] = 9, ["name"] = "default:sandstone" }, { ["x"] = 5, ["meta"] = { ["fields"] = {  }, ["inventory"] = {  } }, ["param2"] = 0, ["y"] = 0, ["param1"] = 0, ["z"] = 10, ["name"] = "default:sandstone" }, { ["x"] = 5, ["meta"] = { ["fields"] = {  }, ["inventory"] = {  } }, ["param2"] = 0, ["y"] = 0, ["param1"] = 0, ["z"] = 11, ["name"] = "default:sandstone" }, { ["x"] = 5, ["meta"] = { ["fields"] = {  }, ["inventory"] = {  } }, ["param2"] = 0, ["y"] = 0, ["param1"] = 0, ["z"] = 12, ["name"] = "default:cobble" }, { ["x"] = 5, ["meta"] = { ["fields"] = {  }, ["inventory"] = {  } }, ["param2"] = 0, ["y"] = 0, ["param1"] = 0, ["z"] = 13, ["name"] = "farming:soil_wet" }, { ["x"] = 5, ["meta"] = { ["fields"] = {  }, ["inventory"] = {  } }, ["param2"] = 0, ["y"] = 0, ["param1"] = 0, ["z"] = 14, ["name"] = "farming:soil_wet" }, { ["x"] = 5, ["meta"] = { ["fields"] = {  }, ["inventory"] = {  } }, ["param2"] = 0, ["y"] = 0, ["param1"] = 0, ["z"] = 15, ["name"] = "default:dirt_with_grass" }, { ["x"] = 5, ["meta"] = { ["fields"] = {  }, ["inventory"] = {  } }, ["param2"] = 0, ["y"] = 1, ["param1"] = 0, ["z"] = 0, ["name"] = "default:wood" }, { ["x"] = 5, ["meta"] = { ["fields"] = {  }, ["inventory"] = {  } }, ["param2"] = 0, ["y"] = 1, ["param1"] = 0, ["z"] = 3, ["name"] = "default:clay" }, { ["x"] = 5, ["meta"] = { ["fields"] = {  }, ["inventory"] = {  } }, ["param2"] = 2, ["y"] = 1, ["param1"] = 170, ["z"] = 4, ["name"] = "cottages:bench" }, { ["x"] = 5, ["meta"] = { ["fields"] = {  }, ["inventory"] = {  } }, ["param2"] = 2, ["y"] = 1, ["param1"] = 170, ["z"] = 5, ["name"] = "doors:door_wood_b_1" }, { ["x"] = 5, ["meta"] = { ["fields"] = {  }, ["inventory"] = {  } }, ["param2"] = 0, ["y"] = 1, ["param1"] = 0, ["z"] = 8, ["name"] = "default:wood" }, { ["x"] = 5, ["meta"] = { ["fields"] = {  }, ["inventory"] = {  } }, ["param2"] = 3, ["y"] = 1, ["param1"] = 170, ["z"] = 9, ["name"] = "cottages:table" }, { ["x"] = 5, ["meta"] = { ["fields"] = {  }, ["inventory"] = {  } }, ["param2"] = 3, ["y"] = 1, ["param1"] = 187, ["z"] = 10, ["name"] = "cottages:bench" }, { ["x"] = 5, ["meta"] = { ["fields"] = {  }, ["inventory"] = {  } }, ["param2"] = 3, ["y"] = 1, ["param1"] = 204, ["z"] = 11, ["name"] = "cottages:bench" }, { ["x"] = 5, ["meta"] = { ["fields"] = {  }, ["inventory"] = {  } }, ["param2"] = 0, ["y"] = 1, ["param1"] = 0, ["z"] = 12, ["name"] = "default:clay" }, { ["x"] = 5, ["meta"] = { ["fields"] = {  }, ["inventory"] = {  } }, ["param2"] = 0, ["y"] = 1, ["param1"] = 204, ["z"] = 13, ["name"] = "farming:cotton_1" }, { ["x"] = 5, ["meta"] = { ["fields"] = {  }, ["inventory"] = {  } }, ["param2"] = 0, ["y"] = 1, ["param1"] = 189, ["z"] = 14, ["name"] = "farming:cotton_4" }, { ["x"] = 5, ["meta"] = { ["fields"] = {  }, ["inventory"] = {  } }, ["param2"] = 0, ["y"] = 1, ["param1"] = 205, ["z"] = 15, ["name"] = "default:fence_wood" }, { ["x"] = 5, ["meta"] = { ["fields"] = {  }, ["inventory"] = {  } }, ["param2"] = 0, ["y"] = 2, ["param1"] = 189, ["z"] = 0, ["name"] = "cottages:roof_straw" }, { ["x"] = 5, ["meta"] = { ["fields"] = {  }, ["inventory"] = {  } }, ["param2"] = 4, ["y"] = 2, ["param1"] = 0, ["z"] = 2, ["name"] = "default:torch" }, { ["x"] = 5, ["meta"] = { ["fields"] = {  }, ["inventory"] = {  } }, ["param2"] = 0, ["y"] = 2, ["param1"] = 0, ["z"] = 3, ["name"] = "default:clay" }, { ["x"] = 5, ["meta"] = { ["fields"] = {  }, ["inventory"] = {  } }, ["param2"] = 2, ["y"] = 2, ["param1"] = 187, ["z"] = 5, ["name"] = "doors:door_wood_t_1" }, { ["x"] = 5, ["meta"] = { ["fields"] = {  }, ["inventory"] = {  } }, ["param2"] = 4, ["y"] = 2, ["param1"] = 0, ["z"] = 7, ["name"] = "default:torch" }, { ["x"] = 5, ["meta"] = { ["fields"] = {  }, ["inventory"] = {  } }, ["param2"] = 0, ["y"] = 2, ["param1"] = 0, ["z"] = 8, ["name"] = "default:wood" }, { ["x"] = 5, ["meta"] = { ["fields"] = {  }, ["inventory"] = {  } }, ["param2"] = 4, ["y"] = 2, ["param1"] = 0, ["z"] = 11, ["name"] = "default:torch" }, { ["x"] = 5, ["meta"] = { ["fields"] = {  }, ["inventory"] = {  } }, ["param2"] = 0, ["y"] = 2, ["param1"] = 0, ["z"] = 12, ["name"] = "default:clay" }, { ["x"] = 5, ["meta"] = { ["fields"] = {  }, ["inventory"] = {  } }, ["param2"] = 5, ["y"] = 2, ["param1"] = 0, ["z"] = 13, ["name"] = "default:torch" }, { ["x"] = 5, ["meta"] = { ["fields"] = {  }, ["inventory"] = {  } }, ["param2"] = 1, ["y"] = 2, ["param1"] = 15, ["z"] = 15, ["name"] = "default:torch" }, { ["x"] = 5, ["meta"] = { ["fields"] = {  }, ["inventory"] = {  } }, ["param2"] = 0, ["y"] = 3, ["param1"] = 189, ["z"] = 1, ["name"] = "cottages:roof_straw" }, { ["x"] = 5, ["meta"] = { ["fields"] = {  }, ["inventory"] = {  } }, ["param2"] = 0, ["y"] = 3, ["param1"] = 0, ["z"] = 3, ["name"] = "cottages:loam" }, { ["x"] = 5, ["meta"] = { ["fields"] = {  }, ["inventory"] = {  } }, ["param2"] = 0, ["y"] = 3, ["param1"] = 0, ["z"] = 4, ["name"] = "default:wood" }, { ["x"] = 5, ["meta"] = { ["fields"] = {  }, ["inventory"] = {  } }, ["param2"] = 0, ["y"] = 3, ["param1"] = 0, ["z"] = 5, ["name"] = "default:wood" }, { ["x"] = 5, ["meta"] = { ["fields"] = {  }, ["inventory"] = {  } }, ["param2"] = 0, ["y"] = 3, ["param1"] = 0, ["z"] = 7, ["name"] = "default:wood" }, { ["x"] = 5, ["meta"] = { ["fields"] = {  }, ["inventory"] = {  } }, ["param2"] = 0, ["y"] = 3, ["param1"] = 0, ["z"] = 8, ["name"] = "default:wood" }, { ["x"] = 5, ["meta"] = { ["fields"] = {  }, ["inventory"] = {  } }, ["param2"] = 0, ["y"] = 3, ["param1"] = 0, ["z"] = 9, ["name"] = "default:wood" }, { ["x"] = 5, ["meta"] = { ["fields"] = {  }, ["inventory"] = {  } }, ["param2"] = 0, ["y"] = 3, ["param1"] = 0, ["z"] = 10, ["name"] = "default:wood" }, { ["x"] = 5, ["meta"] = { ["fields"] = {  }, ["inventory"] = {  } }, ["param2"] = 0, ["y"] = 3, ["param1"] = 0, ["z"] = 11, ["name"] = "default:wood" }, { ["x"] = 5, ["meta"] = { ["fields"] = {  }, ["inventory"] = {  } }, ["param2"] = 0, ["y"] = 3, ["param1"] = 0, ["z"] = 12, ["name"] = "cottages:loam" }, { ["x"] = 5, ["meta"] = { ["fields"] = {  }, ["inventory"] = {  } }, ["param2"] = 0, ["y"] = 4, ["param1"] = 189, ["z"] = 2, ["name"] = "cottages:roof_straw" }, { ["x"] = 5, ["meta"] = { ["fields"] = {  }, ["inventory"] = {  } }, ["param2"] = 0, ["y"] = 4, ["param1"] = 0, ["z"] = 3, ["name"] = "cottages:loam" }, { ["x"] = 5, ["meta"] = { ["fields"] = {  }, ["inventory"] = {  } }, ["param2"] = 0, ["y"] = 4, ["param1"] = 172, ["z"] = 4, ["name"] = "cottages:bed_foot" }, { ["x"] = 5, ["meta"] = { ["fields"] = {  }, ["inventory"] = {  } }, ["param2"] = 0, ["y"] = 4, ["param1"] = 188, ["z"] = 5, ["name"] = "cottages:bed_head" }, { ["x"] = 5, ["meta"] = { ["fields"] = {  }, ["inventory"] = {  } }, ["param2"] = 0, ["y"] = 4, ["param1"] = 172, ["z"] = 6, ["name"] = "stairs:slab_wood" }, { ["x"] = 5, ["meta"] = { ["fields"] = {  }, ["inventory"] = {  } }, ["param2"] = 0, ["y"] = 4, ["param1"] = 0, ["z"] = 7, ["name"] = "default:wood" }, { ["x"] = 5, ["meta"] = { ["fields"] = {  }, ["inventory"] = {  } }, ["param2"] = 3, ["y"] = 4, ["param1"] = 172, ["z"] = 8, ["name"] = "cottages:bench" }, { ["x"] = 5, ["meta"] = { ["fields"] = {  }, ["inventory"] = {  } }, ["param2"] = 3, ["y"] = 4, ["param1"] = 156, ["z"] = 9, ["name"] = "cottages:bed_head" }, { ["x"] = 5, ["meta"] = { ["fields"] = {  }, ["inventory"] = {  } }, ["param2"] = 3, ["y"] = 4, ["param1"] = 172, ["z"] = 10, ["name"] = "cottages:bed_head" }, { ["x"] = 5, ["meta"] = { ["fields"] = {  }, ["inventory"] = {  } }, ["param2"] = 3, ["y"] = 4, ["param1"] = 188, ["z"] = 11, ["name"] = "cottages:bench" }, { ["x"] = 5, ["meta"] = { ["fields"] = {  }, ["inventory"] = {  } }, ["param2"] = 0, ["y"] = 4, ["param1"] = 0, ["z"] = 12, ["name"] = "cottages:loam" }, { ["x"] = 5, ["meta"] = { ["fields"] = {  }, ["inventory"] = {  } }, ["param2"] = 1, ["y"] = 5, ["param1"] = 173, ["z"] = 2, ["name"] = "cottages:roof_straw" }, { ["x"] = 5, ["meta"] = { ["fields"] = {  }, ["inventory"] = {  } }, ["param2"] = 1, ["y"] = 5, ["param1"] = 173, ["z"] = 3, ["name"] = "cottages:roof_connector_straw" }, { ["x"] = 5, ["meta"] = { ["fields"] = {  }, ["inventory"] = {  } }, ["param2"] = 1, ["y"] = 5, ["param1"] = 189, ["z"] = 4, ["name"] = "cottages:roof_straw" }, { ["x"] = 5, ["meta"] = { ["fields"] = {  }, ["inventory"] = {  } }, ["param2"] = 1, ["y"] = 5, ["param1"] = 205, ["z"] = 5, ["name"] = "cottages:roof_straw" }, { ["x"] = 5, ["meta"] = { ["fields"] = {  }, ["inventory"] = {  } }, ["param2"] = 1, ["y"] = 5, ["param1"] = 189, ["z"] = 6, ["name"] = "cottages:roof_straw" }, { ["x"] = 5, ["meta"] = { ["fields"] = {  }, ["inventory"] = {  } }, ["param2"] = 1, ["y"] = 5, ["param1"] = 173, ["z"] = 7, ["name"] = "cottages:roof_straw" }, { ["x"] = 5, ["meta"] = { ["fields"] = {  }, ["inventory"] = {  } }, ["param2"] = 1, ["y"] = 5, ["param1"] = 189, ["z"] = 8, ["name"] = "cottages:roof_straw" }, { ["x"] = 5, ["meta"] = { ["fields"] = {  }, ["inventory"] = {  } }, ["param2"] = 1, ["y"] = 5, ["param1"] = 173, ["z"] = 9, ["name"] = "cottages:roof_straw" }, { ["x"] = 5, ["meta"] = { ["fields"] = {  }, ["inventory"] = {  } }, ["param2"] = 1, ["y"] = 5, ["param1"] = 189, ["z"] = 10, ["name"] = "cottages:roof_straw" }, { ["x"] = 5, ["meta"] = { ["fields"] = {  }, ["inventory"] = {  } }, ["param2"] = 1, ["y"] = 5, ["param1"] = 205, ["z"] = 11, ["name"] = "cottages:roof_straw" }, { ["x"] = 5, ["meta"] = { ["fields"] = {  }, ["inventory"] = {  } }, ["param2"] = 1, ["y"] = 5, ["param1"] = 189, ["z"] = 12, ["name"] = "cottages:roof_connector_straw" }, { ["x"] = 5, ["meta"] = { ["fields"] = {  }, ["inventory"] = {  } }, ["param2"] = 1, ["y"] = 5, ["param1"] = 173, ["z"] = 13, ["name"] = "cottages:roof_straw" }, { ["x"] = 6, ["meta"] = { ["fields"] = {  }, ["inventory"] = {  } }, ["param2"] = 0, ["y"] = 0, ["param1"] = 0, ["z"] = 0, ["name"] = "cottages:straw_ground" }, { ["x"] = 6, ["meta"] = { ["fields"] = {  }, ["inventory"] = {  } }, ["param2"] = 0, ["y"] = 0, ["param1"] = 0, ["z"] = 1, ["name"] = "cottages:straw_ground" }, { ["x"] = 6, ["meta"] = { ["fields"] = {  }, ["inventory"] = {  } }, ["param2"] = 0, ["y"] = 0, ["param1"] = 0, ["z"] = 2, ["name"] = "cottages:straw_ground" }, { ["x"] = 6, ["meta"] = { ["fields"] = {  }, ["inventory"] = {  } }, ["param2"] = 0, ["y"] = 0, ["param1"] = 0, ["z"] = 3, ["name"] = "default:cobble" }, { ["x"] = 6, ["meta"] = { ["fields"] = {  }, ["inventory"] = {  } }, ["param2"] = 0, ["y"] = 0, ["param1"] = 0, ["z"] = 4, ["name"] = "default:sandstone" }, { ["x"] = 6, ["meta"] = { ["fields"] = {  }, ["inventory"] = {  } }, ["param2"] = 0, ["y"] = 0, ["param1"] = 0, ["z"] = 5, ["name"] = "default:sandstone" }, { ["x"] = 6, ["meta"] = { ["fields"] = {  }, ["inventory"] = {  } }, ["param2"] = 0, ["y"] = 0, ["param1"] = 0, ["z"] = 6, ["name"] = "default:sandstone" }, { ["x"] = 6, ["meta"] = { ["fields"] = {  }, ["inventory"] = {  } }, ["param2"] = 0, ["y"] = 0, ["param1"] = 0, ["z"] = 7, ["name"] = "default:sandstone" }, { ["x"] = 6, ["meta"] = { ["fields"] = {  }, ["inventory"] = {  } }, ["param2"] = 0, ["y"] = 0, ["param1"] = 0, ["z"] = 8, ["name"] = "default:sandstone" }, { ["x"] = 6, ["meta"] = { ["fields"] = {  }, ["inventory"] = {  } }, ["param2"] = 0, ["y"] = 0, ["param1"] = 0, ["z"] = 9, ["name"] = "default:sandstone" }, { ["x"] = 6, ["meta"] = { ["fields"] = {  }, ["inventory"] = {  } }, ["param2"] = 0, ["y"] = 0, ["param1"] = 0, ["z"] = 10, ["name"] = "default:sandstone" }, { ["x"] = 6, ["meta"] = { ["fields"] = {  }, ["inventory"] = {  } }, ["param2"] = 0, ["y"] = 0, ["param1"] = 0, ["z"] = 11, ["name"] = "default:sandstone" }, { ["x"] = 6, ["meta"] = { ["fields"] = {  }, ["inventory"] = {  } }, ["param2"] = 0, ["y"] = 0, ["param1"] = 0, ["z"] = 12, ["name"] = "default:cobble" }, { ["x"] = 6, ["meta"] = { ["fields"] = {  }, ["inventory"] = {  } }, ["param2"] = 0, ["y"] = 0, ["param1"] = 0, ["z"] = 13, ["name"] = "farming:soil_wet" }, { ["x"] = 6, ["meta"] = { ["fields"] = {  }, ["inventory"] = {  } }, ["param2"] = 0, ["y"] = 0, ["param1"] = 0, ["z"] = 14, ["name"] = "farming:soil_wet" }, { ["x"] = 6, ["meta"] = { ["fields"] = {  }, ["inventory"] = {  } }, ["param2"] = 0, ["y"] = 0, ["param1"] = 0, ["z"] = 15, ["name"] = "default:dirt_with_grass" }, { ["x"] = 6, ["meta"] = { ["fields"] = {  }, ["inventory"] = {  } }, ["param2"] = 0, ["y"] = 1, ["param1"] = 0, ["z"] = 0, ["name"] = "default:wood" }, { ["x"] = 6, ["meta"] = { ["fields"] = {  }, ["inventory"] = {  } }, ["param2"] = 0, ["y"] = 1, ["param1"] = 0, ["z"] = 3, ["name"] = "default:clay" }, { ["x"] = 6, ["meta"] = { ["fields"] = {  }, ["inventory"] = {  } }, ["param2"] = 1, ["y"] = 1, ["param1"] = 187, ["z"] = 4, ["name"] = "cottages:bed_foot" }, { ["x"] = 6, ["meta"] = { ["fields"] = {  }, ["inventory"] = {  } }, ["param2"] = 0, ["y"] = 1, ["param1"] = 0, ["z"] = 5, ["name"] = "default:wood" }, { ["x"] = 6, ["meta"] = { ["fields"] = {  }, ["inventory"] = {  } }, ["param2"] = 1, ["y"] = 1, ["param1"] = 204, ["z"] = 6, ["name"] = "stairs:stair_wood" }, { ["x"] = 6, ["meta"] = { ["fields"] = {  }, ["inventory"] = {  } }, ["param2"] = 0, ["y"] = 1, ["param1"] = 170, ["z"] = 8, ["name"] = "doors:door_wood_b_1" }, { ["x"] = 6, ["meta"] = { ["fields"] = { ["src_totaltime"] = "0", ["formspec"] = "size[8,9]image[2,2;1,1;default_furnace_fire_bg.png]list[current_name;fuel;2,3;1,1;]list[current_name;src;2,1;1,1;]list[current_name;dst;5,1;2,2;]list[current_player;main;0,5;8,4;]", ["fuel_time"] = "0", ["fuel_totaltime"] = "0", ["src_time"] = "0", ["infotext"] = "Furnace out of fuel" }, ["inventory"] = {  } }, ["param2"] = 0, ["y"] = 1, ["param1"] = 0, ["z"] = 11, ["name"] = "default:furnace" }, { ["x"] = 6, ["meta"] = { ["fields"] = {  }, ["inventory"] = {  } }, ["param2"] = 0, ["y"] = 1, ["param1"] = 0, ["z"] = 12, ["name"] = "default:clay" }, { ["x"] = 6, ["meta"] = { ["fields"] = {  }, ["inventory"] = {  } }, ["param2"] = 0, ["y"] = 1, ["param1"] = 188, ["z"] = 13, ["name"] = "farming:cotton_3" }, { ["x"] = 6, ["meta"] = { ["fields"] = {  }, ["inventory"] = {  } }, ["param2"] = 0, ["y"] = 1, ["param1"] = 173, ["z"] = 14, ["name"] = "farming:cotton_2" }, { ["x"] = 6, ["meta"] = { ["fields"] = {  }, ["inventory"] = {  } }, ["param2"] = 0, ["y"] = 1, ["param1"] = 189, ["z"] = 15, ["name"] = "default:fence_wood" }, { ["x"] = 6, ["meta"] = { ["fields"] = {  }, ["inventory"] = {  } }, ["param2"] = 0, ["y"] = 2, ["param1"] = 173, ["z"] = 0, ["name"] = "cottages:roof_straw" }, { ["x"] = 6, ["meta"] = { ["fields"] = {  }, ["inventory"] = {  } }, ["param2"] = 0, ["y"] = 2, ["param1"] = 0, ["z"] = 3, ["name"] = "default:clay" }, { ["x"] = 6, ["meta"] = { ["fields"] = {  }, ["inventory"] = {  } }, ["param2"] = 0, ["y"] = 2, ["param1"] = 0, ["z"] = 5, ["name"] = "default:wood" }, { ["x"] = 6, ["meta"] = { ["fields"] = {  }, ["inventory"] = {  } }, ["param2"] = 5, ["y"] = 2, ["param1"] = 0, ["z"] = 6, ["name"] = "default:torch" }, { ["x"] = 6, ["meta"] = { ["fields"] = {  }, ["inventory"] = {  } }, ["param2"] = 0, ["y"] = 2, ["param1"] = 187, ["z"] = 8, ["name"] = "doors:door_wood_t_1" }, { ["x"] = 6, ["meta"] = { ["fields"] = {  }, ["inventory"] = {  } }, ["param2"] = 2, ["y"] = 2, ["param1"] = 188, ["z"] = 12, ["name"] = "cottages:glass_pane" }, { ["x"] = 6, ["meta"] = { ["fields"] = {  }, ["inventory"] = {  } }, ["param2"] = 2, ["y"] = 2, ["param1"] = 205, ["z"] = 13, ["name"] = "cottages:window_shutter_open" }, { ["x"] = 6, ["meta"] = { ["fields"] = {  }, ["inventory"] = {  } }, ["param2"] = 0, ["y"] = 3, ["param1"] = 173, ["z"] = 1, ["name"] = "cottages:roof_straw" }, { ["x"] = 6, ["meta"] = { ["fields"] = {  }, ["inventory"] = {  } }, ["param2"] = 0, ["y"] = 3, ["param1"] = 0, ["z"] = 3, ["name"] = "cottages:loam" }, { ["x"] = 6, ["meta"] = { ["fields"] = {  }, ["inventory"] = {  } }, ["param2"] = 0, ["y"] = 3, ["param1"] = 0, ["z"] = 4, ["name"] = "default:wood" }, { ["x"] = 6, ["meta"] = { ["fields"] = {  }, ["inventory"] = {  } }, ["param2"] = 0, ["y"] = 3, ["param1"] = 0, ["z"] = 5, ["name"] = "default:wood" }, { ["x"] = 6, ["meta"] = { ["fields"] = {  }, ["inventory"] = {  } }, ["param2"] = 0, ["y"] = 3, ["param1"] = 0, ["z"] = 7, ["name"] = "default:wood" }, { ["x"] = 6, ["meta"] = { ["fields"] = {  }, ["inventory"] = {  } }, ["param2"] = 0, ["y"] = 3, ["param1"] = 0, ["z"] = 8, ["name"] = "default:wood" }, { ["x"] = 6, ["meta"] = { ["fields"] = {  }, ["inventory"] = {  } }, ["param2"] = 0, ["y"] = 3, ["param1"] = 0, ["z"] = 9, ["name"] = "default:wood" }, { ["x"] = 6, ["meta"] = { ["fields"] = {  }, ["inventory"] = {  } }, ["param2"] = 0, ["y"] = 3, ["param1"] = 0, ["z"] = 10, ["name"] = "default:wood" }, { ["x"] = 6, ["meta"] = { ["fields"] = {  }, ["inventory"] = {  } }, ["param2"] = 0, ["y"] = 3, ["param1"] = 0, ["z"] = 11, ["name"] = "default:wood" }, { ["x"] = 6, ["meta"] = { ["fields"] = {  }, ["inventory"] = {  } }, ["param2"] = 0, ["y"] = 3, ["param1"] = 0, ["z"] = 12, ["name"] = "cottages:loam" }, { ["x"] = 6, ["meta"] = { ["fields"] = {  }, ["inventory"] = {  } }, ["param2"] = 0, ["y"] = 4, ["param1"] = 173, ["z"] = 2, ["name"] = "cottages:roof_straw" }, { ["x"] = 6, ["meta"] = { ["fields"] = {  }, ["inventory"] = {  } }, ["param2"] = 0, ["y"] = 4, ["param1"] = 0, ["z"] = 3, ["name"] = "cottages:loam" }, { ["x"] = 6, ["meta"] = { ["fields"] = {  }, ["inventory"] = {  } }, ["param2"] = 0, ["y"] = 4, ["param1"] = 0, ["z"] = 5, ["name"] = "cottages:chest_private" }, { ["x"] = 6, ["meta"] = { ["fields"] = {  }, ["inventory"] = {  } }, ["param2"] = 0, ["y"] = 4, ["param1"] = 0, ["z"] = 7, ["name"] = "default:wood" }, { ["x"] = 6, ["meta"] = { ["fields"] = {  }, ["inventory"] = {  } }, ["param2"] = 3, ["y"] = 4, ["param1"] = 171, ["z"] = 9, ["name"] = "cottages:bed_foot" }, { ["x"] = 6, ["meta"] = { ["fields"] = {  }, ["inventory"] = {  } }, ["param2"] = 3, ["y"] = 4, ["param1"] = 187, ["z"] = 10, ["name"] = "cottages:bed_foot" }, { ["x"] = 6, ["meta"] = { ["fields"] = {  }, ["inventory"] = {  } }, ["param2"] = 0, ["y"] = 4, ["param1"] = 0, ["z"] = 12, ["name"] = "cottages:loam" }, { ["x"] = 6, ["meta"] = { ["fields"] = {  }, ["inventory"] = {  } }, ["param2"] = 0, ["y"] = 5, ["param1"] = 173, ["z"] = 2, ["name"] = "cottages:window_shutter_open" }, { ["x"] = 6, ["meta"] = { ["fields"] = {  }, ["inventory"] = {  } }, ["param2"] = 2, ["y"] = 5, ["param1"] = 188, ["z"] = 3, ["name"] = "cottages:glass_pane" }, { ["x"] = 6, ["meta"] = { ["fields"] = {  }, ["inventory"] = {  } }, ["param2"] = 4, ["y"] = 5, ["param1"] = 0, ["z"] = 5, ["name"] = "default:torch" }, { ["x"] = 6, ["meta"] = { ["fields"] = {  }, ["inventory"] = {  } }, ["param2"] = 0, ["y"] = 5, ["param1"] = 0, ["z"] = 6, ["name"] = "default:wood" }, { ["x"] = 6, ["meta"] = { ["fields"] = {  }, ["inventory"] = {  } }, ["param2"] = 0, ["y"] = 5, ["param1"] = 0, ["z"] = 7, ["name"] = "default:wood" }, { ["x"] = 6, ["meta"] = { ["fields"] = {  }, ["inventory"] = {  } }, ["param2"] = 4, ["y"] = 5, ["param1"] = 0, ["z"] = 11, ["name"] = "default:torch" }, { ["x"] = 6, ["meta"] = { ["fields"] = {  }, ["inventory"] = {  } }, ["param2"] = 0, ["y"] = 5, ["param1"] = 0, ["z"] = 12, ["name"] = "cottages:loam" }, { ["x"] = 6, ["meta"] = { ["fields"] = {  }, ["inventory"] = {  } }, ["param2"] = 1, ["y"] = 6, ["param1"] = 157, ["z"] = 2, ["name"] = "cottages:roof_straw" }, { ["x"] = 6, ["meta"] = { ["fields"] = {  }, ["inventory"] = {  } }, ["param2"] = 1, ["y"] = 6, ["param1"] = 173, ["z"] = 3, ["name"] = "cottages:roof_connector_straw" }, { ["x"] = 6, ["meta"] = { ["fields"] = {  }, ["inventory"] = {  } }, ["param2"] = 1, ["y"] = 6, ["param1"] = 189, ["z"] = 4, ["name"] = "cottages:roof_straw" }, { ["x"] = 6, ["meta"] = { ["fields"] = {  }, ["inventory"] = {  } }, ["param2"] = 1, ["y"] = 6, ["param1"] = 205, ["z"] = 5, ["name"] = "cottages:roof_straw" }, { ["x"] = 6, ["meta"] = { ["fields"] = {  }, ["inventory"] = {  } }, ["param2"] = 1, ["y"] = 6, ["param1"] = 189, ["z"] = 6, ["name"] = "cottages:roof_straw" }, { ["x"] = 6, ["meta"] = { ["fields"] = {  }, ["inventory"] = {  } }, ["param2"] = 1, ["y"] = 6, ["param1"] = 173, ["z"] = 7, ["name"] = "cottages:roof_straw" }, { ["x"] = 6, ["meta"] = { ["fields"] = {  }, ["inventory"] = {  } }, ["param2"] = 1, ["y"] = 6, ["param1"] = 189, ["z"] = 8, ["name"] = "cottages:roof_straw" }, { ["x"] = 6, ["meta"] = { ["fields"] = {  }, ["inventory"] = {  } }, ["param2"] = 1, ["y"] = 6, ["param1"] = 173, ["z"] = 9, ["name"] = "cottages:roof_straw" }, { ["x"] = 6, ["meta"] = { ["fields"] = {  }, ["inventory"] = {  } }, ["param2"] = 1, ["y"] = 6, ["param1"] = 189, ["z"] = 10, ["name"] = "cottages:roof_straw" }, { ["x"] = 6, ["meta"] = { ["fields"] = {  }, ["inventory"] = {  } }, ["param2"] = 1, ["y"] = 6, ["param1"] = 205, ["z"] = 11, ["name"] = "cottages:roof_straw" }, { ["x"] = 6, ["meta"] = { ["fields"] = {  }, ["inventory"] = {  } }, ["param2"] = 1, ["y"] = 6, ["param1"] = 189, ["z"] = 12, ["name"] = "cottages:roof_connector_straw" }, { ["x"] = 6, ["meta"] = { ["fields"] = {  }, ["inventory"] = {  } }, ["param2"] = 1, ["y"] = 6, ["param1"] = 173, ["z"] = 13, ["name"] = "cottages:roof_straw" }, { ["x"] = 7, ["meta"] = { ["fields"] = {  }, ["inventory"] = {  } }, ["param2"] = 0, ["y"] = 0, ["param1"] = 0, ["z"] = 0, ["name"] = "cottages:straw_ground" }, { ["x"] = 7, ["meta"] = { ["fields"] = {  }, ["inventory"] = {  } }, ["param2"] = 0, ["y"] = 0, ["param1"] = 0, ["z"] = 1, ["name"] = "cottages:straw_ground" }, { ["x"] = 7, ["meta"] = { ["fields"] = {  }, ["inventory"] = {  } }, ["param2"] = 0, ["y"] = 0, ["param1"] = 0, ["z"] = 2, ["name"] = "cottages:straw_ground" }, { ["x"] = 7, ["meta"] = { ["fields"] = {  }, ["inventory"] = {  } }, ["param2"] = 0, ["y"] = 0, ["param1"] = 0, ["z"] = 3, ["name"] = "default:cobble" }, { ["x"] = 7, ["meta"] = { ["fields"] = {  }, ["inventory"] = {  } }, ["param2"] = 0, ["y"] = 0, ["param1"] = 0, ["z"] = 4, ["name"] = "default:sandstone" }, { ["x"] = 7, ["meta"] = { ["fields"] = {  }, ["inventory"] = {  } }, ["param2"] = 0, ["y"] = 0, ["param1"] = 0, ["z"] = 5, ["name"] = "default:sandstone" }, { ["x"] = 7, ["meta"] = { ["fields"] = {  }, ["inventory"] = {  } }, ["param2"] = 0, ["y"] = 0, ["param1"] = 0, ["z"] = 6, ["name"] = "default:sandstone" }, { ["x"] = 7, ["meta"] = { ["fields"] = {  }, ["inventory"] = {  } }, ["param2"] = 0, ["y"] = 0, ["param1"] = 0, ["z"] = 7, ["name"] = "default:sandstone" }, { ["x"] = 7, ["meta"] = { ["fields"] = {  }, ["inventory"] = {  } }, ["param2"] = 0, ["y"] = 0, ["param1"] = 0, ["z"] = 8, ["name"] = "default:sandstone" }, { ["x"] = 7, ["meta"] = { ["fields"] = {  }, ["inventory"] = {  } }, ["param2"] = 0, ["y"] = 0, ["param1"] = 0, ["z"] = 9, ["name"] = "default:sandstone" }, { ["x"] = 7, ["meta"] = { ["fields"] = {  }, ["inventory"] = {  } }, ["param2"] = 0, ["y"] = 0, ["param1"] = 0, ["z"] = 10, ["name"] = "default:sandstone" }, { ["x"] = 7, ["meta"] = { ["fields"] = {  }, ["inventory"] = {  } }, ["param2"] = 0, ["y"] = 0, ["param1"] = 0, ["z"] = 11, ["name"] = "default:sandstone" }, { ["x"] = 7, ["meta"] = { ["fields"] = {  }, ["inventory"] = {  } }, ["param2"] = 0, ["y"] = 0, ["param1"] = 0, ["z"] = 12, ["name"] = "default:cobble" }, { ["x"] = 7, ["meta"] = { ["fields"] = {  }, ["inventory"] = {  } }, ["param2"] = 0, ["y"] = 0, ["param1"] = 0, ["z"] = 13, ["name"] = "farming:soil_wet" }, { ["x"] = 7, ["meta"] = { ["fields"] = {  }, ["inventory"] = {  } }, ["param2"] = 0, ["y"] = 0, ["param1"] = 0, ["z"] = 14, ["name"] = "farming:soil_wet" }, { ["x"] = 7, ["meta"] = { ["fields"] = {  }, ["inventory"] = {  } }, ["param2"] = 0, ["y"] = 0, ["param1"] = 0, ["z"] = 15, ["name"] = "default:dirt_with_grass" }, { ["x"] = 7, ["meta"] = { ["fields"] = {  }, ["inventory"] = {  } }, ["param2"] = 0, ["y"] = 1, ["param1"] = 0, ["z"] = 0, ["name"] = "default:wood" }, { ["x"] = 7, ["meta"] = { ["fields"] = {  }, ["inventory"] = {  } }, ["param2"] = 0, ["y"] = 1, ["param1"] = 0, ["z"] = 3, ["name"] = "default:tree" }, { ["x"] = 7, ["meta"] = { ["fields"] = {  }, ["inventory"] = {  } }, ["param2"] = 1, ["y"] = 1, ["param1"] = 204, ["z"] = 4, ["name"] = "cottages:bed_head" }, { ["x"] = 7, ["meta"] = { ["fields"] = {  }, ["inventory"] = {  } }, ["param2"] = 0, ["y"] = 1, ["param1"] = 0, ["z"] = 5, ["name"] = "default:wood" }, { ["x"] = 7, ["meta"] = { ["fields"] = {  }, ["inventory"] = {  } }, ["param2"] = 2, ["y"] = 1, ["param1"] = 0, ["z"] = 6, ["name"] = "cottages:chest_work" }, { ["x"] = 7, ["meta"] = { ["fields"] = {  }, ["inventory"] = {  } }, ["param2"] = 0, ["y"] = 1, ["param1"] = 0, ["z"] = 8, ["name"] = "default:wood" }, { ["x"] = 7, ["meta"] = { ["fields"] = {  }, ["inventory"] = {  } }, ["param2"] = 1, ["y"] = 1, ["param1"] = 187, ["z"] = 10, ["name"] = "cottages:bench" }, { ["x"] = 7, ["meta"] = { ["fields"] = {  }, ["inventory"] = {  } }, ["param2"] = 1, ["y"] = 1, ["param1"] = 204, ["z"] = 11, ["name"] = "cottages:bench" }, { ["x"] = 7, ["meta"] = { ["fields"] = {  }, ["inventory"] = {  } }, ["param2"] = 0, ["y"] = 1, ["param1"] = 0, ["z"] = 12, ["name"] = "default:tree" }, { ["x"] = 7, ["meta"] = { ["fields"] = {  }, ["inventory"] = {  } }, ["param2"] = 0, ["y"] = 1, ["param1"] = 188, ["z"] = 13, ["name"] = "farming:cotton_3" }, { ["x"] = 7, ["meta"] = { ["fields"] = {  }, ["inventory"] = {  } }, ["param2"] = 0, ["y"] = 1, ["param1"] = 173, ["z"] = 14, ["name"] = "farming:cotton_3" }, { ["x"] = 7, ["meta"] = { ["fields"] = {  }, ["inventory"] = {  } }, ["param2"] = 0, ["y"] = 1, ["param1"] = 189, ["z"] = 15, ["name"] = "default:fence_wood" }, { ["x"] = 7, ["meta"] = { ["fields"] = {  }, ["inventory"] = {  } }, ["param2"] = 0, ["y"] = 2, ["param1"] = 157, ["z"] = 0, ["name"] = "cottages:roof_straw" }, { ["x"] = 7, ["meta"] = { ["fields"] = {  }, ["inventory"] = {  } }, ["param2"] = 0, ["y"] = 2, ["param1"] = 0, ["z"] = 3, ["name"] = "default:tree" }, { ["x"] = 7, ["meta"] = { ["fields"] = {  }, ["inventory"] = {  } }, ["param2"] = 2, ["y"] = 2, ["param1"] = 0, ["z"] = 4, ["name"] = "default:torch" }, { ["x"] = 7, ["meta"] = { ["fields"] = {  }, ["inventory"] = {  } }, ["param2"] = 0, ["y"] = 2, ["param1"] = 0, ["z"] = 5, ["name"] = "default:wood" }, { ["x"] = 7, ["meta"] = { ["fields"] = {  }, ["inventory"] = {  } }, ["param2"] = 1, ["y"] = 2, ["param1"] = 204, ["z"] = 6, ["name"] = "stairs:stair_wood" }, { ["x"] = 7, ["meta"] = { ["fields"] = {  }, ["inventory"] = {  } }, ["param2"] = 0, ["y"] = 2, ["param1"] = 0, ["z"] = 8, ["name"] = "default:wood" }, { ["x"] = 7, ["meta"] = { ["fields"] = {  }, ["inventory"] = {  } }, ["param2"] = 4, ["y"] = 2, ["param1"] = 0, ["z"] = 11, ["name"] = "default:torch" }, { ["x"] = 7, ["meta"] = { ["fields"] = {  }, ["inventory"] = {  } }, ["param2"] = 0, ["y"] = 2, ["param1"] = 0, ["z"] = 12, ["name"] = "default:tree" }, { ["x"] = 7, ["meta"] = { ["fields"] = {  }, ["inventory"] = {  } }, ["param2"] = 0, ["y"] = 3, ["param1"] = 157, ["z"] = 1, ["name"] = "cottages:roof_straw" }, { ["x"] = 7, ["meta"] = { ["fields"] = {  }, ["inventory"] = {  } }, ["param2"] = 0, ["y"] = 3, ["param1"] = 0, ["z"] = 3, ["name"] = "default:tree" }, { ["x"] = 7, ["meta"] = { ["fields"] = {  }, ["inventory"] = {  } }, ["param2"] = 0, ["y"] = 3, ["param1"] = 0, ["z"] = 4, ["name"] = "default:wood" }, { ["x"] = 7, ["meta"] = { ["fields"] = {  }, ["inventory"] = {  } }, ["param2"] = 0, ["y"] = 3, ["param1"] = 0, ["z"] = 5, ["name"] = "default:wood" }, { ["x"] = 7, ["meta"] = { ["fields"] = {  }, ["inventory"] = {  } }, ["param2"] = 0, ["y"] = 3, ["param1"] = 0, ["z"] = 7, ["name"] = "default:wood" }, { ["x"] = 7, ["meta"] = { ["fields"] = {  }, ["inventory"] = {  } }, ["param2"] = 0, ["y"] = 3, ["param1"] = 0, ["z"] = 8, ["name"] = "default:wood" }, { ["x"] = 7, ["meta"] = { ["fields"] = {  }, ["inventory"] = {  } }, ["param2"] = 0, ["y"] = 3, ["param1"] = 0, ["z"] = 9, ["name"] = "default:wood" }, { ["x"] = 7, ["meta"] = { ["fields"] = {  }, ["inventory"] = {  } }, ["param2"] = 0, ["y"] = 3, ["param1"] = 0, ["z"] = 10, ["name"] = "default:wood" }, { ["x"] = 7, ["meta"] = { ["fields"] = {  }, ["inventory"] = {  } }, ["param2"] = 0, ["y"] = 3, ["param1"] = 0, ["z"] = 11, ["name"] = "default:wood" }, { ["x"] = 7, ["meta"] = { ["fields"] = {  }, ["inventory"] = {  } }, ["param2"] = 0, ["y"] = 3, ["param1"] = 0, ["z"] = 12, ["name"] = "default:tree" }, { ["x"] = 7, ["meta"] = { ["fields"] = {  }, ["inventory"] = {  } }, ["param2"] = 0, ["y"] = 4, ["param1"] = 157, ["z"] = 2, ["name"] = "cottages:roof_straw" }, { ["x"] = 7, ["meta"] = { ["fields"] = {  }, ["inventory"] = {  } }, ["param2"] = 0, ["y"] = 4, ["param1"] = 0, ["z"] = 3, ["name"] = "default:tree" }, { ["x"] = 7, ["meta"] = { ["fields"] = {  }, ["inventory"] = {  } }, ["param2"] = 0, ["y"] = 4, ["param1"] = 0, ["z"] = 5, ["name"] = "default:wood" }, { ["x"] = 7, ["meta"] = { ["fields"] = {  }, ["inventory"] = {  } }, ["param2"] = 0, ["y"] = 4, ["param1"] = 0, ["z"] = 7, ["name"] = "default:wood" }, { ["x"] = 7, ["meta"] = { ["fields"] = {  }, ["inventory"] = {  } }, ["param2"] = 0, ["y"] = 4, ["param1"] = 0, ["z"] = 12, ["name"] = "default:tree" }, { ["x"] = 7, ["meta"] = { ["fields"] = {  }, ["inventory"] = {  } }, ["param2"] = 0, ["y"] = 5, ["param1"] = 0, ["z"] = 3, ["name"] = "default:tree" }, { ["x"] = 7, ["meta"] = { ["fields"] = {  }, ["inventory"] = {  } }, ["param2"] = 0, ["y"] = 5, ["param1"] = 0, ["z"] = 5, ["name"] = "default:wood" }, { ["x"] = 7, ["meta"] = { ["fields"] = {  }, ["inventory"] = {  } }, ["param2"] = 0, ["y"] = 5, ["param1"] = 0, ["z"] = 7, ["name"] = "default:wood" }, { ["x"] = 7, ["meta"] = { ["fields"] = {  }, ["inventory"] = {  } }, ["param2"] = 5, ["y"] = 5, ["param1"] = 0, ["z"] = 8, ["name"] = "default:torch" }, { ["x"] = 7, ["meta"] = { ["fields"] = {  }, ["inventory"] = {  } }, ["param2"] = 0, ["y"] = 5, ["param1"] = 0, ["z"] = 12, ["name"] = "default:tree" }, { ["x"] = 7, ["meta"] = { ["fields"] = {  }, ["inventory"] = {  } }, ["param2"] = 0, ["y"] = 6, ["param1"] = 0, ["z"] = 3, ["name"] = "default:tree" }, { ["x"] = 7, ["meta"] = { ["fields"] = {  }, ["inventory"] = {  } }, ["param2"] = 0, ["y"] = 6, ["param1"] = 0, ["z"] = 7, ["name"] = "default:wood" }, { ["x"] = 7, ["meta"] = { ["fields"] = {  }, ["inventory"] = {  } }, ["param2"] = 0, ["y"] = 6, ["param1"] = 0, ["z"] = 12, ["name"] = "default:tree" }, { ["x"] = 7, ["meta"] = { ["fields"] = {  }, ["inventory"] = {  } }, ["param2"] = 0, ["y"] = 7, ["param1"] = 141, ["z"] = 2, ["name"] = "cottages:roof_flat_straw" }, { ["x"] = 7, ["meta"] = { ["fields"] = {  }, ["inventory"] = {  } }, ["param2"] = 2, ["y"] = 7, ["param1"] = 157, ["z"] = 3, ["name"] = "cottages:roof_flat_straw" }, { ["x"] = 7, ["meta"] = { ["fields"] = {  }, ["inventory"] = {  } }, ["param2"] = 2, ["y"] = 7, ["param1"] = 173, ["z"] = 4, ["name"] = "cottages:roof_flat_straw" }, { ["x"] = 7, ["meta"] = { ["fields"] = {  }, ["inventory"] = {  } }, ["param2"] = 2, ["y"] = 7, ["param1"] = 173, ["z"] = 5, ["name"] = "cottages:roof_flat_straw" }, { ["x"] = 7, ["meta"] = { ["fields"] = {  }, ["inventory"] = {  } }, ["param2"] = 2, ["y"] = 7, ["param1"] = 157, ["z"] = 6, ["name"] = "cottages:roof_flat_straw" }, { ["x"] = 7, ["meta"] = { ["fields"] = {  }, ["inventory"] = {  } }, ["param2"] = 2, ["y"] = 7, ["param1"] = 173, ["z"] = 7, ["name"] = "cottages:roof_flat_straw" }, { ["x"] = 7, ["meta"] = { ["fields"] = {  }, ["inventory"] = {  } }, ["param2"] = 0, ["y"] = 7, ["param1"] = 189, ["z"] = 8, ["name"] = "cottages:roof_flat_straw" }, { ["x"] = 7, ["meta"] = { ["fields"] = {  }, ["inventory"] = {  } }, ["param2"] = 2, ["y"] = 7, ["param1"] = 173, ["z"] = 9, ["name"] = "cottages:roof_flat_straw" }, { ["x"] = 7, ["meta"] = { ["fields"] = {  }, ["inventory"] = {  } }, ["param2"] = 0, ["y"] = 7, ["param1"] = 157, ["z"] = 10, ["name"] = "cottages:roof_flat_straw" }, { ["x"] = 7, ["meta"] = { ["fields"] = {  }, ["inventory"] = {  } }, ["param2"] = 0, ["y"] = 7, ["param1"] = 173, ["z"] = 11, ["name"] = "cottages:roof_flat_straw" }, { ["x"] = 7, ["meta"] = { ["fields"] = {  }, ["inventory"] = {  } }, ["param2"] = 2, ["y"] = 7, ["param1"] = 157, ["z"] = 12, ["name"] = "cottages:roof_flat_straw" }, { ["x"] = 7, ["meta"] = { ["fields"] = {  }, ["inventory"] = {  } }, ["param2"] = 2, ["y"] = 7, ["param1"] = 141, ["z"] = 13, ["name"] = "cottages:roof_flat_straw" }, { ["x"] = 8, ["meta"] = { ["fields"] = {  }, ["inventory"] = {  } }, ["param2"] = 0, ["y"] = 0, ["param1"] = 0, ["z"] = 0, ["name"] = "cottages:straw_ground" }, { ["x"] = 8, ["meta"] = { ["fields"] = {  }, ["inventory"] = {  } }, ["param2"] = 0, ["y"] = 0, ["param1"] = 0, ["z"] = 1, ["name"] = "cottages:straw_ground" }, { ["x"] = 8, ["meta"] = { ["fields"] = {  }, ["inventory"] = {  } }, ["param2"] = 0, ["y"] = 0, ["param1"] = 0, ["z"] = 2, ["name"] = "cottages:straw_ground" }, { ["x"] = 8, ["meta"] = { ["fields"] = {  }, ["inventory"] = {  } }, ["param2"] = 0, ["y"] = 0, ["param1"] = 0, ["z"] = 3, ["name"] = "default:cobble" }, { ["x"] = 8, ["meta"] = { ["fields"] = {  }, ["inventory"] = {  } }, ["param2"] = 0, ["y"] = 0, ["param1"] = 0, ["z"] = 4, ["name"] = "default:sandstone" }, { ["x"] = 8, ["meta"] = { ["fields"] = {  }, ["inventory"] = {  } }, ["param2"] = 0, ["y"] = 0, ["param1"] = 0, ["z"] = 5, ["name"] = "default:sandstone" }, { ["x"] = 8, ["meta"] = { ["fields"] = {  }, ["inventory"] = {  } }, ["param2"] = 0, ["y"] = 0, ["param1"] = 0, ["z"] = 6, ["name"] = "default:sandstone" }, { ["x"] = 8, ["meta"] = { ["fields"] = {  }, ["inventory"] = {  } }, ["param2"] = 0, ["y"] = 0, ["param1"] = 0, ["z"] = 7, ["name"] = "default:sandstone" }, { ["x"] = 8, ["meta"] = { ["fields"] = {  }, ["inventory"] = {  } }, ["param2"] = 0, ["y"] = 0, ["param1"] = 0, ["z"] = 8, ["name"] = "default:sandstone" }, { ["x"] = 8, ["meta"] = { ["fields"] = {  }, ["inventory"] = {  } }, ["param2"] = 0, ["y"] = 0, ["param1"] = 0, ["z"] = 9, ["name"] = "default:sandstone" }, { ["x"] = 8, ["meta"] = { ["fields"] = {  }, ["inventory"] = {  } }, ["param2"] = 0, ["y"] = 0, ["param1"] = 0, ["z"] = 10, ["name"] = "default:sandstone" }, { ["x"] = 8, ["meta"] = { ["fields"] = {  }, ["inventory"] = {  } }, ["param2"] = 0, ["y"] = 0, ["param1"] = 0, ["z"] = 11, ["name"] = "default:sandstone" }, { ["x"] = 8, ["meta"] = { ["fields"] = {  }, ["inventory"] = {  } }, ["param2"] = 0, ["y"] = 0, ["param1"] = 0, ["z"] = 12, ["name"] = "default:cobble" }, { ["x"] = 8, ["meta"] = { ["fields"] = {  }, ["inventory"] = {  } }, ["param2"] = 0, ["y"] = 0, ["param1"] = 0, ["z"] = 13, ["name"] = "default:dirt" }, { ["x"] = 8, ["meta"] = { ["fields"] = {  }, ["inventory"] = {  } }, ["param2"] = 0, ["y"] = 0, ["param1"] = 0, ["z"] = 14, ["name"] = "default:dirt_with_grass" }, { ["x"] = 8, ["meta"] = { ["fields"] = {  }, ["inventory"] = {  } }, ["param2"] = 0, ["y"] = 0, ["param1"] = 0, ["z"] = 15, ["name"] = "default:dirt_with_grass" }, { ["x"] = 8, ["meta"] = { ["fields"] = {  }, ["inventory"] = {  } }, ["param2"] = 0, ["y"] = 1, ["param1"] = 0, ["z"] = 0, ["name"] = "default:wood" }, { ["x"] = 8, ["meta"] = { ["fields"] = {  }, ["inventory"] = {  } }, ["param2"] = 0, ["y"] = 1, ["param1"] = 0, ["z"] = 3, ["name"] = "default:clay" }, { ["x"] = 8, ["meta"] = { ["fields"] = {  }, ["inventory"] = {  } }, ["param2"] = 0, ["y"] = 1, ["param1"] = 0, ["z"] = 4, ["name"] = "default:wood" }, { ["x"] = 8, ["meta"] = { ["fields"] = {  }, ["inventory"] = {  } }, ["param2"] = 0, ["y"] = 1, ["param1"] = 0, ["z"] = 8, ["name"] = "default:wood" }, { ["x"] = 8, ["meta"] = { ["fields"] = {  }, ["inventory"] = {  } }, ["param2"] = 1, ["y"] = 1, ["param1"] = 187, ["z"] = 9, ["name"] = "doors:door_wood_b_1" }, { ["x"] = 8, ["meta"] = { ["fields"] = {  }, ["inventory"] = {  } }, ["param2"] = 0, ["y"] = 1, ["param1"] = 0, ["z"] = 10, ["name"] = "default:wood" }, { ["x"] = 8, ["meta"] = { ["fields"] = {  }, ["inventory"] = {  } }, ["param2"] = 0, ["y"] = 1, ["param1"] = 0, ["z"] = 11, ["name"] = "default:wood" }, { ["x"] = 8, ["meta"] = { ["fields"] = {  }, ["inventory"] = {  } }, ["param2"] = 0, ["y"] = 1, ["param1"] = 0, ["z"] = 12, ["name"] = "default:clay" }, { ["x"] = 8, ["meta"] = { ["fields"] = {  }, ["inventory"] = {  } }, ["param2"] = 0, ["y"] = 1, ["param1"] = 204, ["z"] = 13, ["name"] = "default:fence_wood" }, { ["x"] = 8, ["meta"] = { ["fields"] = {  }, ["inventory"] = {  } }, ["param2"] = 1, ["y"] = 1, ["param1"] = 189, ["z"] = 14, ["name"] = "cottages:gate_closed" }, { ["x"] = 8, ["meta"] = { ["fields"] = {  }, ["inventory"] = {  } }, ["param2"] = 0, ["y"] = 1, ["param1"] = 205, ["z"] = 15, ["name"] = "default:fence_wood" }, { ["x"] = 8, ["meta"] = { ["fields"] = {  }, ["inventory"] = {  } }, ["param2"] = 0, ["y"] = 2, ["param1"] = 173, ["z"] = 0, ["name"] = "cottages:roof_straw" }, { ["x"] = 8, ["meta"] = { ["fields"] = {  }, ["inventory"] = {  } }, ["param2"] = 0, ["y"] = 2, ["param1"] = 0, ["z"] = 3, ["name"] = "default:clay" }, { ["x"] = 8, ["meta"] = { ["fields"] = {  }, ["inventory"] = {  } }, ["param2"] = 0, ["y"] = 2, ["param1"] = 0, ["z"] = 4, ["name"] = "default:wood" }, { ["x"] = 8, ["meta"] = { ["fields"] = {  }, ["inventory"] = {  } }, ["param2"] = 4, ["y"] = 2, ["param1"] = 0, ["z"] = 7, ["name"] = "default:torch" }, { ["x"] = 8, ["meta"] = { ["fields"] = {  }, ["inventory"] = {  } }, ["param2"] = 0, ["y"] = 2, ["param1"] = 0, ["z"] = 8, ["name"] = "default:wood" }, { ["x"] = 8, ["meta"] = { ["fields"] = {  }, ["inventory"] = {  } }, ["param2"] = 1, ["y"] = 2, ["param1"] = 204, ["z"] = 9, ["name"] = "doors:door_wood_t_1" }, { ["x"] = 8, ["meta"] = { ["fields"] = {  }, ["inventory"] = {  } }, ["param2"] = 0, ["y"] = 2, ["param1"] = 0, ["z"] = 10, ["name"] = "default:wood" }, { ["x"] = 8, ["meta"] = { ["fields"] = {  }, ["inventory"] = {  } }, ["param2"] = 0, ["y"] = 2, ["param1"] = 0, ["z"] = 11, ["name"] = "default:wood" }, { ["x"] = 8, ["meta"] = { ["fields"] = {  }, ["inventory"] = {  } }, ["param2"] = 0, ["y"] = 2, ["param1"] = 0, ["z"] = 12, ["name"] = "default:clay" }, { ["x"] = 8, ["meta"] = { ["fields"] = {  }, ["inventory"] = {  } }, ["param2"] = 1, ["y"] = 2, ["param1"] = 0, ["z"] = 13, ["name"] = "default:torch" }, { ["x"] = 8, ["meta"] = { ["fields"] = {  }, ["inventory"] = {  } }, ["param2"] = 1, ["y"] = 2, ["param1"] = 15, ["z"] = 15, ["name"] = "default:torch" }, { ["x"] = 8, ["meta"] = { ["fields"] = {  }, ["inventory"] = {  } }, ["param2"] = 0, ["y"] = 3, ["param1"] = 173, ["z"] = 1, ["name"] = "cottages:roof_straw" }, { ["x"] = 8, ["meta"] = { ["fields"] = {  }, ["inventory"] = {  } }, ["param2"] = 0, ["y"] = 3, ["param1"] = 0, ["z"] = 3, ["name"] = "cottages:loam" }, { ["x"] = 8, ["meta"] = { ["fields"] = {  }, ["inventory"] = {  } }, ["param2"] = 0, ["y"] = 3, ["param1"] = 0, ["z"] = 4, ["name"] = "default:wood" }, { ["x"] = 8, ["meta"] = { ["fields"] = {  }, ["inventory"] = {  } }, ["param2"] = 0, ["y"] = 3, ["param1"] = 0, ["z"] = 5, ["name"] = "default:wood" }, { ["x"] = 8, ["meta"] = { ["fields"] = {  }, ["inventory"] = {  } }, ["param2"] = 1, ["y"] = 3, ["param1"] = 187, ["z"] = 6, ["name"] = "stairs:stair_wood" }, { ["x"] = 8, ["meta"] = { ["fields"] = {  }, ["inventory"] = {  } }, ["param2"] = 0, ["y"] = 3, ["param1"] = 0, ["z"] = 7, ["name"] = "default:wood" }, { ["x"] = 8, ["meta"] = { ["fields"] = {  }, ["inventory"] = {  } }, ["param2"] = 0, ["y"] = 3, ["param1"] = 0, ["z"] = 8, ["name"] = "default:wood" }, { ["x"] = 8, ["meta"] = { ["fields"] = {  }, ["inventory"] = {  } }, ["param2"] = 0, ["y"] = 3, ["param1"] = 0, ["z"] = 9, ["name"] = "default:wood" }, { ["x"] = 8, ["meta"] = { ["fields"] = {  }, ["inventory"] = {  } }, ["param2"] = 0, ["y"] = 3, ["param1"] = 0, ["z"] = 10, ["name"] = "default:wood" }, { ["x"] = 8, ["meta"] = { ["fields"] = {  }, ["inventory"] = {  } }, ["param2"] = 0, ["y"] = 3, ["param1"] = 0, ["z"] = 11, ["name"] = "default:wood" }, { ["x"] = 8, ["meta"] = { ["fields"] = {  }, ["inventory"] = {  } }, ["param2"] = 0, ["y"] = 3, ["param1"] = 0, ["z"] = 12, ["name"] = "cottages:loam" }, { ["x"] = 8, ["meta"] = { ["fields"] = {  }, ["inventory"] = {  } }, ["param2"] = 0, ["y"] = 4, ["param1"] = 173, ["z"] = 2, ["name"] = "cottages:roof_straw" }, { ["x"] = 8, ["meta"] = { ["fields"] = {  }, ["inventory"] = {  } }, ["param2"] = 0, ["y"] = 4, ["param1"] = 0, ["z"] = 3, ["name"] = "cottages:loam" }, { ["x"] = 8, ["meta"] = { ["fields"] = {  }, ["inventory"] = {  } }, ["param2"] = 2, ["y"] = 4, ["param1"] = 187, ["z"] = 5, ["name"] = "doors:door_wood_b_1" }, { ["x"] = 8, ["meta"] = { ["fields"] = {  }, ["inventory"] = {  } }, ["param2"] = 0, ["y"] = 4, ["param1"] = 171, ["z"] = 7, ["name"] = "doors:door_wood_b_1" }, { ["x"] = 8, ["meta"] = { ["fields"] = {  }, ["inventory"] = {  } }, ["param2"] = 0, ["y"] = 4, ["param1"] = 0, ["z"] = 12, ["name"] = "cottages:loam" }, { ["x"] = 8, ["meta"] = { ["fields"] = {  }, ["inventory"] = {  } }, ["param2"] = 0, ["y"] = 5, ["param1"] = 0, ["z"] = 3, ["name"] = "cottages:loam" }, { ["x"] = 8, ["meta"] = { ["fields"] = {  }, ["inventory"] = {  } }, ["param2"] = 5, ["y"] = 5, ["param1"] = 0, ["z"] = 4, ["name"] = "default:torch" }, { ["x"] = 8, ["meta"] = { ["fields"] = {  }, ["inventory"] = {  } }, ["param2"] = 2, ["y"] = 5, ["param1"] = 204, ["z"] = 5, ["name"] = "doors:door_wood_t_1" }, { ["x"] = 8, ["meta"] = { ["fields"] = {  }, ["inventory"] = {  } }, ["param2"] = 0, ["y"] = 5, ["param1"] = 188, ["z"] = 7, ["name"] = "doors:door_wood_t_1" }, { ["x"] = 8, ["meta"] = { ["fields"] = {  }, ["inventory"] = {  } }, ["param2"] = 2, ["y"] = 5, ["param1"] = 172, ["z"] = 12, ["name"] = "cottages:glass_pane" }, { ["x"] = 8, ["meta"] = { ["fields"] = {  }, ["inventory"] = {  } }, ["param2"] = 2, ["y"] = 5, ["param1"] = 173, ["z"] = 13, ["name"] = "cottages:window_shutter_open" }, { ["x"] = 8, ["meta"] = { ["fields"] = {  }, ["inventory"] = {  } }, ["param2"] = 3, ["y"] = 6, ["param1"] = 173, ["z"] = 2, ["name"] = "cottages:roof_straw" }, { ["x"] = 8, ["meta"] = { ["fields"] = {  }, ["inventory"] = {  } }, ["param2"] = 3, ["y"] = 6, ["param1"] = 189, ["z"] = 3, ["name"] = "cottages:roof_connector_straw" }, { ["x"] = 8, ["meta"] = { ["fields"] = {  }, ["inventory"] = {  } }, ["param2"] = 3, ["y"] = 6, ["param1"] = 205, ["z"] = 4, ["name"] = "cottages:roof_straw" }, { ["x"] = 8, ["meta"] = { ["fields"] = {  }, ["inventory"] = {  } }, ["param2"] = 3, ["y"] = 6, ["param1"] = 189, ["z"] = 5, ["name"] = "cottages:roof_straw" }, { ["x"] = 8, ["meta"] = { ["fields"] = {  }, ["inventory"] = {  } }, ["param2"] = 3, ["y"] = 6, ["param1"] = 173, ["z"] = 6, ["name"] = "cottages:roof_straw" }, { ["x"] = 8, ["meta"] = { ["fields"] = {  }, ["inventory"] = {  } }, ["param2"] = 3, ["y"] = 6, ["param1"] = 173, ["z"] = 7, ["name"] = "cottages:roof_straw" }, { ["x"] = 8, ["meta"] = { ["fields"] = {  }, ["inventory"] = {  } }, ["param2"] = 3, ["y"] = 6, ["param1"] = 189, ["z"] = 8, ["name"] = "cottages:roof_straw" }, { ["x"] = 8, ["meta"] = { ["fields"] = {  }, ["inventory"] = {  } }, ["param2"] = 3, ["y"] = 6, ["param1"] = 173, ["z"] = 9, ["name"] = "cottages:roof_straw" }, { ["x"] = 8, ["meta"] = { ["fields"] = {  }, ["inventory"] = {  } }, ["param2"] = 3, ["y"] = 6, ["param1"] = 157, ["z"] = 10, ["name"] = "cottages:roof_straw" }, { ["x"] = 8, ["meta"] = { ["fields"] = {  }, ["inventory"] = {  } }, ["param2"] = 3, ["y"] = 6, ["param1"] = 173, ["z"] = 11, ["name"] = "cottages:roof_straw" }, { ["x"] = 8, ["meta"] = { ["fields"] = {  }, ["inventory"] = {  } }, ["param2"] = 3, ["y"] = 6, ["param1"] = 157, ["z"] = 12, ["name"] = "cottages:roof_connector_straw" }, { ["x"] = 8, ["meta"] = { ["fields"] = {  }, ["inventory"] = {  } }, ["param2"] = 3, ["y"] = 6, ["param1"] = 157, ["z"] = 13, ["name"] = "cottages:roof_straw" }, { ["x"] = 9, ["meta"] = { ["fields"] = {  }, ["inventory"] = {  } }, ["param2"] = 0, ["y"] = 0, ["param1"] = 0, ["z"] = 0, ["name"] = "cottages:straw_ground" }, { ["x"] = 9, ["meta"] = { ["fields"] = {  }, ["inventory"] = {  } }, ["param2"] = 0, ["y"] = 0, ["param1"] = 171, ["z"] = 1, ["name"] = "default:water_source" }, { ["x"] = 9, ["meta"] = { ["fields"] = {  }, ["inventory"] = {  } }, ["param2"] = 0, ["y"] = 0, ["param1"] = 0, ["z"] = 2, ["name"] = "cottages:straw_ground" }, { ["x"] = 9, ["meta"] = { ["fields"] = {  }, ["inventory"] = {  } }, ["param2"] = 0, ["y"] = 0, ["param1"] = 0, ["z"] = 3, ["name"] = "default:cobble" }, { ["x"] = 9, ["meta"] = { ["fields"] = {  }, ["inventory"] = {  } }, ["param2"] = 0, ["y"] = 0, ["param1"] = 0, ["z"] = 4, ["name"] = "default:sandstone" }, { ["x"] = 9, ["meta"] = { ["fields"] = {  }, ["inventory"] = {  } }, ["param2"] = 0, ["y"] = 0, ["param1"] = 0, ["z"] = 5, ["name"] = "default:sandstone" }, { ["x"] = 9, ["meta"] = { ["fields"] = {  }, ["inventory"] = {  } }, ["param2"] = 0, ["y"] = 0, ["param1"] = 0, ["z"] = 6, ["name"] = "default:sandstone" }, { ["x"] = 9, ["meta"] = { ["fields"] = {  }, ["inventory"] = {  } }, ["param2"] = 0, ["y"] = 0, ["param1"] = 170, ["z"] = 7, ["name"] = "default:water_source" }, { ["x"] = 9, ["meta"] = { ["fields"] = {  }, ["inventory"] = {  } }, ["param2"] = 0, ["y"] = 0, ["param1"] = 0, ["z"] = 8, ["name"] = "default:sandstone" }, { ["x"] = 9, ["meta"] = { ["fields"] = {  }, ["inventory"] = {  } }, ["param2"] = 0, ["y"] = 0, ["param1"] = 0, ["z"] = 9, ["name"] = "default:sandstone" }, { ["x"] = 9, ["meta"] = { ["fields"] = {  }, ["inventory"] = {  } }, ["param2"] = 0, ["y"] = 0, ["param1"] = 0, ["z"] = 10, ["name"] = "default:sandstone" }, { ["x"] = 9, ["meta"] = { ["fields"] = {  }, ["inventory"] = {  } }, ["param2"] = 0, ["y"] = 0, ["param1"] = 0, ["z"] = 11, ["name"] = "default:sandstone" }, { ["x"] = 9, ["meta"] = { ["fields"] = {  }, ["inventory"] = {  } }, ["param2"] = 0, ["y"] = 0, ["param1"] = 0, ["z"] = 12, ["name"] = "default:cobble" }, { ["x"] = 9, ["meta"] = { ["fields"] = {  }, ["inventory"] = {  } }, ["param2"] = 0, ["y"] = 0, ["param1"] = 0, ["z"] = 13, ["name"] = "default:cobble" }, { ["x"] = 9, ["meta"] = { ["fields"] = {  }, ["inventory"] = {  } }, ["param2"] = 0, ["y"] = 0, ["param1"] = 0, ["z"] = 14, ["name"] = "default:dirt_with_grass" }, { ["x"] = 9, ["meta"] = { ["fields"] = {  }, ["inventory"] = {  } }, ["param2"] = 0, ["y"] = 0, ["param1"] = 0, ["z"] = 15, ["name"] = "default:dirt_with_grass" }, { ["x"] = 9, ["meta"] = { ["fields"] = {  }, ["inventory"] = {  } }, ["param2"] = 0, ["y"] = 1, ["param1"] = 0, ["z"] = 0, ["name"] = "default:wood" }, { ["x"] = 9, ["meta"] = { ["fields"] = {  }, ["inventory"] = {  } }, ["param2"] = 1, ["y"] = 1, ["param1"] = 188, ["z"] = 1, ["name"] = "cottages:washing" }, { ["x"] = 9, ["meta"] = { ["fields"] = {  }, ["inventory"] = {  } }, ["param2"] = 0, ["y"] = 1, ["param1"] = 0, ["z"] = 3, ["name"] = "default:clay" }, { ["x"] = 9, ["meta"] = { ["fields"] = {  }, ["inventory"] = {  } }, ["param2"] = 2, ["y"] = 1, ["param1"] = 137, ["z"] = 4, ["name"] = "cottages:shelf" }, { ["x"] = 9, ["meta"] = { ["fields"] = {  }, ["inventory"] = {  } }, ["param2"] = 1, ["y"] = 1, ["param1"] = 154, ["z"] = 5, ["name"] = "cottages:shelf" }, { ["x"] = 9, ["meta"] = { ["fields"] = { ["src_totaltime"] = "0", ["formspec"] = "size[8,9]image[2,2;1,1;default_furnace_fire_bg.png]list[current_name;fuel;2,3;1,1;]list[current_name;src;2,1;1,1;]list[current_name;dst;5,1;2,2;]list[current_player;main;0,5;8,4;]", ["fuel_time"] = "0", ["fuel_totaltime"] = "0", ["src_time"] = "0", ["infotext"] = "Furnace out of fuel" }, ["inventory"] = {  } }, ["param2"] = 1, ["y"] = 1, ["param1"] = 0, ["z"] = 6, ["name"] = "default:furnace" }, { ["x"] = 9, ["meta"] = { ["fields"] = {  }, ["inventory"] = {  } }, ["param2"] = 1, ["y"] = 1, ["param1"] = 187, ["z"] = 7, ["name"] = "cottages:washing" }, { ["x"] = 9, ["meta"] = { ["fields"] = {  }, ["inventory"] = {  } }, ["param2"] = 0, ["y"] = 1, ["param1"] = 0, ["z"] = 8, ["name"] = "default:wood" }, { ["x"] = 9, ["meta"] = { ["fields"] = {  }, ["inventory"] = {  } }, ["param2"] = 1, ["y"] = 1, ["param1"] = 204, ["z"] = 9, ["name"] = "cottages:bench" }, { ["x"] = 9, ["meta"] = { ["fields"] = {  }, ["inventory"] = {  } }, ["param2"] = 0, ["y"] = 1, ["param1"] = 187, ["z"] = 10, ["name"] = "cottages:bed_foot" }, { ["x"] = 9, ["meta"] = { ["fields"] = {  }, ["inventory"] = {  } }, ["param2"] = 0, ["y"] = 1, ["param1"] = 204, ["z"] = 11, ["name"] = "cottages:bed_head" }, { ["x"] = 9, ["meta"] = { ["fields"] = {  }, ["inventory"] = {  } }, ["param2"] = 0, ["y"] = 1, ["param1"] = 0, ["z"] = 12, ["name"] = "default:clay" }, { ["x"] = 9, ["meta"] = { ["fields"] = {  }, ["inventory"] = {  } }, ["param2"] = 0, ["y"] = 2, ["param1"] = 189, ["z"] = 0, ["name"] = "cottages:roof_straw" }, { ["x"] = 9, ["meta"] = { ["fields"] = {  }, ["inventory"] = {  } }, ["param2"] = 4, ["y"] = 2, ["param1"] = 0, ["z"] = 2, ["name"] = "default:torch" }, { ["x"] = 9, ["meta"] = { ["fields"] = {  }, ["inventory"] = {  } }, ["param2"] = 0, ["y"] = 2, ["param1"] = 0, ["z"] = 3, ["name"] = "default:clay" }, { ["x"] = 9, ["meta"] = { ["fields"] = {  }, ["inventory"] = {  } }, ["param2"] = 2, ["y"] = 2, ["param1"] = 154, ["z"] = 4, ["name"] = "cottages:shelf" }, { ["x"] = 9, ["meta"] = { ["fields"] = { ["src_totaltime"] = "0", ["formspec"] = "size[8,9]image[2,2;1,1;default_furnace_fire_bg.png]list[current_name;fuel;2,3;1,1;]list[current_name;src;2,1;1,1;]list[current_name;dst;5,1;2,2;]list[current_player;main;0,5;8,4;]", ["fuel_time"] = "0", ["fuel_totaltime"] = "0", ["src_time"] = "0", ["infotext"] = "Furnace out of fuel" }, ["inventory"] = {  } }, ["param2"] = 3, ["y"] = 2, ["param1"] = 0, ["z"] = 6, ["name"] = "default:furnace" }, { ["x"] = 9, ["meta"] = { ["fields"] = {  }, ["inventory"] = {  } }, ["param2"] = 0, ["y"] = 2, ["param1"] = 0, ["z"] = 8, ["name"] = "default:wood" }, { ["x"] = 9, ["meta"] = { ["fields"] = {  }, ["inventory"] = {  } }, ["param2"] = 2, ["y"] = 2, ["param1"] = 0, ["z"] = 9, ["name"] = "default:torch" }, { ["x"] = 9, ["meta"] = { ["fields"] = {  }, ["inventory"] = {  } }, ["param2"] = 2, ["y"] = 2, ["param1"] = 0, ["z"] = 11, ["name"] = "default:torch" }, { ["x"] = 9, ["meta"] = { ["fields"] = {  }, ["inventory"] = {  } }, ["param2"] = 0, ["y"] = 2, ["param1"] = 0, ["z"] = 12, ["name"] = "default:clay" }, { ["x"] = 9, ["meta"] = { ["fields"] = {  }, ["inventory"] = {  } }, ["param2"] = 5, ["y"] = 2, ["param1"] = 0, ["z"] = 13, ["name"] = "default:torch" }, { ["x"] = 9, ["meta"] = { ["fields"] = {  }, ["inventory"] = {  } }, ["param2"] = 0, ["y"] = 3, ["param1"] = 189, ["z"] = 1, ["name"] = "cottages:roof_straw" }, { ["x"] = 9, ["meta"] = { ["fields"] = {  }, ["inventory"] = {  } }, ["param2"] = 0, ["y"] = 3, ["param1"] = 0, ["z"] = 3, ["name"] = "cottages:loam" }, { ["x"] = 9, ["meta"] = { ["fields"] = {  }, ["inventory"] = {  } }, ["param2"] = 0, ["y"] = 3, ["param1"] = 0, ["z"] = 4, ["name"] = "default:wood" }, { ["x"] = 9, ["meta"] = { ["fields"] = { ["src_totaltime"] = "0", ["formspec"] = "size[8,9]image[2,2;1,1;default_furnace_fire_bg.png]list[current_name;fuel;2,3;1,1;]list[current_name;src;2,1;1,1;]list[current_name;dst;5,1;2,2;]list[current_player;main;0,5;8,4;]", ["fuel_time"] = "0", ["fuel_totaltime"] = "0", ["src_time"] = "0", ["infotext"] = "Furnace out of fuel" }, ["inventory"] = {  } }, ["param2"] = 1, ["y"] = 3, ["param1"] = 0, ["z"] = 6, ["name"] = "default:furnace" }, { ["x"] = 9, ["meta"] = { ["fields"] = {  }, ["inventory"] = {  } }, ["param2"] = 0, ["y"] = 3, ["param1"] = 0, ["z"] = 7, ["name"] = "default:wood" }, { ["x"] = 9, ["meta"] = { ["fields"] = {  }, ["inventory"] = {  } }, ["param2"] = 0, ["y"] = 3, ["param1"] = 0, ["z"] = 8, ["name"] = "default:wood" }, { ["x"] = 9, ["meta"] = { ["fields"] = {  }, ["inventory"] = {  } }, ["param2"] = 0, ["y"] = 3, ["param1"] = 0, ["z"] = 9, ["name"] = "default:wood" }, { ["x"] = 9, ["meta"] = { ["fields"] = {  }, ["inventory"] = {  } }, ["param2"] = 0, ["y"] = 3, ["param1"] = 0, ["z"] = 10, ["name"] = "default:wood" }, { ["x"] = 9, ["meta"] = { ["fields"] = {  }, ["inventory"] = {  } }, ["param2"] = 0, ["y"] = 3, ["param1"] = 0, ["z"] = 11, ["name"] = "default:wood" }, { ["x"] = 9, ["meta"] = { ["fields"] = {  }, ["inventory"] = {  } }, ["param2"] = 0, ["y"] = 3, ["param1"] = 0, ["z"] = 12, ["name"] = "cottages:loam" }, { ["x"] = 9, ["meta"] = { ["fields"] = {  }, ["inventory"] = {  } }, ["param2"] = 0, ["y"] = 4, ["param1"] = 189, ["z"] = 2, ["name"] = "cottages:roof_straw" }, { ["x"] = 9, ["meta"] = { ["fields"] = {  }, ["inventory"] = {  } }, ["param2"] = 0, ["y"] = 4, ["param1"] = 0, ["z"] = 3, ["name"] = "cottages:loam" }, { ["x"] = 9, ["meta"] = { ["fields"] = {  }, ["inventory"] = {  } }, ["param2"] = 0, ["y"] = 4, ["param1"] = 188, ["z"] = 4, ["name"] = "cottages:bed_foot" }, { ["x"] = 9, ["meta"] = { ["fields"] = {  }, ["inventory"] = {  } }, ["param2"] = 0, ["y"] = 4, ["param1"] = 172, ["z"] = 5, ["name"] = "cottages:bed_head" }, { ["x"] = 9, ["meta"] = { ["fields"] = { ["src_totaltime"] = "0", ["formspec"] = "size[8,9]image[2,2;1,1;default_furnace_fire_bg.png]list[current_name;fuel;2,3;1,1;]list[current_name;src;2,1;1,1;]list[current_name;dst;5,1;2,2;]list[current_player;main;0,5;8,4;]", ["fuel_time"] = "0", ["fuel_totaltime"] = "0", ["src_time"] = "0", ["infotext"] = "Furnace out of fuel" }, ["inventory"] = {  } }, ["param2"] = 2, ["y"] = 4, ["param1"] = 0, ["z"] = 6, ["name"] = "default:furnace" }, { ["x"] = 9, ["meta"] = { ["fields"] = {  }, ["inventory"] = {  } }, ["param2"] = 1, ["y"] = 4, ["param1"] = 172, ["z"] = 8, ["name"] = "cottages:bench" }, { ["x"] = 9, ["meta"] = { ["fields"] = {  }, ["inventory"] = {  } }, ["param2"] = 1, ["y"] = 4, ["param1"] = 0, ["z"] = 9, ["name"] = "cottages:chest_private" }, { ["x"] = 9, ["meta"] = { ["fields"] = {  }, ["inventory"] = {  } }, ["param2"] = 1, ["y"] = 4, ["param1"] = 0, ["z"] = 10, ["name"] = "cottages:chest_private" }, { ["x"] = 9, ["meta"] = { ["fields"] = {  }, ["inventory"] = {  } }, ["param2"] = 1, ["y"] = 4, ["param1"] = 156, ["z"] = 11, ["name"] = "cottages:shelf" }, { ["x"] = 9, ["meta"] = { ["fields"] = {  }, ["inventory"] = {  } }, ["param2"] = 0, ["y"] = 4, ["param1"] = 0, ["z"] = 12, ["name"] = "cottages:loam" }, { ["x"] = 9, ["meta"] = { ["fields"] = {  }, ["inventory"] = {  } }, ["param2"] = 3, ["y"] = 5, ["param1"] = 173, ["z"] = 2, ["name"] = "cottages:roof_straw" }, { ["x"] = 9, ["meta"] = { ["fields"] = {  }, ["inventory"] = {  } }, ["param2"] = 3, ["y"] = 5, ["param1"] = 189, ["z"] = 3, ["name"] = "cottages:roof_connector_straw" }, { ["x"] = 9, ["meta"] = { ["fields"] = {  }, ["inventory"] = {  } }, ["param2"] = 3, ["y"] = 5, ["param1"] = 205, ["z"] = 4, ["name"] = "cottages:roof_straw" }, { ["x"] = 9, ["meta"] = { ["fields"] = {  }, ["inventory"] = {  } }, ["param2"] = 3, ["y"] = 5, ["param1"] = 189, ["z"] = 5, ["name"] = "cottages:roof_straw" }, { ["x"] = 9, ["meta"] = { ["fields"] = { ["src_totaltime"] = "0", ["formspec"] = "size[8,9]image[2,2;1,1;default_furnace_fire_bg.png]list[current_name;fuel;2,3;1,1;]list[current_name;src;2,1;1,1;]list[current_name;dst;5,1;2,2;]list[current_player;main;0,5;8,4;]", ["fuel_time"] = "0", ["fuel_totaltime"] = "0", ["src_time"] = "0", ["infotext"] = "Furnace out of fuel" }, ["inventory"] = {  } }, ["param2"] = 0, ["y"] = 5, ["param1"] = 0, ["z"] = 6, ["name"] = "default:furnace" }, { ["x"] = 9, ["meta"] = { ["fields"] = {  }, ["inventory"] = {  } }, ["param2"] = 3, ["y"] = 5, ["param1"] = 173, ["z"] = 7, ["name"] = "cottages:roof_straw" }, { ["x"] = 9, ["meta"] = { ["fields"] = {  }, ["inventory"] = {  } }, ["param2"] = 3, ["y"] = 5, ["param1"] = 189, ["z"] = 8, ["name"] = "cottages:roof_straw" }, { ["x"] = 9, ["meta"] = { ["fields"] = {  }, ["inventory"] = {  } }, ["param2"] = 3, ["y"] = 5, ["param1"] = 173, ["z"] = 9, ["name"] = "cottages:roof_straw" }, { ["x"] = 9, ["meta"] = { ["fields"] = {  }, ["inventory"] = {  } }, ["param2"] = 3, ["y"] = 5, ["param1"] = 157, ["z"] = 10, ["name"] = "cottages:roof_straw" }, { ["x"] = 9, ["meta"] = { ["fields"] = {  }, ["inventory"] = {  } }, ["param2"] = 3, ["y"] = 5, ["param1"] = 173, ["z"] = 11, ["name"] = "cottages:roof_straw" }, { ["x"] = 9, ["meta"] = { ["fields"] = {  }, ["inventory"] = {  } }, ["param2"] = 3, ["y"] = 5, ["param1"] = 157, ["z"] = 12, ["name"] = "cottages:roof_connector_straw" }, { ["x"] = 9, ["meta"] = { ["fields"] = {  }, ["inventory"] = {  } }, ["param2"] = 3, ["y"] = 5, ["param1"] = 173, ["z"] = 13, ["name"] = "cottages:roof_straw" }, { ["x"] = 9, ["meta"] = { ["fields"] = { ["src_totaltime"] = "0", ["formspec"] = "size[8,9]image[2,2;1,1;default_furnace_fire_bg.png]list[current_name;fuel;2,3;1,1;]list[current_name;src;2,1;1,1;]list[current_name;dst;5,1;2,2;]list[current_player;main;0,5;8,4;]", ["fuel_time"] = "0", ["fuel_totaltime"] = "0", ["src_time"] = "0", ["infotext"] = "Furnace out of fuel" }, ["inventory"] = {  } }, ["param2"] = 1, ["y"] = 6, ["param1"] = 0, ["z"] = 6, ["name"] = "default:furnace" }, { ["x"] = 9, ["meta"] = { ["fields"] = { ["src_totaltime"] = "0", ["formspec"] = "size[8,9]image[2,2;1,1;default_furnace_fire_bg.png]list[current_name;fuel;2,3;1,1;]list[current_name;src;2,1;1,1;]list[current_name;dst;5,1;2,2;]list[current_player;main;0,5;8,4;]", ["fuel_time"] = "0", ["fuel_totaltime"] = "0", ["src_time"] = "0", ["infotext"] = "Furnace out of fuel" }, ["inventory"] = {  } }, ["param2"] = 3, ["y"] = 7, ["param1"] = 0, ["z"] = 6, ["name"] = "default:furnace" }, { ["x"] = 10, ["meta"] = { ["fields"] = {  }, ["inventory"] = {  } }, ["param2"] = 0, ["y"] = 0, ["param1"] = 0, ["z"] = 0, ["name"] = "cottages:straw_ground" }, { ["x"] = 10, ["meta"] = { ["fields"] = {  }, ["inventory"] = {  } }, ["param2"] = 0, ["y"] = 0, ["param1"] = 0, ["z"] = 1, ["name"] = "cottages:straw_ground" }, { ["x"] = 10, ["meta"] = { ["fields"] = {  }, ["inventory"] = {  } }, ["param2"] = 0, ["y"] = 0, ["param1"] = 0, ["z"] = 2, ["name"] = "cottages:straw_ground" }, { ["x"] = 10, ["meta"] = { ["fields"] = {  }, ["inventory"] = {  } }, ["param2"] = 0, ["y"] = 0, ["param1"] = 0, ["z"] = 3, ["name"] = "default:cobble" }, { ["x"] = 10, ["meta"] = { ["fields"] = {  }, ["inventory"] = {  } }, ["param2"] = 0, ["y"] = 0, ["param1"] = 0, ["z"] = 4, ["name"] = "default:cobble" }, { ["x"] = 10, ["meta"] = { ["fields"] = {  }, ["inventory"] = {  } }, ["param2"] = 0, ["y"] = 0, ["param1"] = 0, ["z"] = 5, ["name"] = "default:cobble" }, { ["x"] = 10, ["meta"] = { ["fields"] = {  }, ["inventory"] = {  } }, ["param2"] = 0, ["y"] = 0, ["param1"] = 0, ["z"] = 6, ["name"] = "default:cobble" }, { ["x"] = 10, ["meta"] = { ["fields"] = {  }, ["inventory"] = {  } }, ["param2"] = 0, ["y"] = 0, ["param1"] = 0, ["z"] = 7, ["name"] = "default:cobble" }, { ["x"] = 10, ["meta"] = { ["fields"] = {  }, ["inventory"] = {  } }, ["param2"] = 0, ["y"] = 0, ["param1"] = 0, ["z"] = 8, ["name"] = "default:cobble" }, { ["x"] = 10, ["meta"] = { ["fields"] = {  }, ["inventory"] = {  } }, ["param2"] = 0, ["y"] = 0, ["param1"] = 0, ["z"] = 9, ["name"] = "default:cobble" }, { ["x"] = 10, ["meta"] = { ["fields"] = {  }, ["inventory"] = {  } }, ["param2"] = 0, ["y"] = 0, ["param1"] = 0, ["z"] = 10, ["name"] = "default:cobble" }, { ["x"] = 10, ["meta"] = { ["fields"] = {  }, ["inventory"] = {  } }, ["param2"] = 0, ["y"] = 0, ["param1"] = 0, ["z"] = 11, ["name"] = "default:cobble" }, { ["x"] = 10, ["meta"] = { ["fields"] = {  }, ["inventory"] = {  } }, ["param2"] = 0, ["y"] = 0, ["param1"] = 0, ["z"] = 12, ["name"] = "default:cobble" }, { ["x"] = 10, ["meta"] = { ["fields"] = {  }, ["inventory"] = {  } }, ["param2"] = 0, ["y"] = 0, ["param1"] = 0, ["z"] = 13, ["name"] = "default:cobble" }, { ["x"] = 10, ["meta"] = { ["fields"] = {  }, ["inventory"] = {  } }, ["param2"] = 0, ["y"] = 0, ["param1"] = 0, ["z"] = 14, ["name"] = "default:dirt_with_grass" }, { ["x"] = 10, ["meta"] = { ["fields"] = {  }, ["inventory"] = {  } }, ["param2"] = 0, ["y"] = 0, ["param1"] = 0, ["z"] = 15, ["name"] = "default:dirt_with_grass" }, { ["x"] = 10, ["meta"] = { ["fields"] = {  }, ["inventory"] = {  } }, ["param2"] = 0, ["y"] = 1, ["param1"] = 157, ["z"] = 0, ["name"] = "default:fence_wood" }, { ["x"] = 10, ["meta"] = { ["fields"] = {  }, ["inventory"] = {  } }, ["param2"] = 0, ["y"] = 1, ["param1"] = 173, ["z"] = 1, ["name"] = "default:fence_wood" }, { ["x"] = 10, ["meta"] = { ["fields"] = {  }, ["inventory"] = {  } }, ["param2"] = 0, ["y"] = 1, ["param1"] = 188, ["z"] = 2, ["name"] = "default:fence_wood" }, { ["x"] = 10, ["meta"] = { ["fields"] = {  }, ["inventory"] = {  } }, ["param2"] = 0, ["y"] = 1, ["param1"] = 0, ["z"] = 3, ["name"] = "default:tree" }, { ["x"] = 10, ["meta"] = { ["fields"] = {  }, ["inventory"] = {  } }, ["param2"] = 0, ["y"] = 1, ["param1"] = 0, ["z"] = 4, ["name"] = "default:clay" }, { ["x"] = 10, ["meta"] = { ["fields"] = {  }, ["inventory"] = {  } }, ["param2"] = 0, ["y"] = 1, ["param1"] = 0, ["z"] = 5, ["name"] = "default:clay" }, { ["x"] = 10, ["meta"] = { ["fields"] = {  }, ["inventory"] = {  } }, ["param2"] = 0, ["y"] = 1, ["param1"] = 0, ["z"] = 6, ["name"] = "default:tree" }, { ["x"] = 10, ["meta"] = { ["fields"] = {  }, ["inventory"] = {  } }, ["param2"] = 0, ["y"] = 1, ["param1"] = 0, ["z"] = 7, ["name"] = "default:clay" }, { ["x"] = 10, ["meta"] = { ["fields"] = {  }, ["inventory"] = {  } }, ["param2"] = 0, ["y"] = 1, ["param1"] = 0, ["z"] = 8, ["name"] = "default:clay" }, { ["x"] = 10, ["meta"] = { ["fields"] = {  }, ["inventory"] = {  } }, ["param2"] = 0, ["y"] = 1, ["param1"] = 0, ["z"] = 9, ["name"] = "default:tree" }, { ["x"] = 10, ["meta"] = { ["fields"] = {  }, ["inventory"] = {  } }, ["param2"] = 0, ["y"] = 1, ["param1"] = 0, ["z"] = 10, ["name"] = "default:clay" }, { ["x"] = 10, ["meta"] = { ["fields"] = {  }, ["inventory"] = {  } }, ["param2"] = 0, ["y"] = 1, ["param1"] = 0, ["z"] = 11, ["name"] = "default:clay" }, { ["x"] = 10, ["meta"] = { ["fields"] = {  }, ["inventory"] = {  } }, ["param2"] = 0, ["y"] = 1, ["param1"] = 0, ["z"] = 12, ["name"] = "default:tree" }, { ["x"] = 10, ["meta"] = { ["fields"] = {  }, ["inventory"] = {  } }, ["param2"] = 0, ["y"] = 2, ["param1"] = 173, ["z"] = 0, ["name"] = "cottages:roof_straw" }, { ["x"] = 10, ["meta"] = { ["fields"] = {  }, ["inventory"] = {  } }, ["param2"] = 0, ["y"] = 2, ["param1"] = 189, ["z"] = 1, ["name"] = "default:fence_wood" }, { ["x"] = 10, ["meta"] = { ["fields"] = {  }, ["inventory"] = {  } }, ["param2"] = 0, ["y"] = 2, ["param1"] = 204, ["z"] = 2, ["name"] = "default:fence_wood" }, { ["x"] = 10, ["meta"] = { ["fields"] = {  }, ["inventory"] = {  } }, ["param2"] = 0, ["y"] = 2, ["param1"] = 0, ["z"] = 3, ["name"] = "default:tree" }, { ["x"] = 10, ["meta"] = { ["fields"] = {  }, ["inventory"] = {  } }, ["param2"] = 0, ["y"] = 2, ["param1"] = 0, ["z"] = 4, ["name"] = "default:clay" }, { ["x"] = 10, ["meta"] = { ["fields"] = {  }, ["inventory"] = {  } }, ["param2"] = 1, ["y"] = 2, ["param1"] = 188, ["z"] = 5, ["name"] = "cottages:glass_pane" }, { ["x"] = 10, ["meta"] = { ["fields"] = {  }, ["inventory"] = {  } }, ["param2"] = 0, ["y"] = 2, ["param1"] = 0, ["z"] = 6, ["name"] = "default:tree" }, { ["x"] = 10, ["meta"] = { ["fields"] = {  }, ["inventory"] = {  } }, ["param2"] = 3, ["y"] = 2, ["param1"] = 188, ["z"] = 7, ["name"] = "cottages:glass_pane" }, { ["x"] = 10, ["meta"] = { ["fields"] = {  }, ["inventory"] = {  } }, ["param2"] = 0, ["y"] = 2, ["param1"] = 0, ["z"] = 8, ["name"] = "default:clay" }, { ["x"] = 10, ["meta"] = { ["fields"] = {  }, ["inventory"] = {  } }, ["param2"] = 0, ["y"] = 2, ["param1"] = 0, ["z"] = 9, ["name"] = "default:tree" }, { ["x"] = 10, ["meta"] = { ["fields"] = {  }, ["inventory"] = {  } }, ["param2"] = 3, ["y"] = 2, ["param1"] = 188, ["z"] = 10, ["name"] = "cottages:glass_pane" }, { ["x"] = 10, ["meta"] = { ["fields"] = {  }, ["inventory"] = {  } }, ["param2"] = 0, ["y"] = 2, ["param1"] = 0, ["z"] = 11, ["name"] = "default:clay" }, { ["x"] = 10, ["meta"] = { ["fields"] = {  }, ["inventory"] = {  } }, ["param2"] = 0, ["y"] = 2, ["param1"] = 0, ["z"] = 12, ["name"] = "default:tree" }, { ["x"] = 10, ["meta"] = { ["fields"] = {  }, ["inventory"] = {  } }, ["param2"] = 0, ["y"] = 3, ["param1"] = 173, ["z"] = 1, ["name"] = "cottages:roof_straw" }, { ["x"] = 10, ["meta"] = { ["fields"] = {  }, ["inventory"] = {  } }, ["param2"] = 0, ["y"] = 3, ["param1"] = 188, ["z"] = 2, ["name"] = "default:fence_wood" }, { ["x"] = 10, ["meta"] = { ["fields"] = {  }, ["inventory"] = {  } }, ["param2"] = 0, ["y"] = 3, ["param1"] = 0, ["z"] = 3, ["name"] = "default:tree" }, { ["x"] = 10, ["meta"] = { ["fields"] = {  }, ["inventory"] = {  } }, ["param2"] = 0, ["y"] = 3, ["param1"] = 0, ["z"] = 4, ["name"] = "cottages:loam" }, { ["x"] = 10, ["meta"] = { ["fields"] = {  }, ["inventory"] = {  } }, ["param2"] = 0, ["y"] = 3, ["param1"] = 0, ["z"] = 5, ["name"] = "cottages:loam" }, { ["x"] = 10, ["meta"] = { ["fields"] = {  }, ["inventory"] = {  } }, ["param2"] = 0, ["y"] = 3, ["param1"] = 0, ["z"] = 6, ["name"] = "default:tree" }, { ["x"] = 10, ["meta"] = { ["fields"] = {  }, ["inventory"] = {  } }, ["param2"] = 0, ["y"] = 3, ["param1"] = 0, ["z"] = 7, ["name"] = "cottages:loam" }, { ["x"] = 10, ["meta"] = { ["fields"] = {  }, ["inventory"] = {  } }, ["param2"] = 0, ["y"] = 3, ["param1"] = 0, ["z"] = 8, ["name"] = "cottages:loam" }, { ["x"] = 10, ["meta"] = { ["fields"] = {  }, ["inventory"] = {  } }, ["param2"] = 0, ["y"] = 3, ["param1"] = 0, ["z"] = 9, ["name"] = "default:tree" }, { ["x"] = 10, ["meta"] = { ["fields"] = {  }, ["inventory"] = {  } }, ["param2"] = 0, ["y"] = 3, ["param1"] = 0, ["z"] = 10, ["name"] = "cottages:loam" }, { ["x"] = 10, ["meta"] = { ["fields"] = {  }, ["inventory"] = {  } }, ["param2"] = 0, ["y"] = 3, ["param1"] = 0, ["z"] = 11, ["name"] = "cottages:loam" }, { ["x"] = 10, ["meta"] = { ["fields"] = {  }, ["inventory"] = {  } }, ["param2"] = 0, ["y"] = 3, ["param1"] = 0, ["z"] = 12, ["name"] = "default:tree" }, { ["x"] = 10, ["meta"] = { ["fields"] = {  }, ["inventory"] = {  } },