return { { ["x"] = 0, ["meta"] = { ["fields"] = {  }, ["inventory"] = {  } }, ["param2"] = 0, ["y"] = 0, ["param1"] = 0, ["z"] = 0, ["name"] = "default:desert_sand" }, { ["x"] = 0, ["meta"] = { ["fields"] = {  }, ["inventory"] = {  } }, ["param2"] = 0, ["y"] = 0, ["param1"] = 0, ["z"] = 1, ["name"] = "default:desert_sand" }, { ["x"] = 0, ["meta"] = { ["fields"] = {  }, ["inventory"] = {  } }, ["param2"] = 0, ["y"] = 0, ["param1"] = 0, ["z"] = 2, ["name"] = "default:desert_sand" }, { ["x"] = 0, ["meta"] = { ["fields"] = {  }, ["inventory"] = {  } }, ["param2"] = 0, ["y"] = 0, ["param1"] = 0, ["z"] = 3, ["name"] = "default:desert_sand" }, { ["x"] = 0, ["meta"] = { ["fields"] = {  }, ["inventory"] = {  } }, ["param2"] = 0, ["y"] = 0, ["param1"] = 0, ["z"] = 4, ["name"] = "default:desert_sand" }, { ["x"] = 0, ["meta"] = { ["fields"] = {  }, ["inventory"] = {  } }, ["param2"] = 0, ["y"] = 0, ["param1"] = 0, ["z"] = 5, ["name"] = "default:desert_sand" }, { ["x"] = 0, ["meta"] = { ["fields"] = {  }, ["inventory"] = {  } }, ["param2"] = 0, ["y"] = 0, ["param1"] = 0, ["z"] = 6, ["name"] = "default:desert_sand" }, { ["x"] = 0, ["meta"] = { ["fields"] = {  }, ["inventory"] = {  } }, ["param2"] = 1, ["y"] = 3, ["param1"] = 13, ["z"] = 2, ["name"] = "dryplants:wetreed_roof_corner" }, { ["x"] = 0, ["meta"] = { ["fields"] = {  }, ["inventory"] = {  } }, ["param2"] = 1, ["y"] = 3, ["param1"] = 13, ["z"] = 3, ["name"] = "dryplants:wetreed_roof" }, { ["x"] = 0, ["meta"] = { ["fields"] = {  }, ["inventory"] = {  } }, ["param2"] = 2, ["y"] = 3, ["param1"] = 13, ["z"] = 4, ["name"] = "dryplants:wetreed_roof_corner" }, { ["x"] = 1, ["meta"] = { ["fields"] = {  }, ["inventory"] = {  } }, ["param2"] = 0, ["y"] = 0, ["param1"] = 0, ["z"] = 0, ["name"] = "default:desert_sand" }, { ["x"] = 1, ["meta"] = { ["fields"] = {  }, ["inventory"] = {  } }, ["param2"] = 0, ["y"] = 0, ["param1"] = 0, ["z"] = 1, ["name"] = "default:desert_sand" }, { ["x"] = 1, ["meta"] = { ["fields"] = {  }, ["inventory"] = {  } }, ["param2"] = 0, ["y"] = 0, ["param1"] = 0, ["z"] = 2, ["name"] = "default:desert_sand" }, { ["x"] = 1, ["meta"] = { ["fields"] = {  }, ["inventory"] = {  } }, ["param2"] = 0, ["y"] = 0, ["param1"] = 0, ["z"] = 3, ["name"] = "default:desert_sand" }, { ["x"] = 1, ["meta"] = { ["fields"] = {  }, ["inventory"] = {  } }, ["param2"] = 0, ["y"] = 0, ["param1"] = 0, ["z"] = 4, ["name"] = "default:desert_sand" }, { ["x"] = 1, ["meta"] = { ["fields"] = {  }, ["inventory"] = {  } }, ["param2"] = 0, ["y"] = 0, ["param1"] = 0, ["z"] = 5, ["name"] = "default:desert_sand" }, { ["x"] = 1, ["meta"] = { ["fields"] = {  }, ["inventory"] = {  } }, ["param2"] = 0, ["y"] = 0, ["param1"] = 0, ["z"] = 6, ["name"] = "default:desert_sand" }, { ["x"] = 1, ["meta"] = { ["fields"] = {  }, ["inventory"] = {  } }, ["param2"] = 17, ["y"] = 1, ["param1"] = 12, ["z"] = 2, ["name"] = "dryplants:reed_slab" }, { ["x"] = 1, ["meta"] = { ["fields"] = {  }, ["inventory"] = {  } }, ["param2"] = 13, ["y"] = 1, ["param1"] = 12, ["z"] = 3, ["name"] = "dryplants:reed_slab" }, { ["x"] = 1, ["meta"] = { ["fields"] = {  }, ["inventory"] = {  } }, ["param2"] = 17, ["y"] = 1, ["param1"] = 12, ["z"] = 4, ["name"] = "dryplants:reed_slab" }, { ["x"] = 1, ["meta"] = { ["fields"] = {  }, ["inventory"] = {  } }, ["param2"] = 17, ["y"] = 2, ["param1"] = 12, ["z"] = 2, ["name"] = "dryplants:reed_slab" }, { ["x"] = 1, ["meta"] = { ["fields"] = {  }, ["inventory"] = {  } }, ["param2"] = 13, ["y"] = 2, ["param1"] = 12, ["z"] = 3, ["name"] = "dryplants:reed_slab" }, { ["x"] = 1, ["meta"] = { ["fields"] = {  }, ["inventory"] = {  } }, ["param2"] = 17, ["y"] = 2, ["param1"] = 12, ["z"] = 4, ["name"] = "dryplants:reed_slab" }, { ["x"] = 1, ["meta"] = { ["fields"] = {  }, ["inventory"] = {  } }, ["param2"] = 1, ["y"] = 3, ["param1"] = 13, ["z"] = 1, ["name"] = "dryplants:wetreed_roof_corner" }, { ["x"] = 1, ["meta"] = { ["fields"] = {  }, ["inventory"] = {  } }, ["param2"] = 3, ["y"] = 3, ["param1"] = 12, ["z"] = 2, ["name"] = "dryplants:wetreed_roof_corner" }, { ["x"] = 1, ["meta"] = { ["fields"] = {  }, ["inventory"] = {  } }, ["param2"] = 13, ["y"] = 3, ["param1"] = 12, ["z"] = 3, ["name"] = "dryplants:reed_slab" }, { ["x"] = 1, ["meta"] = { ["fields"] = {  }, ["inventory"] = {  } }, ["param2"] = 0, ["y"] = 3, ["param1"] = 12, ["z"] = 4, ["name"] = "dryplants:wetreed_roof_corner" }, { ["x"] = 1, ["meta"] = { ["fields"] = {  }, ["inventory"] = {  } }, ["param2"] = 2, ["y"] = 3, ["param1"] = 13, ["z"] = 5, ["name"] = "dryplants:wetreed_roof_corner" }, { ["x"] = 1, ["meta"] = { ["fields"] = {  }, ["inventory"] = {  } }, ["param2"] = 1, ["y"] = 4, ["param1"] = 13, ["z"] = 2, ["name"] = "dryplants:wetreed_roof_corner" }, { ["x"] = 1, ["meta"] = { ["fields"] = {  }, ["inventory"] = {  } }, ["param2"] = 1, ["y"] = 4, ["param1"] = 13, ["z"] = 3, ["name"] = "dryplants:wetreed_roof" }, { ["x"] = 1, ["meta"] = { ["fields"] = {  }, ["inventory"] = {  } }, ["param2"] = 2, ["y"] = 4, ["param1"] = 13, ["z"] = 4, ["name"] = "dryplants:wetreed_roof_corner" }, { ["x"] = 2, ["meta"] = { ["fields"] = {  }, ["inventory"] = {  } }, ["param2"] = 0, ["y"] = 0, ["param1"] = 0, ["z"] = 0, ["name"] = "default:desert_sand" }, { ["x"] = 2, ["meta"] = { ["fields"] = {  }, ["inventory"] = {  } }, ["param2"] = 0, ["y"] = 0, ["param1"] = 0, ["z"] = 1, ["name"] = "default:desert_sand" }, { ["x"] = 2, ["meta"] = { ["fields"] = {  }, ["inventory"] = {  } }, ["param2"] = 0, ["y"] = 0, ["param1"] = 0, ["z"] = 2, ["name"] = "default:desert_sand" }, { ["x"] = 2, ["meta"] = { ["fields"] = {  }, ["inventory"] = {  } }, ["param2"] = 0, ["y"] = 0, ["param1"] = 0, ["z"] = 3, ["name"] = "default:desert_sand" }, { ["x"] = 2, ["meta"] = { ["fields"] = {  }, ["inventory"] = {  } }, ["param2"] = 0, ["y"] = 0, ["param1"] = 0, ["z"] = 4, ["name"] = "default:desert_sand" }, { ["x"] = 2, ["meta"] = { ["fields"] = {  }, ["inventory"] = {  } }, ["param2"] = 0, ["y"] = 0, ["param1"] = 0, ["z"] = 5, ["name"] = "default:desert_sand" }, { ["x"] = 2, ["meta"] = { ["fields"] = {  }, ["inventory"] = {  } }, ["param2"] = 0, ["y"] = 0, ["param1"] = 0, ["z"] = 6, ["name"] = "default:desert_sand" }, { ["x"] = 2, ["meta"] = { ["fields"] = {  }, ["inventory"] = {  } }, ["param2"] = 8, ["y"] = 1, ["param1"] = 12, ["z"] = 1, ["name"] = "dryplants:reed_slab" }, { ["x"] = 2, ["meta"] = { ["fields"] = {  }, ["inventory"] = {  } }, ["param2"] = 0, ["y"] = 1, ["param1"] = 11, ["z"] = 3, ["name"] = "cottages:straw_mat" }, { ["x"] = 2, ["meta"] = { ["fields"] = {  }, ["inventory"] = {  } }, ["param2"] = 0, ["y"] = 1, ["param1"] = 11, ["z"] = 4, ["name"] = "cottages:straw_mat" }, { ["x"] = 2, ["meta"] = { ["fields"] = {  }, ["inventory"] = {  } }, ["param2"] = 4, ["y"] = 1, ["param1"] = 12, ["z"] = 5, ["name"] = "dryplants:reed_slab" }, { ["x"] = 2, ["meta"] = { ["fields"] = {  }, ["inventory"] = {  } }, ["param2"] = 8, ["y"] = 2, ["param1"] = 12, ["z"] = 1, ["name"] = "dryplants:reed_slab" }, { ["x"] = 2, ["meta"] = { ["fields"] = {  }, ["inventory"] = {  } }, ["param2"] = 4, ["y"] = 2, ["param1"] = 12, ["z"] = 5, ["name"] = "dryplants:reed_slab" }, { ["x"] = 2, ["meta"] = { ["fields"] = {  }, ["inventory"] = {  } }, ["param2"] = 1, ["y"] = 3, ["param1"] = 13, ["z"] = 0, ["name"] = "dryplants:wetreed_roof_corner" }, { ["x"] = 2, ["meta"] = { ["fields"] = {  }, ["inventory"] = {  } }, ["param2"] = 3, ["y"] = 3, ["param1"] = 12, ["z"] = 1, ["name"] = "dryplants:wetreed_roof_corner" }, { ["x"] = 2, ["meta"] = { ["fields"] = {  }, ["inventory"] = {  } }, ["param2"] = 0, ["y"] = 3, ["param1"] = 12, ["z"] = 5, ["name"] = "dryplants:wetreed_roof_corner" }, { ["x"] = 2, ["meta"] = { ["fields"] = {  }, ["inventory"] = {  } }, ["param2"] = 2, ["y"] = 3, ["param1"] = 13, ["z"] = 6, ["name"] = "dryplants:wetreed_roof_corner" }, { ["x"] = 2, ["meta"] = { ["fields"] = {  }, ["inventory"] = {  } }, ["param2"] = 1, ["y"] = 4, ["param1"] = 13, ["z"] = 1, ["name"] = "dryplants:wetreed_roof_corner" }, { ["x"] = 2, ["meta"] = { ["fields"] = {  }, ["inventory"] = {  } }, ["param2"] = 20, ["y"] = 4, ["param1"] = 12, ["z"] = 2, ["name"] = "dryplants:wetreed_slab" }, { ["x"] = 2, ["meta"] = { ["fields"] = {  }, ["inventory"] = {  } }, ["param2"] = 20, ["y"] = 4, ["param1"] = 12, ["z"] = 4, ["name"] = "dryplants:wetreed_slab" }, { ["x"] = 2, ["meta"] = { ["fields"] = {  }, ["inventory"] = {  } }, ["param2"] = 2, ["y"] = 4, ["param1"] = 13, ["z"] = 5, ["name"] = "dryplants:wetreed_roof_corner" }, { ["x"] = 2, ["meta"] = { ["fields"] = {  }, ["inventory"] = {  } }, ["param2"] = 1, ["y"] = 5, ["param1"] = 13, ["z"] = 2, ["name"] = "dryplants:wetreed_roof_corner" }, { ["x"] = 2, ["meta"] = { ["fields"] = {  }, ["inventory"] = {  } }, ["param2"] = 1, ["y"] = 5, ["param1"] = 13, ["z"] = 3, ["name"] = "dryplants:wetreed_roof" }, { ["x"] = 2, ["meta"] = { ["fields"] = {  }, ["inventory"] = {  } }, ["param2"] = 2, ["y"] = 5, ["param1"] = 13, ["z"] = 4, ["name"] = "dryplants:wetreed_roof_corner" }, { ["x"] = 3, ["meta"] = { ["fields"] = {  }, ["inventory"] = {  } }, ["param2"] = 0, ["y"] = 0, ["param1"] = 0, ["z"] = 0, ["name"] = "default:desert_sand" }, { ["x"] = 3, ["meta"] = { ["fields"] = {  }, ["inventory"] = {  } }, ["param2"] = 0, ["y"] = 0, ["param1"] = 0, ["z"] = 1, ["name"] = "default:desert_sand" }, { ["x"] = 3, ["meta"] = { ["fields"] = {  }, ["inventory"] = {  } }, ["param2"] = 0, ["y"] = 0, ["param1"] = 0, ["z"] = 2, ["name"] = "default:desert_sand" }, { ["x"] = 3, ["meta"] = { ["fields"] = {  }, ["inventory"] = {  } }, ["param2"] = 0, ["y"] = 0, ["param1"] = 0, ["z"] = 3, ["name"] = "default:desert_sand" }, { ["x"] = 3, ["meta"] = { ["fields"] = {  }, ["inventory"] = {  } }, ["param2"] = 0, ["y"] = 0, ["param1"] = 0, ["z"] = 4, ["name"] = "default:desert_sand" }, { ["x"] = 3, ["meta"] = { ["fields"] = {  }, ["inventory"] = {  } }, ["param2"] = 0, ["y"] = 0, ["param1"] = 0, ["z"] = 5, ["name"] = "default:desert_sand" }, { ["x"] = 3, ["meta"] = { ["fields"] = {  }, ["inventory"] = {  } }, ["param2"] = 0, ["y"] = 0, ["param1"] = 0, ["z"] = 6, ["name"] = "default:desert_sand" }, { ["x"] = 3, ["meta"] = { ["fields"] = {  }, ["inventory"] = {  } }, ["param2"] = 4, ["y"] = 1, ["param1"] = 12, ["z"] = 1, ["name"] = "dryplants:reed_slab" }, { ["x"] = 3, ["meta"] = { ["fields"] = {  }, ["inventory"] = {  } }, ["param2"] = 1, ["y"] = 1, ["param1"] = 11, ["z"] = 4, ["name"] = "cottages:straw_mat" }, { ["x"] = 3, ["meta"] = { ["fields"] = {  }, ["inventory"] = {  } }, ["param2"] = 8, ["y"] = 1, ["param1"] = 12, ["z"] = 5, ["name"] = "dryplants:reed_slab" }, { ["x"] = 3, ["meta"] = { ["fields"] = {  }, ["inventory"] = {  } }, ["param2"] = 8, ["y"] = 2, ["param1"] = 12, ["z"] = 5, ["name"] = "dryplants:reed_slab" }, { ["x"] = 3, ["meta"] = { ["fields"] = {  }, ["inventory"] = {  } }, ["param2"] = 0, ["y"] = 3, ["param1"] = 13, ["z"] = 0, ["name"] = "dryplants:wetreed_roof" }, { ["x"] = 3, ["meta"] = { ["fields"] = {  }, ["inventory"] = {  } }, ["param2"] = 4, ["y"] = 3, ["param1"] = 12, ["z"] = 1, ["name"] = "dryplants:reed_slab" }, { ["x"] = 3, ["meta"] = { ["fields"] = {  }, ["inventory"] = {  } }, ["param2"] = 8, ["y"] = 3, ["param1"] = 12, ["z"] = 5, ["name"] = "dryplants:reed_slab" }, { ["x"] = 3, ["meta"] = { ["fields"] = {  }, ["inventory"] = {  } }, ["param2"] = 2, ["y"] = 3, ["param1"] = 13, ["z"] = 6, ["name"] = "dryplants:wetreed_roof" }, { ["x"] = 3, ["meta"] = { ["fields"] = {  }, ["inventory"] = {  } }, ["param2"] = 0, ["y"] = 4, ["param1"] = 13, ["z"] = 1, ["name"] = "dryplants:wetreed_roof" }, { ["x"] = 3, ["meta"] = { ["fields"] = {  }, ["inventory"] = {  } }, ["param2"] = 2, ["y"] = 4, ["param1"] = 13, ["z"] = 5, ["name"] = "dryplants:wetreed_roof" }, { ["x"] = 3, ["meta"] = { ["fields"] = {  }, ["inventory"] = {  } }, ["param2"] = 0, ["y"] = 5, ["param1"] = 13, ["z"] = 2, ["name"] = "dryplants:wetreed_roof" }, { ["x"] = 3, ["meta"] = { ["fields"] = {  }, ["inventory"] = {  } }, ["param2"] = 2, ["y"] = 5, ["param1"] = 13, ["z"] = 4, ["name"] = "dryplants:wetreed_roof" }, { ["x"] = 3, ["meta"] = { ["fields"] = {  }, ["inventory"] = {  } }, ["param2"] = 2, ["y"] = 6, ["param1"] = 13, ["z"] = 3, ["name"] = "dryplants:wetreed_slab" }, { ["x"] = 4, ["meta"] = { ["fields"] = {  }, ["inventory"] = {  } }, ["param2"] = 0, ["y"] = 0, ["param1"] = 0, ["z"] = 0, ["name"] = "default:desert_sand" }, { ["x"] = 4, ["meta"] = { ["fields"] = {  }, ["inventory"] = {  } }, ["param2"] = 0, ["y"] = 0, ["param1"] = 0, ["z"] = 1, ["name"] = "default:desert_sand" }, { ["x"] = 4, ["meta"] = { ["fields"] = {  }, ["inventory"] = {  } }, ["param2"] = 0, ["y"] = 0, ["param1"] = 0, ["z"] = 2, ["name"] = "default:desert_sand" }, { ["x"] = 4, ["meta"] = { ["fields"] = {  }, ["inventory"] = {  } }, ["param2"] = 0, ["y"] = 0, ["param1"] = 0, ["z"] = 3, ["name"] = "default:desert_sand" }, { ["x"] = 4, ["meta"] = { ["fields"] = {  }, ["inventory"] = {  } }, ["param2"] = 0, ["y"] = 0, ["param1"] = 0, ["z"] = 4, ["name"] = "default:desert_sand" }, { ["x"] = 4, ["meta"] = { ["fields"] = {  }, ["inventory"] = {  } }, ["param2"] = 0, ["y"] = 0, ["param1"] = 0, ["z"] = 5, ["name"] = "default:desert_sand" }, { ["x"] = 4, ["meta"] = { ["fields"] = {  }, ["inventory"] = {  } }, ["param2"] = 0, ["y"] = 0, ["param1"] = 0, ["z"] = 6, ["name"] = "default:desert_sand" }, { ["x"] = 4, ["meta"] = { ["fields"] = {  }, ["inventory"] = {  } }, ["param2"] = 8, ["y"] = 1, ["param1"] = 12, ["z"] = 1, ["name"] = "dryplants:reed_slab" }, { ["x"] = 4, ["meta"] = { ["fields"] = {  }, ["inventory"] = {  } }, ["param2"] = 1, ["y"] = 1, ["param1"] = 11, ["z"] = 4, ["name"] = "cottages:straw_mat" }, { ["x"] = 4, ["meta"] = { ["fields"] = {  }, ["inventory"] = {  } }, ["param2"] = 4, ["y"] = 1, ["param1"] = 12, ["z"] = 5, ["name"] = "dryplants:reed_slab" }, { ["x"] = 4, ["meta"] = { ["fields"] = {  }, ["inventory"] = {  } }, ["param2"] = 8, ["y"] = 2, ["param1"] = 12, ["z"] = 1, ["name"] = "dryplants:reed_slab" }, { ["x"] = 4, ["meta"] = { ["fields"] = {  }, ["inventory"] = {  } }, ["param2"] = 4, ["y"] = 2, ["param1"] = 12, ["z"] = 5, ["name"] = "dryplants:reed_slab" }, { ["x"] = 4, ["meta"] = { ["fields"] = {  }, ["inventory"] = {  } }, ["param2"] = 0, ["y"] = 3, ["param1"] = 13, ["z"] = 0, ["name"] = "dryplants:wetreed_roof_corner" }, { ["x"] = 4, ["meta"] = { ["fields"] = {  }, ["inventory"] = {  } }, ["param2"] = 2, ["y"] = 3, ["param1"] = 12, ["z"] = 1, ["name"] = "dryplants:wetreed_roof_corner" }, { ["x"] = 4, ["meta"] = { ["fields"] = {  }, ["inventory"] = {  } }, ["param2"] = 1, ["y"] = 3, ["param1"] = 12, ["z"] = 5, ["name"] = "dryplants:wetreed_roof_corner" }, { ["x"] = 4, ["meta"] = { ["fields"] = {  }, ["inventory"] = {  } }, ["param2"] = 3, ["y"] = 3, ["param1"] = 13, ["z"] = 6, ["name"] = "dryplants:wetreed_roof_corner" }, { ["x"] = 4, ["meta"] = { ["fields"] = {  }, ["inventory"] = {  } }, ["param2"] = 0, ["y"] = 4, ["param1"] = 13, ["z"] = 1, ["name"] = "dryplants:wetreed_roof_corner" }, { ["x"] = 4, ["meta"] = { ["fields"] = {  }, ["inventory"] = {  } }, ["param2"] = 20, ["y"] = 4, ["param1"] = 12, ["z"] = 2, ["name"] = "dryplants:wetreed_slab" }, { ["x"] = 4, ["meta"] = { ["fields"] = {  }, ["inventory"] = {  } }, ["param2"] = 20, ["y"] = 4, ["param1"] = 12, ["z"] = 4, ["name"] = "dryplants:wetreed_slab" }, { ["x"] = 4, ["meta"] = { ["fields"] = {  }, ["inventory"] = {  } }, ["param2"] = 3, ["y"] = 4, ["param1"] = 13, ["z"] = 5, ["name"] = "dryplants:wetreed_roof_corner" }, { ["x"] = 4, ["meta"] = { ["fields"] = {  }, ["inventory"] = {  } }, ["param2"] = 0, ["y"] = 5, ["param1"] = 13, ["z"] = 2, ["name"] = "dryplants:wetreed_roof_corner" }, { ["x"] = 4, ["meta"] = { ["fields"] = {  }, ["inventory"] = {  } }, ["param2"] = 3, ["y"] = 5, ["param1"] = 13, ["z"] = 3, ["name"] = "dryplants:wetreed_roof" }, { ["x"] = 4, ["meta"] = { ["fields"] = {  }, ["inventory"] = {  } }, ["param2"] = 3, ["y"] = 5, ["param1"] = 13, ["z"] = 4, ["name"] = "dryplants:wetreed_roof_corner" }, { ["x"] = 5, ["meta"] = { ["fields"] = {  }, ["inventory"] = {  } }, ["param2"] = 0, ["y"] = 0, ["param1"] = 0, ["z"] = 0, ["name"] = "default:desert_sand" }, { ["x"] = 5, ["meta"] = { ["fields"] = {  }, ["inventory"] = {  } }, ["param2"] = 0, ["y"] = 0, ["param1"] = 0, ["z"] = 1, ["name"] = "default:desert_sand" }, { ["x"] = 5, ["meta"] = { ["fields"] = {  }, ["inventory"] = {  } }, ["param2"] = 0, ["y"] = 0, ["param1"] = 0, ["z"] = 2, ["name"] = "default:desert_sand" }, { ["x"] = 5, ["meta"] = { ["fields"] = {  }, ["inventory"] = {  } }, ["param2"] = 0, ["y"] = 0, ["param1"] = 0, ["z"] = 3, ["name"] = "default:desert_sand" }, { ["x"] = 5, ["meta"] = { ["fields"] = {  }, ["inventory"] = {  } }, ["param2"] = 0, ["y"] = 0, ["param1"] = 0, ["z"] = 4, ["name"] = "default:desert_sand" }, { ["x"] = 5, ["meta"] = { ["fields"] = {  }, ["inventory"] = {  } }, ["param2"] = 0, ["y"] = 0, ["param1"] = 0, ["z"] = 5, ["name"] = "default:desert_sand" }, { ["x"] = 5, ["meta"] = { ["fields"] = {  }, ["inventory"] = {  } }, ["param2"] = 0, ["y"] = 0, ["param1"] = 0, ["z"] = 6, ["name"] = "default:desert_sand" }, { ["x"] = 5, ["meta"] = { ["fields"] = {  }, ["inventory"] = {  } }, ["param2"] = 13, ["y"] = 1, ["param1"] = 12, ["z"] = 2, ["name"] = "dryplants:reed_slab" }, { ["x"] = 5, ["meta"] = { ["fields"] = {  }, ["inventory"] = {  } }, ["param2"] = 13, ["y"] = 1, ["param1"] = 12, ["z"] = 4, ["name"] = "dryplants:reed_slab" }, { ["x"] = 5, ["meta"] = { ["fields"] = {  }, ["inventory"] = {  } }, ["param2"] = 13, ["y"] = 2, ["param1"] = 12, ["z"] = 2, ["name"] = "dryplants:reed_slab" }, { ["x"] = 5, ["meta"] = { ["fields"] = {  }, ["inventory"] = {  } }, ["param2"] = 13, ["y"] = 2, ["param1"] = 12, ["z"] = 4, ["name"] = "dryplants:reed_slab" }, { ["x"] = 5, ["meta"] = { ["fields"] = {  }, ["inventory"] = {  } }, ["param2"] = 0, ["y"] = 3, ["param1"] = 13, ["z"] = 1, ["name"] = "dryplants:wetreed_roof_corner" }, { ["x"] = 5, ["meta"] = { ["fields"] = {  }, ["inventory"] = {  } }, ["param2"] = 2, ["y"] = 3, ["param1"] = 12, ["z"] = 2, ["name"] = "dryplants:wetreed_roof_corner" }, { ["x"] = 5, ["meta"] = { ["fields"] = {  }, ["inventory"] = {  } }, ["param2"] = 17, ["y"] = 3, ["param1"] = 12, ["z"] = 3, ["name"] = "dryplants:reed_slab" }, { ["x"] = 5, ["meta"] = { ["fields"] = {  }, ["inventory"] = {  } }, ["param2"] = 1, ["y"] = 3, ["param1"] = 12, ["z"] = 4, ["name"] = "dryplants:wetreed_roof_corner" }, { ["x"] = 5, ["meta"] = { ["fields"] = {  }, ["inventory"] = {  } }, ["param2"] = 3, ["y"] = 3, ["param1"] = 13, ["z"] = 5, ["name"] = "dryplants:wetreed_roof_corner" }, { ["x"] = 5, ["meta"] = { ["fields"] = {  }, ["inventory"] = {  } }, ["param2"] = 0, ["y"] = 4, ["param1"] = 13, ["z"] = 2, ["name"] = "dryplants:wetreed_roof_corner" }, { ["x"] = 5, ["meta"] = { ["fields"] = {  }, ["inventory"] = {  } }, ["param2"] = 3, ["y"] = 4, ["param1"] = 13, ["z"] = 3, ["name"] = "dryplants:wetreed_roof" }, { ["x"] = 5, ["meta"] = { ["fields"] = {  }, ["inventory"] = {  } }, ["param2"] = 3, ["y"] = 4, ["param1"] = 13, ["z"] = 4, ["name"] = "dryplants:wetreed_roof_corner" }, { ["x"] = 6, ["meta"] = { ["fields"] = {  }, ["inventory"] = {  } }, ["param2"] = 0, ["y"] = 0, ["param1"] = 0, ["z"] = 0, ["name"] = "default:desert_sand" }, { ["x"] = 6, ["meta"] = { ["fields"] = {  }, ["inventory"] = {  } }, ["param2"] = 0, ["y"] = 0, ["param1"] = 0, ["z"] = 1, ["name"] = "default:desert_sand" }, { ["x"] = 6, ["meta"] = { ["fields"] = {  }, ["inventory"] = {  } }, ["param2"] = 0, ["y"] = 0, ["param1"] = 0, ["z"] = 2, ["name"] = "default:desert_sand" }, { ["x"] = 6, ["meta"] = { ["fields"] = {  }, ["inventory"] = {  } }, ["param2"] = 0, ["y"] = 0, ["param1"] = 0, ["z"] = 3, ["name"] = "default:desert_sand" }, { ["x"] = 6, ["meta"] = { ["fields"] = {  }, ["inventory"] = {  } }, ["param2"] = 0, ["y"] = 0, ["param1"] = 0, ["z"] = 4, ["name"] = "default:desert_sand" }, { ["x"] = 6, ["meta"] = { ["fields"] = {  }, ["inventory"] = {  } }, ["param2"] = 0, ["y"] = 0, ["param1"] = 0, ["z"] = 5, ["name"] = "default:desert_sand" }, { ["x"] = 6, ["meta"] = { ["fields"] = {  }, ["inventory"] = {  } }, ["param2"] = 0, ["y"] = 0, ["param1"] = 0, ["z"] = 6, ["name"] = "default:desert_sand" }, { ["x"] = 6, ["meta"] = { ["fields"] = {  }, ["inventory"] = {  } }, ["param2"] = 0, ["y"] = 3, ["param1"] = 13, ["z"] = 2, ["name"] = "dryplants:wetreed_roof_corner" }, { ["x"] = 6, ["meta"] = { ["fields"] = {  }, ["inventory"] = {  } }, ["param2"] = 3, ["y"] = 3, ["param1"] = 13, ["z"] = 3, ["name"] = "dryplants:wetreed_roof" }, { ["x"] = 6, ["meta"] = { ["fields"] = {  }, ["inventory"] = {  } }, ["param2"] = 3, ["y"] = 3, ["param1"] = 13, ["z"] = 4, ["name"] = "dryplants:wetreed_roof_corner" } }