return { { ["x"] = 0, ["meta"] = { ["fields"] = {  }, ["inventory"] = {  } }, ["param2"] = 0, ["y"] = 0, ["param1"] = 0, ["z"] = 0, ["name"] = "default:junglewood" }, { ["x"] = 0, ["meta"] = { ["fields"] = {  }, ["inventory"] = {  } }, ["param2"] = 0, ["y"] = 0, ["param1"] = 0, ["z"] = 1, ["name"] = "default:junglewood" }, { ["x"] = 0, ["meta"] = { ["fields"] = {  }, ["inventory"] = {  } }, ["param2"] = 0, ["y"] = 0, ["param1"] = 0, ["z"] = 2, ["name"] = "default:junglewood" }, { ["x"] = 0, ["meta"] = { ["fields"] = {  }, ["inventory"] = {  } }, ["param2"] = 0, ["y"] = 0, ["param1"] = 0, ["z"] = 3, ["name"] = "default:gravel" }, { ["x"] = 0, ["meta"] = { ["fields"] = {  }, ["inventory"] = {  } }, ["param2"] = 0, ["y"] = 0, ["param1"] = 0, ["z"] = 4, ["name"] = "default:gravel" }, { ["x"] = 0, ["meta"] = { ["fields"] = {  }, ["inventory"] = {  } }, ["param2"] = 0, ["y"] = 0, ["param1"] = 0, ["z"] = 5, ["name"] = "default:gravel" }, { ["x"] = 0, ["meta"] = { ["fields"] = {  }, ["inventory"] = {  } }, ["param2"] = 0, ["y"] = 0, ["param1"] = 0, ["z"] = 6, ["name"] = "default:gravel" }, { ["x"] = 0, ["meta"] = { ["fields"] = {  }, ["inventory"] = {  } }, ["param2"] = 3, ["y"] = 1, ["param1"] = 93, ["z"] = 0, ["name"] = "default:fence_wood" }, { ["x"] = 0, ["meta"] = { ["fields"] = { ["liquid_level"] = "0", ["formspec"] = "size[8,9]image[2.6,2;2,3;default_sandstone.png^[lowpart:93:default_desert_stone.png]label[2.2,0;Pour:]list[current_name;input;3,0.5;1,1;]label[5,3.3;Fill:]list[current_name;output;5,3.8;1,1;]list[current_player;main;0,5;8,4;]" }, ["inventory"] = { ["input"] = { "" }, ["output"] = { "" } } }, ["param2"] = 0, ["y"] = 1, ["param1"] = 125, ["z"] = 2, ["name"] = "cottages:barrel" }, { ["x"] = 0, ["meta"] = { ["fields"] = {  }, ["inventory"] = {  } }, ["param2"] = 19, ["y"] = 1, ["param1"] = 141, ["z"] = 3, ["name"] = "stairs:slab_wood" }, { ["x"] = 0, ["meta"] = { ["fields"] = {  }, ["inventory"] = {  } }, ["param2"] = 19, ["y"] = 1, ["param1"] = 157, ["z"] = 4, ["name"] = "stairs:slab_wood" }, { ["x"] = 0, ["meta"] = { ["fields"] = {  }, ["inventory"] = {  } }, ["param2"] = 19, ["y"] = 1, ["param1"] = 173, ["z"] = 5, ["name"] = "stairs:slab_wood" }, { ["x"] = 0, ["meta"] = { ["fields"] = {  }, ["inventory"] = {  } }, ["param2"] = 3, ["y"] = 2, ["param1"] = 109, ["z"] = 0, ["name"] = "default:fence_wood" }, { ["x"] = 0, ["meta"] = { ["fields"] = {  }, ["inventory"] = {  } }, ["param2"] = 19, ["y"] = 2, ["param1"] = 157, ["z"] = 3, ["name"] = "stairs:slab_wood" }, { ["x"] = 0, ["meta"] = { ["fields"] = {  }, ["inventory"] = {  } }, ["param2"] = 19, ["y"] = 2, ["param1"] = 173, ["z"] = 4, ["name"] = "stairs:slab_wood" }, { ["x"] = 0, ["meta"] = { ["fields"] = {  }, ["inventory"] = {  } }, ["param2"] = 19, ["y"] = 2, ["param1"] = 189, ["z"] = 5, ["name"] = "stairs:slab_wood" }, { ["x"] = 0, ["meta"] = { ["fields"] = {  }, ["inventory"] = {  } }, ["param2"] = 0, ["y"] = 3, ["param1"] = 93, ["z"] = 0, ["name"] = "stairs:slab_cobble" }, { ["x"] = 0, ["meta"] = { ["fields"] = {  }, ["inventory"] = {  } }, ["param2"] = 0, ["y"] = 3, ["param1"] = 109, ["z"] = 1, ["name"] = "stairs:slab_cobble" }, { ["x"] = 0, ["meta"] = { ["fields"] = {  }, ["inventory"] = {  } }, ["param2"] = 0, ["y"] = 3, ["param1"] = 125, ["z"] = 2, ["name"] = "stairs:slab_cobble" }, { ["x"] = 0, ["meta"] = { ["fields"] = {  }, ["inventory"] = {  } }, ["param2"] = 0, ["y"] = 3, ["param1"] = 141, ["z"] = 3, ["name"] = "stairs:slab_cobble" }, { ["x"] = 0, ["meta"] = { ["fields"] = {  }, ["inventory"] = {  } }, ["param2"] = 0, ["y"] = 3, ["param1"] = 157, ["z"] = 4, ["name"] = "stairs:slab_cobble" }, { ["x"] = 0, ["meta"] = { ["fields"] = {  }, ["inventory"] = {  } }, ["param2"] = 0, ["y"] = 3, ["param1"] = 173, ["z"] = 5, ["name"] = "stairs:slab_cobble" }, { ["x"] = 0, ["meta"] = { ["fields"] = {  }, ["inventory"] = {  } }, ["param2"] = 0, ["y"] = 3, ["param1"] = 157, ["z"] = 6, ["name"] = "stairs:slab_cobble" }, { ["x"] = 1, ["meta"] = { ["fields"] = {  }, ["inventory"] = {  } }, ["param2"] = 0, ["y"] = 0, ["param1"] = 0, ["z"] = 0, ["name"] = "default:junglewood" }, { ["x"] = 1, ["meta"] = { ["fields"] = {  }, ["inventory"] = {  } }, ["param2"] = 0, ["y"] = 0, ["param1"] = 0, ["z"] = 1, ["name"] = "default:junglewood" }, { ["x"] = 1, ["meta"] = { ["fields"] = {  }, ["inventory"] = {  } }, ["param2"] = 0, ["y"] = 0, ["param1"] = 0, ["z"] = 2, ["name"] = "default:junglewood" }, { ["x"] = 1, ["meta"] = { ["fields"] = {  }, ["inventory"] = {  } }, ["param2"] = 0, ["y"] = 0, ["param1"] = 0, ["z"] = 3, ["name"] = "default:junglewood" }, { ["x"] = 1, ["meta"] = { ["fields"] = {  }, ["inventory"] = {  } }, ["param2"] = 0, ["y"] = 0, ["param1"] = 0, ["z"] = 4, ["name"] = "default:junglewood" }, { ["x"] = 1, ["meta"] = { ["fields"] = {  }, ["inventory"] = {  } }, ["param2"] = 0, ["y"] = 0, ["param1"] = 0, ["z"] = 5, ["name"] = "default:junglewood" }, { ["x"] = 1, ["meta"] = { ["fields"] = {  }, ["inventory"] = {  } }, ["param2"] = 0, ["y"] = 0, ["param1"] = 0, ["z"] = 6, ["name"] = "default:gravel" }, { ["x"] = 1, ["meta"] = { ["fields"] = {  }, ["inventory"] = {  } }, ["param2"] = 3, ["y"] = 1, ["param1"] = 109, ["z"] = 0, ["name"] = "default:fence_wood" }, { ["x"] = 1, ["meta"] = { ["fields"] = {  }, ["inventory"] = {  } }, ["param2"] = 8, ["y"] = 1, ["param1"] = 140, ["z"] = 2, ["name"] = "stairs:slab_wood" }, { ["x"] = 1, ["meta"] = { ["fields"] = { ["infotext"] = "Chest", ["formspec"] = "size[8,9]bgcolor[#080808BB;true]background[5,5;1,1;gui_formbg.png;true]listcolors[#00000069;#5A5A5A;#141318;#30434C;#FFF]list[current_name;main;0,0.3;8,4;]list[current_player;main;0,4.85;8,1;]list[current_player;main;0,6.08;8,3;8]image[0,4.85;1,1;gui_hb_bg.png]image[1,4.85;1,1;gui_hb_bg.png]image[2,4.85;1,1;gui_hb_bg.png]image[3,4.85;1,1;gui_hb_bg.png]image[4,4.85;1,1;gui_hb_bg.png]image[5,4.85;1,1;gui_hb_bg.png]image[6,4.85;1,1;gui_hb_bg.png]image[7,4.85;1,1;gui_hb_bg.png]" }, ["inventory"] = { ["main"] = { "", "", "", "", "", "", "", "", "", "", "", "", "", "", "", "", "", "", "", "", "", "", "", "", "", "", "", "", "", "", "", "" } } }, ["param2"] = 3, ["y"] = 1, ["param1"] = 0, ["z"] = 3, ["name"] = "default:chest" }, { ["x"] = 1, ["meta"] = { ["fields"] = { ["infotext"] = "Chest", ["formspec"] = "size[8,9]bgcolor[#080808BB;true]background[5,5;1,1;gui_formbg.png;true]listcolors[#00000069;#5A5A5A;#141318;#30434C;#FFF]list[current_name;main;0,0.3;8,4;]list[current_player;main;0,4.85;8,1;]list[current_player;main;0,6.08;8,3;8]image[0,4.85;1,1;gui_hb_bg.png]image[1,4.85;1,1;gui_hb_bg.png]image[2,4.85;1,1;gui_hb_bg.png]image[3,4.85;1,1;gui_hb_bg.png]image[4,4.85;1,1;gui_hb_bg.png]image[5,4.85;1,1;gui_hb_bg.png]image[6,4.85;1,1;gui_hb_bg.png]image[7,4.85;1,1;gui_hb_bg.png]" }, ["inventory"] = { ["main"] = { "", "", "", "", "", "", "", "", "", "", "", "", "", "", "", "", "", "", "", "", "", "", "", "", "", "", "", "", "", "", "", "" } } }, ["param2"] = 3, ["y"] = 1, ["param1"] = 0, ["z"] = 4, ["name"] = "default:chest" }, { ["x"] = 1, ["meta"] = { ["fields"] = { ["infotext"] = "open storage shelf", ["formspec"] = "size[8,8]list[current_name;main;0,0;8,3;]list[current_player;main;0,4;8,4;]" }, ["inventory"] = { ["main"] = { "", "", "", "", "", "", "", "", "", "", "", "", "", "", "", "", "", "", "", "", "", "", "", "" } } }, ["param2"] = 3, ["y"] = 1, ["param1"] = 188, ["z"] = 5, ["name"] = "cottages:shelf" }, { ["x"] = 1, ["meta"] = { ["fields"] = {  }, ["inventory"] = {  } }, ["param2"] = 4, ["y"] = 1, ["param1"] = 173, ["z"] = 6, ["name"] = "stairs:slab_wood" }, { ["x"] = 1, ["meta"] = { ["fields"] = {  }, ["inventory"] = {  } }, ["param2"] = 8, ["y"] = 2, ["param1"] = 156, ["z"] = 2, ["name"] = "stairs:slab_wood" }, { ["x"] = 1, ["meta"] = { ["fields"] = {  }, ["inventory"] = {  } }, ["param2"] = 3, ["y"] = 2, ["param1"] = 172, ["z"] = 3, ["name"] = "cottages:sleeping_mat" }, { ["x"] = 1, ["meta"] = { ["fields"] = {  }, ["inventory"] = {  } }, ["param2"] = 3, ["y"] = 2, ["param1"] = 188, ["z"] = 4, ["name"] = "cottages:sleeping_mat" }, { ["x"] = 1, ["meta"] = { ["fields"] = { ["infotext"] = "open storage shelf", ["formspec"] = "size[8,8]list[current_name;main;0,0;8,3;]list[current_player;main;0,4;8,4;]" }, ["inventory"] = { ["main"] = { "", "", "", "", "", "", "", "", "", "", "", "", "", "", "", "", "", "", "", "", "", "", "", "" } } }, ["param2"] = 3, ["y"] = 2, ["param1"] = 204, ["z"] = 5, ["name"] = "cottages:shelf" }, { ["x"] = 1, ["meta"] = { ["fields"] = {  }, ["inventory"] = {  } }, ["param2"] = 4, ["y"] = 2, ["param1"] = 189, ["z"] = 6, ["name"] = "stairs:slab_wood" }, { ["x"] = 1, ["meta"] = { ["fields"] = {  }, ["inventory"] = {  } }, ["param2"] = 20, ["y"] = 3, ["param1"] = 109, ["z"] = 0, ["name"] = "stairs:slab_cobble" }, { ["x"] = 1, ["meta"] = { ["fields"] = {  }, ["inventory"] = {  } }, ["param2"] = 20, ["y"] = 3, ["param1"] = 125, ["z"] = 1, ["name"] = "stairs:slab_cobble" }, { ["x"] = 1, ["meta"] = { ["fields"] = {  }, ["inventory"] = {  } }, ["param2"] = 20, ["y"] = 3, ["param1"] = 141, ["z"] = 2, ["name"] = "stairs:stair_cobble" }, { ["x"] = 1, ["meta"] = { ["fields"] = {  }, ["inventory"] = {  } }, ["param2"] = 20, ["y"] = 3, ["param1"] = 157, ["z"] = 3, ["name"] = "stairs:slab_cobble" }, { ["x"] = 1, ["meta"] = { ["fields"] = {  }, ["inventory"] = {  } }, ["param2"] = 20, ["y"] = 3, ["param1"] = 173, ["z"] = 4, ["name"] = "stairs:slab_cobble" }, { ["x"] = 1, ["meta"] = { ["fields"] = {  }, ["inventory"] = {  } }, ["param2"] = 20, ["y"] = 3, ["param1"] = 189, ["z"] = 5, ["name"] = "stairs:slab_cobble" }, { ["x"] = 1, ["meta"] = { ["fields"] = {  }, ["inventory"] = {  } }, ["param2"] = 22, ["y"] = 3, ["param1"] = 173, ["z"] = 6, ["name"] = "stairs:stair_cobble" }, { ["x"] = 2, ["meta"] = { ["fields"] = {  }, ["inventory"] = {  } }, ["param2"] = 0, ["y"] = 0, ["param1"] = 0, ["z"] = 0, ["name"] = "default:junglewood" }, { ["x"] = 2, ["meta"] = { ["fields"] = {  }, ["inventory"] = {  } }, ["param2"] = 0, ["y"] = 0, ["param1"] = 0, ["z"] = 1, ["name"] = "default:junglewood" }, { ["x"] = 2, ["meta"] = { ["fields"] = {  }, ["inventory"] = {  } }, ["param2"] = 0, ["y"] = 0, ["param1"] = 0, ["z"] = 2, ["name"] = "default:junglewood" }, { ["x"] = 2, ["meta"] = { ["fields"] = {  }, ["inventory"] = {  } }, ["param2"] = 0, ["y"] = 0, ["param1"] = 0, ["z"] = 3, ["name"] = "default:junglewood" }, { ["x"] = 2, ["meta"] = { ["fields"] = {  }, ["inventory"] = {  } }, ["param2"] = 0, ["y"] = 0, ["param1"] = 0, ["z"] = 4, ["name"] = "default:junglewood" }, { ["x"] = 2, ["meta"] = { ["fields"] = {  }, ["inventory"] = {  } }, ["param2"] = 0, ["y"] = 0, ["param1"] = 0, ["z"] = 5, ["name"] = "default:junglewood" }, { ["x"] = 2, ["meta"] = { ["fields"] = {  }, ["inventory"] = {  } }, ["param2"] = 0, ["y"] = 0, ["param1"] = 0, ["z"] = 6, ["name"] = "default:dirt" }, { ["x"] = 2, ["meta"] = { ["fields"] = {  }, ["inventory"] = {  } }, ["param2"] = 2, ["y"] = 1, ["param1"] = 155, ["z"] = 2, ["name"] = "doors:door_wood_b_1" }, { ["x"] = 2, ["meta"] = { ["fields"] = { ["src_totaltime"] = "0", ["formspec"] = "size[8,9]image[2,2;1,1;default_furnace_fire_bg.png]list[current_name;fuel;2,3;1,1;]list[current_name;src;2,1;1,1;]list[current_name;dst;5,1;2,2;]list[current_player;main;0,5;8,4;]", ["fuel_time"] = "0", ["fuel_totaltime"] = "0", ["src_time"] = "0", ["infotext"] = "Furnace out of fuel" }, ["inventory"] = { ["fuel"] = { "" }, ["dst"] = { "", "", "", "" }, ["src"] = { "" } } }, ["param2"] = 0, ["y"] = 1, ["param1"] = 0, ["z"] = 6, ["name"] = "default:furnace" }, { ["x"] = 2, ["meta"] = { ["fields"] = {  }, ["inventory"] = {  } }, ["param2"] = 2, ["y"] = 2, ["param1"] = 171, ["z"] = 2, ["name"] = "doors:door_wood_t_1" }, { ["x"] = 2, ["meta"] = { ["fields"] = {  }, ["inventory"] = {  } }, ["param2"] = 4, ["y"] = 2, ["param1"] = 0, ["z"] = 5, ["name"] = "default:torch" }, { ["x"] = 2, ["meta"] = { ["fields"] = {  }, ["inventory"] = {  } }, ["param2"] = 0, ["y"] = 2, ["param1"] = 0, ["z"] = 6, ["name"] = "default:stonebrick" }, { ["x"] = 2, ["meta"] = { ["fields"] = {  }, ["inventory"] = {  } }, ["param2"] = 20, ["y"] = 3, ["param1"] = 156, ["z"] = 2, ["name"] = "stairs:stair_cobble" }, { ["x"] = 2, ["meta"] = { ["fields"] = {  }, ["inventory"] = {  } }, ["param2"] = 0, ["y"] = 3, ["param1"] = 0, ["z"] = 6, ["name"] = "default:stonebrick" }, { ["x"] = 2, ["meta"] = { ["fields"] = {  }, ["inventory"] = {  } }, ["param2"] = 0, ["y"] = 4, ["param1"] = 109, ["z"] = 0, ["name"] = "stairs:slab_cobble" }, { ["x"] = 2, ["meta"] = { ["fields"] = {  }, ["inventory"] = {  } }, ["param2"] = 0, ["y"] = 4, ["param1"] = 125, ["z"] = 1, ["name"] = "stairs:slab_cobble" }, { ["x"] = 2, ["meta"] = { ["fields"] = {  }, ["inventory"] = {  } }, ["param2"] = 0, ["y"] = 4, ["param1"] = 141, ["z"] = 2, ["name"] = "stairs:slab_cobble" }, { ["x"] = 2, ["meta"] = { ["fields"] = {  }, ["inventory"] = {  } }, ["param2"] = 0, ["y"] = 4, ["param1"] = 157, ["z"] = 3, ["name"] = "stairs:slab_cobble" }, { ["x"] = 2, ["meta"] = { ["fields"] = {  }, ["inventory"] = {  } }, ["param2"] = 0, ["y"] = 4, ["param1"] = 173, ["z"] = 4, ["name"] = "stairs:slab_cobble" }, { ["x"] = 2, ["meta"] = { ["fields"] = {  }, ["inventory"] = {  } }, ["param2"] = 0, ["y"] = 4, ["param1"] = 189, ["z"] = 5, ["name"] = "stairs:slab_cobble" }, { ["x"] = 2, ["meta"] = { ["fields"] = {  }, ["inventory"] = {  } }, ["param2"] = 0, ["y"] = 4, ["param1"] = 0, ["z"] = 6, ["name"] = "default:stonebrick" }, { ["x"] = 3, ["meta"] = { ["fields"] = {  }, ["inventory"] = {  } }, ["param2"] = 0, ["y"] = 0, ["param1"] = 0, ["z"] = 0, ["name"] = "default:junglewood" }, { ["x"] = 3, ["meta"] = { ["fields"] = {  }, ["inventory"] = {  } }, ["param2"] = 0, ["y"] = 0, ["param1"] = 0, ["z"] = 1, ["name"] = "default:junglewood" }, { ["x"] = 3, ["meta"] = { ["fields"] = {  }, ["inventory"] = {  } }, ["param2"] = 0, ["y"] = 0, ["param1"] = 0, ["z"] = 2, ["name"] = "default:junglewood" }, { ["x"] = 3, ["meta"] = { ["fields"] = { ["infotext"] = "Mill, powered by punching (owned by singleplayer)", ["owner"] = "singleplayer", ["formspec"] = "size[8,8]image[0,1;1,1;farming_wheat_seed.png]list[current_name;seeds;1,1;1,1;]list[current_name;flour;5,1;2,2;]label[0,0.5;Wheat seeds:]label[4,0.5;Flour:]label[0,-0.5;Mill]label[2.5,-0.5;Owner: singleplayer]label[0,2.5;Punch this hand-driven mill]label[0,3.0;to convert wheat seeds into flour.]list[current_player;main;0,4;8,4;]" }, ["inventory"] = { ["flour"] = { "", "", "", "" }, ["seeds"] = { "" } } }, ["param2"] = 1, ["y"] = 0, ["param1"] = 139, ["z"] = 3, ["name"] = "cottages:handmill" }, { ["x"] = 3, ["meta"] = { ["fields"] = {  }, ["inventory"] = {  } }, ["param2"] = 0, ["y"] = 0, ["param1"] = 0, ["z"] = 4, ["name"] = "default:junglewood" }, { ["x"] = 3, ["meta"] = { ["fields"] = {  }, ["inventory"] = {  } }, ["param2"] = 0, ["y"] = 0, ["param1"] = 0, ["z"] = 5, ["name"] = "default:junglewood" }, { ["x"] = 3, ["meta"] = { ["fields"] = {  }, ["inventory"] = {  } }, ["param2"] = 0, ["y"] = 0, ["param1"] = 0, ["z"] = 6, ["name"] = "default:gravel" }, { ["x"] = 3, ["meta"] = { ["fields"] = {  }, ["inventory"] = {  } }, ["param2"] = 0, ["y"] = 1, ["param1"] = 109, ["z"] = 0, ["name"] = "default:fence_wood" }, { ["x"] = 3, ["meta"] = { ["fields"] = {  }, ["inventory"] = {  } }, ["param2"] = 8, ["y"] = 1, ["param1"] = 140, ["z"] = 2, ["name"] = "stairs:slab_wood" }, { ["x"] = 3, ["meta"] = { ["fields"] = {  }, ["inventory"] = {  } }, ["param2"] = 1, ["y"] = 1, ["param1"] = 156, ["z"] = 3, ["name"] = "cottages:hatch_wood" }, { ["x"] = 3, ["meta"] = { ["fields"] = {  }, ["inventory"] = {  } }, ["param2"] = 0, ["y"] = 1, ["param1"] = 172, ["z"] = 4, ["name"] = "cottages:table" }, { ["x"] = 3, ["meta"] = { ["fields"] = {  }, ["inventory"] = {  } }, ["param2"] = 0, ["y"] = 1, ["param1"] = 188, ["z"] = 5, ["name"] = "cottages:bench" }, { ["x"] = 3, ["meta"] = { ["fields"] = {  }, ["inventory"] = {  } }, ["param2"] = 4, ["y"] = 1, ["param1"] = 173, ["z"] = 6, ["name"] = "stairs:slab_wood" }, { ["x"] = 3, ["meta"] = { ["fields"] = {  }, ["inventory"] = {  } }, ["param2"] = 8, ["y"] = 2, ["param1"] = 156, ["z"] = 2, ["name"] = "stairs:slab_wood" }, { ["x"] = 3, ["meta"] = { ["fields"] = {  }, ["inventory"] = {  } }, ["param2"] = 1, ["y"] = 2, ["param1"] = 188, ["z"] = 4, ["name"] = "cottages:window_shutter_open" }, { ["x"] = 3, ["meta"] = { ["fields"] = {  }, ["inventory"] = {  } }, ["param2"] = 4, ["y"] = 2, ["param1"] = 189, ["z"] = 6, ["name"] = "stairs:slab_wood" }, { ["x"] = 3, ["meta"] = { ["fields"] = {  }, ["inventory"] = {  } }, ["param2"] = 20, ["y"] = 3, ["param1"] = 109, ["z"] = 0, ["name"] = "stairs:slab_cobble" }, { ["x"] = 3, ["meta"] = { ["fields"] = {  }, ["inventory"] = {  } }, ["param2"] = 20, ["y"] = 3, ["param1"] = 125, ["z"] = 1, ["name"] = "stairs:slab_cobble" }, { ["x"] = 3, ["meta"] = { ["fields"] = {  }, ["inventory"] = {  } }, ["param2"] = 20, ["y"] = 3, ["param1"] = 141, ["z"] = 2, ["name"] = "stairs:stair_cobble" }, { ["x"] = 3, ["meta"] = { ["fields"] = {  }, ["inventory"] = {  } }, ["param2"] = 20, ["y"] = 3, ["param1"] = 157, ["z"] = 3, ["name"] = "stairs:slab_cobble" }, { ["x"] = 3, ["meta"] = { ["fields"] = {  }, ["inventory"] = {  } }, ["param2"] = 20, ["y"] = 3, ["param1"] = 173, ["z"] = 4, ["name"] = "stairs:slab_cobble" }, { ["x"] = 3, ["meta"] = { ["fields"] = {  }, ["inventory"] = {  } }, ["param2"] = 20, ["y"] = 3, ["param1"] = 189, ["z"] = 5, ["name"] = "stairs:slab_cobble" }, { ["x"] = 3, ["meta"] = { ["fields"] = {  }, ["inventory"] = {  } }, ["param2"] = 22, ["y"] = 3, ["param1"] = 173, ["z"] = 6, ["name"] = "stairs:stair_cobble" }, { ["x"] = 4, ["meta"] = { ["fields"] = {  }, ["inventory"] = {  } }, ["param2"] = 0, ["y"] = 0, ["param1"] = 0, ["z"] = 0, ["name"] = "default:junglewood" }, { ["x"] = 4, ["meta"] = { ["fields"] = {  }, ["inventory"] = {  } }, ["param2"] = 0, ["y"] = 0, ["param1"] = 0, ["z"] = 1, ["name"] = "default:junglewood" }, { ["x"] = 4, ["meta"] = { ["fields"] = {  }, ["inventory"] = {  } }, ["param2"] = 0, ["y"] = 0, ["param1"] = 0, ["z"] = 2, ["name"] = "default:junglewood" }, { ["x"] = 4, ["meta"] = { ["fields"] = {  }, ["inventory"] = {  } }, ["param2"] = 0, ["y"] = 0, ["param1"] = 0, ["z"] = 3, ["name"] = "default:gravel" }, { ["x"] = 4, ["meta"] = { ["fields"] = {  }, ["inventory"] = {  } }, ["param2"] = 0, ["y"] = 0, ["param1"] = 0, ["z"] = 4, ["name"] = "default:gravel" }, { ["x"] = 4, ["meta"] = { ["fields"] = {  }, ["inventory"] = {  } }, ["param2"] = 0, ["y"] = 0, ["param1"] = 0, ["z"] = 5, ["name"] = "default:gravel" }, { ["x"] = 4, ["meta"] = { ["fields"] = {  }, ["inventory"] = {  } }, ["param2"] = 0, ["y"] = 0, ["param1"] = 0, ["z"] = 6, ["name"] = "default:gravel" }, { ["x"] = 4, ["meta"] = { ["fields"] = {  }, ["inventory"] = {  } }, ["param2"] = 1, ["y"] = 1, ["param1"] = 93, ["z"] = 0, ["name"] = "default:fence_wood" }, { ["x"] = 4, ["meta"] = { ["fields"] = {  }, ["inventory"] = {  } }, ["param2"] = 0, ["y"] = 1, ["param1"] = 125, ["z"] = 2, ["name"] = "cottages:tub" }, { ["x"] = 4, ["meta"] = { ["fields"] = {  }, ["inventory"] = {  } }, ["param2"] = 13, ["y"] = 1, ["param1"] = 141, ["z"] = 3, ["name"] = "stairs:slab_wood" }, { ["x"] = 4, ["meta"] = { ["fields"] = {  }, ["inventory"] = {  } }, ["param2"] = 13, ["y"] = 1, ["param1"] = 157, ["z"] = 4, ["name"] = "stairs:slab_wood" }, { ["x"] = 4, ["meta"] = { ["fields"] = {  }, ["inventory"] = {  } }, ["param2"] = 13, ["y"] = 1, ["param1"] = 173, ["z"] = 5, ["name"] = "stairs:slab_wood" }, { ["x"] = 4, ["meta"] = { ["fields"] = {  }, ["inventory"] = {  } }, ["param2"] = 1, ["y"] = 2, ["param1"] = 109, ["z"] = 0, ["name"] = "default:fence_wood" }, { ["x"] = 4, ["meta"] = { ["fields"] = {  }, ["inventory"] = {  } }, ["param2"] = 13, ["y"] = 2, ["param1"] = 157, ["z"] = 3, ["name"] = "stairs:slab_wood" }, { ["x"] = 4, ["meta"] = { ["fields"] = {  }, ["inventory"] = {  } }, ["param2"] = 13, ["y"] = 2, ["param1"] = 189, ["z"] = 5, ["name"] = "stairs:slab_wood" }, { ["x"] = 4, ["meta"] = { ["fields"] = {  }, ["inventory"] = {  } }, ["param2"] = 0, ["y"] = 3, ["param1"] = 93, ["z"] = 0, ["name"] = "stairs:slab_cobble" }, { ["x"] = 4, ["meta"] = { ["fields"] = {  }, ["inventory"] = {  } }, ["param2"] = 0, ["y"] = 3, ["param1"] = 109, ["z"] = 1, ["name"] = "stairs:slab_cobble" }, { ["x"] = 4, ["meta"] = { ["fields"] = {  }, ["inventory"] = {  } }, ["param2"] = 0, ["y"] = 3, ["param1"] = 125, ["z"] = 2, ["name"] = "stairs:slab_cobble" }, { ["x"] = 4, ["meta"] = { ["fields"] = {  }, ["inventory"] = {  } }, ["param2"] = 0, ["y"] = 3, ["param1"] = 141, ["z"] = 3, ["name"] = "stairs:slab_cobble" }, { ["x"] = 4, ["meta"] = { ["fields"] = {  }, ["inventory"] = {  } }, ["param2"] = 0, ["y"] = 3, ["param1"] = 157, ["z"] = 4, ["name"] = "stairs:slab_cobble" }, { ["x"] = 4, ["meta"] = { ["fields"] = {  }, ["inventory"] = {  } }, ["param2"] = 0, ["y"] = 3, ["param1"] = 173, ["z"] = 5, ["name"] = "stairs:slab_cobble" }, { ["x"] = 4, ["meta"] = { ["fields"] = {  }, ["inventory"] = {  } }, ["param2"] = 0, ["y"] = 3, ["param1"] = 157, ["z"] = 6, ["name"] = "stairs:slab_cobble" } }