return { { ["x"] = 0, ["meta"] = { ["fields"] = { ["owner_info"] = "return { [\"y\"] = 75, [\"x\"] = 614, [\"z\"] = -794 }" }, ["inventory"] = {  } }, ["param2"] = 2, ["y"] = 3, ["param1"] = 0, ["z"] = 4, ["name"] = "default:torch" }, { ["x"] = 0, ["meta"] = { ["fields"] = {  }, ["inventory"] = {  } }, ["param2"] = 1, ["y"] = 3, ["param1"] = 205, ["z"] = 6, ["name"] = "cottages:window_shutter_open" }, { ["x"] = 0, ["meta"] = { ["fields"] = { ["owner_info"] = "return { [\"y\"] = 75, [\"x\"] = 614, [\"z\"] = -794 }" }, ["inventory"] = {  } }, ["param2"] = 2, ["y"] = 3, ["param1"] = 0, ["z"] = 7, ["name"] = "default:torch" }, { ["x"] = 0, ["meta"] = { ["fields"] = { ["owner_info"] = "return { [\"y\"] = 75, [\"x\"] = 614, [\"z\"] = -794 }" }, ["inventory"] = {  } }, ["param2"] = 1, ["y"] = 4, ["param1"] = 173, ["z"] = 2, ["name"] = "cottages:roof_wood" }, { ["x"] = 0, ["meta"] = { ["fields"] = { ["owner_info"] = "return { [\"y\"] = 75, [\"x\"] = 614, [\"z\"] = -794 }" }, ["inventory"] = {  } }, ["param2"] = 1, ["y"] = 4, ["param1"] = 189, ["z"] = 3, ["name"] = "cottages:roof_wood" }, { ["x"] = 0, ["meta"] = { ["fields"] = { ["owner_info"] = "return { [\"y\"] = 75, [\"x\"] = 614, [\"z\"] = -794 }" }, ["inventory"] = {  } }, ["param2"] = 1, ["y"] = 4, ["param1"] = 205, ["z"] = 4, ["name"] = "cottages:roof_wood" }, { ["x"] = 0, ["meta"] = { ["fields"] = { ["owner_info"] = "return { [\"y\"] = 75, [\"x\"] = 614, [\"z\"] = -794 }" }, ["inventory"] = {  } }, ["param2"] = 1, ["y"] = 4, ["param1"] = 189, ["z"] = 5, ["name"] = "cottages:roof_wood" }, { ["x"] = 0, ["meta"] = { ["fields"] = { ["owner_info"] = "return { [\"y\"] = 75, [\"x\"] = 614, [\"z\"] = -794 }" }, ["inventory"] = {  } }, ["param2"] = 1, ["y"] = 4, ["param1"] = 189, ["z"] = 6, ["name"] = "cottages:roof_wood" }, { ["x"] = 0, ["meta"] = { ["fields"] = { ["owner_info"] = "return { [\"y\"] = 75, [\"x\"] = 614, [\"z\"] = -794 }" }, ["inventory"] = {  } }, ["param2"] = 1, ["y"] = 4, ["param1"] = 205, ["z"] = 7, ["name"] = "cottages:roof_wood" }, { ["x"] = 0, ["meta"] = { ["fields"] = { ["owner_info"] = "return { [\"y\"] = 75, [\"x\"] = 614, [\"z\"] = -794 }" }, ["inventory"] = {  } }, ["param2"] = 1, ["y"] = 4, ["param1"] = 189, ["z"] = 8, ["name"] = "cottages:roof_wood" }, { ["x"] = 0, ["meta"] = { ["fields"] = { ["owner_info"] = "return { [\"y\"] = 75, [\"x\"] = 614, [\"z\"] = -794 }" }, ["inventory"] = {  } }, ["param2"] = 1, ["y"] = 4, ["param1"] = 173, ["z"] = 9, ["name"] = "cottages:roof_wood" }, { ["x"] = 1, ["meta"] = { ["fields"] = { ["owner_info"] = "return { [\"y\"] = 75, [\"x\"] = 614, [\"z\"] = -794 }" }, ["inventory"] = {  } }, ["param2"] = 1, ["y"] = 0, ["param1"] = 125, ["z"] = 0, ["name"] = "stairs:slab_wood" }, { ["x"] = 1, ["meta"] = { ["fields"] = { ["owner_info"] = "return { [\"y\"] = 75, [\"x\"] = 614, [\"z\"] = -794 }" }, ["inventory"] = {  } }, ["param2"] = 1, ["y"] = 0, ["param1"] = 141, ["z"] = 1, ["name"] = "stairs:slab_wood" }, { ["x"] = 1, ["meta"] = { ["fields"] = { ["owner_info"] = "return { [\"y\"] = 75, [\"x\"] = 614, [\"z\"] = -794 }" }, ["inventory"] = {  } }, ["param2"] = 1, ["y"] = 0, ["param1"] = 156, ["z"] = 2, ["name"] = "stairs:slab_wood" }, { ["x"] = 1, ["meta"] = { ["fields"] = { ["owner_info"] = "return { [\"y\"] = 75, [\"x\"] = 614, [\"z\"] = -794 }" }, ["inventory"] = {  } }, ["param2"] = 1, ["y"] = 0, ["param1"] = 0, ["z"] = 3, ["name"] = "default:tree" }, { ["x"] = 1, ["meta"] = { ["fields"] = { ["owner_info"] = "return { [\"y\"] = 75, [\"x\"] = 614, [\"z\"] = -794 }" }, ["inventory"] = {  } }, ["param2"] = 1, ["y"] = 0, ["param1"] = 0, ["z"] = 8, ["name"] = "default:tree" }, { ["x"] = 1, ["meta"] = { ["fields"] = { ["owner_info"] = "return { [\"y\"] = 75, [\"x\"] = 614, [\"z\"] = -794 }" }, ["inventory"] = {  } }, ["param2"] = 1, ["y"] = 1, ["param1"] = 0, ["z"] = 3, ["name"] = "default:tree" }, { ["x"] = 1, ["meta"] = { ["fields"] = { ["owner_info"] = "return { [\"y\"] = 75, [\"x\"] = 614, [\"z\"] = -794 }" }, ["inventory"] = {  } }, ["param2"] = 1, ["y"] = 1, ["param1"] = 0, ["z"] = 4, ["name"] = "default:wood" }, { ["x"] = 1, ["meta"] = { ["fields"] = { ["owner_info"] = "return { [\"y\"] = 75, [\"x\"] = 614, [\"z\"] = -794 }" }, ["inventory"] = {  } }, ["param2"] = 1, ["y"] = 1, ["param1"] = 0, ["z"] = 5, ["name"] = "default:wood" }, { ["x"] = 1, ["meta"] = { ["fields"] = { ["owner_info"] = "return { [\"y\"] = 75, [\"x\"] = 614, [\"z\"] = -794 }" }, ["inventory"] = {  } }, ["param2"] = 1, ["y"] = 1, ["param1"] = 0, ["z"] = 6, ["name"] = "default:wood" }, { ["x"] = 1, ["meta"] = { ["fields"] = { ["owner_info"] = "return { [\"y\"] = 75, [\"x\"] = 614, [\"z\"] = -794 }" }, ["inventory"] = {  } }, ["param2"] = 1, ["y"] = 1, ["param1"] = 0, ["z"] = 7, ["name"] = "default:wood" }, { ["x"] = 1, ["meta"] = { ["fields"] = { ["owner_info"] = "return { [\"y\"] = 75, [\"x\"] = 614, [\"z\"] = -794 }" }, ["inventory"] = {  } }, ["param2"] = 1, ["y"] = 1, ["param1"] = 0, ["z"] = 8, ["name"] = "default:tree" }, { ["x"] = 1, ["meta"] = { ["fields"] = { ["owner_info"] = "return { [\"y\"] = 75, [\"x\"] = 614, [\"z\"] = -794 }" }, ["inventory"] = {  } }, ["param2"] = 1, ["y"] = 2, ["param1"] = 0, ["z"] = 3, ["name"] = "default:tree" }, { ["x"] = 1, ["meta"] = { ["fields"] = { ["owner_info"] = "return { [\"y\"] = 75, [\"x\"] = 614, [\"z\"] = -794 }" }, ["inventory"] = {  } }, ["param2"] = 1, ["y"] = 2, ["param1"] = 0, ["z"] = 4, ["name"] = "default:wood" }, { ["x"] = 1, ["meta"] = { ["fields"] = { ["owner_info"] = "return { [\"y\"] = 75, [\"x\"] = 614, [\"z\"] = -794 }" }, ["inventory"] = {  } }, ["param2"] = 1, ["y"] = 2, ["param1"] = 0, ["z"] = 5, ["name"] = "default:wood" }, { ["x"] = 1, ["meta"] = { ["fields"] = { ["owner_info"] = "return { [\"y\"] = 75, [\"x\"] = 614, [\"z\"] = -794 }" }, ["inventory"] = {  } }, ["param2"] = 1, ["y"] = 2, ["param1"] = 0, ["z"] = 6, ["name"] = "default:wood" }, { ["x"] = 1, ["meta"] = { ["fields"] = { ["owner_info"] = "return { [\"y\"] = 75, [\"x\"] = 614, [\"z\"] = -794 }" }, ["inventory"] = {  } }, ["param2"] = 1, ["y"] = 2, ["param1"] = 0, ["z"] = 7, ["name"] = "default:wood" }, { ["x"] = 1, ["meta"] = { ["fields"] = { ["owner_info"] = "return { [\"y\"] = 75, [\"x\"] = 614, [\"z\"] = -794 }" }, ["inventory"] = {  } }, ["param2"] = 1, ["y"] = 2, ["param1"] = 0, ["z"] = 8, ["name"] = "default:tree" }, { ["x"] = 1, ["meta"] = { ["fields"] = { ["owner_info"] = "return { [\"y\"] = 75, [\"x\"] = 614, [\"z\"] = -794 }" }, ["inventory"] = {  } }, ["param2"] = 1, ["y"] = 3, ["param1"] = 0, ["z"] = 3, ["name"] = "default:tree" }, { ["x"] = 1, ["meta"] = { ["fields"] = { ["owner_info"] = "return { [\"y\"] = 75, [\"x\"] = 614, [\"z\"] = -794 }" }, ["inventory"] = {  } }, ["param2"] = 1, ["y"] = 3, ["param1"] = 0, ["z"] = 4, ["name"] = "default:wood" }, { ["x"] = 1, ["meta"] = { ["fields"] = {  }, ["inventory"] = {  } }, ["param2"] = 3, ["y"] = 3, ["param1"] = 0, ["z"] = 5, ["name"] = "default:wood" }, { ["x"] = 1, ["meta"] = { ["fields"] = {  }, ["inventory"] = {  } }, ["param2"] = 3, ["y"] = 3, ["param1"] = 188, ["z"] = 6, ["name"] = "cottages:glass_pane" }, { ["x"] = 1, ["meta"] = { ["fields"] = { ["owner_info"] = "return { [\"y\"] = 75, [\"x\"] = 614, [\"z\"] = -794 }" }, ["inventory"] = {  } }, ["param2"] = 1, ["y"] = 3, ["param1"] = 0, ["z"] = 7, ["name"] = "default:wood" }, { ["x"] = 1, ["meta"] = { ["fields"] = { ["owner_info"] = "return { [\"y\"] = 75, [\"x\"] = 614, [\"z\"] = -794 }" }, ["inventory"] = {  } }, ["param2"] = 1, ["y"] = 3, ["param1"] = 0, ["z"] = 8, ["name"] = "default:tree" }, { ["x"] = 1, ["meta"] = { ["fields"] = { ["owner_info"] = "return { [\"y\"] = 75, [\"x\"] = 614, [\"z\"] = -794 }" }, ["inventory"] = {  } }, ["param2"] = 1, ["y"] = 4, ["param1"] = 0, ["z"] = 3, ["name"] = "default:tree" }, { ["x"] = 1, ["meta"] = { ["fields"] = { ["owner_info"] = "return { [\"y\"] = 75, [\"x\"] = 614, [\"z\"] = -794 }" }, ["inventory"] = {  } }, ["param2"] = 1, ["y"] = 4, ["param1"] = 0, ["z"] = 4, ["name"] = "default:wood" }, { ["x"] = 1, ["meta"] = { ["fields"] = { ["owner_info"] = "return { [\"y\"] = 75, [\"x\"] = 614, [\"z\"] = -794 }" }, ["inventory"] = {  } }, ["param2"] = 1, ["y"] = 4, ["param1"] = 0, ["z"] = 5, ["name"] = "default:wood" }, { ["x"] = 1, ["meta"] = { ["fields"] = { ["owner_info"] = "return { [\"y\"] = 75, [\"x\"] = 614, [\"z\"] = -794 }" }, ["inventory"] = {  } }, ["param2"] = 1, ["y"] = 4, ["param1"] = 0, ["z"] = 6, ["name"] = "default:wood" }, { ["x"] = 1, ["meta"] = { ["fields"] = { ["owner_info"] = "return { [\"y\"] = 75, [\"x\"] = 614, [\"z\"] = -794 }" }, ["inventory"] = {  } }, ["param2"] = 1, ["y"] = 4, ["param1"] = 0, ["z"] = 7, ["name"] = "default:wood" }, { ["x"] = 1, ["meta"] = { ["fields"] = { ["owner_info"] = "return { [\"y\"] = 75, [\"x\"] = 614, [\"z\"] = -794 }" }, ["inventory"] = {  } }, ["param2"] = 1, ["y"] = 4, ["param1"] = 0, ["z"] = 8, ["name"] = "default:tree" }, { ["x"] = 1, ["meta"] = { ["fields"] = { ["owner_info"] = "return { [\"y\"] = 75, [\"x\"] = 614, [\"z\"] = -794 }" }, ["inventory"] = {  } }, ["param2"] = 1, ["y"] = 5, ["param1"] = 205, ["z"] = 2, ["name"] = "cottages:roof_wood" }, { ["x"] = 1, ["meta"] = { ["fields"] = { ["owner_info"] = "return { [\"y\"] = 75, [\"x\"] = 614, [\"z\"] = -794 }" }, ["inventory"] = {  } }, ["param2"] = 1, ["y"] = 5, ["param1"] = 189, ["z"] = 3, ["name"] = "cottages:roof_connector_wood" }, { ["x"] = 1, ["meta"] = { ["fields"] = { ["owner_info"] = "return { [\"y\"] = 75, [\"x\"] = 614, [\"z\"] = -794 }" }, ["inventory"] = {  } }, ["param2"] = 1, ["y"] = 5, ["param1"] = 205, ["z"] = 4, ["name"] = "cottages:roof_wood" }, { ["x"] = 1, ["meta"] = { ["fields"] = { ["owner_info"] = "return { [\"y\"] = 75, [\"x\"] = 614, [\"z\"] = -794 }" }, ["inventory"] = {  } }, ["param2"] = 1, ["y"] = 5, ["param1"] = 189, ["z"] = 5, ["name"] = "cottages:roof_wood" }, { ["x"] = 1, ["meta"] = { ["fields"] = { ["owner_info"] = "return { [\"y\"] = 75, [\"x\"] = 614, [\"z\"] = -794 }" }, ["inventory"] = {  } }, ["param2"] = 1, ["y"] = 5, ["param1"] = 173, ["z"] = 6, ["name"] = "cottages:roof_wood" }, { ["x"] = 1, ["meta"] = { ["fields"] = { ["owner_info"] = "return { [\"y\"] = 75, [\"x\"] = 614, [\"z\"] = -794 }" }, ["inventory"] = {  } }, ["param2"] = 1, ["y"] = 5, ["param1"] = 173, ["z"] = 7, ["name"] = "cottages:roof_wood" }, { ["x"] = 1, ["meta"] = { ["fields"] = { ["owner_info"] = "return { [\"y\"] = 75, [\"x\"] = 614, [\"z\"] = -794 }" }, ["inventory"] = {  } }, ["param2"] = 1, ["y"] = 5, ["param1"] = 189, ["z"] = 8, ["name"] = "cottages:roof_connector_wood" }, { ["x"] = 1, ["meta"] = { ["fields"] = { ["owner_info"] = "return { [\"y\"] = 75, [\"x\"] = 614, [\"z\"] = -794 }" }, ["inventory"] = {  } }, ["param2"] = 1, ["y"] = 5, ["param1"] = 205, ["z"] = 9, ["name"] = "cottages:roof_wood" }, { ["x"] = 2, ["meta"] = { ["fields"] = { ["owner_info"] = "return { [\"y\"] = 75, [\"x\"] = 614, [\"z\"] = -794 }" }, ["inventory"] = {  } }, ["param2"] = 1, ["y"] = 0, ["param1"] = 141, ["z"] = 0, ["name"] = "stairs:slab_wood" }, { ["x"] = 2, ["meta"] = { ["fields"] = { ["owner_info"] = "return { [\"y\"] = 75, [\"x\"] = 614, [\"z\"] = -794 }" }, ["inventory"] = {  } }, ["param2"] = 1, ["y"] = 0, ["param1"] = 0, ["z"] = 1, ["name"] = "default:wood" }, { ["x"] = 2, ["meta"] = { ["fields"] = { ["owner_info"] = "return { [\"y\"] = 75, [\"x\"] = 614, [\"z\"] = -794 }" }, ["inventory"] = {  } }, ["param2"] = 1, ["y"] = 0, ["param1"] = 0, ["z"] = 2, ["name"] = "default:wood" }, { ["x"] = 2, ["meta"] = { ["fields"] = { ["owner_info"] = "return { [\"y\"] = 75, [\"x\"] = 614, [\"z\"] = -794 }" }, ["inventory"] = {  } }, ["param2"] = 1, ["y"] = 1, ["param1"] = 0, ["z"] = 3, ["name"] = "default:wood" }, { ["x"] = 2, ["meta"] = { ["fields"] = { ["owner_info"] = "return { [\"y\"] = 75, [\"x\"] = 614, [\"z\"] = -794 }" }, ["inventory"] = {  } }, ["param2"] = 1, ["y"] = 1, ["param1"] = 0, ["z"] = 4, ["name"] = "default:wood" }, { ["x"] = 2, ["meta"] = { ["fields"] = { ["owner_info"] = "return { [\"y\"] = 75, [\"x\"] = 614, [\"z\"] = -794 }" }, ["inventory"] = {  } }, ["param2"] = 1, ["y"] = 1, ["param1"] = 0, ["z"] = 5, ["name"] = "default:wood" }, { ["x"] = 2, ["meta"] = { ["fields"] = { ["owner_info"] = "return { [\"y\"] = 75, [\"x\"] = 614, [\"z\"] = -794 }" }, ["inventory"] = {  } }, ["param2"] = 1, ["y"] = 1, ["param1"] = 0, ["z"] = 6, ["name"] = "default:wood" }, { ["x"] = 2, ["meta"] = { ["fields"] = { ["owner_info"] = "return { [\"y\"] = 75, [\"x\"] = 614, [\"z\"] = -794 }" }, ["inventory"] = {  } }, ["param2"] = 1, ["y"] = 1, ["param1"] = 0, ["z"] = 7, ["name"] = "default:wood" }, { ["x"] = 2, ["meta"] = { ["fields"] = { ["owner_info"] = "return { [\"y\"] = 75, [\"x\"] = 614, [\"z\"] = -794 }" }, ["inventory"] = {  } }, ["param2"] = 1, ["y"] = 1, ["param1"] = 0, ["z"] = 8, ["name"] = "default:wood" }, { ["x"] = 2, ["meta"] = { ["fields"] = { ["owner_info"] = "return { [\"y\"] = 75, [\"x\"] = 614, [\"z\"] = -794 }" }, ["inventory"] = {  } }, ["param2"] = 1, ["y"] = 2, ["param1"] = 0, ["z"] = 3, ["name"] = "default:wood" }, { ["x"] = 2, ["meta"] = { ["fields"] = { ["owner_info"] = "return { [\"y\"] = 75, [\"x\"] = 614, [\"z\"] = -794 }" }, ["inventory"] = {  } }, ["param2"] = 0, ["y"] = 2, ["param1"] = 204, ["z"] = 4, ["name"] = "cottages:bed_foot" }, { ["x"] = 2, ["meta"] = { ["fields"] = { ["owner_info"] = "return { [\"y\"] = 75, [\"x\"] = 614, [\"z\"] = -794 }" }, ["inventory"] = {  } }, ["param2"] = 0, ["y"] = 2, ["param1"] = 187, ["z"] = 5, ["name"] = "cottages:bed_head" }, { ["x"] = 2, ["meta"] = { ["fields"] = {  }, ["inventory"] = {  } }, ["param2"] = 3, ["y"] = 2, ["param1"] = 187, ["z"] = 6, ["name"] = "cottages:bench" }, { ["x"] = 2, ["meta"] = { ["fields"] = { ["src_totaltime"] = "0", ["formspec"] = "size[8,8.5]bgcolor[#080808BB;true]background[5,5;1,1;gui_formbg.png;true]listcolors[#00000069;#5A5A5A;#141318;#30434C;#FFF]list[current_name;src;2.75,0.5;1,1;]list[current_name;fuel;2.75,2.5;1,1;]image[2.75,1.5;1,1;default_furnace_fire_bg.png]image[3.75,1.5;1,1;gui_furnace_arrow_bg.png^[transformR270]list[current_name;dst;4.75,0.96;2,2;]list[current_player;main;0,4.25;8,1;]list[current_player;main;0,5.5;8,3;8]image[0,4.25;1,1;gui_hb_bg.png]image[1,4.25;1,1;gui_hb_bg.png]image[2,4.25;1,1;gui_hb_bg.png]image[3,4.25;1,1;gui_hb_bg.png]image[4,4.25;1,1;gui_hb_bg.png]image[5,4.25;1,1;gui_hb_bg.png]image[6,4.25;1,1;gui_hb_bg.png]image[7,4.25;1,1;gui_hb_bg.png]", ["fuel_time"] = "0", ["fuel_totaltime"] = "0", ["src_time"] = "0", ["infotext"] = "Furnace out of fuel" }, ["inventory"] = { ["fuel"] = { "" }, ["dst"] = { "", "", "", "" }, ["src"] = { "" } } }, ["param2"] = 3, ["y"] = 2, ["param1"] = 0, ["z"] = 7, ["name"] = "default:furnace" }, { ["x"] = 2, ["meta"] = { ["fields"] = { ["owner_info"] = "return { [\"y\"] = 75, [\"x\"] = 614, [\"z\"] = -794 }" }, ["inventory"] = {  } }, ["param2"] = 1, ["y"] = 2, ["param1"] = 0, ["z"] = 8, ["name"] = "default:wood" }, { ["x"] = 2, ["meta"] = { ["fields"] = { ["owner_info"] = "return { [\"y\"] = 75, [\"x\"] = 614, [\"z\"] = -794 }" }, ["inventory"] = {  } }, ["param2"] = 4, ["y"] = 3, ["param1"] = 0, ["z"] = 2, ["name"] = "default:torch" }, { ["x"] = 2, ["meta"] = { ["fields"] = { ["owner_info"] = "return { [\"y\"] = 75, [\"x\"] = 614, [\"z\"] = -794 }" }, ["inventory"] = {  } }, ["param2"] = 1, ["y"] = 3, ["param1"] = 0, ["z"] = 3, ["name"] = "default:wood" }, { ["x"] = 2, ["meta"] = { ["fields"] = { ["owner_info"] = "return { [\"y\"] = 75, [\"x\"] = 614, [\"z\"] = -794 }" }, ["inventory"] = {  } }, ["param2"] = 5, ["y"] = 3, ["param1"] = 0, ["z"] = 4, ["name"] = "default:torch" }, { ["x"] = 2, ["meta"] = { ["fields"] = { ["owner_info"] = "return { [\"y\"] = 75, [\"x\"] = 614, [\"z\"] = -794 }" }, ["inventory"] = {  } }, ["param2"] = 4, ["y"] = 3, ["param1"] = 0, ["z"] = 7, ["name"] = "default:torch" }, { ["x"] = 2, ["meta"] = { ["fields"] = { ["owner_info"] = "return { [\"y\"] = 75, [\"x\"] = 614, [\"z\"] = -794 }" }, ["inventory"] = {  } }, ["param2"] = 1, ["y"] = 3, ["param1"] = 0, ["z"] = 8, ["name"] = "default:wood" }, { ["x"] = 2, ["meta"] = { ["fields"] = { ["owner_info"] = "return { [\"y\"] = 75, [\"x\"] = 614, [\"z\"] = -794 }" }, ["inventory"] = {  } }, ["param2"] = 5, ["y"] = 3, ["param1"] = 0, ["z"] = 9, ["name"] = "default:torch" }, { ["x"] = 2, ["meta"] = { ["fields"] = { ["owner_info"] = "return { [\"y\"] = 75, [\"x\"] = 614, [\"z\"] = -794 }" }, ["inventory"] = {  } }, ["param2"] = 1, ["y"] = 4, ["param1"] = 0, ["z"] = 3, ["name"] = "default:wood" }, { ["x"] = 2, ["meta"] = { ["fields"] = { ["owner_info"] = "return { [\"y\"] = 75, [\"x\"] = 614, [\"z\"] = -794 }" }, ["inventory"] = {  } }, ["param2"] = 1, ["y"] = 4, ["param1"] = 0, ["z"] = 4, ["name"] = "default:wood" }, { ["x"] = 2, ["meta"] = { ["fields"] = { ["owner_info"] = "return { [\"y\"] = 75, [\"x\"] = 614, [\"z\"] = -794 }" }, ["inventory"] = {  } }, ["param2"] = 1, ["y"] = 4, ["param1"] = 0, ["z"] = 5, ["name"] = "default:wood" }, { ["x"] = 2, ["meta"] = { ["fields"] = { ["owner_info"] = "return { [\"y\"] = 75, [\"x\"] = 614, [\"z\"] = -794 }" }, ["inventory"] = {  } }, ["param2"] = 1, ["y"] = 4, ["param1"] = 0, ["z"] = 6, ["name"] = "default:wood" }, { ["x"] = 2, ["meta"] = { ["fields"] = { ["owner_info"] = "return { [\"y\"] = 75, [\"x\"] = 614, [\"z\"] = -794 }" }, ["inventory"] = {  } }, ["param2"] = 1, ["y"] = 4, ["param1"] = 0, ["z"] = 7, ["name"] = "default:wood" }, { ["x"] = 2, ["meta"] = { ["fields"] = { ["owner_info"] = "return { [\"y\"] = 75, [\"x\"] = 614, [\"z\"] = -794 }" }, ["inventory"] = {  } }, ["param2"] = 1, ["y"] = 4, ["param1"] = 0, ["z"] = 8, ["name"] = "default:wood" }, { ["x"] = 2, ["meta"] = { ["fields"] = { ["owner_info"] = "return { [\"y\"] = 75, [\"x\"] = 614, [\"z\"] = -794 }" }, ["inventory"] = {  } }, ["param2"] = 4, ["y"] = 5, ["param1"] = 0, ["z"] = 2, ["name"] = "default:torch" }, { ["x"] = 2, ["meta"] = { ["fields"] = { ["owner_info"] = "return { [\"y\"] = 75, [\"x\"] = 614, [\"z\"] = -794 }" }, ["inventory"] = {  } }, ["param2"] = 1, ["y"] = 5, ["param1"] = 0, ["z"] = 3, ["name"] = "default:wood" }, { ["x"] = 2, ["meta"] = { ["fields"] = { ["owner_info"] = "return { [\"y\"] = 75, [\"x\"] = 614, [\"z\"] = -794 }" }, ["inventory"] = {  } }, ["param2"] = 5, ["y"] = 5, ["param1"] = 0, ["z"] = 4, ["name"] = "default:torch" }, { ["x"] = 2, ["meta"] = { ["fields"] = { ["infotext"] = "Chest", ["formspec"] = "size[8,9]list[current_name;main;0,0;8,4;]list[current_player;main;0,5;8,4;]" }, ["inventory"] = { ["main"] = { "", "", "", "", "", "", "", "", "", "", "", "", "", "", "", "", "", "", "", "", "", "", "", "", "", "", "", "", "", "", "", "" } } }, ["param2"] = 0, ["y"] = 5, ["param1"] = 0, ["z"] = 7, ["name"] = "default:chest" }, { ["x"] = 2, ["meta"] = { ["fields"] = { ["owner_info"] = "return { [\"y\"] = 75, [\"x\"] = 614, [\"z\"] = -794 }" }, ["inventory"] = {  } }, ["param2"] = 1, ["y"] = 5, ["param1"] = 0, ["z"] = 8, ["name"] = "default:wood" }, { ["x"] = 2, ["meta"] = { ["fields"] = { ["owner_info"] = "return { [\"y\"] = 75, [\"x\"] = 614, [\"z\"] = -794 }" }, ["inventory"] = {  } }, ["param2"] = 5, ["y"] = 5, ["param1"] = 0, ["z"] = 9, ["name"] = "default:torch" }, { ["x"] = 2, ["meta"] = { ["fields"] = { ["owner_info"] = "return { [\"y\"] = 75, [\"x\"] = 614, [\"z\"] = -794 }" }, ["inventory"] = {  } }, ["param2"] = 1, ["y"] = 6, ["param1"] = 205, ["z"] = 2, ["name"] = "cottages:roof_wood" }, { ["x"] = 2, ["meta"] = { ["fields"] = { ["owner_info"] = "return { [\"y\"] = 75, [\"x\"] = 614, [\"z\"] = -794 }" }, ["inventory"] = {  } }, ["param2"] = 1, ["y"] = 6, ["param1"] = 189, ["z"] = 3, ["name"] = "cottages:roof_connector_wood" }, { ["x"] = 2, ["meta"] = { ["fields"] = { ["owner_info"] = "return { [\"y\"] = 75, [\"x\"] = 614, [\"z\"] = -794 }" }, ["inventory"] = {  } }, ["param2"] = 1, ["y"] = 6, ["param1"] = 205, ["z"] = 4, ["name"] = "cottages:roof_wood" }, { ["x"] = 2, ["meta"] = { ["fields"] = { ["owner_info"] = "return { [\"y\"] = 75, [\"x\"] = 614, [\"z\"] = -794 }" }, ["inventory"] = {  } }, ["param2"] = 1, ["y"] = 6, ["param1"] = 189, ["z"] = 5, ["name"] = "cottages:roof_wood" }, { ["x"] = 2, ["meta"] = { ["fields"] = { ["owner_info"] = "return { [\"y\"] = 75, [\"x\"] = 614, [\"z\"] = -794 }" }, ["inventory"] = {  } }, ["param2"] = 1, ["y"] = 6, ["param1"] = 173, ["z"] = 6, ["name"] = "cottages:roof_wood" }, { ["x"] = 2, ["meta"] = { ["fields"] = { ["owner_info"] = "return { [\"y\"] = 75, [\"x\"] = 614, [\"z\"] = -794 }" }, ["inventory"] = {  } }, ["param2"] = 1, ["y"] = 6, ["param1"] = 173, ["z"] = 7, ["name"] = "cottages:roof_wood" }, { ["x"] = 2, ["meta"] = { ["fields"] = { ["owner_info"] = "return { [\"y\"] = 75, [\"x\"] = 614, [\"z\"] = -794 }" }, ["inventory"] = {  } }, ["param2"] = 1, ["y"] = 6, ["param1"] = 189, ["z"] = 8, ["name"] = "cottages:roof_connector_wood" }, { ["x"] = 2, ["meta"] = { ["fields"] = { ["owner_info"] = "return { [\"y\"] = 75, [\"x\"] = 614, [\"z\"] = -794 }" }, ["inventory"] = {  } }, ["param2"] = 1, ["y"] = 6, ["param1"] = 205, ["z"] = 9, ["name"] = "cottages:roof_wood" }, { ["x"] = 3, ["meta"] = { ["fields"] = { ["owner_info"] = "return { [\"y\"] = 75, [\"x\"] = 614, [\"z\"] = -794 }" }, ["inventory"] = {  } }, ["param2"] = 1, ["y"] = 0, ["param1"] = 125, ["z"] = 0, ["name"] = "stairs:slab_wood" }, { ["x"] = 3, ["meta"] = { ["fields"] = { ["owner_info"] = "return { [\"y\"] = 75, [\"x\"] = 614, [\"z\"] = -794 }" }, ["inventory"] = {  } }, ["param2"] = 1, ["y"] = 0, ["param1"] = 0, ["z"] = 1, ["name"] = "default:wood" }, { ["x"] = 3, ["meta"] = { ["fields"] = { ["owner_info"] = "return { [\"y\"] = 75, [\"x\"] = 614, [\"z\"] = -794 }" }, ["inventory"] = {  } }, ["param2"] = 1, ["y"] = 0, ["param1"] = 0, ["z"] = 2, ["name"] = "default:wood" }, { ["x"] = 3, ["meta"] = { ["fields"] = { ["owner_info"] = "return { [\"y\"] = 75, [\"x\"] = 614, [\"z\"] = -794 }" }, ["inventory"] = {  } }, ["param2"] = 1, ["y"] = 1, ["param1"] = 173, ["z"] = 2, ["name"] = "stairs:slab_wood" }, { ["x"] = 3, ["meta"] = { ["fields"] = { ["owner_info"] = "return { [\"y\"] = 75, [\"x\"] = 614, [\"z\"] = -794 }" }, ["inventory"] = {  } }, ["param2"] = 1, ["y"] = 1, ["param1"] = 0, ["z"] = 3, ["name"] = "default:wood" }, { ["x"] = 3, ["meta"] = { ["fields"] = { ["owner_info"] = "return { [\"y\"] = 75, [\"x\"] = 614, [\"z\"] = -794 }" }, ["inventory"] = {  } }, ["param2"] = 1, ["y"] = 1, ["param1"] = 0, ["z"] = 4, ["name"] = "default:wood" }, { ["x"] = 3, ["meta"] = { ["fields"] = { ["owner_info"] = "return { [\"y\"] = 75, [\"x\"] = 614, [\"z\"] = -794 }" }, ["inventory"] = {  } }, ["param2"] = 1, ["y"] = 1, ["param1"] = 0, ["z"] = 5, ["name"] = "default:wood" }, { ["x"] = 3, ["meta"] = { ["fields"] = { ["owner_info"] = "return { [\"y\"] = 75, [\"x\"] = 614, [\"z\"] = -794 }" }, ["inventory"] = {  } }, ["param2"] = 1, ["y"] = 1, ["param1"] = 0, ["z"] = 6, ["name"] = "default:wood" }, { ["x"] = 3, ["meta"] = { ["fields"] = { ["owner_info"] = "return { [\"y\"] = 75, [\"x\"] = 614, [\"z\"] = -794 }" }, ["inventory"] = {  } }, ["param2"] = 1, ["y"] = 1, ["param1"] = 0, ["z"] = 7, ["name"] = "default:wood" }, { ["x"] = 3, ["meta"] = { ["fields"] = { ["owner_info"] = "return { [\"y\"] = 75, [\"x\"] = 614, [\"z\"] = -794 }" }, ["inventory"] = {  } }, ["param2"] = 1, ["y"] = 1, ["param1"] = 0, ["z"] = 8, ["name"] = "default:wood" }, { ["x"] = 3, ["meta"] = { ["fields"] = { ["owner_info"] = "return { [\"y\"] = 75, [\"x\"] = 614, [\"z\"] = -794 }" }, ["inventory"] = {  } }, ["param2"] = 0, ["y"] = 2, ["param1"] = 172, ["z"] = 3, ["name"] = "doors:door_wood_b_1" }, { ["x"] = 3, ["meta"] = { ["fields"] = { ["owner_info"] = "return { [\"y\"] = 75, [\"x\"] = 614, [\"z\"] = -794 }" }, ["inventory"] = {  } }, ["param2"] = 1, ["y"] = 2, ["param1"] = 0, ["z"] = 8, ["name"] = "default:wood" }, { ["x"] = 3, ["meta"] = { ["fields"] = { ["owner_info"] = "return { [\"y\"] = 75, [\"x\"] = 614, [\"z\"] = -794 }" }, ["inventory"] = {  } }, ["param2"] = 0, ["y"] = 3, ["param1"] = 188, ["z"] = 3, ["name"] = "doors:door_wood_t_1" }, { ["x"] = 3, ["meta"] = { ["fields"] = {  }, ["inventory"] = {  } }, ["param2"] = 2, ["y"] = 3, ["param1"] = 0, ["z"] = 8, ["name"] = "default:wood" }, { ["x"] = 3, ["meta"] = { ["fields"] = { ["owner_info"] = "return { [\"y\"] = 75, [\"x\"] = 614, [\"z\"] = -794 }" }, ["inventory"] = {  } }, ["param2"] = 1, ["y"] = 4, ["param1"] = 0, ["z"] = 3, ["name"] = "default:wood" }, { ["x"] = 3, ["meta"] = { ["fields"] = { ["owner_info"] = "return { [\"y\"] = 75, [\"x\"] = 614, [\"z\"] = -794 }" }, ["inventory"] = {  } }, ["param2"] = 1, ["y"] = 4, ["param1"] = 0, ["z"] = 4, ["name"] = "default:wood" }, { ["x"] = 3, ["meta"] = { ["fields"] = { ["owner_info"] = "return { [\"y\"] = 75, [\"x\"] = 614, [\"z\"] = -794 }" }, ["inventory"] = {  } }, ["param2"] = 1, ["y"] = 4, ["param1"] = 0, ["z"] = 5, ["name"] = "default:wood" }, { ["x"] = 3, ["meta"] = { ["fields"] = { ["owner_info"] = "return { [\"y\"] = 75, [\"x\"] = 614, [\"z\"] = -794 }" }, ["inventory"] = {  } }, ["param2"] = 1, ["y"] = 4, ["param1"] = 0, ["z"] = 6, ["name"] = "default:wood" }, { ["x"] = 3, ["meta"] = { ["fields"] = { ["owner_info"] = "return { [\"y\"] = 75, [\"x\"] = 614, [\"z\"] = -794 }" }, ["inventory"] = {  } }, ["param2"] = 1, ["y"] = 4, ["param1"] = 0, ["z"] = 7, ["name"] = "default:wood" }, { ["x"] = 3, ["meta"] = { ["fields"] = { ["owner_info"] = "return { [\"y\"] = 75, [\"x\"] = 614, [\"z\"] = -794 }" }, ["inventory"] = {  } }, ["param2"] = 1, ["y"] = 4, ["param1"] = 0, ["z"] = 8, ["name"] = "default:wood" }, { ["x"] = 3, ["meta"] = { ["fields"] = { ["owner_info"] = "return { [\"y\"] = 75, [\"x\"] = 614, [\"z\"] = -794 }" }, ["inventory"] = {  } }, ["param2"] = 1, ["y"] = 5, ["param1"] = 0, ["z"] = 3, ["name"] = "default:wood" }, { ["x"] = 3, ["meta"] = { ["fields"] = { ["owner_info"] = "return { [\"y\"] = 75, [\"x\"] = 614, [\"z\"] = -794 }" }, ["inventory"] = {  } }, ["param2"] = 2, ["y"] = 5, ["param1"] = 204, ["z"] = 4, ["name"] = "cottages:bench" }, { ["x"] = 3, ["meta"] = { ["fields"] = { ["owner_info"] = "return { [\"y\"] = 75, [\"x\"] = 614, [\"z\"] = -794 }" }, ["inventory"] = {  } }, ["param2"] = 0, ["y"] = 5, ["param1"] = 187, ["z"] = 7, ["name"] = "cottages:bench" }, { ["x"] = 3, ["meta"] = { ["fields"] = { ["owner_info"] = "return { [\"y\"] = 75, [\"x\"] = 614, [\"z\"] = -794 }" }, ["inventory"] = {  } }, ["param2"] = 1, ["y"] = 5, ["param1"] = 0, ["z"] = 8, ["name"] = "default:wood" }, { ["x"] = 3, ["meta"] = { ["fields"] = {  }, ["inventory"] = {  } }, ["param2"] = 0, ["y"] = 6, ["param1"] = 189, ["z"] = 2, ["name"] = "cottages:window_shutter_open" }, { ["x"] = 3, ["meta"] = { ["fields"] = {  }, ["inventory"] = {  } }, ["param2"] = 0, ["y"] = 6, ["param1"] = 172, ["z"] = 3, ["name"] = "cottages:glass_pane" }, { ["x"] = 3, ["meta"] = { ["fields"] = {  }, ["inventory"] = {  } }, ["param2"] = 2, ["y"] = 6, ["param1"] = 172, ["z"] = 8, ["name"] = "cottages:glass_pane" }, { ["x"] = 3, ["meta"] = { ["fields"] = {  }, ["inventory"] = {  } }, ["param2"] = 2, ["y"] = 6, ["param1"] = 188, ["z"] = 9, ["name"] = "cottages:window_shutter_open" }, { ["x"] = 3, ["meta"] = { ["fields"] = { ["owner_info"] = "return { [\"y\"] = 75, [\"x\"] = 614, [\"z\"] = -794 }" }, ["inventory"] = {  } }, ["param2"] = 1, ["y"] = 7, ["param1"] = 173, ["z"] = 2, ["name"] = "cottages:roof_wood" }, { ["x"] = 3, ["meta"] = { ["fields"] = { ["owner_info"] = "return { [\"y\"] = 75, [\"x\"] = 614, [\"z\"] = -794 }" }, ["inventory"] = {  } }, ["param2"] = 1, ["y"] = 7, ["param1"] = 157, ["z"] = 3, ["name"] = "cottages:roof_connector_wood" }, { ["x"] = 3, ["meta"] = { ["fields"] = { ["owner_info"] = "return { [\"y\"] = 75, [\"x\"] = 614, [\"z\"] = -794 }" }, ["inventory"] = {  } }, ["param2"] = 1, ["y"] = 7, ["param1"] = 173, ["z"] = 4, ["name"] = "cottages:roof_wood" }, { ["x"] = 3, ["meta"] = { ["fields"] = { ["owner_info"] = "return { [\"y\"] = 75, [\"x\"] = 614, [\"z\"] = -794 }" }, ["inventory"] = {  } }, ["param2"] = 1, ["y"] = 7, ["param1"] = 157, ["z"] = 5, ["name"] = "cottages:roof_wood" }, { ["x"] = 3, ["meta"] = { ["fields"] = { ["owner_info"] = "return { [\"y\"] = 75, [\"x\"] = 614, [\"z\"] = -794 }" }, ["inventory"] = {  } }, ["param2"] = 1, ["y"] = 7, ["param1"] = 141, ["z"] = 6, ["name"] = "cottages:roof_wood" }, { ["x"] = 3, ["meta"] = { ["fields"] = { ["owner_info"] = "return { [\"y\"] = 75, [\"x\"] = 614, [\"z\"] = -794 }" }, ["inventory"] = {  } }, ["param2"] = 1, ["y"] = 7, ["param1"] = 157, ["z"] = 7, ["name"] = "cottages:roof_wood" }, { ["x"] = 3, ["meta"] = { ["fields"] = { ["owner_info"] = "return { [\"y\"] = 75, [\"x\"] = 614, [\"z\"] = -794 }" }, ["inventory"] = {  } }, ["param2"] = 1, ["y"] = 7, ["param1"] = 157, ["z"] = 8, ["name"] = "cottages:roof_connector_wood" }, { ["x"] = 3, ["meta"] = { ["fields"] = { ["owner_info"] = "return { [\"y\"] = 75, [\"x\"] = 614, [\"z\"] = -794 }" }, ["inventory"] = {  } }, ["param2"] = 1, ["y"] = 7, ["param1"] = 173, ["z"] = 9, ["name"] = "cottages:roof_wood" }, { ["x"] = 4, ["meta"] = { ["fields"] = { ["owner_info"] = "return { [\"y\"] = 75, [\"x\"] = 614, [\"z\"] = -794 }" }, ["inventory"] = {  } }, ["param2"] = 1, ["y"] = 0, ["param1"] = 141, ["z"] = 0, ["name"] = "stairs:slab_wood" }, { ["x"] = 4, ["meta"] = { ["fields"] = { ["owner_info"] = "return { [\"y\"] = 75, [\"x\"] = 614, [\"z\"] = -794 }" }, ["inventory"] = {  } }, ["param2"] = 1, ["y"] = 0, ["param1"] = 0, ["z"] = 1, ["name"] = "default:wood" }, { ["x"] = 4, ["meta"] = { ["fields"] = { ["owner_info"] = "return { [\"y\"] = 75, [\"x\"] = 614, [\"z\"] = -794 }" }, ["inventory"] = {  } }, ["param2"] = 1, ["y"] = 0, ["param1"] = 0, ["z"] = 2, ["name"] = "default:wood" }, { ["x"] = 4, ["meta"] = { ["fields"] = { ["owner_info"] = "return { [\"y\"] = 75, [\"x\"] = 614, [\"z\"] = -794 }" }, ["inventory"] = {  } }, ["param2"] = 1, ["y"] = 1, ["param1"] = 0, ["z"] = 3, ["name"] = "default:wood" }, { ["x"] = 4, ["meta"] = { ["fields"] = { ["owner_info"] = "return { [\"y\"] = 75, [\"x\"] = 614, [\"z\"] = -794 }" }, ["inventory"] = {  } }, ["param2"] = 1, ["y"] = 1, ["param1"] = 0, ["z"] = 4, ["name"] = "default:wood" }, { ["x"] = 4, ["meta"] = { ["fields"] = { ["owner_info"] = "return { [\"y\"] = 75, [\"x\"] = 614, [\"z\"] = -794 }" }, ["inventory"] = {  } }, ["param2"] = 1, ["y"] = 1, ["param1"] = 0, ["z"] = 5, ["name"] = "default:wood" }, { ["x"] = 4, ["meta"] = { ["fields"] = { ["owner_info"] = "return { [\"y\"] = 75, [\"x\"] = 614, [\"z\"] = -794 }" }, ["inventory"] = {  } }, ["param2"] = 1, ["y"] = 1, ["param1"] = 0, ["z"] = 6, ["name"] = "default:wood" }, { ["x"] = 4, ["meta"] = { ["fields"] = { ["owner_info"] = "return { [\"y\"] = 75, [\"x\"] = 614, [\"z\"] = -794 }" }, ["inventory"] = {  } }, ["param2"] = 1, ["y"] = 1, ["param1"] = 0, ["z"] = 7, ["name"] = "default:wood" }, { ["x"] = 4, ["meta"] = { ["fields"] = { ["owner_info"] = "return { [\"y\"] = 75, [\"x\"] = 614, [\"z\"] = -794 }" }, ["inventory"] = {  } }, ["param2"] = 1, ["y"] = 1, ["param1"] = 0, ["z"] = 8, ["name"] = "default:wood" }, { ["x"] = 4, ["meta"] = { ["fields"] = { ["owner_info"] = "return { [\"y\"] = 75, [\"x\"] = 614, [\"z\"] = -794 }" }, ["inventory"] = {  } }, ["param2"] = 1, ["y"] = 2, ["param1"] = 0, ["z"] = 3, ["name"] = "default:wood" }, { ["x"] = 4, ["meta"] = { ["fields"] = { ["owner_info"] = "return { [\"y\"] = 75, [\"x\"] = 614, [\"z\"] = -794 }" }, ["inventory"] = {  } }, ["param2"] = 5, ["y"] = 2, ["param1"] = 187, ["z"] = 4, ["name"] = "default:ladder" }, { ["x"] = 4, ["meta"] = { ["fields"] = { ["owner_info"] = "return { [\"y\"] = 75, [\"x\"] = 614, [\"z\"] = -794 }" }, ["inventory"] = {  } }, ["param2"] = 0, ["y"] = 2, ["param1"] = 187, ["z"] = 7, ["name"] = "cottages:bench" }, { ["x"] = 4, ["meta"] = { ["fields"] = { ["owner_info"] = "return { [\"y\"] = 75, [\"x\"] = 614, [\"z\"] = -794 }" }, ["inventory"] = {  } }, ["param2"] = 1, ["y"] = 2, ["param1"] = 0, ["z"] = 8, ["name"] = "default:wood" }, { ["x"] = 4, ["meta"] = { ["fields"] = { ["owner_info"] = "return { [\"y\"] = 75, [\"x\"] = 614, [\"z\"] = -794 }" }, ["inventory"] = {  } }, ["param2"] = 4, ["y"] = 3, ["param1"] = 0, ["z"] = 2, ["name"] = "default:torch" }, { ["x"] = 4, ["meta"] = { ["fields"] = { ["owner_info"] = "return { [\"y\"] = 75, [\"x\"] = 614, [\"z\"] = -794 }" }, ["inventory"] = {  } }, ["param2"] = 1, ["y"] = 3, ["param1"] = 0, ["z"] = 3, ["name"] = "default:wood" }, { ["x"] = 4, ["meta"] = { ["fields"] = { ["owner_info"] = "return { [\"y\"] = 75, [\"x\"] = 614, [\"z\"] = -794 }" }, ["inventory"] = {  } }, ["param2"] = 5, ["y"] = 3, ["param1"] = 204, ["z"] = 4, ["name"] = "default:ladder" }, { ["x"] = 4, ["meta"] = { ["fields"] = {  }, ["inventory"] = {  } }, ["param2"] = 2, ["y"] = 3, ["param1"] = 187, ["z"] = 8, ["name"] = "cottages:glass_pane" }, { ["x"] = 4, ["meta"] = { ["fields"] = {  }, ["inventory"] = {  } }, ["param2"] = 2, ["y"] = 3, ["param1"] = 204, ["z"] = 9, ["name"] = "cottages:window_shutter_open" }, { ["x"] = 4, ["meta"] = { ["fields"] = { ["owner_info"] = "return { [\"y\"] = 75, [\"x\"] = 614, [\"z\"] = -794 }" }, ["inventory"] = {  } }, ["param2"] = 1, ["y"] = 4, ["param1"] = 0, ["z"] = 3, ["name"] = "default:wood" }, { ["x"] = 4, ["meta"] = { ["fields"] = { ["owner_info"] = "return { [\"y\"] = 75, [\"x\"] = 614, [\"z\"] = -794 }" }, ["inventory"] = {  } }, ["param2"] = 5, ["y"] = 4, ["param1"] = 187, ["z"] = 4, ["name"] = "default:ladder" }, { ["x"] = 4, ["meta"] = { ["fields"] = { ["owner_info"] = "return { [\"y\"] = 75, [\"x\"] = 614, [\"z\"] = -794 }" }, ["inventory"] = {  } }, ["param2"] = 1, ["y"] = 4, ["param1"] = 0, ["z"] = 5, ["name"] = "default:wood" }, { ["x"] = 4, ["meta"] = { ["fields"] = { ["owner_info"] = "return { [\"y\"] = 75, [\"x\"] = 614, [\"z\"] = -794 }" }, ["inventory"] = {  } }, ["param2"] = 1, ["y"] = 4, ["param1"] = 0, ["z"] = 6, ["name"] = "default:wood" }, { ["x"] = 4, ["meta"] = { ["fields"] = { ["owner_info"] = "return { [\"y\"] = 75, [\"x\"] = 614, [\"z\"] = -794 }" }, ["inventory"] = {  } }, ["param2"] = 1, ["y"] = 4, ["param1"] = 0, ["z"] = 7, ["name"] = "default:wood" }, { ["x"] = 4, ["meta"] = { ["fields"] = { ["owner_info"] = "return { [\"y\"] = 75, [\"x\"] = 614, [\"z\"] = -794 }" }, ["inventory"] = {  } }, ["param2"] = 1, ["y"] = 4, ["param1"] = 0, ["z"] = 8, ["name"] = "default:wood" }, { ["x"] = 4, ["meta"] = { ["fields"] = { ["owner_info"] = "return { [\"y\"] = 75, [\"x\"] = 614, [\"z\"] = -794 }" }, ["inventory"] = {  } }, ["param2"] = 1, ["y"] = 5, ["param1"] = 0, ["z"] = 3, ["name"] = "default:wood" }, { ["x"] = 4, ["meta"] = { ["fields"] = { ["owner_info"] = "return { [\"y\"] = 75, [\"x\"] = 614, [\"z\"] = -794 }" }, ["inventory"] = {  } }, ["param2"] = 5, ["y"] = 5, ["param1"] = 204, ["z"] = 4, ["name"] = "default:ladder" }, { ["x"] = 4, ["meta"] = { ["fields"] = { ["owner_info"] = "return { [\"y\"] = 75, [\"x\"] = 614, [\"z\"] = -794 }" }, ["inventory"] = {  } }, ["param2"] = 0, ["y"] = 5, ["param1"] = 187, ["z"] = 6, ["name"] = "cottages:bed_foot" }, { ["x"] = 4, ["meta"] = { ["fields"] = { ["owner_info"] = "return { [\"y\"] = 75, [\"x\"] = 614, [\"z\"] = -794 }" }, ["inventory"] = {  } }, ["param2"] = 0, ["y"] = 5, ["param1"] = 204, ["z"] = 7, ["name"] = "cottages:bed_head" }, { ["x"] = 4, ["meta"] = { ["fields"] = { ["owner_info"] = "return { [\"y\"] = 75, [\"x\"] = 614, [\"z\"] = -794 }" }, ["inventory"] = {  } }, ["param2"] = 1, ["y"] = 5, ["param1"] = 0, ["z"] = 8, ["name"] = "default:wood" }, { ["x"] = 4, ["meta"] = { ["fields"] = { ["owner_info"] = "return { [\"y\"] = 75, [\"x\"] = 614, [\"z\"] = -794 }" }, ["inventory"] = {  } }, ["param2"] = 1, ["y"] = 6, ["param1"] = 0, ["z"] = 3, ["name"] = "default:wood" }, { ["x"] = 4, ["meta"] = { ["fields"] = { ["owner_info"] = "return { [\"y\"] = 75, [\"x\"] = 614, [\"z\"] = -794 }" }, ["inventory"] = {  } }, ["param2"] = 5, ["y"] = 6, ["param1"] = 188, ["z"] = 4, ["name"] = "default:ladder" }, { ["x"] = 4, ["meta"] = { ["fields"] = { ["owner_info"] = "return { [\"y\"] = 75, [\"x\"] = 614, [\"z\"] = -794 }" }, ["inventory"] = {  } }, ["param2"] = 1, ["y"] = 6, ["param1"] = 0, ["z"] = 8, ["name"] = "default:wood" }, { ["x"] = 4, ["meta"] = { ["fields"] = { ["owner_info"] = "return { [\"y\"] = 75, [\"x\"] = 614, [\"z\"] = -794 }" }, ["inventory"] = {  } }, ["param2"] = 3, ["y"] = 7, ["param1"] = 173, ["z"] = 2, ["name"] = "cottages:roof_wood" }, { ["x"] = 4, ["meta"] = { ["fields"] = { ["owner_info"] = "return { [\"y\"] = 75, [\"x\"] = 614, [\"z\"] = -794 }" }, ["inventory"] = {  } }, ["param2"] = 3, ["y"] = 7, ["param1"] = 157, ["z"] = 3, ["name"] = "cottages:roof_connector_wood" }, { ["x"] = 4, ["meta"] = { ["fields"] = { ["owner_info"] = "return { [\"y\"] = 75, [\"x\"] = 614, [\"z\"] = -794 }" }, ["inventory"] = {  } }, ["param2"] = 3, ["y"] = 7, ["param1"] = 173, ["z"] = 4, ["name"] = "cottages:roof_wood" }, { ["x"] = 4, ["meta"] = { ["fields"] = { ["owner_info"] = "return { [\"y\"] = 75, [\"x\"] = 614, [\"z\"] = -794 }" }, ["inventory"] = {  } }, ["param2"] = 3, ["y"] = 7, ["param1"] = 157, ["z"] = 5, ["name"] = "cottages:roof_wood" }, { ["x"] = 4, ["meta"] = { ["fields"] = { ["owner_info"] = "return { [\"y\"] = 75, [\"x\"] = 614, [\"z\"] = -794 }" }, ["inventory"] = {  } }, ["param2"] = 3, ["y"] = 7, ["param1"] = 157, ["z"] = 6, ["name"] = "cottages:roof_wood" }, { ["x"] = 4, ["meta"] = { ["fields"] = { ["owner_info"] = "return { [\"y\"] = 75, [\"x\"] = 614, [\"z\"] = -794 }" }, ["inventory"] = {  } }, ["param2"] = 3, ["y"] = 7, ["param1"] = 173, ["z"] = 7, ["name"] = "cottages:roof_wood" }, { ["x"] = 4, ["meta"] = { ["fields"] = { ["owner_info"] = "return { [\"y\"] = 75, [\"x\"] = 614, [\"z\"] = -794 }" }, ["inventory"] = {  } }, ["param2"] = 3, ["y"] = 7, ["param1"] = 157, ["z"] = 8, ["name"] = "cottages:roof_connector_wood" }, { ["x"] = 4, ["meta"] = { ["fields"] = { ["owner_info"] = "return { [\"y\"] = 75, [\"x\"] = 614, [\"z\"] = -794 }" }, ["inventory"] = {  } }, ["param2"] = 3, ["y"] = 7, ["param1"] = 173, ["z"] = 9, ["name"] = "cottages:roof_wood" }, { ["x"] = 5, ["meta"] = { ["fields"] = { ["owner_info"] = "return { [\"y\"] = 75, [\"x\"] = 614, [\"z\"] = -794 }" }, ["inventory"] = {  } }, ["param2"] = 1, ["y"] = 0, ["param1"] = 125, ["z"] = 0, ["name"] = "stairs:slab_wood" }, { ["x"] = 5, ["meta"] = { ["fields"] = { ["owner_info"] = "return { [\"y\"] = 75, [\"x\"] = 614, [\"z\"] = -794 }" }, ["inventory"] = {  } }, ["param2"] = 1, ["y"] = 0, ["param1"] = 0, ["z"] = 1, ["name"] = "default:wood" }, { ["x"] = 5, ["meta"] = { ["fields"] = { ["owner_info"] = "return { [\"y\"] = 75, [\"x\"] = 614, [\"z\"] = -794 }" }, ["inventory"] = {  } }, ["param2"] = 1, ["y"] = 0, ["param1"] = 0, ["z"] = 2, ["name"] = "default:wood" }, { ["x"] = 5, ["meta"] = { ["fields"] = { ["owner_info"] = "return { [\"y\"] = 75, [\"x\"] = 614, [\"z\"] = -794 }" }, ["inventory"] = {  } }, ["param2"] = 0, ["y"] = 1, ["param1"] = 173, ["z"] = 2, ["name"] = "cottages:bench" }, { ["x"] = 5, ["meta"] = { ["fields"] = { ["owner_info"] = "return { [\"y\"] = 75, [\"x\"] = 614, [\"z\"] = -794 }" }, ["inventory"] = {  } }, ["param2"] = 1, ["y"] = 1, ["param1"] = 0, ["z"] = 3, ["name"] = "default:wood" }, { ["x"] = 5, ["meta"] = { ["fields"] = { ["owner_info"] = "return { [\"y\"] = 75, [\"x\"] = 614, [\"z\"] = -794 }" }, ["inventory"] = {  } }, ["param2"] = 1, ["y"] = 1, ["param1"] = 0, ["z"] = 4, ["name"] = "default:wood" }, { ["x"] = 5, ["meta"] = { ["fields"] = { ["owner_info"] = "return { [\"y\"] = 75, [\"x\"] = 614, [\"z\"] = -794 }" }, ["inventory"] = {  } }, ["param2"] = 1, ["y"] = 1, ["param1"] = 0, ["z"] = 5, ["name"] = "default:wood" }, { ["x"] = 5, ["meta"] = { ["fields"] = { ["owner_info"] = "return { [\"y\"] = 75, [\"x\"] = 614, [\"z\"] = -794 }" }, ["inventory"] = {  } }, ["param2"] = 1, ["y"] = 1, ["param1"] = 0, ["z"] = 6, ["name"] = "default:wood" }, { ["x"] = 5, ["meta"] = { ["fields"] = { ["owner_info"] = "return { [\"y\"] = 75, [\"x\"] = 614, [\"z\"] = -794 }" }, ["inventory"] = {  } }, ["param2"] = 1, ["y"] = 1, ["param1"] = 0, ["z"] = 7, ["name"] = "default:wood" }, { ["x"] = 5, ["meta"] = { ["fields"] = { ["owner_info"] = "return { [\"y\"] = 75, [\"x\"] = 614, [\"z\"] = -794 }" }, ["inventory"] = {  } }, ["param2"] = 1, ["y"] = 1, ["param1"] = 0, ["z"] = 8, ["name"] = "default:wood" }, { ["x"] = 5, ["meta"] = { ["fields"] = { ["owner_info"] = "return { [\"y\"] = 75, [\"x\"] = 614, [\"z\"] = -794 }" }, ["inventory"] = {  } }, ["param2"] = 1, ["y"] = 2, ["param1"] = 0, ["z"] = 3, ["name"] = "default:wood" }, { ["x"] = 5, ["meta"] = { ["fields"] = { ["infotext"] = "Chest", ["formspec"] = "size[8,9]list[current_name;main;0,0;8,4;]list[current_player;main;0,5;8,4;]" }, ["inventory"] = { ["main"] = { "", "", "", "", "", "", "", "", "", "", "", "", "", "", "", "", "", "", "", "", "", "", "", "", "", "", "", "", "", "", "", "" } } }, ["param2"] = 1, ["y"] = 2, ["param1"] = 0, ["z"] = 5, ["name"] = "default:chest" }, { ["x"] = 5, ["meta"] = { ["fields"] = { ["owner_info"] = "return { [\"y\"] = 75, [\"x\"] = 614, [\"z\"] = -794 }" }, ["inventory"] = {  } }, ["param2"] = 0, ["y"] = 2, ["param1"] = 187, ["z"] = 6, ["name"] = "cottages:bed_foot" }, { ["x"] = 5, ["meta"] = { ["fields"] = { ["owner_info"] = "return { [\"y\"] = 75, [\"x\"] = 614, [\"z\"] = -794 }" }, ["inventory"] = {  } }, ["param2"] = 0, ["y"] = 2, ["param1"] = 204, ["z"] = 7, ["name"] = "cottages:bed_head" }, { ["x"] = 5, ["meta"] = { ["fields"] = { ["owner_info"] = "return { [\"y\"] = 75, [\"x\"] = 614, [\"z\"] = -794 }" }, ["inventory"] = {  } }, ["param2"] = 1, ["y"] = 2, ["param1"] = 0, ["z"] = 8, ["name"] = "default:wood" }, { ["x"] = 5, ["meta"] = { ["fields"] = {  }, ["inventory"] = {  } }, ["param2"] = 0, ["y"] = 3, ["param1"] = 205, ["z"] = 2, ["name"] = "cottages:window_shutter_open" }, { ["x"] = 5, ["meta"] = { ["fields"] = {  }, ["inventory"] = {  } }, ["param2"] = 0, ["y"] = 3, ["param1"] = 204, ["z"] = 3, ["name"] = "cottages:glass_pane" }, { ["x"] = 5, ["meta"] = { ["fields"] = { ["owner_info"] = "return { [\"y\"] = 75, [\"x\"] = 614, [\"z\"] = -794 }" }, ["inventory"] = {  } }, ["param2"] = 2, ["y"] = 3, ["param1"] = 0, ["z"] = 4, ["name"] = "default:torch" }, { ["x"] = 5, ["meta"] = { ["fields"] = { ["owner_info"] = "return { [\"y\"] = 75, [\"x\"] = 614, [\"z\"] = -794 }" }, ["inventory"] = {  } }, ["param2"] = 4, ["y"] = 3, ["param1"] = 0, ["z"] = 7, ["name"] = "default:torch" }, { ["x"] = 5, ["meta"] = { ["fields"] = { ["owner_info"] = "return { [\"y\"] = 75, [\"x\"] = 614, [\"z\"] = -794 }" }, ["inventory"] = {  } }, ["param2"] = 1, ["y"] = 3, ["param1"] = 0, ["z"] = 8, ["name"] = "default:wood" }, { ["x"] = 5, ["meta"] = { ["fields"] = { ["owner_info"] = "return { [\"y\"] = 75, [\"x\"] = 614, [\"z\"] = -794 }" }, ["inventory"] = {  } }, ["param2"] = 5, ["y"] = 3, ["param1"] = 0, ["z"] = 9, ["name"] = "default:torch" }, { ["x"] = 5, ["meta"] = { ["fields"] = { ["owner_info"] = "return { [\"y\"] = 75, [\"x\"] = 614, [\"z\"] = -794 }" }, ["inventory"] = {  } }, ["param2"] = 1, ["y"] = 4, ["param1"] = 0, ["z"] = 3, ["name"] = "default:wood" }, { ["x"] = 5, ["meta"] = { ["fields"] = { ["owner_info"] = "return { [\"y\"] = 75, [\"x\"] = 614, [\"z\"] = -794 }" }, ["inventory"] = {  } }, ["param2"] = 1, ["y"] = 4, ["param1"] = 0, ["z"] = 4, ["name"] = "default:wood" }, { ["x"] = 5, ["meta"] = { ["fields"] = { ["owner_info"] = "return { [\"y\"] = 75, [\"x\"] = 614, [\"z\"] = -794 }" }, ["inventory"] = {  } }, ["param2"] = 1, ["y"] = 4, ["param1"] = 0, ["z"] = 5, ["name"] = "default:wood" }, { ["x"] = 5, ["meta"] = { ["fields"] = { ["owner_info"] = "return { [\"y\"] = 75, [\"x\"] = 614, [\"z\"] = -794 }" }, ["inventory"] = {  } }, ["param2"] = 1, ["y"] = 4, ["param1"] = 0, ["z"] = 6, ["name"] = "default:wood" }, { ["x"] = 5, ["meta"] = { ["fields"] = { ["owner_info"] = "return { [\"y\"] = 75, [\"x\"] = 614, [\"z\"] = -794 }" }, ["inventory"] = {  } }, ["param2"] = 1, ["y"] = 4, ["param1"] = 0, ["z"] = 7, ["name"] = "default:wood" }, { ["x"] = 5, ["meta"] = { ["fields"] = { ["owner_info"] = "return { [\"y\"] = 75, [\"x\"] = 614, [\"z\"] = -794 }" }, ["inventory"] = {  } }, ["param2"] = 1, ["y"] = 4, ["param1"] = 0, ["z"] = 8, ["name"] = "default:wood" }, { ["x"] = 5, ["meta"] = { ["fields"] = { ["owner_info"] = "return { [\"y\"] = 75, [\"x\"] = 614, [\"z\"] = -794 }" }, ["inventory"] = {  } }, ["param2"] = 4, ["y"] = 5, ["param1"] = 0, ["z"] = 2, ["name"] = "default:torch" }, { ["x"] = 5, ["meta"] = { ["fields"] = { ["owner_info"] = "return { [\"y\"] = 75, [\"x\"] = 614, [\"z\"] = -794 }" }, ["inventory"] = {  } }, ["param2"] = 1, ["y"] = 5, ["param1"] = 0, ["z"] = 3, ["name"] = "default:wood" }, { ["x"] = 5, ["meta"] = { ["fields"] = { ["owner_info"] = "return { [\"y\"] = 75, [\"x\"] = 614, [\"z\"] = -794 }" }, ["inventory"] = {  } }, ["param2"] = 5, ["y"] = 5, ["param1"] = 0, ["z"] = 4, ["name"] = "default:torch" }, { ["x"] = 5, ["meta"] = { ["fields"] = { ["infotext"] = "Chest", ["owner_info"] = "return { [\"y\"] = 75, [\"x\"] = 614, [\"z\"] = -794 }", ["formspec"] = "size[8,9]list[current_name;main;0,0;8,4;]list[current_player;main;0,5;8,4;]" }, ["inventory"] = { ["main"] = { "", "", "", "", "default:axe_stone", "", "farming:string 3", "", "", "", "default:paper 6", "default:paper 6", "", "", "", "", "default:book", "", "default:pick_stone", "", "", "", "", "", "", "", "default:book", "", "default:torch 9", "", "", "" } } }, ["param2"] = 1, ["y"] = 5, ["param1"] = 0, ["z"] = 5, ["name"] = "default:chest" }, { ["x"] = 5, ["meta"] = { ["fields"] = { ["owner_info"] = "return { [\"y\"] = 75, [\"x\"] = 614, [\"z\"] = -794 }" }, ["inventory"] = {  } }, ["param2"] = 4, ["y"] = 5, ["param1"] = 0, ["z"] = 7, ["name"] = "default:torch" }, { ["x"] = 5, ["meta"] = { ["fields"] = { ["owner_info"] = "return { [\"y\"] = 75, [\"x\"] = 614, [\"z\"] = -794 }" }, ["inventory"] = {  } }, ["param2"] = 1, ["y"] = 5, ["param1"] = 0, ["z"] = 8, ["name"] = "default:wood" }, { ["x"] = 5, ["meta"] = { ["fields"] = { ["owner_info"] = "return { [\"y\"] = 75, [\"x\"] = 614, [\"z\"] = -794 }" }, ["inventory"] = {  } }, ["param2"] = 5, ["y"] = 5, ["param1"] = 0, ["z"] = 9, ["name"] = "default:torch" }, { ["x"] = 5, ["meta"] = { ["fields"] = { ["owner_info"] = "return { [\"y\"] = 75, [\"x\"] = 614, [\"z\"] = -794 }" }, ["inventory"] = {  } }, ["param2"] = 3, ["y"] = 6, ["param1"] = 205, ["z"] = 2, ["name"] = "cottages:roof_wood" }, { ["x"] = 5, ["meta"] = { ["fields"] = { ["owner_info"] = "return { [\"y\"] = 75, [\"x\"] = 614, [\"z\"] = -794 }" }, ["inventory"] = {  } }, ["param2"] = 3, ["y"] = 6, ["param1"] = 189, ["z"] = 3, ["name"] = "cottages:roof_connector_wood" }, { ["x"] = 5, ["meta"] = { ["fields"] = { ["owner_info"] = "return { [\"y\"] = 75, [\"x\"] = 614, [\"z\"] = -794 }" }, ["inventory"] = {  } }, ["param2"] = 3, ["y"] = 6, ["param1"] = 205, ["z"] = 4, ["name"] = "cottages:roof_wood" }, { ["x"] = 5, ["meta"] = { ["fields"] = { ["owner_info"] = "return { [\"y\"] = 75, [\"x\"] = 614, [\"z\"] = -794 }" }, ["inventory"] = {  } }, ["param2"] = 3, ["y"] = 6, ["param1"] = 189, ["z"] = 5, ["name"] = "cottages:roof_wood" }, { ["x"] = 5, ["meta"] = { ["fields"] = { ["owner_info"] = "return { [\"y\"] = 75, [\"x\"] = 614, [\"z\"] = -794 }" }, ["inventory"] = {  } }, ["param2"] = 3, ["y"] = 6, ["param1"] = 189, ["z"] = 6, ["name"] = "cottages:roof_wood" }, { ["x"] = 5, ["meta"] = { ["fields"] = { ["owner_info"] = "return { [\"y\"] = 75, [\"x\"] = 614, [\"z\"] = -794 }" }, ["inventory"] = {  } }, ["param2"] = 3, ["y"] = 6, ["param1"] = 205, ["z"] = 7, ["name"] = "cottages:roof_wood" }, { ["x"] = 5, ["meta"] = { ["fields"] = { ["owner_info"] = "return { [\"y\"] = 75, [\"x\"] = 614, [\"z\"] = -794 }" }, ["inventory"] = {  } }, ["param2"] = 3, ["y"] = 6, ["param1"] = 189, ["z"] = 8, ["name"] = "cottages:roof_connector_wood" }, { ["x"] = 5, ["meta"] = { ["fields"] = { ["owner_info"] = "return { [\"y\"] = 75, [\"x\"] = 614, [\"z\"] = -794 }" }, ["inventory"] = {  } }, ["param2"] = 3, ["y"] = 6, ["param1"] = 205, ["z"] = 9, ["name"] = "cottages:roof_wood" }, { ["x"] = 6, ["meta"] = { ["fields"] = { ["owner_info"] = "return { [\"y\"] = 75, [\"x\"] = 614, [\"z\"] = -794 }" }, ["inventory"] = {  } }, ["param2"] = 1, ["y"] = 0, ["param1"] = 109, ["z"] = 0, ["name"] = "stairs:slab_wood" }, { ["x"] = 6, ["meta"] = { ["fields"] = { ["owner_info"] = "return { [\"y\"] = 75, [\"x\"] = 614, [\"z\"] = -794 }" }, ["inventory"] = {  } }, ["param2"] = 1, ["y"] = 0, ["param1"] = 125, ["z"] = 1, ["name"] = "stairs:slab_wood" }, { ["x"] = 6, ["meta"] = { ["fields"] = { ["owner_info"] = "return { [\"y\"] = 75, [\"x\"] = 614, [\"z\"] = -794 }" }, ["inventory"] = {  } }, ["param2"] = 1, ["y"] = 0, ["param1"] = 140, ["z"] = 2, ["name"] = "stairs:slab_wood" }, { ["x"] = 6, ["meta"] = { ["fields"] = { ["owner_info"] = "return { [\"y\"] = 75, [\"x\"] = 614, [\"z\"] = -794 }" }, ["inventory"] = {  } }, ["param2"] = 1, ["y"] = 0, ["param1"] = 0, ["z"] = 3, ["name"] = "default:tree" }, { ["x"] = 6, ["meta"] = { ["fields"] = { ["owner_info"] = "return { [\"y\"] = 75, [\"x\"] = 614, [\"z\"] = -794 }" }, ["inventory"] = {  } }, ["param2"] = 1, ["y"] = 0, ["param1"] = 0, ["z"] = 8, ["name"] = "default:tree" }, { ["x"] = 6, ["meta"] = { ["fields"] = { ["owner_info"] = "return { [\"y\"] = 75, [\"x\"] = 614, [\"z\"] = -794 }" }, ["inventory"] = {  } }, ["param2"] = 1, ["y"] = 1, ["param1"] = 0, ["z"] = 3, ["name"] = "default:tree" }, { ["x"] = 6, ["meta"] = { ["fields"] = { ["owner_info"] = "return { [\"y\"] = 75, [\"x\"] = 614, [\"z\"] = -794 }" }, ["inventory"] = {  } }, ["param2"] = 1, ["y"] = 1, ["param1"] = 0, ["z"] = 4, ["name"] = "default:wood" }, { ["x"] = 6, ["meta"] = { ["fields"] = { ["owner_info"] = "return { [\"y\"] = 75, [\"x\"] = 614, [\"z\"] = -794 }" }, ["inventory"] = {  } }, ["param2"] = 1, ["y"] = 1, ["param1"] = 0, ["z"] = 5, ["name"] = "default:wood" }, { ["x"] = 6, ["meta"] = { ["fields"] = { ["owner_info"] = "return { [\"y\"] = 75, [\"x\"] = 614, [\"z\"] = -794 }" }, ["inventory"] = {  } }, ["param2"] = 1, ["y"] = 1, ["param1"] = 0, ["z"] = 6, ["name"] = "default:wood" }, { ["x"] = 6, ["meta"] = { ["fields"] = { ["owner_info"] = "return { [\"y\"] = 75, [\"x\"] = 614, [\"z\"] = -794 }" }, ["inventory"] = {  } }, ["param2"] = 1, ["y"] = 1, ["param1"] = 0, ["z"] = 7, ["name"] = "default:wood" }, { ["x"] = 6, ["meta"] = { ["fields"] = { ["owner_info"] = "return { [\"y\"] = 75, [\"x\"] = 614, [\"z\"] = -794 }" }, ["inventory"] = {  } }, ["param2"] = 1, ["y"] = 1, ["param1"] = 0, ["z"] = 8, ["name"] = "default:tree" }, { ["x"] = 6, ["meta"] = { ["fields"] = { ["owner_info"] = "return { [\"y\"] = 75, [\"x\"] = 614, [\"z\"] = -794 }" }, ["inventory"] = {  } }, ["param2"] = 1, ["y"] = 2, ["param1"] = 0, ["z"] = 3, ["name"] = "default:tree" }, { ["x"] = 6, ["meta"] = { ["fields"] = { ["owner_info"] = "return { [\"y\"] = 75, [\"x\"] = 614, [\"z\"] = -794 }" }, ["inventory"] = {  } }, ["param2"] = 1, ["y"] = 2, ["param1"] = 0, ["z"] = 4, ["name"] = "default:wood" }, { ["x"] = 6, ["meta"] = { ["fields"] = { ["owner_info"] = "return { [\"y\"] = 75, [\"x\"] = 614, [\"z\"] = -794 }" }, ["inventory"] = {  } }, ["param2"] = 1, ["y"] = 2, ["param1"] = 0, ["z"] = 5, ["name"] = "default:wood" }, { ["x"] = 6, ["meta"] = { ["fields"] = { ["owner_info"] = "return { [\"y\"] = 75, [\"x\"] = 614, [\"z\"] = -794 }" }, ["inventory"] = {  } }, ["param2"] = 1, ["y"] = 2, ["param1"] = 0, ["z"] = 6, ["name"] = "default:wood" }, { ["x"] = 6, ["meta"] = { ["fields"] = { ["owner_info"] = "return { [\"y\"] = 75, [\"x\"] = 614, [\"z\"] = -794 }" }, ["inventory"] = {  } }, ["param2"] = 1, ["y"] = 2, ["param1"] = 0, ["z"] = 7, ["name"] = "default:wood" }, { ["x"] = 6, ["meta"] = { ["fields"] = { ["owner_info"] = "return { [\"y\"] = 75, [\"x\"] = 614, [\"z\"] = -794 }" }, ["inventory"] = {  } }, ["param2"] = 1, ["y"] = 2, ["param1"] = 0, ["z"] = 8, ["name"] = "default:tree" }, { ["x"] = 6, ["meta"] = { ["fields"] = { ["owner_info"] = "return { [\"y\"] = 75, [\"x\"] = 614, [\"z\"] = -794 }" }, ["inventory"] = {  } }, ["param2"] = 1, ["y"] = 3, ["param1"] = 0, ["z"] = 3, ["name"] = "default:tree" }, { ["x"] = 6, ["meta"] = { ["fields"] = { ["owner_info"] = "return { [\"y\"] = 75, [\"x\"] = 614, [\"z\"] = -794 }" }, ["inventory"] = {  } }, ["param2"] = 1, ["y"] = 3, ["param1"] = 0, ["z"] = 4, ["name"] = "default:wood" }, { ["x"] = 6, ["meta"] = { ["fields"] = { ["owner_info"] = "return { [\"y\"] = 75, [\"x\"] = 614, [\"z\"] = -794 }" }, ["inventory"] = {  } }, ["param2"] = 1, ["y"] = 3, ["param1"] = 0, ["z"] = 5, ["name"] = "default:wood" }, { ["x"] = 6, ["meta"] = { ["fields"] = { ["owner_info"] = "return { [\"y\"] = 75, [\"x\"] = 614, [\"z\"] = -794 }" }, ["inventory"] = {  } }, ["param2"] = 1, ["y"] = 3, ["param1"] = 0, ["z"] = 6, ["name"] = "default:wood" }, { ["x"] = 6, ["meta"] = { ["fields"] = { ["owner_info"] = "return { [\"y\"] = 75, [\"x\"] = 614, [\"z\"] = -794 }" }, ["inventory"] = {  } }, ["param2"] = 1, ["y"] = 3, ["param1"] = 0, ["z"] = 7, ["name"] = "default:wood" }, { ["x"] = 6, ["meta"] = { ["fields"] = { ["owner_info"] = "return { [\"y\"] = 75, [\"x\"] = 614, [\"z\"] = -794 }" }, ["inventory"] = {  } }, ["param2"] = 1, ["y"] = 3, ["param1"] = 0, ["z"] = 8, ["name"] = "default:tree" }, { ["x"] = 6, ["meta"] = { ["fields"] = { ["owner_info"] = "return { [\"y\"] = 75, [\"x\"] = 614, [\"z\"] = -794 }" }, ["inventory"] = {  } }, ["param2"] = 1, ["y"] = 4, ["param1"] = 0, ["z"] = 3, ["name"] = "default:tree" }, { ["x"] = 6, ["meta"] = { ["fields"] = { ["owner_info"] = "return { [\"y\"] = 75, [\"x\"] = 614, [\"z\"] = -794 }" }, ["inventory"] = {  } }, ["param2"] = 1, ["y"] = 4, ["param1"] = 0, ["z"] = 4, ["name"] = "default:wood" }, { ["x"] = 6, ["meta"] = { ["fields"] = { ["owner_info"] = "return { [\"y\"] = 75, [\"x\"] = 614, [\"z\"] = -794 }" }, ["inventory"] = {  } }, ["param2"] = 1, ["y"] = 4, ["param1"] = 0, ["z"] = 5, ["name"] = "default:wood" }, { ["x"] = 6, ["meta"] = { ["fields"] = { ["owner_info"] = "return { [\"y\"] = 75, [\"x\"] = 614, [\"z\"] = -794 }" }, ["inventory"] = {  } }, ["param2"] = 1, ["y"] = 4, ["param1"] = 0, ["z"] = 6, ["name"] = "default:wood" }, { ["x"] = 6, ["meta"] = { ["fields"] = { ["owner_info"] = "return { [\"y\"] = 75, [\"x\"] = 614, [\"z\"] = -794 }" }, ["inventory"] = {  } }, ["param2"] = 1, ["y"] = 4, ["param1"] = 0, ["z"] = 7, ["name"] = "default:wood" }, { ["x"] = 6, ["meta"] = { ["fields"] = { ["owner_info"] = "return { [\"y\"] = 75, [\"x\"] = 614, [\"z\"] = -794 }" }, ["inventory"] = {  } }, ["param2"] = 1, ["y"] = 4, ["param1"] = 0, ["z"] = 8, ["name"] = "default:tree" }, { ["x"] = 6, ["meta"] = { ["fields"] = { ["owner_info"] = "return { [\"y\"] = 75, [\"x\"] = 614, [\"z\"] = -794 }" }, ["inventory"] = {  } }, ["param2"] = 3, ["y"] = 5, ["param1"] = 205, ["z"] = 2, ["name"] = "cottages:roof_wood" }, { ["x"] = 6, ["meta"] = { ["fields"] = { ["owner_info"] = "return { [\"y\"] = 75, [\"x\"] = 614, [\"z\"] = -794 }" }, ["inventory"] = {  } }, ["param2"] = 3, ["y"] = 5, ["param1"] = 189, ["z"] = 3, ["name"] = "cottages:roof_connector_wood" }, { ["x"] = 6, ["meta"] = { ["fields"] = { ["owner_info"] = "return { [\"y\"] = 75, [\"x\"] = 614, [\"z\"] = -794 }" }, ["inventory"] = {  } }, ["param2"] = 3, ["y"] = 5, ["param1"] = 205, ["z"] = 4, ["name"] = "cottages:roof_wood" }, { ["x"] = 6, ["meta"] = { ["fields"] = { ["owner_info"] = "return { [\"y\"] = 75, [\"x\"] = 614, [\"z\"] = -794 }" }, ["inventory"] = {  } }, ["param2"] = 3, ["y"] = 5, ["param1"] = 189, ["z"] = 5, ["name"] = "cottages:roof_wood" }, { ["x"] = 6, ["meta"] = { ["fields"] = { ["owner_info"] = "return { [\"y\"] = 75, [\"x\"] = 614, [\"z\"] = -794 }" }, ["inventory"] = {  } }, ["param2"] = 3, ["y"] = 5, ["param1"] = 189, ["z"] = 6, ["name"] = "cottages:roof_wood" }, { ["x"] = 6, ["meta"] = { ["fields"] = { ["owner_info"] = "return { [\"y\"] = 75, [\"x\"] = 614, [\"z\"] = -794 }" }, ["inventory"] = {  } }, ["param2"] = 3, ["y"] = 5, ["param1"] = 205, ["z"] = 7, ["name"] = "cottages:roof_wood" }, { ["x"] = 6, ["meta"] = { ["fields"] = { ["owner_info"] = "return { [\"y\"] = 75, [\"x\"] = 614, [\"z\"] = -794 }" }, ["inventory"] = {  } }, ["param2"] = 3, ["y"] = 5, ["param1"] = 189, ["z"] = 8, ["name"] = "cottages:roof_connector_wood" }, { ["x"] = 6, ["meta"] = { ["fields"] = { ["owner_info"] = "return { [\"y\"] = 75, [\"x\"] = 614, [\"z\"] = -794 }" }, ["inventory"] = {  } }, ["param2"] = 3, ["y"] = 5, ["param1"] = 205, ["z"] = 9, ["name"] = "cottages:roof_wood" }, { ["x"] = 7, ["meta"] = { ["fields"] = { ["owner_info"] = "return { [\"y\"] = 75, [\"x\"] = 614, [\"z\"] = -794 }" }, ["inventory"] = {  } }, ["param2"] = 3, ["y"] = 3, ["param1"] = 0, ["z"] = 4, ["name"] = "default:torch" }, { ["x"] = 7, ["meta"] = { ["fields"] = { ["owner_info"] = "return { [\"y\"] = 75, [\"x\"] = 614, [\"z\"] = -794 }" }, ["inventory"] = {  } }, ["param2"] = 3, ["y"] = 3, ["param1"] = 0, ["z"] = 7, ["name"] = "default:torch" }, { ["x"] = 7, ["meta"] = { ["fields"] = { ["owner_info"] = "return { [\"y\"] = 75, [\"x\"] = 614, [\"z\"] = -794 }" }, ["inventory"] = {  } }, ["param2"] = 3, ["y"] = 4, ["param1"] = 173, ["z"] = 2, ["name"] = "cottages:roof_wood" }, { ["x"] = 7, ["meta"] = { ["fields"] = { ["owner_info"] = "return { [\"y\"] = 75, [\"x\"] = 614, [\"z\"] = -794 }" }, ["inventory"] = {  } }, ["param2"] = 3, ["y"] = 4, ["param1"] = 189, ["z"] = 3, ["name"] = "cottages:roof_wood" }, { ["x"] = 7, ["meta"] = { ["fields"] = { ["owner_info"] = "return { [\"y\"] = 75, [\"x\"] = 614, [\"z\"] = -794 }" }, ["inventory"] = {  } }, ["param2"] = 3, ["y"] = 4, ["param1"] = 205, ["z"] = 4, ["name"] = "cottages:roof_wood" }, { ["x"] = 7, ["meta"] = { ["fields"] = { ["owner_info"] = "return { [\"y\"] = 75, [\"x\"] = 614, [\"z\"] = -794 }" }, ["inventory"] = {  } }, ["param2"] = 3, ["y"] = 4, ["param1"] = 189, ["z"] = 5, ["name"] = "cottages:roof_wood" }, { ["x"] = 7, ["meta"] = { ["fields"] = { ["owner_info"] = "return { [\"y\"] = 75, [\"x\"] = 614, [\"z\"] = -794 }" }, ["inventory"] = {  } }, ["param2"] = 3, ["y"] = 4, ["param1"] = 189, ["z"] = 6, ["name"] = "cottages:roof_wood" }, { ["x"] = 7, ["meta"] = { ["fields"] = { ["owner_info"] = "return { [\"y\"] = 75, [\"x\"] = 614, [\"z\"] = -794 }" }, ["inventory"] = {  } }, ["param2"] = 3, ["y"] = 4, ["param1"] = 205, ["z"] = 7, ["name"] = "cottages:roof_wood" }, { ["x"] = 7, ["meta"] = { ["fields"] = { ["owner_info"] = "return { [\"y\"] = 75, [\"x\"] = 614, [\"z\"] = -794 }" }, ["inventory"] = {  } }, ["param2"] = 3, ["y"] = 4, ["param1"] = 189, ["z"] = 8, ["name"] = "cottages:roof_wood" }, { ["x"] = 7, ["meta"] = { ["fields"] = { ["owner_info"] = "return { [\"y\"] = 75, [\"x\"] = 614, [\"z\"] = -794 }" }, ["inventory"] = {  } }, ["param2"] = 3, ["y"] = 4, ["param1"] = 173, ["z"] = 9, ["name"] = "cottages:roof_wood" } }