return { { ["x"] = 0, ["meta"] = { ["fields"] = {  }, ["inventory"] = {  } }, ["param2"] = 1, ["y"] = 1, ["param1"] = 189, ["z"] = 7, ["name"] = "cottages:window_shutter_open" }, { ["x"] = 0, ["meta"] = { ["fields"] = { ["owner_info"] = "return { [\"y\"] = 75, [\"x\"] = 601, [\"z\"] = -777 }" }, ["inventory"] = {  } }, ["param2"] = 2, ["y"] = 2, ["param1"] = 0, ["z"] = 6, ["name"] = "default:torch" }, { ["x"] = 0, ["meta"] = { ["fields"] = {  }, ["inventory"] = {  } }, ["param2"] = 1, ["y"] = 2, ["param1"] = 205, ["z"] = 7, ["name"] = "cottages:window_shutter_open" }, { ["x"] = 0, ["meta"] = { ["fields"] = { ["owner_info"] = "return { [\"y\"] = 75, [\"x\"] = 601, [\"z\"] = -777 }" }, ["inventory"] = {  } }, ["param2"] = 2, ["y"] = 2, ["param1"] = 0, ["z"] = 8, ["name"] = "default:torch" }, { ["x"] = 0, ["meta"] = { ["fields"] = { ["owner_info"] = "return { [\"y\"] = 75, [\"x\"] = 601, [\"z\"] = -777 }" }, ["inventory"] = {  } }, ["param2"] = 2, ["y"] = 2, ["param1"] = 189, ["z"] = 10, ["name"] = "cottages:roof_wood" }, { ["x"] = 0, ["meta"] = { ["fields"] = { ["owner_info"] = "return { [\"y\"] = 75, [\"x\"] = 601, [\"z\"] = -777 }" }, ["inventory"] = {  } }, ["param2"] = 2, ["y"] = 3, ["param1"] = 189, ["z"] = 9, ["name"] = "cottages:roof_wood" }, { ["x"] = 0, ["meta"] = { ["fields"] = {  }, ["inventory"] = {  } }, ["param2"] = 1, ["y"] = 4, ["param1"] = 173, ["z"] = 7, ["name"] = "cottages:window_shutter_open" }, { ["x"] = 0, ["meta"] = { ["fields"] = { ["owner_info"] = "return { [\"y\"] = 75, [\"x\"] = 601, [\"z\"] = -777 }" }, ["inventory"] = {  } }, ["param2"] = 2, ["y"] = 4, ["param1"] = 189, ["z"] = 8, ["name"] = "cottages:roof_wood" }, { ["x"] = 0, ["meta"] = { ["fields"] = { ["owner_info"] = "return { [\"y\"] = 75, [\"x\"] = 601, [\"z\"] = -777 }" }, ["inventory"] = {  } }, ["param2"] = 1, ["y"] = 5, ["param1"] = 0, ["z"] = 3, ["name"] = "default:wood" }, { ["x"] = 0, ["meta"] = { ["fields"] = { ["owner_info"] = "return { [\"y\"] = 75, [\"x\"] = 601, [\"z\"] = -777 }" }, ["inventory"] = {  } }, ["param2"] = 1, ["y"] = 5, ["param1"] = 0, ["z"] = 4, ["name"] = "default:wood" }, { ["x"] = 0, ["meta"] = { ["fields"] = { ["owner_info"] = "return { [\"y\"] = 75, [\"x\"] = 601, [\"z\"] = -777 }" }, ["inventory"] = {  } }, ["param2"] = 2, ["y"] = 5, ["param1"] = 157, ["z"] = 5, ["name"] = "cottages:roof_wood" }, { ["x"] = 0, ["meta"] = { ["fields"] = { ["owner_info"] = "return { [\"y\"] = 75, [\"x\"] = 601, [\"z\"] = -777 }" }, ["inventory"] = {  } }, ["param2"] = 2, ["y"] = 5, ["param1"] = 173, ["z"] = 6, ["name"] = "cottages:roof_flat_wood" }, { ["x"] = 0, ["meta"] = { ["fields"] = { ["owner_info"] = "return { [\"y\"] = 75, [\"x\"] = 601, [\"z\"] = -777 }" }, ["inventory"] = {  } }, ["param2"] = 2, ["y"] = 5, ["param1"] = 157, ["z"] = 7, ["name"] = "cottages:roof_flat_wood" }, { ["x"] = 1, ["meta"] = { ["fields"] = { ["owner_info"] = "return { [\"y\"] = 75, [\"x\"] = 601, [\"z\"] = -777 }" }, ["inventory"] = {  } }, ["param2"] = 0, ["y"] = 0, ["param1"] = 156, ["z"] = 4, ["name"] = "cottages:bench" }, { ["x"] = 1, ["meta"] = { ["fields"] = { ["owner_info"] = "return { [\"y\"] = 75, [\"x\"] = 601, [\"z\"] = -777 }" }, ["inventory"] = {  } }, ["param2"] = 1, ["y"] = 0, ["param1"] = 0, ["z"] = 5, ["name"] = "default:tree" }, { ["x"] = 1, ["meta"] = { ["fields"] = { ["owner_info"] = "return { [\"y\"] = 75, [\"x\"] = 601, [\"z\"] = -777 }" }, ["inventory"] = {  } }, ["param2"] = 1, ["y"] = 0, ["param1"] = 0, ["z"] = 6, ["name"] = "default:wood" }, { ["x"] = 1, ["meta"] = { ["fields"] = { ["owner_info"] = "return { [\"y\"] = 75, [\"x\"] = 601, [\"z\"] = -777 }" }, ["inventory"] = {  } }, ["param2"] = 1, ["y"] = 0, ["param1"] = 0, ["z"] = 7, ["name"] = "default:wood" }, { ["x"] = 1, ["meta"] = { ["fields"] = { ["owner_info"] = "return { [\"y\"] = 75, [\"x\"] = 601, [\"z\"] = -777 }" }, ["inventory"] = {  } }, ["param2"] = 1, ["y"] = 0, ["param1"] = 0, ["z"] = 8, ["name"] = "default:wood" }, { ["x"] = 1, ["meta"] = { ["fields"] = { ["owner_info"] = "return { [\"y\"] = 75, [\"x\"] = 601, [\"z\"] = -777 }" }, ["inventory"] = {  } }, ["param2"] = 1, ["y"] = 0, ["param1"] = 0, ["z"] = 9, ["name"] = "default:tree" }, { ["x"] = 1, ["meta"] = { ["fields"] = { ["owner_info"] = "return { [\"y\"] = 75, [\"x\"] = 601, [\"z\"] = -777 }" }, ["inventory"] = {  } }, ["param2"] = 1, ["y"] = 1, ["param1"] = 0, ["z"] = 5, ["name"] = "default:tree" }, { ["x"] = 1, ["meta"] = { ["fields"] = { ["owner_info"] = "return { [\"y\"] = 75, [\"x\"] = 601, [\"z\"] = -777 }" }, ["inventory"] = {  } }, ["param2"] = 1, ["y"] = 1, ["param1"] = 0, ["z"] = 6, ["name"] = "default:wood" }, { ["x"] = 1, ["meta"] = { ["fields"] = {  }, ["inventory"] = {  } }, ["param2"] = 1, ["y"] = 1, ["param1"] = 172, ["z"] = 7, ["name"] = "cottages:glass_pane" }, { ["x"] = 1, ["meta"] = { ["fields"] = { ["owner_info"] = "return { [\"y\"] = 75, [\"x\"] = 601, [\"z\"] = -777 }" }, ["inventory"] = {  } }, ["param2"] = 1, ["y"] = 1, ["param1"] = 0, ["z"] = 8, ["name"] = "default:wood" }, { ["x"] = 1, ["meta"] = { ["fields"] = { ["owner_info"] = "return { [\"y\"] = 75, [\"x\"] = 601, [\"z\"] = -777 }" }, ["inventory"] = {  } }, ["param2"] = 1, ["y"] = 1, ["param1"] = 0, ["z"] = 9, ["name"] = "default:tree" }, { ["x"] = 1, ["meta"] = { ["fields"] = { ["owner_info"] = "return { [\"y\"] = 75, [\"x\"] = 601, [\"z\"] = -777 }" }, ["inventory"] = {  } }, ["param2"] = 1, ["y"] = 2, ["param1"] = 0, ["z"] = 5, ["name"] = "default:tree" }, { ["x"] = 1, ["meta"] = { ["fields"] = { ["owner_info"] = "return { [\"y\"] = 75, [\"x\"] = 601, [\"z\"] = -777 }" }, ["inventory"] = {  } }, ["param2"] = 1, ["y"] = 2, ["param1"] = 0, ["z"] = 6, ["name"] = "default:wood" }, { ["x"] = 1, ["meta"] = { ["fields"] = {  }, ["inventory"] = {  } }, ["param2"] = 1, ["y"] = 2, ["param1"] = 188, ["z"] = 7, ["name"] = "cottages:glass_pane" }, { ["x"] = 1, ["meta"] = { ["fields"] = { ["owner_info"] = "return { [\"y\"] = 75, [\"x\"] = 601, [\"z\"] = -777 }" }, ["inventory"] = {  } }, ["param2"] = 1, ["y"] = 2, ["param1"] = 0, ["z"] = 8, ["name"] = "default:wood" }, { ["x"] = 1, ["meta"] = { ["fields"] = { ["owner_info"] = "return { [\"y\"] = 75, [\"x\"] = 601, [\"z\"] = -777 }" }, ["inventory"] = {  } }, ["param2"] = 1, ["y"] = 2, ["param1"] = 0, ["z"] = 9, ["name"] = "default:tree" }, { ["x"] = 1, ["meta"] = { ["fields"] = { ["owner_info"] = "return { [\"y\"] = 75, [\"x\"] = 601, [\"z\"] = -777 }" }, ["inventory"] = {  } }, ["param2"] = 2, ["y"] = 2, ["param1"] = 189, ["z"] = 10, ["name"] = "cottages:roof_wood" }, { ["x"] = 1, ["meta"] = { ["fields"] = { ["owner_info"] = "return { [\"y\"] = 75, [\"x\"] = 601, [\"z\"] = -777 }" }, ["inventory"] = {  } }, ["param2"] = 1, ["y"] = 3, ["param1"] = 0, ["z"] = 5, ["name"] = "default:tree" }, { ["x"] = 1, ["meta"] = { ["fields"] = { ["owner_info"] = "return { [\"y\"] = 75, [\"x\"] = 601, [\"z\"] = -777 }" }, ["inventory"] = {  } }, ["param2"] = 1, ["y"] = 3, ["param1"] = 0, ["z"] = 6, ["name"] = "default:wood" }, { ["x"] = 1, ["meta"] = { ["fields"] = { ["owner_info"] = "return { [\"y\"] = 75, [\"x\"] = 601, [\"z\"] = -777 }" }, ["inventory"] = {  } }, ["param2"] = 1, ["y"] = 3, ["param1"] = 0, ["z"] = 7, ["name"] = "default:wood" }, { ["x"] = 1, ["meta"] = { ["fields"] = { ["owner_info"] = "return { [\"y\"] = 75, [\"x\"] = 601, [\"z\"] = -777 }" }, ["inventory"] = {  } }, ["param2"] = 1, ["y"] = 3, ["param1"] = 0, ["z"] = 8, ["name"] = "default:wood" }, { ["x"] = 1, ["meta"] = { ["fields"] = { ["owner_info"] = "return { [\"y\"] = 75, [\"x\"] = 601, [\"z\"] = -777 }" }, ["inventory"] = {  } }, ["param2"] = 2, ["y"] = 3, ["param1"] = 173, ["z"] = 9, ["name"] = "cottages:roof_connector_wood" }, { ["x"] = 1, ["meta"] = { ["fields"] = { ["owner_info"] = "return { [\"y\"] = 75, [\"x\"] = 601, [\"z\"] = -777 }" }, ["inventory"] = {  } }, ["param2"] = 1, ["y"] = 4, ["param1"] = 0, ["z"] = 5, ["name"] = "default:tree" }, { ["x"] = 1, ["meta"] = { ["fields"] = { ["owner_info"] = "return { [\"y\"] = 75, [\"x\"] = 601, [\"z\"] = -777 }" }, ["inventory"] = {  } }, ["param2"] = 1, ["y"] = 4, ["param1"] = 0, ["z"] = 6, ["name"] = "default:wood" }, { ["x"] = 1, ["meta"] = { ["fields"] = {  }, ["inventory"] = {  } }, ["param2"] = 1, ["y"] = 4, ["param1"] = 188, ["z"] = 7, ["name"] = "cottages:glass_pane" }, { ["x"] = 1, ["meta"] = { ["fields"] = { ["owner_info"] = "return { [\"y\"] = 75, [\"x\"] = 601, [\"z\"] = -777 }" }, ["inventory"] = {  } }, ["param2"] = 2, ["y"] = 4, ["param1"] = 173, ["z"] = 8, ["name"] = "cottages:roof_connector_wood" }, { ["x"] = 1, ["meta"] = { ["fields"] = { ["owner_info"] = "return { [\"y\"] = 75, [\"x\"] = 601, [\"z\"] = -777 }" }, ["inventory"] = {  } }, ["param2"] = 1, ["y"] = 5, ["param1"] = 0, ["z"] = 3, ["name"] = "default:wood" }, { ["x"] = 1, ["meta"] = { ["fields"] = { ["owner_info"] = "return { [\"y\"] = 75, [\"x\"] = 601, [\"z\"] = -777 }" }, ["inventory"] = {  } }, ["param2"] = 1, ["y"] = 5, ["param1"] = 0, ["z"] = 4, ["name"] = "default:wood" }, { ["x"] = 1, ["meta"] = { ["fields"] = { ["owner_info"] = "return { [\"y\"] = 75, [\"x\"] = 601, [\"z\"] = -777 }" }, ["inventory"] = {  } }, ["param2"] = 2, ["y"] = 5, ["param1"] = 173, ["z"] = 5, ["name"] = "cottages:roof_connector_wood" }, { ["x"] = 1, ["meta"] = { ["fields"] = { ["owner_info"] = "return { [\"y\"] = 75, [\"x\"] = 601, [\"z\"] = -777 }" }, ["inventory"] = {  } }, ["param2"] = 2, ["y"] = 5, ["param1"] = 189, ["z"] = 6, ["name"] = "cottages:roof_flat_wood" }, { ["x"] = 1, ["meta"] = { ["fields"] = { ["owner_info"] = "return { [\"y\"] = 75, [\"x\"] = 601, [\"z\"] = -777 }" }, ["inventory"] = {  } }, ["param2"] = 2, ["y"] = 5, ["param1"] = 173, ["z"] = 7, ["name"] = "cottages:roof_flat_wood" }, { ["x"] = 1, ["meta"] = { ["fields"] = { ["owner_info"] = "return { [\"y\"] = 75, [\"x\"] = 601, [\"z\"] = -777 }" }, ["inventory"] = {  } }, ["param2"] = 0, ["y"] = 6, ["param1"] = 125, ["z"] = 3, ["name"] = "cottages:roof_flat_wood" }, { ["x"] = 2, ["meta"] = { ["fields"] = { ["owner_info"] = "return { [\"y\"] = 75, [\"x\"] = 601, [\"z\"] = -777 }" }, ["inventory"] = {  } }, ["param2"] = 0, ["y"] = 0, ["param1"] = 172, ["z"] = 4, ["name"] = "cottages:bench" }, { ["x"] = 2, ["meta"] = { ["fields"] = { ["owner_info"] = "return { [\"y\"] = 75, [\"x\"] = 601, [\"z\"] = -777 }" }, ["inventory"] = {  } }, ["param2"] = 1, ["y"] = 0, ["param1"] = 0, ["z"] = 5, ["name"] = "default:wood" }, { ["x"] = 2, ["meta"] = { ["fields"] = { ["owner_info"] = "return { [\"y\"] = 75, [\"x\"] = 601, [\"z\"] = -777 }" }, ["inventory"] = {  } }, ["param2"] = 1, ["y"] = 0, ["param1"] = 0, ["z"] = 6, ["name"] = "default:wood" }, { ["x"] = 2, ["meta"] = { ["fields"] = { ["owner_info"] = "return { [\"y\"] = 75, [\"x\"] = 601, [\"z\"] = -777 }" }, ["inventory"] = {  } }, ["param2"] = 1, ["y"] = 0, ["param1"] = 0, ["z"] = 7, ["name"] = "default:wood" }, { ["x"] = 2, ["meta"] = { ["fields"] = { ["owner_info"] = "return { [\"y\"] = 75, [\"x\"] = 601, [\"z\"] = -777 }" }, ["inventory"] = {  } }, ["param2"] = 1, ["y"] = 0, ["param1"] = 0, ["z"] = 8, ["name"] = "default:wood" }, { ["x"] = 2, ["meta"] = { ["fields"] = { ["owner_info"] = "return { [\"y\"] = 75, [\"x\"] = 601, [\"z\"] = -777 }" }, ["inventory"] = {  } }, ["param2"] = 1, ["y"] = 0, ["param1"] = 0, ["z"] = 9, ["name"] = "default:wood" }, { ["x"] = 2, ["meta"] = { ["fields"] = { ["owner_info"] = "return { [\"y\"] = 75, [\"x\"] = 601, [\"z\"] = -777 }" }, ["inventory"] = {  } }, ["param2"] = 1, ["y"] = 1, ["param1"] = 0, ["z"] = 5, ["name"] = "default:wood" }, { ["x"] = 2, ["meta"] = { ["fields"] = { ["owner_info"] = "return { [\"y\"] = 75, [\"x\"] = 601, [\"z\"] = -777 }" }, ["inventory"] = {  } }, ["param2"] = 3, ["y"] = 1, ["param1"] = 170, ["z"] = 6, ["name"] = "cottages:bed_head" }, { ["x"] = 2, ["meta"] = { ["fields"] = { ["owner_info"] = "return { [\"y\"] = 75, [\"x\"] = 601, [\"z\"] = -777 }" }, ["inventory"] = {  } }, ["param2"] = 5, ["y"] = 1, ["param1"] = 171, ["z"] = 7, ["name"] = "default:ladder" }, { ["x"] = 2, ["meta"] = { ["fields"] = { ["infotext"] = "Chest", ["owner_info"] = "return { [\"y\"] = 75, [\"x\"] = 601, [\"z\"] = -777 }", ["formspec"] = "size[8,9]list[current_name;main;0,0;8,4;]list[current_player;main;0,5;8,4;]" }, ["inventory"] = { ["main"] = { "", "default:torch 6", "", "default:pick_steel", "farming:string 3", "", "", "", "farming:string", "", "default:paper 3", "", "", "", "", "", "", "", "", "", "", "default:coal_lump 28", "", "", "", "bucket:bucket_lava 3", "default:paper", "default:torch 7", "", "", "", "" } } }, ["param2"] = 0, ["y"] = 1, ["param1"] = 0, ["z"] = 8, ["name"] = "default:chest" }, { ["x"] = 2, ["meta"] = { ["fields"] = { ["owner_info"] = "return { [\"y\"] = 75, [\"x\"] = 601, [\"z\"] = -777 }" }, ["inventory"] = {  } }, ["param2"] = 1, ["y"] = 1, ["param1"] = 0, ["z"] = 9, ["name"] = "default:wood" }, { ["x"] = 2, ["meta"] = { ["fields"] = {  }, ["inventory"] = {  } }, ["param2"] = 0, ["y"] = 2, ["param1"] = 204, ["z"] = 4, ["name"] = "cottages:window_shutter_open" }, { ["x"] = 2, ["meta"] = { ["fields"] = {  }, ["inventory"] = {  } }, ["param2"] = 0, ["y"] = 2, ["param1"] = 187, ["z"] = 5, ["name"] = "cottages:glass_pane" }, { ["x"] = 2, ["meta"] = { ["fields"] = { ["owner_info"] = "return { [\"y\"] = 75, [\"x\"] = 601, [\"z\"] = -777 }" }, ["inventory"] = {  } }, ["param2"] = 3, ["y"] = 2, ["param1"] = 187, ["z"] = 6, ["name"] = "cottages:bed_head" }, { ["x"] = 2, ["meta"] = { ["fields"] = { ["owner_info"] = "return { [\"y\"] = 75, [\"x\"] = 601, [\"z\"] = -777 }" }, ["inventory"] = {  } }, ["param2"] = 5, ["y"] = 2, ["param1"] = 187, ["z"] = 7, ["name"] = "default:ladder" }, { ["x"] = 2, ["meta"] = { ["fields"] = { ["infotext"] = "Chest", ["owner_info"] = "return { [\"y\"] = 75, [\"x\"] = 601, [\"z\"] = -777 }", ["formspec"] = "size[8,9]list[current_name;main;0,0;8,4;]list[current_player;main;0,5;8,4;]" }, ["inventory"] = { ["main"] = { "", "", "", "default:ladder", "", "", "bucket:bucket_empty 3", "", "", "", "", "", "", "", "farming:string 5", "", "", "", "wool:white 8", "", "", "", "", "", "", "", "", "", "", "", "", "default:torch 2" } } }, ["param2"] = 0, ["y"] = 2, ["param1"] = 0, ["z"] = 8, ["name"] = "default:chest" }, { ["x"] = 2, ["meta"] = { ["fields"] = { ["owner_info"] = "return { [\"y\"] = 75, [\"x\"] = 601, [\"z\"] = -777 }" }, ["inventory"] = {  } }, ["param2"] = 1, ["y"] = 2, ["param1"] = 0, ["z"] = 9, ["name"] = "default:wood" }, { ["x"] = 2, ["meta"] = { ["fields"] = { ["owner_info"] = "return { [\"y\"] = 75, [\"x\"] = 601, [\"z\"] = -777 }" }, ["inventory"] = {  } }, ["param2"] = 2, ["y"] = 2, ["param1"] = 205, ["z"] = 10, ["name"] = "cottages:roof_wood" }, { ["x"] = 2, ["meta"] = { ["fields"] = { ["owner_info"] = "return { [\"y\"] = 75, [\"x\"] = 601, [\"z\"] = -777 }" }, ["inventory"] = {  } }, ["param2"] = 1, ["y"] = 3, ["param1"] = 0, ["z"] = 5, ["name"] = "default:wood" }, { ["x"] = 2, ["meta"] = { ["fields"] = { ["owner_info"] = "return { [\"y\"] = 75, [\"x\"] = 601, [\"z\"] = -777 }" }, ["inventory"] = {  } }, ["param2"] = 3, ["y"] = 3, ["param1"] = 204, ["z"] = 6, ["name"] = "cottages:bed_head" }, { ["x"] = 2, ["meta"] = { ["fields"] = { ["owner_info"] = "return { [\"y\"] = 75, [\"x\"] = 601, [\"z\"] = -777 }" }, ["inventory"] = {  } }, ["param2"] = 5, ["y"] = 3, ["param1"] = 187, ["z"] = 7, ["name"] = "default:ladder" }, { ["x"] = 2, ["meta"] = { ["fields"] = { ["infotext"] = "Chest", ["owner_info"] = "return { [\"y\"] = 75, [\"x\"] = 601, [\"z\"] = -777 }", ["formspec"] = "size[8,9]list[current_name;main;0,0;8,4;]list[current_player;main;0,5;8,4;]" }, ["inventory"] = { ["main"] = { "", "", "", "default:paper 5", "default:ladder", "", "", "", "", "", "", "", "wool:white 8", "", "farming:string 4", "farming:string", "", "", "default:steel_ingot 4", "", "default:torch 9", "default:apple 5", "", "", "", "default:coal_lump 14", "", "", "default:paper", "", "", "" } } }, ["param2"] = 0, ["y"] = 3, ["param1"] = 0, ["z"] = 8, ["name"] = "default:chest" }, { ["x"] = 2, ["meta"] = { ["fields"] = { ["owner_info"] = "return { [\"y\"] = 75, [\"x\"] = 601, [\"z\"] = -777 }" }, ["inventory"] = {  } }, ["param2"] = 2, ["y"] = 3, ["param1"] = 173, ["z"] = 9, ["name"] = "cottages:roof_connector_wood" }, { ["x"] = 2, ["meta"] = { ["fields"] = { ["owner_info"] = "return { [\"y\"] = 75, [\"x\"] = 601, [\"z\"] = -777 }" }, ["inventory"] = {  } }, ["param2"] = 4, ["y"] = 4, ["param1"] = 0, ["z"] = 4, ["name"] = "default:torch" }, { ["x"] = 2, ["meta"] = { ["fields"] = { ["owner_info"] = "return { [\"y\"] = 75, [\"x\"] = 601, [\"z\"] = -777 }" }, ["inventory"] = {  } }, ["param2"] = 1, ["y"] = 4, ["param1"] = 0, ["z"] = 5, ["name"] = "default:wood" }, { ["x"] = 2, ["meta"] = { ["fields"] = { ["owner_info"] = "return { [\"y\"] = 75, [\"x\"] = 601, [\"z\"] = -777 }" }, ["inventory"] = {  } }, ["param2"] = 3, ["y"] = 4, ["param1"] = 0, ["z"] = 6, ["name"] = "default:torch" }, { ["x"] = 2, ["meta"] = { ["fields"] = { ["owner_info"] = "return { [\"y\"] = 75, [\"x\"] = 601, [\"z\"] = -777 }" }, ["inventory"] = {  } }, ["param2"] = 2, ["y"] = 4, ["param1"] = 189, ["z"] = 8, ["name"] = "cottages:roof_wood" }, { ["x"] = 2, ["meta"] = { ["fields"] = { ["owner_info"] = "return { [\"y\"] = 75, [\"x\"] = 601, [\"z\"] = -777 }" }, ["inventory"] = {  } }, ["param2"] = 1, ["y"] = 5, ["param1"] = 0, ["z"] = 3, ["name"] = "default:wood" }, { ["x"] = 2, ["meta"] = { ["fields"] = { ["owner_info"] = "return { [\"y\"] = 75, [\"x\"] = 601, [\"z\"] = -777 }" }, ["inventory"] = {  } }, ["param2"] = 1, ["y"] = 5, ["param1"] = 0, ["z"] = 4, ["name"] = "default:wood" }, { ["x"] = 2, ["meta"] = { ["fields"] = { ["owner_info"] = "return { [\"y\"] = 75, [\"x\"] = 601, [\"z\"] = -777 }" }, ["inventory"] = {  } }, ["param2"] = 2, ["y"] = 5, ["param1"] = 189, ["z"] = 5, ["name"] = "cottages:roof_wood" }, { ["x"] = 2, ["meta"] = { ["fields"] = { ["owner_info"] = "return { [\"y\"] = 75, [\"x\"] = 601, [\"z\"] = -777 }" }, ["inventory"] = {  } }, ["param2"] = 2, ["y"] = 5, ["param1"] = 205, ["z"] = 6, ["name"] = "cottages:roof_flat_wood" }, { ["x"] = 2, ["meta"] = { ["fields"] = { ["owner_info"] = "return { [\"y\"] = 75, [\"x\"] = 601, [\"z\"] = -777 }" }, ["inventory"] = {  } }, ["param2"] = 2, ["y"] = 5, ["param1"] = 189, ["z"] = 7, ["name"] = "cottages:roof_flat_wood" }, { ["x"] = 2, ["meta"] = { ["fields"] = { ["owner_info"] = "return { [\"y\"] = 75, [\"x\"] = 601, [\"z\"] = -777 }" }, ["inventory"] = {  } }, ["param2"] = 0, ["y"] = 6, ["param1"] = 141, ["z"] = 3, ["name"] = "cottages:roof_flat_wood" }, { ["x"] = 3, ["meta"] = { ["fields"] = { ["owner_info"] = "return { [\"y\"] = 75, [\"x\"] = 601, [\"z\"] = -777 }" }, ["inventory"] = {  } }, ["param2"] = 1, ["y"] = 0, ["param1"] = 188, ["z"] = 4, ["name"] = "stairs:slab_wood" }, { ["x"] = 3, ["meta"] = { ["fields"] = { ["owner_info"] = "return { [\"y\"] = 75, [\"x\"] = 601, [\"z\"] = -777 }" }, ["inventory"] = {  } }, ["param2"] = 1, ["y"] = 0, ["param1"] = 0, ["z"] = 5, ["name"] = "default:wood" }, { ["x"] = 3, ["meta"] = { ["fields"] = { ["owner_info"] = "return { [\"y\"] = 75, [\"x\"] = 601, [\"z\"] = -777 }" }, ["inventory"] = {  } }, ["param2"] = 1, ["y"] = 0, ["param1"] = 0, ["z"] = 6, ["name"] = "default:wood" }, { ["x"] = 3, ["meta"] = { ["fields"] = { ["owner_info"] = "return { [\"y\"] = 75, [\"x\"] = 601, [\"z\"] = -777 }" }, ["inventory"] = {  } }, ["param2"] = 1, ["y"] = 0, ["param1"] = 0, ["z"] = 7, ["name"] = "default:wood" }, { ["x"] = 3, ["meta"] = { ["fields"] = { ["owner_info"] = "return { [\"y\"] = 75, [\"x\"] = 601, [\"z\"] = -777 }" }, ["inventory"] = {  } }, ["param2"] = 1, ["y"] = 0, ["param1"] = 0, ["z"] = 8, ["name"] = "default:wood" }, { ["x"] = 3, ["meta"] = { ["fields"] = { ["owner_info"] = "return { [\"y\"] = 75, [\"x\"] = 601, [\"z\"] = -777 }" }, ["inventory"] = {  } }, ["param2"] = 1, ["y"] = 0, ["param1"] = 0, ["z"] = 9, ["name"] = "default:wood" }, { ["x"] = 3, ["meta"] = { ["fields"] = { ["owner_info"] = "return { [\"y\"] = 75, [\"x\"] = 601, [\"z\"] = -777 }" }, ["inventory"] = {  } }, ["param2"] = 1, ["y"] = 0, ["param1"] = 189, ["z"] = 10, ["name"] = "stairs:slab_wood" }, { ["x"] = 3, ["meta"] = { ["fields"] = { ["owner_info"] = "return { [\"y\"] = 75, [\"x\"] = 601, [\"z\"] = -777 }" }, ["inventory"] = {  } }, ["param2"] = 1, ["y"] = 1, ["param1"] = 0, ["z"] = 5, ["name"] = "default:wood" }, { ["x"] = 3, ["meta"] = { ["fields"] = { ["owner_info"] = "return { [\"y\"] = 75, [\"x\"] = 601, [\"z\"] = -777 }" }, ["inventory"] = {  } }, ["param2"] = 3, ["y"] = 1, ["param1"] = 170, ["z"] = 6, ["name"] = "cottages:bed_foot" }, { ["x"] = 3, ["meta"] = { ["fields"] = { ["src_totaltime"] = "0", ["src_time"] = "0", ["formspec"] = "size[8,8.5]bgcolor[#080808BB;true]background[5,5;1,1;gui_formbg.png;true]listcolors[#00000069;#5A5A5A;#141318;#30434C;#FFF]list[current_name;src;2.75,0.5;1,1;]list[current_name;fuel;2.75,2.5;1,1;]image[2.75,1.5;1,1;default_furnace_fire_bg.png]image[3.75,1.5;1,1;gui_furnace_arrow_bg.png^[transformR270]list[current_name;dst;4.75,0.96;2,2;]list[current_player;main;0,4.25;8,1;]list[current_player;main;0,5.5;8,3;8]image[0,4.25;1,1;gui_hb_bg.png]image[1,4.25;1,1;gui_hb_bg.png]image[2,4.25;1,1;gui_hb_bg.png]image[3,4.25;1,1;gui_hb_bg.png]image[4,4.25;1,1;gui_hb_bg.png]image[5,4.25;1,1;gui_hb_bg.png]image[6,4.25;1,1;gui_hb_bg.png]image[7,4.25;1,1;gui_hb_bg.png]", ["fuel_time"] = "0", ["fuel_totaltime"] = "0", ["owner_info"] = "return { [\"y\"] = 75, [\"x\"] = 601, [\"z\"] = -777 }", ["infotext"] = "Furnace out of fuel" }, ["inventory"] = { ["fuel"] = { "" }, ["dst"] = { "", "", "", "" }, ["src"] = { "" } } }, ["param2"] = 0, ["y"] = 1, ["param1"] = 0, ["z"] = 8, ["name"] = "default:furnace" }, { ["x"] = 3, ["meta"] = { ["fields"] = { ["owner_info"] = "return { [\"y\"] = 75, [\"x\"] = 601, [\"z\"] = -777 }" }, ["inventory"] = {  } }, ["param2"] = 1, ["y"] = 1, ["param1"] = 0, ["z"] = 9, ["name"] = "default:wood" }, { ["x"] = 3, ["meta"] = { ["fields"] = { ["owner_info"] = "return { [\"y\"] = 75, [\"x\"] = 601, [\"z\"] = -777 }" }, ["inventory"] = {  } }, ["param2"] = 4, ["y"] = 2, ["param1"] = 0, ["z"] = 4, ["name"] = "default:torch" }, { ["x"] = 3, ["meta"] = { ["fields"] = { ["owner_info"] = "return { [\"y\"] = 75, [\"x\"] = 601, [\"z\"] = -777 }" }, ["inventory"] = {  } }, ["param2"] = 1, ["y"] = 2, ["param1"] = 0, ["z"] = 5, ["name"] = "default:wood" }, { ["x"] = 3, ["meta"] = { ["fields"] = { ["owner_info"] = "return { [\"y\"] = 75, [\"x\"] = 601, [\"z\"] = -777 }" }, ["inventory"] = {  } }, ["param2"] = 3, ["y"] = 2, ["param1"] = 187, ["z"] = 6, ["name"] = "cottages:bed_foot" }, { ["x"] = 3, ["meta"] = { ["fields"] = { ["owner_info"] = "return { [\"y\"] = 75, [\"x\"] = 601, [\"z\"] = -777 }" }, ["inventory"] = {  } }, ["param2"] = 4, ["y"] = 2, ["param1"] = 0, ["z"] = 8, ["name"] = "default:torch" }, { ["x"] = 3, ["meta"] = { ["fields"] = { ["owner_info"] = "return { [\"y\"] = 75, [\"x\"] = 601, [\"z\"] = -777 }" }, ["inventory"] = {  } }, ["param2"] = 1, ["y"] = 2, ["param1"] = 0, ["z"] = 9, ["name"] = "default:wood" }, { ["x"] = 3, ["meta"] = { ["fields"] = { ["owner_info"] = "return { [\"y\"] = 75, [\"x\"] = 601, [\"z\"] = -777 }" }, ["inventory"] = {  } }, ["param2"] = 5, ["y"] = 2, ["param1"] = 15, ["z"] = 10, ["name"] = "default:torch" }, { ["x"] = 3, ["meta"] = { ["fields"] = { ["owner_info"] = "return { [\"y\"] = 75, [\"x\"] = 601, [\"z\"] = -777 }" }, ["inventory"] = {  } }, ["param2"] = 1, ["y"] = 3, ["param1"] = 0, ["z"] = 5, ["name"] = "default:wood" }, { ["x"] = 3, ["meta"] = { ["fields"] = { ["owner_info"] = "return { [\"y\"] = 75, [\"x\"] = 601, [\"z\"] = -777 }" }, ["inventory"] = {  } }, ["param2"] = 3, ["y"] = 3, ["param1"] = 204, ["z"] = 6, ["name"] = "cottages:bed_foot" }, { ["x"] = 3, ["meta"] = { ["fields"] = { ["owner_info"] = "return { [\"y\"] = 75, [\"x\"] = 601, [\"z\"] = -777 }" }, ["inventory"] = {  } }, ["param2"] = 2, ["y"] = 3, ["param1"] = 189, ["z"] = 9, ["name"] = "cottages:roof_wood" }, { ["x"] = 3, ["meta"] = { ["fields"] = { ["owner_info"] = "return { [\"y\"] = 75, [\"x\"] = 601, [\"z\"] = -777 }" }, ["inventory"] = {  } }, ["param2"] = 1, ["y"] = 4, ["param1"] = 0, ["z"] = 5, ["name"] = "default:wood" }, { ["x"] = 3, ["meta"] = { ["fields"] = { ["owner_info"] = "return { [\"y\"] = 75, [\"x\"] = 601, [\"z\"] = -777 }" }, ["inventory"] = {  } }, ["param2"] = 2, ["y"] = 4, ["param1"] = 189, ["z"] = 8, ["name"] = "cottages:roof_wood" }, { ["x"] = 3, ["meta"] = { ["fields"] = { ["owner_info"] = "return { [\"y\"] = 75, [\"x\"] = 601, [\"z\"] = -777 }" }, ["inventory"] = {  } }, ["param2"] = 1, ["y"] = 5, ["param1"] = 0, ["z"] = 3, ["name"] = "default:wood" }, { ["x"] = 3, ["meta"] = { ["fields"] = { ["owner_info"] = "return { [\"y\"] = 75, [\"x\"] = 601, [\"z\"] = -777 }" }, ["inventory"] = {  } }, ["param2"] = 1, ["y"] = 5, ["param1"] = 0, ["z"] = 4, ["name"] = "default:wood" }, { ["x"] = 3, ["meta"] = { ["fields"] = { ["owner_info"] = "return { [\"y\"] = 75, [\"x\"] = 601, [\"z\"] = -777 }" }, ["inventory"] = {  } }, ["param2"] = 2, ["y"] = 5, ["param1"] = 173, ["z"] = 5, ["name"] = "cottages:roof_wood" }, { ["x"] = 3, ["meta"] = { ["fields"] = { ["owner_info"] = "return { [\"y\"] = 75, [\"x\"] = 601, [\"z\"] = -777 }" }, ["inventory"] = {  } }, ["param2"] = 2, ["y"] = 5, ["param1"] = 189, ["z"] = 6, ["name"] = "cottages:roof_flat_wood" }, { ["x"] = 3, ["meta"] = { ["fields"] = { ["owner_info"] = "return { [\"y\"] = 75, [\"x\"] = 601, [\"z\"] = -777 }" }, ["inventory"] = {  } }, ["param2"] = 2, ["y"] = 5, ["param1"] = 173, ["z"] = 7, ["name"] = "cottages:roof_flat_wood" }, { ["x"] = 4, ["meta"] = { ["fields"] = {  }, ["inventory"] = {  } }, ["param2"] = 18, ["y"] = 0, ["param1"] = 0, ["z"] = 0, ["name"] = "default:tree" }, { ["x"] = 4, ["meta"] = { ["fields"] = {  }, ["inventory"] = {  } }, ["param2"] = 18, ["y"] = 0, ["param1"] = 0, ["z"] = 1, ["name"] = "default:tree" }, { ["x"] = 4, ["meta"] = { ["fields"] = { ["owner_info"] = "return { [\"y\"] = 75, [\"x\"] = 601, [\"z\"] = -777 }" }, ["inventory"] = {  } }, ["param2"] = 1, ["y"] = 0, ["param1"] = 172, ["z"] = 4, ["name"] = "stairs:slab_wood" }, { ["x"] = 4, ["meta"] = { ["fields"] = { ["owner_info"] = "return { [\"y\"] = 75, [\"x\"] = 601, [\"z\"] = -777 }" }, ["inventory"] = {  } }, ["param2"] = 1, ["y"] = 0, ["param1"] = 0, ["z"] = 5, ["name"] = "default:wood" }, { ["x"] = 4, ["meta"] = { ["fields"] = { ["owner_info"] = "return { [\"y\"] = 75, [\"x\"] = 601, [\"z\"] = -777 }" }, ["inventory"] = {  } }, ["param2"] = 1, ["y"] = 0, ["param1"] = 0, ["z"] = 6, ["name"] = "default:wood" }, { ["x"] = 4, ["meta"] = { ["fields"] = { ["owner_info"] = "return { [\"y\"] = 75, [\"x\"] = 601, [\"z\"] = -777 }" }, ["inventory"] = {  } }, ["param2"] = 1, ["y"] = 0, ["param1"] = 0, ["z"] = 7, ["name"] = "default:wood" }, { ["x"] = 4, ["meta"] = { ["fields"] = { ["owner_info"] = "return { [\"y\"] = 75, [\"x\"] = 601, [\"z\"] = -777 }" }, ["inventory"] = {  } }, ["param2"] = 1, ["y"] = 0, ["param1"] = 0, ["z"] = 8, ["name"] = "default:wood" }, { ["x"] = 4, ["meta"] = { ["fields"] = { ["owner_info"] = "return { [\"y\"] = 75, [\"x\"] = 601, [\"z\"] = -777 }" }, ["inventory"] = {  } }, ["param2"] = 1, ["y"] = 0, ["param1"] = 0, ["z"] = 9, ["name"] = "default:wood" }, { ["x"] = 4, ["meta"] = { ["fields"] = { ["owner_info"] = "return { [\"y\"] = 75, [\"x\"] = 601, [\"z\"] = -777 }" }, ["inventory"] = {  } }, ["param2"] = 1, ["y"] = 0, ["param1"] = 173, ["z"] = 10, ["name"] = "stairs:slab_wood" }, { ["x"] = 4, ["meta"] = { ["fields"] = { ["owner_info"] = "return { [\"y\"] = 75, [\"x\"] = 601, [\"z\"] = -777 }" }, ["inventory"] = {  } }, ["param2"] = 1, ["y"] = 1, ["param1"] = 15, ["z"] = 0, ["name"] = "default:torch" }, { ["x"] = 4, ["meta"] = { ["fields"] = {  }, ["inventory"] = {  } }, ["param2"] = 18, ["y"] = 1, ["param1"] = 0, ["z"] = 1, ["name"] = "default:tree" }, { ["x"] = 4, ["meta"] = { ["fields"] = { ["owner_info"] = "return { [\"y\"] = 75, [\"x\"] = 601, [\"z\"] = -777 }" }, ["inventory"] = {  } }, ["param2"] = 0, ["y"] = 1, ["param1"] = 171, ["z"] = 5, ["name"] = "doors:door_wood_b_1" }, { ["x"] = 4, ["meta"] = { ["fields"] = { ["owner_info"] = "return { [\"y\"] = 75, [\"x\"] = 601, [\"z\"] = -777 }" }, ["inventory"] = {  } }, ["param2"] = 2, ["y"] = 1, ["param1"] = 173, ["z"] = 9, ["name"] = "doors:door_wood_b_1" }, { ["x"] = 4, ["meta"] = { ["fields"] = { ["owner_info"] = "return { [\"y\"] = 75, [\"x\"] = 601, [\"z\"] = -777 }" }, ["inventory"] = {  } }, ["param2"] = 0, ["y"] = 2, ["param1"] = 187, ["z"] = 5, ["name"] = "doors:door_wood_t_1" }, { ["x"] = 4, ["meta"] = { ["fields"] = { ["owner_info"] = "return { [\"y\"] = 75, [\"x\"] = 601, [\"z\"] = -777 }" }, ["inventory"] = {  } }, ["param2"] = 2, ["y"] = 2, ["param1"] = 189, ["z"] = 9, ["name"] = "doors:door_wood_t_1" }, { ["x"] = 4, ["meta"] = { ["fields"] = { ["owner_info"] = "return { [\"y\"] = 75, [\"x\"] = 601, [\"z\"] = -777 }" }, ["inventory"] = {  } }, ["param2"] = 1, ["y"] = 3, ["param1"] = 0, ["z"] = 5, ["name"] = "default:wood" }, { ["x"] = 4, ["meta"] = { ["fields"] = { ["owner_info"] = "return { [\"y\"] = 75, [\"x\"] = 601, [\"z\"] = -777 }" }, ["inventory"] = {  } }, ["param2"] = 5, ["y"] = 3, ["param1"] = 0, ["z"] = 6, ["name"] = "default:torch" }, { ["x"] = 4, ["meta"] = { ["fields"] = { ["owner_info"] = "return { [\"y\"] = 75, [\"x\"] = 601, [\"z\"] = -777 }" }, ["inventory"] = {  } }, ["param2"] = 2, ["y"] = 3, ["param1"] = 173, ["z"] = 9, ["name"] = "cottages:roof_wood" }, { ["x"] = 4, ["meta"] = { ["fields"] = { ["owner_info"] = "return { [\"y\"] = 75, [\"x\"] = 601, [\"z\"] = -777 }" }, ["inventory"] = {  } }, ["param2"] = 1, ["y"] = 4, ["param1"] = 0, ["z"] = 5, ["name"] = "default:wood" }, { ["x"] = 4, ["meta"] = { ["fields"] = { ["owner_info"] = "return { [\"y\"] = 75, [\"x\"] = 601, [\"z\"] = -777 }" }, ["inventory"] = {  } }, ["param2"] = 2, ["y"] = 4, ["param1"] = 173, ["z"] = 8, ["name"] = "cottages:roof_wood" }, { ["x"] = 4, ["meta"] = { ["fields"] = { ["owner_info"] = "return { [\"y\"] = 75, [\"x\"] = 601, [\"z\"] = -777 }" }, ["inventory"] = {  } }, ["param2"] = 1, ["y"] = 5, ["param1"] = 0, ["z"] = 3, ["name"] = "default:wood" }, { ["x"] = 4, ["meta"] = { ["fields"] = { ["owner_info"] = "return { [\"y\"] = 75, [\"x\"] = 601, [\"z\"] = -777 }" }, ["inventory"] = {  } }, ["param2"] = 1, ["y"] = 5, ["param1"] = 0, ["z"] = 4, ["name"] = "default:wood" }, { ["x"] = 4, ["meta"] = { ["fields"] = { ["owner_info"] = "return { [\"y\"] = 75, [\"x\"] = 601, [\"z\"] = -777 }" }, ["inventory"] = {  } }, ["param2"] = 2, ["y"] = 5, ["param1"] = 173, ["z"] = 5, ["name"] = "cottages:roof_wood" }, { ["x"] = 4, ["meta"] = { ["fields"] = { ["owner_info"] = "return { [\"y\"] = 75, [\"x\"] = 601, [\"z\"] = -777 }" }, ["inventory"] = {  } }, ["param2"] = 2, ["y"] = 5, ["param1"] = 189, ["z"] = 6, ["name"] = "cottages:roof_flat_wood" }, { ["x"] = 4, ["meta"] = { ["fields"] = { ["owner_info"] = "return { [\"y\"] = 75, [\"x\"] = 601, [\"z\"] = -777 }" }, ["inventory"] = {  } }, ["param2"] = 2, ["y"] = 5, ["param1"] = 173, ["z"] = 7, ["name"] = "cottages:roof_flat_wood" }, { ["x"] = 5, ["meta"] = { ["fields"] = {  }, ["inventory"] = {  } }, ["param2"] = 18, ["y"] = 0, ["param1"] = 0, ["z"] = 0, ["name"] = "default:tree" }, { ["x"] = 5, ["meta"] = { ["fields"] = {  }, ["inventory"] = {  } }, ["param2"] = 18, ["y"] = 0, ["param1"] = 0, ["z"] = 1, ["name"] = "default:tree" }, { ["x"] = 5, ["meta"] = { ["fields"] = {  }, ["inventory"] = {  } }, ["param2"] = 18, ["y"] = 0, ["param1"] = 0, ["z"] = 2, ["name"] = "default:tree" }, { ["x"] = 5, ["meta"] = { ["fields"] = { ["owner_info"] = "return { [\"y\"] = 75, [\"x\"] = 601, [\"z\"] = -777 }" }, ["inventory"] = {  } }, ["param2"] = 1, ["y"] = 0, ["param1"] = 187, ["z"] = 4, ["name"] = "stairs:slab_wood" }, { ["x"] = 5, ["meta"] = { ["fields"] = { ["owner_info"] = "return { [\"y\"] = 75, [\"x\"] = 601, [\"z\"] = -777 }" }, ["inventory"] = {  } }, ["param2"] = 1, ["y"] = 0, ["param1"] = 0, ["z"] = 5, ["name"] = "default:wood" }, { ["x"] = 5, ["meta"] = { ["fields"] = { ["owner_info"] = "return { [\"y\"] = 75, [\"x\"] = 601, [\"z\"] = -777 }" }, ["inventory"] = {  } }, ["param2"] = 1, ["y"] = 0, ["param1"] = 0, ["z"] = 6, ["name"] = "default:wood" }, { ["x"] = 5, ["meta"] = { ["fields"] = { ["owner_info"] = "return { [\"y\"] = 75, [\"x\"] = 601, [\"z\"] = -777 }" }, ["inventory"] = {  } }, ["param2"] = 1, ["y"] = 0, ["param1"] = 0, ["z"] = 7, ["name"] = "default:wood" }, { ["x"] = 5, ["meta"] = { ["fields"] = { ["owner_info"] = "return { [\"y\"] = 75, [\"x\"] = 601, [\"z\"] = -777 }" }, ["inventory"] = {  } }, ["param2"] = 1, ["y"] = 0, ["param1"] = 0, ["z"] = 8, ["name"] = "default:wood" }, { ["x"] = 5, ["meta"] = { ["fields"] = { ["owner_info"] = "return { [\"y\"] = 75, [\"x\"] = 601, [\"z\"] = -777 }" }, ["inventory"] = {  } }, ["param2"] = 1, ["y"] = 0, ["param1"] = 0, ["z"] = 9, ["name"] = "default:wood" }, { ["x"] = 5, ["meta"] = { ["fields"] = { ["owner_info"] = "return { [\"y\"] = 75, [\"x\"] = 601, [\"z\"] = -777 }" }, ["inventory"] = {  } }, ["param2"] = 1, ["y"] = 0, ["param1"] = 189, ["z"] = 10, ["name"] = "stairs:slab_wood" }, { ["x"] = 5, ["meta"] = { ["fields"] = {  }, ["inventory"] = {  } }, ["param2"] = 18, ["y"] = 1, ["param1"] = 0, ["z"] = 0, ["name"] = "default:tree" }, { ["x"] = 5, ["meta"] = { ["fields"] = {  }, ["inventory"] = {  } }, ["param2"] = 18, ["y"] = 1, ["param1"] = 0, ["z"] = 1, ["name"] = "default:tree" }, { ["x"] = 5, ["meta"] = { ["fields"] = { ["owner_info"] = "return { [\"y\"] = 75, [\"x\"] = 601, [\"z\"] = -777 }" }, ["inventory"] = {  } }, ["param2"] = 1, ["y"] = 1, ["param1"] = 0, ["z"] = 5, ["name"] = "default:wood" }, { ["x"] = 5, ["meta"] = { ["fields"] = { ["owner_info"] = "return { [\"y\"] = 75, [\"x\"] = 601, [\"z\"] = -777 }" }, ["inventory"] = {  } }, ["param2"] = 1, ["y"] = 1, ["param1"] = 170, ["z"] = 6, ["name"] = "cottages:bed_foot" }, { ["x"] = 5, ["meta"] = { ["fields"] = { ["infotext"] = "Chest", ["owner_info"] = "return { [\"y\"] = 75, [\"x\"] = 601, [\"z\"] = -777 }", ["formspec"] = "size[8,9]list[current_name;main;0,0;8,4;]list[current_player;main;0,5;8,4;]" }, ["inventory"] = { ["main"] = { "", "farming:string 5", "", "", "", "", "", "default:coal_lump 29", "", "", "", "", "", "", "", "", "", "", "", "", "", "", "", "farming:string 4", "", "", "", "", "", "", "", "wool:white 8" } } }, ["param2"] = 0, ["y"] = 1, ["param1"] = 0, ["z"] = 8, ["name"] = "default:chest" }, { ["x"] = 5, ["meta"] = { ["fields"] = { ["owner_info"] = "return { [\"y\"] = 75, [\"x\"] = 601, [\"z\"] = -777 }" }, ["inventory"] = {  } }, ["param2"] = 1, ["y"] = 1, ["param1"] = 0, ["z"] = 9, ["name"] = "default:wood" }, { ["x"] = 5, ["meta"] = { ["fields"] = { ["owner_info"] = "return { [\"y\"] = 75, [\"x\"] = 601, [\"z\"] = -777 }" }, ["inventory"] = {  } }, ["param2"] = 4, ["y"] = 2, ["param1"] = 0, ["z"] = 4, ["name"] = "default:torch" }, { ["x"] = 5, ["meta"] = { ["fields"] = { ["owner_info"] = "return { [\"y\"] = 75, [\"x\"] = 601, [\"z\"] = -777 }" }, ["inventory"] = {  } }, ["param2"] = 1, ["y"] = 2, ["param1"] = 0, ["z"] = 5, ["name"] = "default:wood" }, { ["x"] = 5, ["meta"] = { ["fields"] = { ["owner_info"] = "return { [\"y\"] = 75, [\"x\"] = 601, [\"z\"] = -777 }" }, ["inventory"] = {  } }, ["param2"] = 1, ["y"] = 2, ["param1"] = 187, ["z"] = 6, ["name"] = "cottages:bed_foot" }, { ["x"] = 5, ["meta"] = { ["fields"] = { ["infotext"] = "Chest", ["owner_info"] = "return { [\"y\"] = 75, [\"x\"] = 601, [\"z\"] = -777 }", ["formspec"] = "size[8,9]list[current_name;main;0,0;8,4;]list[current_player;main;0,5;8,4;]" }, ["inventory"] = { ["main"] = { "", "", "", "", "", "", "", "", "default:coal_lump 18", "", "", "", "", "", "", "", "", "", "", "", "default:steel_ingot", "", "", "", "default:paper 4", "", "", "", "default:paper 4", "", "", "" } } }, ["param2"] = 0, ["y"] = 2, ["param1"] = 0, ["z"] = 8, ["name"] = "default:chest" }, { ["x"] = 5, ["meta"] = { ["fields"] = { ["owner_info"] = "return { [\"y\"] = 75, [\"x\"] = 601, [\"z\"] = -777 }" }, ["inventory"] = {  } }, ["param2"] = 1, ["y"] = 2, ["param1"] = 0, ["z"] = 9, ["name"] = "default:wood" }, { ["x"] = 5, ["meta"] = { ["fields"] = { ["owner_info"] = "return { [\"y\"] = 75, [\"x\"] = 601, [\"z\"] = -777 }" }, ["inventory"] = {  } }, ["param2"] = 5, ["y"] = 2, ["param1"] = 15, ["z"] = 10, ["name"] = "default:torch" }, { ["x"] = 5, ["meta"] = { ["fields"] = { ["owner_info"] = "return { [\"y\"] = 75, [\"x\"] = 601, [\"z\"] = -777 }" }, ["inventory"] = {  } }, ["param2"] = 1, ["y"] = 3, ["param1"] = 0, ["z"] = 5, ["name"] = "default:wood" }, { ["x"] = 5, ["meta"] = { ["fields"] = { ["owner_info"] = "return { [\"y\"] = 75, [\"x\"] = 601, [\"z\"] = -777 }" }, ["inventory"] = {  } }, ["param2"] = 1, ["y"] = 3, ["param1"] = 204, ["z"] = 6, ["name"] = "cottages:bed_foot" }, { ["x"] = 5, ["meta"] = { ["fields"] = { ["infotext"] = "Chest", ["owner_info"] = "return { [\"y\"] = 75, [\"x\"] = 601, [\"z\"] = -777 }", ["formspec"] = "size[8,9]list[current_name;main;0,0;8,4;]list[current_player;main;0,5;8,4;]" }, ["inventory"] = { ["main"] = { "", "", "", "", "default:paper 4", "", "", "", "", "", "", "farming:string", "", "", "", "", "", "default:paper 5", "", "", "", "", "", "", "default:torch 2", "default:apple 2", "", "", "", "", "", "default:ladder" } } }, ["param2"] = 0, ["y"] = 3, ["param1"] = 0, ["z"] = 8, ["name"] = "default:chest" }, { ["x"] = 5, ["meta"] = { ["fields"] = { ["owner_info"] = "return { [\"y\"] = 75, [\"x\"] = 601, [\"z\"] = -777 }" }, ["inventory"] = {  } }, ["param2"] = 2, ["y"] = 3, ["param1"] = 189, ["z"] = 9, ["name"] = "cottages:roof_connector_wood" }, { ["x"] = 5, ["meta"] = { ["fields"] = { ["owner_info"] = "return { [\"y\"] = 75, [\"x\"] = 601, [\"z\"] = -777 }" }, ["inventory"] = {  } }, ["param2"] = 1, ["y"] = 4, ["param1"] = 0, ["z"] = 5, ["name"] = "default:wood" }, { ["x"] = 5, ["meta"] = { ["fields"] = { ["owner_info"] = "return { [\"y\"] = 75, [\"x\"] = 601, [\"z\"] = -777 }" }, ["inventory"] = {  } }, ["param2"] = 5, ["y"] = 4, ["param1"] = 0, ["z"] = 6, ["name"] = "default:torch" }, { ["x"] = 5, ["meta"] = { ["fields"] = { ["owner_info"] = "return { [\"y\"] = 75, [\"x\"] = 601, [\"z\"] = -777 }" }, ["inventory"] = {  } }, ["param2"] = 2, ["y"] = 4, ["param1"] = 189, ["z"] = 8, ["name"] = "cottages:roof_wood" }, { ["x"] = 5, ["meta"] = { ["fields"] = { ["owner_info"] = "return { [\"y\"] = 75, [\"x\"] = 601, [\"z\"] = -777 }" }, ["inventory"] = {  } }, ["param2"] = 1, ["y"] = 5, ["param1"] = 0, ["z"] = 3, ["name"] = "default:wood" }, { ["x"] = 5, ["meta"] = { ["fields"] = { ["owner_info"] = "return { [\"y\"] = 75, [\"x\"] = 601, [\"z\"] = -777 }" }, ["inventory"] = {  } }, ["param2"] = 1, ["y"] = 5, ["param1"] = 0, ["z"] = 4, ["name"] = "default:wood" }, { ["x"] = 5, ["meta"] = { ["fields"] = { ["owner_info"] = "return { [\"y\"] = 75, [\"x\"] = 601, [\"z\"] = -777 }" }, ["inventory"] = {  } }, ["param2"] = 2, ["y"] = 5, ["param1"] = 189, ["z"] = 5, ["name"] = "cottages:roof_wood" }, { ["x"] = 5, ["meta"] = { ["fields"] = { ["owner_info"] = "return { [\"y\"] = 75, [\"x\"] = 601, [\"z\"] = -777 }" }, ["inventory"] = {  } }, ["param2"] = 2, ["y"] = 5, ["param1"] = 205, ["z"] = 6, ["name"] = "cottages:roof_flat_wood" }, { ["x"] = 5, ["meta"] = { ["fields"] = { ["owner_info"] = "return { [\"y\"] = 75, [\"x\"] = 601, [\"z\"] = -777 }" }, ["inventory"] = {  } }, ["param2"] = 2, ["y"] = 5, ["param1"] = 189, ["z"] = 7, ["name"] = "cottages:roof_flat_wood" }, { ["x"] = 6, ["meta"] = { ["fields"] = {  }, ["inventory"] = {  } }, ["param2"] = 18, ["y"] = 0, ["param1"] = 0, ["z"] = 0, ["name"] = "default:tree" }, { ["x"] = 6, ["meta"] = { ["fields"] = {  }, ["inventory"] = {  } }, ["param2"] = 18, ["y"] = 0, ["param1"] = 0, ["z"] = 1, ["name"] = "default:tree" }, { ["x"] = 6, ["meta"] = { ["fields"] = {  }, ["inventory"] = {  } }, ["param2"] = 18, ["y"] = 0, ["param1"] = 0, ["z"] = 2, ["name"] = "default:tree" }, { ["x"] = 6, ["meta"] = { ["fields"] = { ["owner_info"] = "return { [\"y\"] = 75, [\"x\"] = 601, [\"z\"] = -777 }" }, ["inventory"] = {  } }, ["param2"] = 0, ["y"] = 0, ["param1"] = 171, ["z"] = 4, ["name"] = "cottages:bench" }, { ["x"] = 6, ["meta"] = { ["fields"] = { ["owner_info"] = "return { [\"y\"] = 75, [\"x\"] = 601, [\"z\"] = -777 }" }, ["inventory"] = {  } }, ["param2"] = 1, ["y"] = 0, ["param1"] = 0, ["z"] = 5, ["name"] = "default:wood" }, { ["x"] = 6, ["meta"] = { ["fields"] = { ["owner_info"] = "return { [\"y\"] = 75, [\"x\"] = 601, [\"z\"] = -777 }" }, ["inventory"] = {  } }, ["param2"] = 1, ["y"] = 0, ["param1"] = 0, ["z"] = 6, ["name"] = "default:wood" }, { ["x"] = 6, ["meta"] = { ["fields"] = { ["owner_info"] = "return { [\"y\"] = 75, [\"x\"] = 601, [\"z\"] = -777 }" }, ["inventory"] = {  } }, ["param2"] = 1, ["y"] = 0, ["param1"] = 0, ["z"] = 7, ["name"] = "default:wood" }, { ["x"] = 6, ["meta"] = { ["fields"] = { ["owner_info"] = "return { [\"y\"] = 75, [\"x\"] = 601, [\"z\"] = -777 }" }, ["inventory"] = {  } }, ["param2"] = 1, ["y"] = 0, ["param1"] = 0, ["z"] = 8, ["name"] = "default:wood" }, { ["x"] = 6, ["meta"] = { ["fields"] = { ["owner_info"] = "return { [\"y\"] = 75, [\"x\"] = 601, [\"z\"] = -777 }" }, ["inventory"] = {  } }, ["param2"] = 1, ["y"] = 0, ["param1"] = 0, ["z"] = 9, ["name"] = "default:wood" }, { ["x"] = 6, ["meta"] = { ["fields"] = {  }, ["inventory"] = {  } }, ["param2"] = 18, ["y"] = 1, ["param1"] = 0, ["z"] = 0, ["name"] = "default:tree" }, { ["x"] = 6, ["meta"] = { ["fields"] = {  }, ["inventory"] = {  } }, ["param2"] = 18, ["y"] = 1, ["param1"] = 0, ["z"] = 1, ["name"] = "default:tree" }, { ["x"] = 6, ["meta"] = { ["fields"] = { ["owner_info"] = "return { [\"y\"] = 75, [\"x\"] = 601, [\"z\"] = -777 }" }, ["inventory"] = {  } }, ["param2"] = 1, ["y"] = 1, ["param1"] = 0, ["z"] = 5, ["name"] = "default:wood" }, { ["x"] = 6, ["meta"] = { ["fields"] = { ["owner_info"] = "return { [\"y\"] = 75, [\"x\"] = 601, [\"z\"] = -777 }" }, ["inventory"] = {  } }, ["param2"] = 1, ["y"] = 1, ["param1"] = 170, ["z"] = 6, ["name"] = "cottages:bed_head" }, { ["x"] = 6, ["meta"] = { ["fields"] = { ["owner_info"] = "return { [\"y\"] = 75, [\"x\"] = 601, [\"z\"] = -777 }" }, ["inventory"] = {  } }, ["param2"] = 5, ["y"] = 1, ["param1"] = 187, ["z"] = 7, ["name"] = "default:ladder" }, { ["x"] = 6, ["meta"] = { ["fields"] = { ["owner_info"] = "return { [\"y\"] = 75, [\"x\"] = 601, [\"z\"] = -777 }" }, ["inventory"] = {  } }, ["param2"] = 0, ["y"] = 1, ["param1"] = 204, ["z"] = 8, ["name"] = "cottages:bench" }, { ["x"] = 6, ["meta"] = { ["fields"] = { ["owner_info"] = "return { [\"y\"] = 75, [\"x\"] = 601, [\"z\"] = -777 }" }, ["inventory"] = {  } }, ["param2"] = 1, ["y"] = 1, ["param1"] = 0, ["z"] = 9, ["name"] = "default:wood" }, { ["x"] = 6, ["meta"] = { ["fields"] = {  }, ["inventory"] = {  } }, ["param2"] = 0, ["y"] = 2, ["param1"] = 204, ["z"] = 4, ["name"] = "cottages:window_shutter_open" }, { ["x"] = 6, ["meta"] = { ["fields"] = {  }, ["inventory"] = {  } }, ["param2"] = 0, ["y"] = 2, ["param1"] = 187, ["z"] = 5, ["name"] = "cottages:glass_pane" }, { ["x"] = 6, ["meta"] = { ["fields"] = { ["owner_info"] = "return { [\"y\"] = 75, [\"x\"] = 601, [\"z\"] = -777 }" }, ["inventory"] = {  } }, ["param2"] = 1, ["y"] = 2, ["param1"] = 187, ["z"] = 6, ["name"] = "cottages:bed_head" }, { ["x"] = 6, ["meta"] = { ["fields"] = { ["owner_info"] = "return { [\"y\"] = 75, [\"x\"] = 601, [\"z\"] = -777 }" }, ["inventory"] = {  } }, ["param2"] = 5, ["y"] = 2, ["param1"] = 204, ["z"] = 7, ["name"] = "default:ladder" }, { ["x"] = 6, ["meta"] = { ["fields"] = { ["owner_info"] = "return { [\"y\"] = 75, [\"x\"] = 601, [\"z\"] = -777 }" }, ["inventory"] = {  } }, ["param2"] = 4, ["y"] = 2, ["param1"] = 0, ["z"] = 8, ["name"] = "default:torch" }, { ["x"] = 6, ["meta"] = { ["fields"] = { ["owner_info"] = "return { [\"y\"] = 75, [\"x\"] = 601, [\"z\"] = -777 }" }, ["inventory"] = {  } }, ["param2"] = 1, ["y"] = 2, ["param1"] = 0, ["z"] = 9, ["name"] = "default:wood" }, { ["x"] = 6, ["meta"] = { ["fields"] = { ["owner_info"] = "return { [\"y\"] = 75, [\"x\"] = 601, [\"z\"] = -777 }" }, ["inventory"] = {  } }, ["param2"] = 2, ["y"] = 2, ["param1"] = 205, ["z"] = 10, ["name"] = "cottages:roof_wood" }, { ["x"] = 6, ["meta"] = { ["fields"] = { ["owner_info"] = "return { [\"y\"] = 75, [\"x\"] = 601, [\"z\"] = -777 }" }, ["inventory"] = {  } }, ["param2"] = 1, ["y"] = 3, ["param1"] = 0, ["z"] = 5, ["name"] = "default:wood" }, { ["x"] = 6, ["meta"] = { ["fields"] = { ["owner_info"] = "return { [\"y\"] = 75, [\"x\"] = 601, [\"z\"] = -777 }" }, ["inventory"] = {  } }, ["param2"] = 1, ["y"] = 3, ["param1"] = 187, ["z"] = 6, ["name"] = "cottages:bed_head" }, { ["x"] = 6, ["meta"] = { ["fields"] = { ["owner_info"] = "return { [\"y\"] = 75, [\"x\"] = 601, [\"z\"] = -777 }" }, ["inventory"] = {  } }, ["param2"] = 5, ["y"] = 3, ["param1"] = 187, ["z"] = 7, ["name"] = "default:ladder" }, { ["x"] = 6, ["meta"] = { ["fields"] = { ["owner_info"] = "return { [\"y\"] = 75, [\"x\"] = 601, [\"z\"] = -777 }" }, ["inventory"] = {  } }, ["param2"] = 2, ["y"] = 3, ["param1"] = 189, ["z"] = 9, ["name"] = "cottages:roof_connector_wood" }, { ["x"] = 6, ["meta"] = { ["fields"] = { ["owner_info"] = "return { [\"y\"] = 75, [\"x\"] = 601, [\"z\"] = -777 }" }, ["inventory"] = {  } }, ["param2"] = 1, ["y"] = 4, ["param1"] = 0, ["z"] = 5, ["name"] = "default:wood" }, { ["x"] = 6, ["meta"] = { ["fields"] = { ["owner_info"] = "return { [\"y\"] = 75, [\"x\"] = 601, [\"z\"] = -777 }" }, ["inventory"] = {  } }, ["param2"] = 2, ["y"] = 4, ["param1"] = 189, ["z"] = 8, ["name"] = "cottages:roof_wood" }, { ["x"] = 6, ["meta"] = { ["fields"] = { ["owner_info"] = "return { [\"y\"] = 75, [\"x\"] = 601, [\"z\"] = -777 }" }, ["inventory"] = {  } }, ["param2"] = 1, ["y"] = 5, ["param1"] = 0, ["z"] = 3, ["name"] = "default:wood" }, { ["x"] = 6, ["meta"] = { ["fields"] = { ["owner_info"] = "return { [\"y\"] = 75, [\"x\"] = 601, [\"z\"] = -777 }" }, ["inventory"] = {  } }, ["param2"] = 1, ["y"] = 5, ["param1"] = 0, ["z"] = 4, ["name"] = "default:wood" }, { ["x"] = 6, ["meta"] = { ["fields"] = { ["owner_info"] = "return { [\"y\"] = 75, [\"x\"] = 601, [\"z\"] = -777 }" }, ["inventory"] = {  } }, ["param2"] = 2, ["y"] = 5, ["param1"] = 173, ["z"] = 5, ["name"] = "cottages:roof_wood" }, { ["x"] = 6, ["meta"] = { ["fields"] = { ["owner_info"] = "return { [\"y\"] = 75, [\"x\"] = 601, [\"z\"] = -777 }" }, ["inventory"] = {  } }, ["param2"] = 2, ["y"] = 5, ["param1"] = 189, ["z"] = 6, ["name"] = "cottages:roof_flat_wood" }, { ["x"] = 6, ["meta"] = { ["fields"] = { ["owner_info"] = "return { [\"y\"] = 75, [\"x\"] = 601, [\"z\"] = -777 }" }, ["inventory"] = {  } }, ["param2"] = 2, ["y"] = 5, ["param1"] = 173, ["z"] = 7, ["name"] = "cottages:roof_flat_wood" }, { ["x"] = 7, ["meta"] = { ["fields"] = {  }, ["inventory"] = {  } }, ["param2"] = 18, ["y"] = 0, ["param1"] = 0, ["z"] = 0, ["name"] = "default:tree" }, { ["x"] = 7, ["meta"] = { ["fields"] = {  }, ["inventory"] = {  } }, ["param2"] = 18, ["y"] = 0, ["param1"] = 0, ["z"] = 1, ["name"] = "default:tree" }, { ["x"] = 7, ["meta"] = { ["fields"] = {  }, ["inventory"] = {  } }, ["param2"] = 18, ["y"] = 0, ["param1"] = 0, ["z"] = 2, ["name"] = "default:tree" }, { ["x"] = 7, ["meta"] = { ["fields"] = { ["owner_info"] = "return { [\"y\"] = 75, [\"x\"] = 601, [\"z\"] = -777 }" }, ["inventory"] = {  } }, ["param2"] = 0, ["y"] = 0, ["param1"] = 155, ["z"] = 4, ["name"] = "cottages:bench" }, { ["x"] = 7, ["meta"] = { ["fields"] = { ["owner_info"] = "return { [\"y\"] = 75, [\"x\"] = 601, [\"z\"] = -777 }" }, ["inventory"] = {  } }, ["param2"] = 1, ["y"] = 0, ["param1"] = 0, ["z"] = 5, ["name"] = "default:wood" }, { ["x"] = 7, ["meta"] = { ["fields"] = { ["owner_info"] = "return { [\"y\"] = 75, [\"x\"] = 601, [\"z\"] = -777 }" }, ["inventory"] = {  } }, ["param2"] = 1, ["y"] = 0, ["param1"] = 0, ["z"] = 6, ["name"] = "default:wood" }, { ["x"] = 7, ["meta"] = { ["fields"] = { ["owner_info"] = "return { [\"y\"] = 75, [\"x\"] = 601, [\"z\"] = -777 }" }, ["inventory"] = {  } }, ["param2"] = 1, ["y"] = 0, ["param1"] = 0, ["z"] = 7, ["name"] = "default:wood" }, { ["x"] = 7, ["meta"] = { ["fields"] = { ["owner_info"] = "return { [\"y\"] = 75, [\"x\"] = 601, [\"z\"] = -777 }" }, ["inventory"] = {  } }, ["param2"] = 1, ["y"] = 0, ["param1"] = 0, ["z"] = 8, ["name"] = "default:wood" }, { ["x"] = 7, ["meta"] = { ["fields"] = { ["owner_info"] = "return { [\"y\"] = 75, [\"x\"] = 601, [\"z\"] = -777 }" }, ["inventory"] = {  } }, ["param2"] = 1, ["y"] = 0, ["param1"] = 0, ["z"] = 9, ["name"] = "default:wood" }, { ["x"] = 7, ["meta"] = { ["fields"] = {  }, ["inventory"] = {  } }, ["param2"] = 18, ["y"] = 1, ["param1"] = 0, ["z"] = 0, ["name"] = "default:tree" }, { ["x"] = 7, ["meta"] = { ["fields"] = {  }, ["inventory"] = {  } }, ["param2"] = 18, ["y"] = 1, ["param1"] = 0, ["z"] = 1, ["name"] = "default:tree" }, { ["x"] = 7, ["meta"] = { ["fields"] = { ["owner_info"] = "return { [\"y\"] = 75, [\"x\"] = 601, [\"z\"] = -777 }" }, ["inventory"] = {  } }, ["param2"] = 1, ["y"] = 1, ["param1"] = 0, ["z"] = 5, ["name"] = "default:wood" }, { ["x"] = 7, ["meta"] = { ["fields"] = { ["owner_info"] = "return { [\"y\"] = 75, [\"x\"] = 601, [\"z\"] = -777 }" }, ["inventory"] = {  } }, ["param2"] = 2, ["y"] = 1, ["param1"] = 170, ["z"] = 6, ["name"] = "cottages:bed_head" }, { ["x"] = 7, ["meta"] = { ["fields"] = { ["owner_info"] = "return { [\"y\"] = 75, [\"x\"] = 601, [\"z\"] = -777 }" }, ["inventory"] = {  } }, ["param2"] = 2, ["y"] = 1, ["param1"] = 170, ["z"] = 7, ["name"] = "cottages:bed_foot" }, { ["x"] = 7, ["meta"] = { ["fields"] = { ["infotext"] = "Chest", ["owner_info"] = "return { [\"y\"] = 75, [\"x\"] = 601, [\"z\"] = -777 }", ["formspec"] = "size[8,9]list[current_name;main;0,0;8,4;]list[current_player;main;0,5;8,4;]" }, ["inventory"] = { ["main"] = { "", "", "", "", "", "", "wool:white 4", "", "", "", "", "", "", "", "default:pick_stone", "default:apple", "", "default:torch 3", "", "", "", "", "", "", "", "", "default:steel_ingot", "", "", "default:paper 3", "", "" } } }, ["param2"] = 1, ["y"] = 1, ["param1"] = 0, ["z"] = 8, ["name"] = "default:chest" }, { ["x"] = 7, ["meta"] = { ["fields"] = { ["owner_info"] = "return { [\"y\"] = 75, [\"x\"] = 601, [\"z\"] = -777 }" }, ["inventory"] = {  } }, ["param2"] = 1, ["y"] = 1, ["param1"] = 0, ["z"] = 9, ["name"] = "default:wood" }, { ["x"] = 7, ["meta"] = { ["fields"] = { ["owner_info"] = "return { [\"y\"] = 75, [\"x\"] = 601, [\"z\"] = -777 }" }, ["inventory"] = {  } }, ["param2"] = 1, ["y"] = 2, ["param1"] = 0, ["z"] = 5, ["name"] = "default:wood" }, { ["x"] = 7, ["meta"] = { ["fields"] = { ["owner_info"] = "return { [\"y\"] = 75, [\"x\"] = 601, [\"z\"] = -777 }" }, ["inventory"] = {  } }, ["param2"] = 2, ["y"] = 2, ["param1"] = 187, ["z"] = 6, ["name"] = "cottages:bed_head" }, { ["x"] = 7, ["meta"] = { ["fields"] = { ["owner_info"] = "return { [\"y\"] = 75, [\"x\"] = 601, [\"z\"] = -777 }" }, ["inventory"] = {  } }, ["param2"] = 2, ["y"] = 2, ["param1"] = 187, ["z"] = 7, ["name"] = "cottages:bed_foot" }, { ["x"] = 7, ["meta"] = { ["fields"] = { ["infotext"] = "Chest", ["owner_info"] = "return { [\"y\"] = 75, [\"x\"] = 601, [\"z\"] = -777 }", ["formspec"] = "size[8,9]list[current_name;main;0,0;8,4;]list[current_player;main;0,5;8,4;]" }, ["inventory"] = { ["main"] = { "", "", "", "", "", "", "", "farming:string 4", "default:paper 5", "farming:string 4", "", "", "", "bucket:bucket_empty 3", "", "", "", "", "", "", "", "", "", "", "default:steel_ingot", "", "", "", "", "", "", "" } } }, ["param2"] = 1, ["y"] = 2, ["param1"] = 0, ["z"] = 8, ["name"] = "default:chest" }, { ["x"] = 7, ["meta"] = { ["fields"] = { ["owner_info"] = "return { [\"y\"] = 75, [\"x\"] = 601, [\"z\"] = -777 }" }, ["inventory"] = {  } }, ["param2"] = 1, ["y"] = 2, ["param1"] = 0, ["z"] = 9, ["name"] = "default:wood" }, { ["x"] = 7, ["meta"] = { ["fields"] = { ["owner_info"] = "return { [\"y\"] = 75, [\"x\"] = 601, [\"z\"] = -777 }" }, ["inventory"] = {  } }, ["param2"] = 2, ["y"] = 2, ["param1"] = 189, ["z"] = 10, ["name"] = "cottages:roof_wood" }, { ["x"] = 7, ["meta"] = { ["fields"] = { ["owner_info"] = "return { [\"y\"] = 75, [\"x\"] = 601, [\"z\"] = -777 }" }, ["inventory"] = {  } }, ["param2"] = 1, ["y"] = 3, ["param1"] = 0, ["z"] = 5, ["name"] = "default:wood" }, { ["x"] = 7, ["meta"] = { ["fields"] = { ["owner_info"] = "return { [\"y\"] = 75, [\"x\"] = 601, [\"z\"] = -777 }" }, ["inventory"] = {  } }, ["param2"] = 2, ["y"] = 3, ["param1"] = 204, ["z"] = 6, ["name"] = "cottages:bed_head" }, { ["x"] = 7, ["meta"] = { ["fields"] = { ["owner_info"] = "return { [\"y\"] = 75, [\"x\"] = 601, [\"z\"] = -777 }" }, ["inventory"] = {  } }, ["param2"] = 2, ["y"] = 3, ["param1"] = 187, ["z"] = 7, ["name"] = "cottages:bed_foot" }, { ["x"] = 7, ["meta"] = { ["fields"] = { ["infotext"] = "Chest", ["owner_info"] = "return { [\"y\"] = 75, [\"x\"] = 601, [\"z\"] = -777 }", ["formspec"] = "size[8,9]list[current_name;main;0,0;8,4;]list[current_player;main;0,5;8,4;]" }, ["inventory"] = { ["main"] = { "", "default:steel_ingot", "", "default:shovel_stone", "default:paper 3", "", "", "", "", "", "", "", "", "", "", "default:book", "", "default:coal_lump 21", "", "", "", "", "", "", "", "", "", "", "", "", "farming:string 2", "" } } }, ["param2"] = 1, ["y"] = 3, ["param1"] = 0, ["z"] = 8, ["name"] = "default:chest" }, { ["x"] = 7, ["meta"] = { ["fields"] = { ["owner_info"] = "return { [\"y\"] = 75, [\"x\"] = 601, [\"z\"] = -777 }" }, ["inventory"] = {  } }, ["param2"] = 2, ["y"] = 3, ["param1"] = 173, ["z"] = 9, ["name"] = "cottages:roof_connector_wood" }, { ["x"] = 7, ["meta"] = { ["fields"] = { ["owner_info"] = "return { [\"y\"] = 75, [\"x\"] = 601, [\"z\"] = -777 }" }, ["inventory"] = {  } }, ["param2"] = 4, ["y"] = 4, ["param1"] = 0, ["z"] = 4, ["name"] = "default:torch" }, { ["x"] = 7, ["meta"] = { ["fields"] = { ["owner_info"] = "return { [\"y\"] = 75, [\"x\"] = 601, [\"z\"] = -777 }" }, ["inventory"] = {  } }, ["param2"] = 1, ["y"] = 4, ["param1"] = 0, ["z"] = 5, ["name"] = "default:wood" }, { ["x"] = 7, ["meta"] = { ["fields"] = { ["owner_info"] = "return { [\"y\"] = 75, [\"x\"] = 601, [\"z\"] = -777 }" }, ["inventory"] = {  } }, ["param2"] = 2, ["y"] = 4, ["param1"] = 0, ["z"] = 6, ["name"] = "default:torch" }, { ["x"] = 7, ["meta"] = { ["fields"] = { ["owner_info"] = "return { [\"y\"] = 75, [\"x\"] = 601, [\"z\"] = -777 }" }, ["inventory"] = {  } }, ["param2"] = 2, ["y"] = 4, ["param1"] = 189, ["z"] = 8, ["name"] = "cottages:roof_wood" }, { ["x"] = 7, ["meta"] = { ["fields"] = { ["owner_info"] = "return { [\"y\"] = 75, [\"x\"] = 601, [\"z\"] = -777 }" }, ["inventory"] = {  } }, ["param2"] = 1, ["y"] = 5, ["param1"] = 0, ["z"] = 3, ["name"] = "default:wood" }, { ["x"] = 7, ["meta"] = { ["fields"] = { ["owner_info"] = "return { [\"y\"] = 75, [\"x\"] = 601, [\"z\"] = -777 }" }, ["inventory"] = {  } }, ["param2"] = 1, ["y"] = 5, ["param1"] = 0, ["z"] = 4, ["name"] = "default:wood" }, { ["x"] = 7, ["meta"] = { ["fields"] = { ["owner_info"] = "return { [\"y\"] = 75, [\"x\"] = 601, [\"z\"] = -777 }" }, ["inventory"] = {  } }, ["param2"] = 2, ["y"] = 5, ["param1"] = 189, ["z"] = 5, ["name"] = "cottages:roof_wood" }, { ["x"] = 7, ["meta"] = { ["fields"] = { ["owner_info"] = "return { [\"y\"] = 75, [\"x\"] = 601, [\"z\"] = -777 }" }, ["inventory"] = {  } }, ["param2"] = 2, ["y"] = 5, ["param1"] = 205, ["z"] = 6, ["name"] = "cottages:roof_flat_wood" }, { ["x"] = 7, ["meta"] = { ["fields"] = { ["owner_info"] = "return { [\"y\"] = 75, [\"x\"] = 601, [\"z\"] = -777 }" }, ["inventory"] = {  } }, ["param2"] = 2, ["y"] = 5, ["param1"] = 189, ["z"] = 7, ["name"] = "cottages:roof_flat_wood" }, { ["x"] = 7, ["meta"] = { ["fields"] = { ["owner_info"] = "return { [\"y\"] = 75, [\"x\"] = 601, [\"z\"] = -777 }" }, ["inventory"] = {  } }, ["param2"] = 0, ["y"] = 6, ["param1"] = 141, ["z"] = 3, ["name"] = "cottages:roof_flat_wood" }, { ["x"] = 8, ["meta"] = { ["fields"] = {  }, ["inventory"] = {  } }, ["param2"] = 18, ["y"] = 0, ["param1"] = 0, ["z"] = 0, ["name"] = "default:tree" }, { ["x"] = 8, ["meta"] = { ["fields"] = {  }, ["inventory"] = {  } }, ["param2"] = 18, ["y"] = 0, ["param1"] = 0, ["z"] = 2, ["name"] = "default:tree" }, { ["x"] = 8, ["meta"] = { ["fields"] = { ["owner_info"] = "return { [\"y\"] = 75, [\"x\"] = 601, [\"z\"] = -777 }" }, ["inventory"] = {  } }, ["param2"] = 0, ["y"] = 0, ["param1"] = 140, ["z"] = 4, ["name"] = "cottages:bench" }, { ["x"] = 8, ["meta"] = { ["fields"] = { ["owner_info"] = "return { [\"y\"] = 75, [\"x\"] = 601, [\"z\"] = -777 }" }, ["inventory"] = {  } }, ["param2"] = 1, ["y"] = 0, ["param1"] = 0, ["z"] = 5, ["name"] = "default:tree" }, { ["x"] = 8, ["meta"] = { ["fields"] = { ["owner_info"] = "return { [\"y\"] = 75, [\"x\"] = 601, [\"z\"] = -777 }" }, ["inventory"] = {  } }, ["param2"] = 1, ["y"] = 0, ["param1"] = 0, ["z"] = 6, ["name"] = "default:wood" }, { ["x"] = 8, ["meta"] = { ["fields"] = { ["owner_info"] = "return { [\"y\"] = 75, [\"x\"] = 601, [\"z\"] = -777 }" }, ["inventory"] = {  } }, ["param2"] = 1, ["y"] = 0, ["param1"] = 0, ["z"] = 7, ["name"] = "default:wood" }, { ["x"] = 8, ["meta"] = { ["fields"] = { ["owner_info"] = "return { [\"y\"] = 75, [\"x\"] = 601, [\"z\"] = -777 }" }, ["inventory"] = {  } }, ["param2"] = 1, ["y"] = 0, ["param1"] = 0, ["z"] = 8, ["name"] = "default:wood" }, { ["x"] = 8, ["meta"] = { ["fields"] = { ["owner_info"] = "return { [\"y\"] = 75, [\"x\"] = 601, [\"z\"] = -777 }" }, ["inventory"] = {  } }, ["param2"] = 1, ["y"] = 0, ["param1"] = 0, ["z"] = 9, ["name"] = "default:tree" }, { ["x"] = 8, ["meta"] = { ["fields"] = { ["owner_info"] = "return { [\"y\"] = 75, [\"x\"] = 601, [\"z\"] = -777 }" }, ["inventory"] = {  } }, ["param2"] = 1, ["y"] = 1, ["param1"] = 15, ["z"] = 0, ["name"] = "default:torch" }, { ["x"] = 8, ["meta"] = { ["fields"] = { ["owner_info"] = "return { [\"y\"] = 75, [\"x\"] = 601, [\"z\"] = -777 }" }, ["inventory"] = {  } }, ["param2"] = 1, ["y"] = 1, ["param1"] = 0, ["z"] = 5, ["name"] = "default:tree" }, { ["x"] = 8, ["meta"] = { ["fields"] = { ["owner_info"] = "return { [\"y\"] = 75, [\"x\"] = 601, [\"z\"] = -777 }" }, ["inventory"] = {  } }, ["param2"] = 1, ["y"] = 1, ["param1"] = 0, ["z"] = 6, ["name"] = "default:wood" }, { ["x"] = 8, ["meta"] = { ["fields"] = { ["owner_info"] = "return { [\"y\"] = 75, [\"x\"] = 601, [\"z\"] = -777 }" }, ["inventory"] = {  } }, ["param2"] = 1, ["y"] = 1, ["param1"] = 0, ["z"] = 7, ["name"] = "default:wood" }, { ["x"] = 8, ["meta"] = { ["fields"] = { ["owner_info"] = "return { [\"y\"] = 75, [\"x\"] = 601, [\"z\"] = -777 }" }, ["inventory"] = {  } }, ["param2"] = 1, ["y"] = 1, ["param1"] = 0, ["z"] = 8, ["name"] = "default:wood" }, { ["x"] = 8, ["meta"] = { ["fields"] = { ["owner_info"] = "return { [\"y\"] = 75, [\"x\"] = 601, [\"z\"] = -777 }" }, ["inventory"] = {  } }, ["param2"] = 1, ["y"] = 1, ["param1"] = 0, ["z"] = 9, ["name"] = "default:tree" }, { ["x"] = 8, ["meta"] = { ["fields"] = { ["owner_info"] = "return { [\"y\"] = 75, [\"x\"] = 601, [\"z\"] = -777 }" }, ["inventory"] = {  } }, ["param2"] = 1, ["y"] = 2, ["param1"] = 0, ["z"] = 5, ["name"] = "default:tree" }, { ["x"] = 8, ["meta"] = { ["fields"] = { ["owner_info"] = "return { [\"y\"] = 75, [\"x\"] = 601, [\"z\"] = -777 }" }, ["inventory"] = {  } }, ["param2"] = 1, ["y"] = 2, ["param1"] = 0, ["z"] = 6, ["name"] = "default:wood" }, { ["x"] = 8, ["meta"] = { ["fields"] = {  }, ["inventory"] = {  } }, ["param2"] = 3, ["y"] = 2, ["param1"] = 188, ["z"] = 7, ["name"] = "cottages:glass_pane" }, { ["x"] = 8, ["meta"] = { ["fields"] = { ["owner_info"] = "return { [\"y\"] = 75, [\"x\"] = 601, [\"z\"] = -777 }" }, ["inventory"] = {  } }, ["param2"] = 1, ["y"] = 2, ["param1"] = 0, ["z"] = 8, ["name"] = "default:wood" }, { ["x"] = 8, ["meta"] = { ["fields"] = { ["owner_info"] = "return { [\"y\"] = 75, [\"x\"] = 601, [\"z\"] = -777 }" }, ["inventory"] = {  } }, ["param2"] = 1, ["y"] = 2, ["param1"] = 0, ["z"] = 9, ["name"] = "default:tree" }, { ["x"] = 8, ["meta"] = { ["fields"] = { ["owner_info"] = "return { [\"y\"] = 75, [\"x\"] = 601, [\"z\"] = -777 }" }, ["inventory"] = {  } }, ["param2"] = 2, ["y"] = 2, ["param1"] = 173, ["z"] = 10, ["name"] = "cottages:roof_wood" }, { ["x"] = 8, ["meta"] = { ["fields"] = { ["owner_info"] = "return { [\"y\"] = 75, [\"x\"] = 601, [\"z\"] = -777 }" }, ["inventory"] = {  } }, ["param2"] = 1, ["y"] = 3, ["param1"] = 0, ["z"] = 5, ["name"] = "default:tree" }, { ["x"] = 8, ["meta"] = { ["fields"] = { ["owner_info"] = "return { [\"y\"] = 75, [\"x\"] = 601, [\"z\"] = -777 }" }, ["inventory"] = {  } }, ["param2"] = 1, ["y"] = 3, ["param1"] = 0, ["z"] = 6, ["name"] = "default:wood" }, { ["x"] = 8, ["meta"] = { ["fields"] = { ["owner_info"] = "return { [\"y\"] = 75, [\"x\"] = 601, [\"z\"] = -777 }" }, ["inventory"] = {  } }, ["param2"] = 1, ["y"] = 3, ["param1"] = 0, ["z"] = 7, ["name"] = "default:wood" }, { ["x"] = 8, ["meta"] = { ["fields"] = { ["owner_info"] = "return { [\"y\"] = 75, [\"x\"] = 601, [\"z\"] = -777 }" }, ["inventory"] = {  } }, ["param2"] = 1, ["y"] = 3, ["param1"] = 0, ["z"] = 8, ["name"] = "default:wood" }, { ["x"] = 8, ["meta"] = { ["fields"] = { ["owner_info"] = "return { [\"y\"] = 75, [\"x\"] = 601, [\"z\"] = -777 }" }, ["inventory"] = {  } }, ["param2"] = 2, ["y"] = 3, ["param1"] = 173, ["z"] = 9, ["name"] = "cottages:roof_connector_wood" }, { ["x"] = 8, ["meta"] = { ["fields"] = { ["owner_info"] = "return { [\"y\"] = 75, [\"x\"] = 601, [\"z\"] = -777 }" }, ["inventory"] = {  } }, ["param2"] = 1, ["y"] = 4, ["param1"] = 0, ["z"] = 5, ["name"] = "default:tree" }, { ["x"] = 8, ["meta"] = { ["fields"] = { ["owner_info"] = "return { [\"y\"] = 75, [\"x\"] = 601, [\"z\"] = -777 }" }, ["inventory"] = {  } }, ["param2"] = 1, ["y"] = 4, ["param1"] = 0, ["z"] = 6, ["name"] = "default:wood" }, { ["x"] = 8, ["meta"] = { ["fields"] = {  }, ["inventory"] = {  } }, ["param2"] = 3, ["y"] = 4, ["param1"] = 188, ["z"] = 7, ["name"] = "cottages:glass_pane" }, { ["x"] = 8, ["meta"] = { ["fields"] = { ["owner_info"] = "return { [\"y\"] = 75, [\"x\"] = 601, [\"z\"] = -777 }" }, ["inventory"] = {  } }, ["param2"] = 2, ["y"] = 4, ["param1"] = 173, ["z"] = 8, ["name"] = "cottages:roof_connector_wood" }, { ["x"] = 8, ["meta"] = { ["fields"] = { ["owner_info"] = "return { [\"y\"] = 75, [\"x\"] = 601, [\"z\"] = -777 }" }, ["inventory"] = {  } }, ["param2"] = 1, ["y"] = 5, ["param1"] = 0, ["z"] = 3, ["name"] = "default:wood" }, { ["x"] = 8, ["meta"] = { ["fields"] = { ["owner_info"] = "return { [\"y\"] = 75, [\"x\"] = 601, [\"z\"] = -777 }" }, ["inventory"] = {  } }, ["param2"] = 1, ["y"] = 5, ["param1"] = 0, ["z"] = 4, ["name"] = "default:wood" }, { ["x"] = 8, ["meta"] = { ["fields"] = { ["owner_info"] = "return { [\"y\"] = 75, [\"x\"] = 601, [\"z\"] = -777 }" }, ["inventory"] = {  } }, ["param2"] = 2, ["y"] = 5, ["param1"] = 173, ["z"] = 5, ["name"] = "cottages:roof_connector_wood" }, { ["x"] = 8, ["meta"] = { ["fields"] = { ["owner_info"] = "return { [\"y\"] = 75, [\"x\"] = 601, [\"z\"] = -777 }" }, ["inventory"] = {  } }, ["param2"] = 2, ["y"] = 5, ["param1"] = 189, ["z"] = 6, ["name"] = "cottages:roof_flat_wood" }, { ["x"] = 8, ["meta"] = { ["fields"] = { ["owner_info"] = "return { [\"y\"] = 75, [\"x\"] = 601, [\"z\"] = -777 }" }, ["inventory"] = {  } }, ["param2"] = 2, ["y"] = 5, ["param1"] = 173, ["z"] = 7, ["name"] = "cottages:roof_flat_wood" }, { ["x"] = 8, ["meta"] = { ["fields"] = { ["owner_info"] = "return { [\"y\"] = 75, [\"x\"] = 601, [\"z\"] = -777 }" }, ["inventory"] = {  } }, ["param2"] = 0, ["y"] = 6, ["param1"] = 125, ["z"] = 3, ["name"] = "cottages:roof_flat_wood" }, { ["x"] = 9, ["meta"] = { ["fields"] = { ["owner_info"] = "return { [\"y\"] = 75, [\"x\"] = 601, [\"z\"] = -777 }" }, ["inventory"] = {  } }, ["param2"] = 3, ["y"] = 2, ["param1"] = 0, ["z"] = 6, ["name"] = "default:torch" }, { ["x"] = 9, ["meta"] = { ["fields"] = {  }, ["inventory"] = {  } }, ["param2"] = 3, ["y"] = 2, ["param1"] = 205, ["z"] = 7, ["name"] = "cottages:window_shutter_open" }, { ["x"] = 9, ["meta"] = { ["fields"] = { ["owner_info"] = "return { [\"y\"] = 75, [\"x\"] = 601, [\"z\"] = -777 }" }, ["inventory"] = {  } }, ["param2"] = 3, ["y"] = 2, ["param1"] = 0, ["z"] = 8, ["name"] = "default:torch" }, { ["x"] = 9, ["meta"] = { ["fields"] = { ["owner_info"] = "return { [\"y\"] = 75, [\"x\"] = 601, [\"z\"] = -777 }" }, ["inventory"] = {  } }, ["param2"] = 2, ["y"] = 2, ["param1"] = 189, ["z"] = 10, ["name"] = "cottages:roof_wood" }, { ["x"] = 9, ["meta"] = { ["fields"] = { ["owner_info"] = "return { [\"y\"] = 75, [\"x\"] = 601, [\"z\"] = -777 }" }, ["inventory"] = {  } }, ["param2"] = 2, ["y"] = 3, ["param1"] = 189, ["z"] = 9, ["name"] = "cottages:roof_wood" }, { ["x"] = 9, ["meta"] = { ["fields"] = {  }, ["inventory"] = {  } }, ["param2"] = 3, ["y"] = 4, ["param1"] = 173, ["z"] = 7, ["name"] = "cottages:window_shutter_open" }, { ["x"] = 9, ["meta"] = { ["fields"] = { ["owner_info"] = "return { [\"y\"] = 75, [\"x\"] = 601, [\"z\"] = -777 }" }, ["inventory"] = {  } }, ["param2"] = 2, ["y"] = 4, ["param1"] = 189, ["z"] = 8, ["name"] = "cottages:roof_wood" }, { ["x"] = 9, ["meta"] = { ["fields"] = { ["owner_info"] = "return { [\"y\"] = 75, [\"x\"] = 601, [\"z\"] = -777 }" }, ["inventory"] = {  } }, ["param2"] = 1, ["y"] = 5, ["param1"] = 0, ["z"] = 3, ["name"] = "default:wood" }, { ["x"] = 9, ["meta"] = { ["fields"] = { ["owner_info"] = "return { [\"y\"] = 75, [\"x\"] = 601, [\"z\"] = -777 }" }, ["inventory"] = {  } }, ["param2"] = 1, ["y"] = 5, ["param1"] = 0, ["z"] = 4, ["name"] = "default:wood" }, { ["x"] = 9, ["meta"] = { ["fields"] = { ["owner_info"] = "return { [\"y\"] = 75, [\"x\"] = 601, [\"z\"] = -777 }" }, ["inventory"] = {  } }, ["param2"] = 2, ["y"] = 5, ["param1"] = 173, ["z"] = 5, ["name"] = "cottages:roof_wood" }, { ["x"] = 9, ["meta"] = { ["fields"] = { ["owner_info"] = "return { [\"y\"] = 75, [\"x\"] = 601, [\"z\"] = -777 }" }, ["inventory"] = {  } }, ["param2"] = 2, ["y"] = 5, ["param1"] = 173, ["z"] = 6, ["name"] = "cottages:roof_flat_wood" }, { ["x"] = 9, ["meta"] = { ["fields"] = { ["owner_info"] = "return { [\"y\"] = 75, [\"x\"] = 601, [\"z\"] = -777 }" }, ["inventory"] = {  } }, ["param2"] = 2, ["y"] = 5, ["param1"] = 157, ["z"] = 7, ["name"] = "cottages:roof_flat_wood" } }