return { { ["x"] = 0, ["meta"] = { ["fields"] = { ["owner_info"] = "return { [\"y\"] = 75, [\"x\"] = 656, [\"z\"] = -779 }" }, ["inventory"] = {  } }, ["param2"] = 1, ["y"] = 0, ["param1"] = 205, ["z"] = 2, ["name"] = "cottages:bench" }, { ["x"] = 0, ["meta"] = { ["fields"] = { ["owner_info"] = "return { [\"y\"] = 75, [\"x\"] = 656, [\"z\"] = -779 }" }, ["inventory"] = {  } }, ["param2"] = 1, ["y"] = 0, ["param1"] = 189, ["z"] = 3, ["name"] = "cottages:bench" }, { ["x"] = 0, ["meta"] = { ["fields"] = { ["owner_info"] = "return { [\"y\"] = 75, [\"x\"] = 656, [\"z\"] = -779 }" }, ["inventory"] = {  } }, ["param2"] = 1, ["y"] = 0, ["param1"] = 189, ["z"] = 4, ["name"] = "cottages:bench" }, { ["x"] = 0, ["meta"] = { ["fields"] = { ["owner_info"] = "return { [\"y\"] = 75, [\"x\"] = 656, [\"z\"] = -779 }" }, ["inventory"] = {  } }, ["param2"] = 1, ["y"] = 0, ["param1"] = 205, ["z"] = 5, ["name"] = "cottages:bench" }, { ["x"] = 0, ["meta"] = { ["fields"] = { ["owner_info"] = "return { [\"y\"] = 75, [\"x\"] = 656, [\"z\"] = -779 }" }, ["inventory"] = {  } }, ["param2"] = 2, ["y"] = 1, ["param1"] = 0, ["z"] = 2, ["name"] = "default:torch" }, { ["x"] = 0, ["meta"] = { ["fields"] = { ["owner_info"] = "return { [\"y\"] = 75, [\"x\"] = 656, [\"z\"] = -779 }" }, ["inventory"] = {  } }, ["param2"] = 2, ["y"] = 1, ["param1"] = 0, ["z"] = 5, ["name"] = "default:torch" }, { ["x"] = 0, ["meta"] = { ["fields"] = {  }, ["inventory"] = {  } }, ["param2"] = 1, ["y"] = 2, ["param1"] = 205, ["z"] = 2, ["name"] = "cottages:window_shutter_open" }, { ["x"] = 0, ["meta"] = { ["fields"] = {  }, ["inventory"] = {  } }, ["param2"] = 1, ["y"] = 2, ["param1"] = 205, ["z"] = 5, ["name"] = "cottages:window_shutter_open" }, { ["x"] = 0, ["meta"] = { ["fields"] = {  }, ["inventory"] = {  } }, ["param2"] = 2, ["y"] = 3, ["param1"] = 0, ["z"] = 1, ["name"] = "default:torch" }, { ["x"] = 0, ["meta"] = { ["fields"] = {  }, ["inventory"] = {  } }, ["param2"] = 2, ["y"] = 3, ["param1"] = 0, ["z"] = 6, ["name"] = "default:torch" }, { ["x"] = 0, ["meta"] = { ["fields"] = {  }, ["inventory"] = {  } }, ["param2"] = 0, ["y"] = 4, ["param1"] = 189, ["z"] = 0, ["name"] = "cottages:roof_wood" }, { ["x"] = 0, ["meta"] = { ["fields"] = {  }, ["inventory"] = {  } }, ["param2"] = 18, ["y"] = 4, ["param1"] = 0, ["z"] = 1, ["name"] = "default:tree" }, { ["x"] = 0, ["meta"] = { ["fields"] = {  }, ["inventory"] = {  } }, ["param2"] = 18, ["y"] = 4, ["param1"] = 0, ["z"] = 6, ["name"] = "default:tree" }, { ["x"] = 0, ["meta"] = { ["fields"] = { ["owner_info"] = "return { [\"y\"] = 75, [\"x\"] = 656, [\"z\"] = -779 }" }, ["inventory"] = {  } }, ["param2"] = 2, ["y"] = 4, ["param1"] = 189, ["z"] = 7, ["name"] = "cottages:roof_wood" }, { ["x"] = 0, ["meta"] = { ["fields"] = { ["owner_info"] = "return { [\"y\"] = 75, [\"x\"] = 656, [\"z\"] = -779 }" }, ["inventory"] = {  } }, ["param2"] = 0, ["y"] = 5, ["param1"] = 205, ["z"] = 1, ["name"] = "cottages:roof_wood" }, { ["x"] = 0, ["meta"] = { ["fields"] = { ["owner_info"] = "return { [\"y\"] = 75, [\"x\"] = 656, [\"z\"] = -779 }" }, ["inventory"] = {  } }, ["param2"] = 2, ["y"] = 5, ["param1"] = 0, ["z"] = 2, ["name"] = "default:torch" }, { ["x"] = 0, ["meta"] = { ["fields"] = {  }, ["inventory"] = {  } }, ["param2"] = 1, ["y"] = 5, ["param1"] = 205, ["z"] = 3, ["name"] = "cottages:window_shutter_open" }, { ["x"] = 0, ["meta"] = { ["fields"] = { ["owner_info"] = "return { [\"y\"] = 75, [\"x\"] = 656, [\"z\"] = -779 }" }, ["inventory"] = {  } }, ["param2"] = 2, ["y"] = 5, ["param1"] = 0, ["z"] = 5, ["name"] = "default:torch" }, { ["x"] = 0, ["meta"] = { ["fields"] = { ["owner_info"] = "return { [\"y\"] = 75, [\"x\"] = 656, [\"z\"] = -779 }" }, ["inventory"] = {  } }, ["param2"] = 2, ["y"] = 5, ["param1"] = 205, ["z"] = 6, ["name"] = "cottages:roof_wood" }, { ["x"] = 0, ["meta"] = { ["fields"] = { ["owner_info"] = "return { [\"y\"] = 75, [\"x\"] = 656, [\"z\"] = -779 }" }, ["inventory"] = {  } }, ["param2"] = 0, ["y"] = 6, ["param1"] = 205, ["z"] = 2, ["name"] = "cottages:roof_wood" }, { ["x"] = 0, ["meta"] = { ["fields"] = {  }, ["inventory"] = {  } }, ["param2"] = 1, ["y"] = 6, ["param1"] = 189, ["z"] = 3, ["name"] = "cottages:window_shutter_open" }, { ["x"] = 0, ["meta"] = { ["fields"] = { ["owner_info"] = "return { [\"y\"] = 75, [\"x\"] = 656, [\"z\"] = -779 }" }, ["inventory"] = {  } }, ["param2"] = 2, ["y"] = 6, ["param1"] = 205, ["z"] = 5, ["name"] = "cottages:roof_wood" }, { ["x"] = 0, ["meta"] = { ["fields"] = { ["owner_info"] = "return { [\"y\"] = 75, [\"x\"] = 656, [\"z\"] = -779 }" }, ["inventory"] = {  } }, ["param2"] = 0, ["y"] = 7, ["param1"] = 173, ["z"] = 3, ["name"] = "cottages:roof_wood" }, { ["x"] = 0, ["meta"] = { ["fields"] = { ["owner_info"] = "return { [\"y\"] = 75, [\"x\"] = 656, [\"z\"] = -779 }" }, ["inventory"] = {  } }, ["param2"] = 2, ["y"] = 7, ["param1"] = 173, ["z"] = 4, ["name"] = "cottages:roof_wood" }, { ["x"] = 1, ["meta"] = { ["fields"] = { ["owner_info"] = "return { [\"y\"] = 75, [\"x\"] = 656, [\"z\"] = -779 }" }, ["inventory"] = {  } }, ["param2"] = 1, ["y"] = 0, ["param1"] = 0, ["z"] = 1, ["name"] = "default:tree" }, { ["x"] = 1, ["meta"] = { ["fields"] = { ["owner_info"] = "return { [\"y\"] = 75, [\"x\"] = 656, [\"z\"] = -779 }" }, ["inventory"] = {  } }, ["param2"] = 1, ["y"] = 0, ["param1"] = 0, ["z"] = 2, ["name"] = "default:wood" }, { ["x"] = 1, ["meta"] = { ["fields"] = { ["owner_info"] = "return { [\"y\"] = 75, [\"x\"] = 656, [\"z\"] = -779 }" }, ["inventory"] = {  } }, ["param2"] = 1, ["y"] = 0, ["param1"] = 0, ["z"] = 3, ["name"] = "default:wood" }, { ["x"] = 1, ["meta"] = { ["fields"] = { ["owner_info"] = "return { [\"y\"] = 75, [\"x\"] = 656, [\"z\"] = -779 }" }, ["inventory"] = {  } }, ["param2"] = 1, ["y"] = 0, ["param1"] = 0, ["z"] = 4, ["name"] = "default:wood" }, { ["x"] = 1, ["meta"] = { ["fields"] = { ["owner_info"] = "return { [\"y\"] = 75, [\"x\"] = 656, [\"z\"] = -779 }" }, ["inventory"] = {  } }, ["param2"] = 1, ["y"] = 0, ["param1"] = 0, ["z"] = 5, ["name"] = "default:wood" }, { ["x"] = 1, ["meta"] = { ["fields"] = { ["owner_info"] = "return { [\"y\"] = 75, [\"x\"] = 656, [\"z\"] = -779 }" }, ["inventory"] = {  } }, ["param2"] = 1, ["y"] = 0, ["param1"] = 0, ["z"] = 6, ["name"] = "default:tree" }, { ["x"] = 1, ["meta"] = { ["fields"] = { ["owner_info"] = "return { [\"y\"] = 75, [\"x\"] = 656, [\"z\"] = -779 }" }, ["inventory"] = {  } }, ["param2"] = 1, ["y"] = 1, ["param1"] = 0, ["z"] = 1, ["name"] = "default:tree" }, { ["x"] = 1, ["meta"] = { ["fields"] = { ["owner_info"] = "return { [\"y\"] = 75, [\"x\"] = 656, [\"z\"] = -779 }" }, ["inventory"] = {  } }, ["param2"] = 1, ["y"] = 1, ["param1"] = 0, ["z"] = 2, ["name"] = "default:wood" }, { ["x"] = 1, ["meta"] = { ["fields"] = { ["owner_info"] = "return { [\"y\"] = 75, [\"x\"] = 656, [\"z\"] = -779 }" }, ["inventory"] = {  } }, ["param2"] = 1, ["y"] = 1, ["param1"] = 0, ["z"] = 3, ["name"] = "default:wood" }, { ["x"] = 1, ["meta"] = { ["fields"] = { ["owner_info"] = "return { [\"y\"] = 75, [\"x\"] = 656, [\"z\"] = -779 }" }, ["inventory"] = {  } }, ["param2"] = 1, ["y"] = 1, ["param1"] = 0, ["z"] = 4, ["name"] = "default:wood" }, { ["x"] = 1, ["meta"] = { ["fields"] = { ["owner_info"] = "return { [\"y\"] = 75, [\"x\"] = 656, [\"z\"] = -779 }" }, ["inventory"] = {  } }, ["param2"] = 1, ["y"] = 1, ["param1"] = 0, ["z"] = 5, ["name"] = "default:wood" }, { ["x"] = 1, ["meta"] = { ["fields"] = { ["owner_info"] = "return { [\"y\"] = 75, [\"x\"] = 656, [\"z\"] = -779 }" }, ["inventory"] = {  } }, ["param2"] = 1, ["y"] = 1, ["param1"] = 0, ["z"] = 6, ["name"] = "default:tree" }, { ["x"] = 1, ["meta"] = { ["fields"] = { ["owner_info"] = "return { [\"y\"] = 75, [\"x\"] = 656, [\"z\"] = -779 }" }, ["inventory"] = {  } }, ["param2"] = 1, ["y"] = 2, ["param1"] = 0, ["z"] = 1, ["name"] = "default:tree" }, { ["x"] = 1, ["meta"] = { ["fields"] = {  }, ["inventory"] = {  } }, ["param2"] = 1, ["y"] = 2, ["param1"] = 188, ["z"] = 2, ["name"] = "cottages:glass_pane" }, { ["x"] = 1, ["meta"] = { ["fields"] = { ["owner_info"] = "return { [\"y\"] = 75, [\"x\"] = 656, [\"z\"] = -779 }" }, ["inventory"] = {  } }, ["param2"] = 1, ["y"] = 2, ["param1"] = 0, ["z"] = 3, ["name"] = "default:wood" }, { ["x"] = 1, ["meta"] = { ["fields"] = { ["owner_info"] = "return { [\"y\"] = 75, [\"x\"] = 656, [\"z\"] = -779 }" }, ["inventory"] = {  } }, ["param2"] = 1, ["y"] = 2, ["param1"] = 0, ["z"] = 4, ["name"] = "default:wood" }, { ["x"] = 1, ["meta"] = { ["fields"] = {  }, ["inventory"] = {  } }, ["param2"] = 1, ["y"] = 2, ["param1"] = 188, ["z"] = 5, ["name"] = "cottages:glass_pane" }, { ["x"] = 1, ["meta"] = { ["fields"] = { ["owner_info"] = "return { [\"y\"] = 75, [\"x\"] = 656, [\"z\"] = -779 }" }, ["inventory"] = {  } }, ["param2"] = 1, ["y"] = 2, ["param1"] = 0, ["z"] = 6, ["name"] = "default:tree" }, { ["x"] = 1, ["meta"] = { ["fields"] = {  }, ["inventory"] = {  } }, ["param2"] = 1, ["y"] = 3, ["param1"] = 0, ["z"] = 1, ["name"] = "default:tree" }, { ["x"] = 1, ["meta"] = { ["fields"] = { ["owner_info"] = "return { [\"y\"] = 75, [\"x\"] = 656, [\"z\"] = -779 }" }, ["inventory"] = {  } }, ["param2"] = 1, ["y"] = 3, ["param1"] = 0, ["z"] = 2, ["name"] = "default:wood" }, { ["x"] = 1, ["meta"] = { ["fields"] = { ["owner_info"] = "return { [\"y\"] = 75, [\"x\"] = 656, [\"z\"] = -779 }" }, ["inventory"] = {  } }, ["param2"] = 1, ["y"] = 3, ["param1"] = 0, ["z"] = 3, ["name"] = "default:wood" }, { ["x"] = 1, ["meta"] = { ["fields"] = { ["owner_info"] = "return { [\"y\"] = 75, [\"x\"] = 656, [\"z\"] = -779 }" }, ["inventory"] = {  } }, ["param2"] = 1, ["y"] = 3, ["param1"] = 0, ["z"] = 4, ["name"] = "default:wood" }, { ["x"] = 1, ["meta"] = { ["fields"] = { ["owner_info"] = "return { [\"y\"] = 75, [\"x\"] = 656, [\"z\"] = -779 }" }, ["inventory"] = {  } }, ["param2"] = 1, ["y"] = 3, ["param1"] = 0, ["z"] = 5, ["name"] = "default:wood" }, { ["x"] = 1, ["meta"] = { ["fields"] = {  }, ["inventory"] = {  } }, ["param2"] = 1, ["y"] = 3, ["param1"] = 0, ["z"] = 6, ["name"] = "default:tree" }, { ["x"] = 1, ["meta"] = { ["fields"] = {  }, ["inventory"] = {  } }, ["param2"] = 0, ["y"] = 4, ["param1"] = 173, ["z"] = 0, ["name"] = "cottages:roof_wood" }, { ["x"] = 1, ["meta"] = { ["fields"] = {  }, ["inventory"] = {  } }, ["param2"] = 18, ["y"] = 4, ["param1"] = 0, ["z"] = 1, ["name"] = "default:tree" }, { ["x"] = 1, ["meta"] = { ["fields"] = { ["owner_info"] = "return { [\"y\"] = 75, [\"x\"] = 656, [\"z\"] = -779 }" }, ["inventory"] = {  } }, ["param2"] = 1, ["y"] = 4, ["param1"] = 0, ["z"] = 2, ["name"] = "default:wood" }, { ["x"] = 1, ["meta"] = { ["fields"] = { ["owner_info"] = "return { [\"y\"] = 75, [\"x\"] = 656, [\"z\"] = -779 }" }, ["inventory"] = {  } }, ["param2"] = 1, ["y"] = 4, ["param1"] = 0, ["z"] = 3, ["name"] = "default:wood" }, { ["x"] = 1, ["meta"] = { ["fields"] = { ["owner_info"] = "return { [\"y\"] = 75, [\"x\"] = 656, [\"z\"] = -779 }" }, ["inventory"] = {  } }, ["param2"] = 1, ["y"] = 4, ["param1"] = 0, ["z"] = 4, ["name"] = "default:wood" }, { ["x"] = 1, ["meta"] = { ["fields"] = { ["owner_info"] = "return { [\"y\"] = 75, [\"x\"] = 656, [\"z\"] = -779 }" }, ["inventory"] = {  } }, ["param2"] = 1, ["y"] = 4, ["param1"] = 0, ["z"] = 5, ["name"] = "default:wood" }, { ["x"] = 1, ["meta"] = { ["fields"] = {  }, ["inventory"] = {  } }, ["param2"] = 18, ["y"] = 4, ["param1"] = 0, ["z"] = 6, ["name"] = "default:tree" }, { ["x"] = 1, ["meta"] = { ["fields"] = { ["owner_info"] = "return { [\"y\"] = 75, [\"x\"] = 656, [\"z\"] = -779 }" }, ["inventory"] = {  } }, ["param2"] = 2, ["y"] = 4, ["param1"] = 173, ["z"] = 7, ["name"] = "cottages:roof_wood" }, { ["x"] = 1, ["meta"] = { ["fields"] = { ["owner_info"] = "return { [\"y\"] = 75, [\"x\"] = 656, [\"z\"] = -779 }" }, ["inventory"] = {  } }, ["param2"] = 0, ["y"] = 5, ["param1"] = 189, ["z"] = 1, ["name"] = "cottages:roof_connector_wood" }, { ["x"] = 1, ["meta"] = { ["fields"] = { ["owner_info"] = "return { [\"y\"] = 75, [\"x\"] = 656, [\"z\"] = -779 }" }, ["inventory"] = {  } }, ["param2"] = 1, ["y"] = 5, ["param1"] = 0, ["z"] = 2, ["name"] = "default:wood" }, { ["x"] = 1, ["meta"] = { ["fields"] = {  }, ["inventory"] = {  } }, ["param2"] = 1, ["y"] = 5, ["param1"] = 188, ["z"] = 3, ["name"] = "cottages:glass_pane" }, { ["x"] = 1, ["meta"] = { ["fields"] = { ["owner_info"] = "return { [\"y\"] = 75, [\"x\"] = 656, [\"z\"] = -779 }" }, ["inventory"] = {  } }, ["param2"] = 1, ["y"] = 5, ["param1"] = 0, ["z"] = 4, ["name"] = "default:wood" }, { ["x"] = 1, ["meta"] = { ["fields"] = { ["owner_info"] = "return { [\"y\"] = 75, [\"x\"] = 656, [\"z\"] = -779 }" }, ["inventory"] = {  } }, ["param2"] = 1, ["y"] = 5, ["param1"] = 0, ["z"] = 5, ["name"] = "default:wood" }, { ["x"] = 1, ["meta"] = { ["fields"] = { ["owner_info"] = "return { [\"y\"] = 75, [\"x\"] = 656, [\"z\"] = -779 }" }, ["inventory"] = {  } }, ["param2"] = 2, ["y"] = 5, ["param1"] = 189, ["z"] = 6, ["name"] = "cottages:roof_connector_wood" }, { ["x"] = 1, ["meta"] = { ["fields"] = { ["owner_info"] = "return { [\"y\"] = 75, [\"x\"] = 656, [\"z\"] = -779 }" }, ["inventory"] = {  } }, ["param2"] = 0, ["y"] = 6, ["param1"] = 189, ["z"] = 2, ["name"] = "cottages:roof_connector_wood" }, { ["x"] = 1, ["meta"] = { ["fields"] = {  }, ["inventory"] = {  } }, ["param2"] = 1, ["y"] = 6, ["param1"] = 172, ["z"] = 3, ["name"] = "cottages:glass_pane" }, { ["x"] = 1, ["meta"] = { ["fields"] = { ["owner_info"] = "return { [\"y\"] = 75, [\"x\"] = 656, [\"z\"] = -779 }" }, ["inventory"] = {  } }, ["param2"] = 1, ["y"] = 6, ["param1"] = 0, ["z"] = 4, ["name"] = "default:wood" }, { ["x"] = 1, ["meta"] = { ["fields"] = { ["owner_info"] = "return { [\"y\"] = 75, [\"x\"] = 656, [\"z\"] = -779 }" }, ["inventory"] = {  } }, ["param2"] = 2, ["y"] = 6, ["param1"] = 189, ["z"] = 5, ["name"] = "cottages:roof_connector_wood" }, { ["x"] = 1, ["meta"] = { ["fields"] = { ["owner_info"] = "return { [\"y\"] = 75, [\"x\"] = 656, [\"z\"] = -779 }" }, ["inventory"] = {  } }, ["param2"] = 0, ["y"] = 7, ["param1"] = 157, ["z"] = 3, ["name"] = "cottages:roof_connector_wood" }, { ["x"] = 1, ["meta"] = { ["fields"] = { ["owner_info"] = "return { [\"y\"] = 75, [\"x\"] = 656, [\"z\"] = -779 }" }, ["inventory"] = {  } }, ["param2"] = 2, ["y"] = 7, ["param1"] = 157, ["z"] = 4, ["name"] = "cottages:roof_connector_wood" }, { ["x"] = 2, ["meta"] = { ["fields"] = { ["owner_info"] = "return { [\"y\"] = 75, [\"x\"] = 656, [\"z\"] = -779 }" }, ["inventory"] = {  } }, ["param2"] = 0, ["y"] = 0, ["param1"] = 157, ["z"] = 0, ["name"] = "cottages:bench" }, { ["x"] = 2, ["meta"] = { ["fields"] = { ["owner_info"] = "return { [\"y\"] = 75, [\"x\"] = 656, [\"z\"] = -779 }" }, ["inventory"] = {  } }, ["param2"] = 1, ["y"] = 0, ["param1"] = 0, ["z"] = 1, ["name"] = "default:wood" }, { ["x"] = 2, ["meta"] = { ["fields"] = { ["owner_info"] = "return { [\"y\"] = 75, [\"x\"] = 656, [\"z\"] = -779 }" }, ["inventory"] = {  } }, ["param2"] = 1, ["y"] = 0, ["param1"] = 0, ["z"] = 2, ["name"] = "default:wood" }, { ["x"] = 2, ["meta"] = { ["fields"] = { ["owner_info"] = "return { [\"y\"] = 75, [\"x\"] = 656, [\"z\"] = -779 }" }, ["inventory"] = {  } }, ["param2"] = 1, ["y"] = 0, ["param1"] = 0, ["z"] = 3, ["name"] = "default:wood" }, { ["x"] = 2, ["meta"] = { ["fields"] = { ["owner_info"] = "return { [\"y\"] = 75, [\"x\"] = 656, [\"z\"] = -779 }" }, ["inventory"] = {  } }, ["param2"] = 1, ["y"] = 0, ["param1"] = 0, ["z"] = 4, ["name"] = "default:wood" }, { ["x"] = 2, ["meta"] = { ["fields"] = { ["owner_info"] = "return { [\"y\"] = 75, [\"x\"] = 656, [\"z\"] = -779 }" }, ["inventory"] = {  } }, ["param2"] = 1, ["y"] = 0, ["param1"] = 0, ["z"] = 5, ["name"] = "default:wood" }, { ["x"] = 2, ["meta"] = { ["fields"] = { ["owner_info"] = "return { [\"y\"] = 75, [\"x\"] = 656, [\"z\"] = -779 }" }, ["inventory"] = {  } }, ["param2"] = 1, ["y"] = 0, ["param1"] = 0, ["z"] = 6, ["name"] = "default:wood" }, { ["x"] = 2, ["meta"] = { ["fields"] = { ["owner_info"] = "return { [\"y\"] = 75, [\"x\"] = 656, [\"z\"] = -779 }" }, ["inventory"] = {  } }, ["param2"] = 1, ["y"] = 1, ["param1"] = 0, ["z"] = 1, ["name"] = "default:wood" }, { ["x"] = 2, ["meta"] = { ["fields"] = { ["owner_info"] = "return { [\"y\"] = 75, [\"x\"] = 656, [\"z\"] = -779 }" }, ["inventory"] = {  } }, ["param2"] = 3, ["y"] = 1, ["param1"] = 187, ["z"] = 2, ["name"] = "cottages:bench" }, { ["x"] = 2, ["meta"] = { ["fields"] = { ["owner_info"] = "return { [\"y\"] = 75, [\"x\"] = 656, [\"z\"] = -779 }" }, ["inventory"] = {  } }, ["param2"] = 3, ["y"] = 1, ["param1"] = 204, ["z"] = 3, ["name"] = "cottages:bench" }, { ["x"] = 2, ["meta"] = { ["fields"] = { ["owner_info"] = "return { [\"y\"] = 75, [\"x\"] = 656, [\"z\"] = -779 }" }, ["inventory"] = {  } }, ["param2"] = 0, ["y"] = 1, ["param1"] = 187, ["z"] = 4, ["name"] = "cottages:bed_foot" }, { ["x"] = 2, ["meta"] = { ["fields"] = { ["owner_info"] = "return { [\"y\"] = 75, [\"x\"] = 656, [\"z\"] = -779 }" }, ["inventory"] = {  } }, ["param2"] = 0, ["y"] = 1, ["param1"] = 170, ["z"] = 5, ["name"] = "cottages:bed_head" }, { ["x"] = 2, ["meta"] = { ["fields"] = { ["owner_info"] = "return { [\"y\"] = 75, [\"x\"] = 656, [\"z\"] = -779 }" }, ["inventory"] = {  } }, ["param2"] = 1, ["y"] = 1, ["param1"] = 0, ["z"] = 6, ["name"] = "default:wood" }, { ["x"] = 2, ["meta"] = { ["fields"] = {  }, ["inventory"] = {  } }, ["param2"] = 0, ["y"] = 2, ["param1"] = 189, ["z"] = 0, ["name"] = "cottages:window_shutter_open" }, { ["x"] = 2, ["meta"] = { ["fields"] = {  }, ["inventory"] = {  } }, ["param2"] = 0, ["y"] = 2, ["param1"] = 188, ["z"] = 1, ["name"] = "cottages:glass_pane" }, { ["x"] = 2, ["meta"] = { ["fields"] = { ["owner_info"] = "return { [\"y\"] = 75, [\"x\"] = 656, [\"z\"] = -779 }" }, ["inventory"] = {  } }, ["param2"] = 3, ["y"] = 2, ["param1"] = 0, ["z"] = 3, ["name"] = "default:torch" }, { ["x"] = 2, ["meta"] = { ["fields"] = { ["owner_info"] = "return { [\"y\"] = 75, [\"x\"] = 656, [\"z\"] = -779 }" }, ["inventory"] = {  } }, ["param2"] = 0, ["y"] = 2, ["param1"] = 204, ["z"] = 4, ["name"] = "cottages:bed_foot" }, { ["x"] = 2, ["meta"] = { ["fields"] = { ["owner_info"] = "return { [\"y\"] = 75, [\"x\"] = 656, [\"z\"] = -779 }" }, ["inventory"] = {  } }, ["param2"] = 0, ["y"] = 2, ["param1"] = 187, ["z"] = 5, ["name"] = "cottages:bed_head" }, { ["x"] = 2, ["meta"] = { ["fields"] = { ["owner_info"] = "return { [\"y\"] = 75, [\"x\"] = 656, [\"z\"] = -779 }" }, ["inventory"] = {  } }, ["param2"] = 1, ["y"] = 2, ["param1"] = 0, ["z"] = 6, ["name"] = "default:wood" }, { ["x"] = 2, ["meta"] = { ["fields"] = {  }, ["inventory"] = {  } }, ["param2"] = 1, ["y"] = 3, ["param1"] = 0, ["z"] = 1, ["name"] = "default:wood" }, { ["x"] = 2, ["meta"] = { ["fields"] = {  }, ["inventory"] = {  } }, ["param2"] = 1, ["y"] = 3, ["param1"] = 0, ["z"] = 6, ["name"] = "default:wood" }, { ["x"] = 2, ["meta"] = { ["fields"] = {  }, ["inventory"] = {  } }, ["param2"] = 0, ["y"] = 4, ["param1"] = 157, ["z"] = 0, ["name"] = "cottages:roof_wood" }, { ["x"] = 2, ["meta"] = { ["fields"] = {  }, ["inventory"] = {  } }, ["param2"] = 18, ["y"] = 4, ["param1"] = 0, ["z"] = 1, ["name"] = "default:tree" }, { ["x"] = 2, ["meta"] = { ["fields"] = { ["owner_info"] = "return { [\"y\"] = 75, [\"x\"] = 656, [\"z\"] = -779 }" }, ["inventory"] = {  } }, ["param2"] = 1, ["y"] = 4, ["param1"] = 0, ["z"] = 2, ["name"] = "default:wood" }, { ["x"] = 2, ["meta"] = { ["fields"] = { ["owner_info"] = "return { [\"y\"] = 75, [\"x\"] = 656, [\"z\"] = -779 }" }, ["inventory"] = {  } }, ["param2"] = 1, ["y"] = 4, ["param1"] = 0, ["z"] = 3, ["name"] = "default:wood" }, { ["x"] = 2, ["meta"] = { ["fields"] = { ["owner_info"] = "return { [\"y\"] = 75, [\"x\"] = 656, [\"z\"] = -779 }" }, ["inventory"] = {  } }, ["param2"] = 1, ["y"] = 4, ["param1"] = 0, ["z"] = 4, ["name"] = "default:wood" }, { ["x"] = 2, ["meta"] = { ["fields"] = { ["owner_info"] = "return { [\"y\"] = 75, [\"x\"] = 656, [\"z\"] = -779 }" }, ["inventory"] = {  } }, ["param2"] = 1, ["y"] = 4, ["param1"] = 0, ["z"] = 5, ["name"] = "default:wood" }, { ["x"] = 2, ["meta"] = { ["fields"] = {  }, ["inventory"] = {  } }, ["param2"] = 18, ["y"] = 4, ["param1"] = 0, ["z"] = 6, ["name"] = "default:tree" }, { ["x"] = 2, ["meta"] = { ["fields"] = { ["owner_info"] = "return { [\"y\"] = 75, [\"x\"] = 656, [\"z\"] = -779 }" }, ["inventory"] = {  } }, ["param2"] = 2, ["y"] = 4, ["param1"] = 157, ["z"] = 7, ["name"] = "cottages:roof_wood" }, { ["x"] = 2, ["meta"] = { ["fields"] = { ["owner_info"] = "return { [\"y\"] = 75, [\"x\"] = 656, [\"z\"] = -779 }" }, ["inventory"] = {  } }, ["param2"] = 0, ["y"] = 5, ["param1"] = 173, ["z"] = 1, ["name"] = "cottages:roof_wood" }, { ["x"] = 2, ["meta"] = { ["fields"] = {  }, ["inventory"] = {  } }, ["param2"] = 2, ["y"] = 5, ["param1"] = 156, ["z"] = 2, ["name"] = "cottages:bench" }, { ["x"] = 2, ["meta"] = { ["fields"] = { ["infotext"] = "Chest", ["formspec"] = "size[8,9]list[current_name;main;0,0;8,4;]list[current_player;main;0,5;8,4;]" }, ["inventory"] = { ["main"] = { "", "", "", "", "", "", "", "", "", "", "", "", "", "", "", "", "", "", "", "", "", "", "", "", "", "", "", "", "", "", "", "" } } }, ["param2"] = 0, ["y"] = 5, ["param1"] = 0, ["z"] = 5, ["name"] = "default:chest" }, { ["x"] = 2, ["meta"] = { ["fields"] = { ["owner_info"] = "return { [\"y\"] = 75, [\"x\"] = 656, [\"z\"] = -779 }" }, ["inventory"] = {  } }, ["param2"] = 2, ["y"] = 5, ["param1"] = 173, ["z"] = 6, ["name"] = "cottages:roof_wood" }, { ["x"] = 2, ["meta"] = { ["fields"] = { ["owner_info"] = "return { [\"y\"] = 75, [\"x\"] = 656, [\"z\"] = -779 }" }, ["inventory"] = {  } }, ["param2"] = 0, ["y"] = 6, ["param1"] = 173, ["z"] = 2, ["name"] = "cottages:roof_wood" }, { ["x"] = 2, ["meta"] = { ["fields"] = { ["owner_info"] = "return { [\"y\"] = 75, [\"x\"] = 656, [\"z\"] = -779 }" }, ["inventory"] = {  } }, ["param2"] = 2, ["y"] = 6, ["param1"] = 173, ["z"] = 5, ["name"] = "cottages:roof_wood" }, { ["x"] = 2, ["meta"] = { ["fields"] = { ["owner_info"] = "return { [\"y\"] = 75, [\"x\"] = 656, [\"z\"] = -779 }" }, ["inventory"] = {  } }, ["param2"] = 0, ["y"] = 7, ["param1"] = 141, ["z"] = 3, ["name"] = "cottages:roof_wood" }, { ["x"] = 2, ["meta"] = { ["fields"] = { ["owner_info"] = "return { [\"y\"] = 75, [\"x\"] = 656, [\"z\"] = -779 }" }, ["inventory"] = {  } }, ["param2"] = 2, ["y"] = 7, ["param1"] = 141, ["z"] = 4, ["name"] = "cottages:roof_wood" }, { ["x"] = 3, ["meta"] = { ["fields"] = { ["owner_info"] = "return { [\"y\"] = 75, [\"x\"] = 656, [\"z\"] = -779 }" }, ["inventory"] = {  } }, ["param2"] = 0, ["y"] = 0, ["param1"] = 173, ["z"] = 0, ["name"] = "cottages:bench" }, { ["x"] = 3, ["meta"] = { ["fields"] = { ["owner_info"] = "return { [\"y\"] = 75, [\"x\"] = 656, [\"z\"] = -779 }" }, ["inventory"] = {  } }, ["param2"] = 1, ["y"] = 0, ["param1"] = 0, ["z"] = 1, ["name"] = "default:wood" }, { ["x"] = 3, ["meta"] = { ["fields"] = { ["owner_info"] = "return { [\"y\"] = 75, [\"x\"] = 656, [\"z\"] = -779 }" }, ["inventory"] = {  } }, ["param2"] = 1, ["y"] = 0, ["param1"] = 0, ["z"] = 2, ["name"] = "default:wood" }, { ["x"] = 3, ["meta"] = { ["fields"] = { ["owner_info"] = "return { [\"y\"] = 75, [\"x\"] = 656, [\"z\"] = -779 }" }, ["inventory"] = {  } }, ["param2"] = 1, ["y"] = 0, ["param1"] = 0, ["z"] = 3, ["name"] = "default:wood" }, { ["x"] = 3, ["meta"] = { ["fields"] = { ["owner_info"] = "return { [\"y\"] = 75, [\"x\"] = 656, [\"z\"] = -779 }" }, ["inventory"] = {  } }, ["param2"] = 1, ["y"] = 0, ["param1"] = 0, ["z"] = 4, ["name"] = "default:wood" }, { ["x"] = 3, ["meta"] = { ["fields"] = { ["owner_info"] = "return { [\"y\"] = 75, [\"x\"] = 656, [\"z\"] = -779 }" }, ["inventory"] = {  } }, ["param2"] = 1, ["y"] = 0, ["param1"] = 0, ["z"] = 5, ["name"] = "default:wood" }, { ["x"] = 3, ["meta"] = { ["fields"] = { ["owner_info"] = "return { [\"y\"] = 75, [\"x\"] = 656, [\"z\"] = -779 }" }, ["inventory"] = {  } }, ["param2"] = 1, ["y"] = 0, ["param1"] = 0, ["z"] = 6, ["name"] = "default:wood" }, { ["x"] = 3, ["meta"] = { ["fields"] = { ["owner_info"] = "return { [\"y\"] = 75, [\"x\"] = 656, [\"z\"] = -779 }" }, ["inventory"] = {  } }, ["param2"] = 1, ["y"] = 1, ["param1"] = 0, ["z"] = 1, ["name"] = "default:wood" }, { ["x"] = 3, ["meta"] = { ["fields"] = { ["owner_info"] = "return { [\"y\"] = 75, [\"x\"] = 656, [\"z\"] = -779 }" }, ["inventory"] = {  } }, ["param2"] = 2, ["y"] = 1, ["param1"] = 187, ["z"] = 2, ["name"] = "cottages:bench" }, { ["x"] = 3, ["meta"] = { ["fields"] = {  }, ["inventory"] = {  } }, ["param2"] = 0, ["y"] = 1, ["param1"] = 187, ["z"] = 3, ["name"] = "cottages:bench" }, { ["x"] = 3, ["meta"] = { ["fields"] = { ["owner_info"] = "return { [\"y\"] = 75, [\"x\"] = 656, [\"z\"] = -779 }" }, ["inventory"] = {  } }, ["param2"] = 4, ["y"] = 1, ["param1"] = 170, ["z"] = 4, ["name"] = "default:ladder" }, { ["x"] = 3, ["meta"] = { ["fields"] = { ["owner_info"] = "return { [\"y\"] = 75, [\"x\"] = 656, [\"z\"] = -779 }" }, ["inventory"] = {  } }, ["param2"] = 1, ["y"] = 1, ["param1"] = 153, ["z"] = 5, ["name"] = "cottages:bed_foot" }, { ["x"] = 3, ["meta"] = { ["fields"] = { ["owner_info"] = "return { [\"y\"] = 75, [\"x\"] = 656, [\"z\"] = -779 }" }, ["inventory"] = {  } }, ["param2"] = 1, ["y"] = 1, ["param1"] = 0, ["z"] = 6, ["name"] = "default:wood" }, { ["x"] = 3, ["meta"] = { ["fields"] = { ["owner_info"] = "return { [\"y\"] = 75, [\"x\"] = 656, [\"z\"] = -779 }" }, ["inventory"] = {  } }, ["param2"] = 5, ["y"] = 1, ["param1"] = 0, ["z"] = 7, ["name"] = "default:torch" }, { ["x"] = 3, ["meta"] = { ["fields"] = { ["owner_info"] = "return { [\"y\"] = 75, [\"x\"] = 656, [\"z\"] = -779 }" }, ["inventory"] = {  } }, ["param2"] = 1, ["y"] = 2, ["param1"] = 0, ["z"] = 1, ["name"] = "default:wood" }, { ["x"] = 3, ["meta"] = { ["fields"] = { ["owner_info"] = "return { [\"y\"] = 75, [\"x\"] = 656, [\"z\"] = -779 }" }, ["inventory"] = {  } }, ["param2"] = 4, ["y"] = 2, ["param1"] = 187, ["z"] = 4, ["name"] = "default:ladder" }, { ["x"] = 3, ["meta"] = { ["fields"] = { ["owner_info"] = "return { [\"y\"] = 75, [\"x\"] = 656, [\"z\"] = -779 }" }, ["inventory"] = {  } }, ["param2"] = 1, ["y"] = 2, ["param1"] = 170, ["z"] = 5, ["name"] = "cottages:bed_foot" }, { ["x"] = 3, ["meta"] = { ["fields"] = { ["owner_info"] = "return { [\"y\"] = 75, [\"x\"] = 656, [\"z\"] = -779 }" }, ["inventory"] = {  } }, ["param2"] = 1, ["y"] = 2, ["param1"] = 0, ["z"] = 6, ["name"] = "default:wood" }, { ["x"] = 3, ["meta"] = { ["fields"] = {  }, ["inventory"] = {  } }, ["param2"] = 1, ["y"] = 3, ["param1"] = 0, ["z"] = 1, ["name"] = "default:wood" }, { ["x"] = 3, ["meta"] = { ["fields"] = {  }, ["inventory"] = {  } }, ["param2"] = 1, ["y"] = 3, ["param1"] = 0, ["z"] = 6, ["name"] = "default:wood" }, { ["x"] = 3, ["meta"] = { ["fields"] = {  }, ["inventory"] = {  } }, ["param2"] = 0, ["y"] = 4, ["param1"] = 173, ["z"] = 0, ["name"] = "cottages:roof_wood" }, { ["x"] = 3, ["meta"] = { ["fields"] = {  }, ["inventory"] = {  } }, ["param2"] = 18, ["y"] = 4, ["param1"] = 0, ["z"] = 1, ["name"] = "default:tree" }, { ["x"] = 3, ["meta"] = { ["fields"] = { ["owner_info"] = "return { [\"y\"] = 75, [\"x\"] = 656, [\"z\"] = -779 }" }, ["inventory"] = {  } }, ["param2"] = 1, ["y"] = 4, ["param1"] = 0, ["z"] = 2, ["name"] = "default:wood" }, { ["x"] = 3, ["meta"] = { ["fields"] = { ["owner_info"] = "return { [\"y\"] = 75, [\"x\"] = 656, [\"z\"] = -779 }" }, ["inventory"] = {  } }, ["param2"] = 1, ["y"] = 4, ["param1"] = 0, ["z"] = 3, ["name"] = "default:wood" }, { ["x"] = 3, ["meta"] = { ["fields"] = { ["owner_info"] = "return { [\"y\"] = 75, [\"x\"] = 656, [\"z\"] = -779 }" }, ["inventory"] = {  } }, ["param2"] = 1, ["y"] = 4, ["param1"] = 0, ["z"] = 4, ["name"] = "default:wood" }, { ["x"] = 3, ["meta"] = { ["fields"] = { ["owner_info"] = "return { [\"y\"] = 75, [\"x\"] = 656, [\"z\"] = -779 }" }, ["inventory"] = {  } }, ["param2"] = 1, ["y"] = 4, ["param1"] = 0, ["z"] = 5, ["name"] = "default:wood" }, { ["x"] = 3, ["meta"] = { ["fields"] = {  }, ["inventory"] = {  } }, ["param2"] = 18, ["y"] = 4, ["param1"] = 0, ["z"] = 6, ["name"] = "default:tree" }, { ["x"] = 3, ["meta"] = { ["fields"] = { ["owner_info"] = "return { [\"y\"] = 75, [\"x\"] = 656, [\"z\"] = -779 }" }, ["inventory"] = {  } }, ["param2"] = 2, ["y"] = 4, ["param1"] = 173, ["z"] = 7, ["name"] = "cottages:roof_wood" }, { ["x"] = 3, ["meta"] = { ["fields"] = { ["owner_info"] = "return { [\"y\"] = 75, [\"x\"] = 656, [\"z\"] = -779 }" }, ["inventory"] = {  } }, ["param2"] = 0, ["y"] = 5, ["param1"] = 157, ["z"] = 1, ["name"] = "cottages:roof_wood" }, { ["x"] = 3, ["meta"] = { ["fields"] = { ["owner_info"] = "return { [\"y\"] = 75, [\"x\"] = 656, [\"z\"] = -779 }" }, ["inventory"] = {  } }, ["param2"] = 2, ["y"] = 5, ["param1"] = 140, ["z"] = 2, ["name"] = "cottages:bench" }, { ["x"] = 3, ["meta"] = { ["fields"] = {  }, ["inventory"] = {  } }, ["param2"] = 0, ["y"] = 5, ["param1"] = 139, ["z"] = 4, ["name"] = "cottages:bed_foot" }, { ["x"] = 3, ["meta"] = { ["fields"] = {  }, ["inventory"] = {  } }, ["param2"] = 0, ["y"] = 5, ["param1"] = 140, ["z"] = 5, ["name"] = "cottages:bed_head" }, { ["x"] = 3, ["meta"] = { ["fields"] = { ["owner_info"] = "return { [\"y\"] = 75, [\"x\"] = 656, [\"z\"] = -779 }" }, ["inventory"] = {  } }, ["param2"] = 2, ["y"] = 5, ["param1"] = 157, ["z"] = 6, ["name"] = "cottages:roof_wood" }, { ["x"] = 3, ["meta"] = { ["fields"] = { ["owner_info"] = "return { [\"y\"] = 75, [\"x\"] = 656, [\"z\"] = -779 }" }, ["inventory"] = {  } }, ["param2"] = 0, ["y"] = 6, ["param1"] = 157, ["z"] = 2, ["name"] = "cottages:roof_wood" }, { ["x"] = 3, ["meta"] = { ["fields"] = {  }, ["inventory"] = {  } }, ["param2"] = 2, ["y"] = 6, ["param1"] = 157, ["z"] = 5, ["name"] = "cottages:roof_wood" }, { ["x"] = 3, ["meta"] = { ["fields"] = { ["owner_info"] = "return { [\"y\"] = 75, [\"x\"] = 656, [\"z\"] = -779 }" }, ["inventory"] = {  } }, ["param2"] = 0, ["y"] = 7, ["param1"] = 125, ["z"] = 3, ["name"] = "cottages:roof_wood" }, { ["x"] = 3, ["meta"] = { ["fields"] = { ["owner_info"] = "return { [\"y\"] = 75, [\"x\"] = 656, [\"z\"] = -779 }" }, ["inventory"] = {  } }, ["param2"] = 2, ["y"] = 7, ["param1"] = 125, ["z"] = 4, ["name"] = "cottages:roof_wood" }, { ["x"] = 4, ["meta"] = { ["fields"] = { ["owner_info"] = "return { [\"y\"] = 75, [\"x\"] = 656, [\"z\"] = -779 }" }, ["inventory"] = {  } }, ["param2"] = 1, ["y"] = 0, ["param1"] = 189, ["z"] = 0, ["name"] = "stairs:slab_wood" }, { ["x"] = 4, ["meta"] = { ["fields"] = { ["owner_info"] = "return { [\"y\"] = 75, [\"x\"] = 656, [\"z\"] = -779 }" }, ["inventory"] = {  } }, ["param2"] = 1, ["y"] = 0, ["param1"] = 0, ["z"] = 1, ["name"] = "default:wood" }, { ["x"] = 4, ["meta"] = { ["fields"] = { ["owner_info"] = "return { [\"y\"] = 75, [\"x\"] = 656, [\"z\"] = -779 }" }, ["inventory"] = {  } }, ["param2"] = 1, ["y"] = 0, ["param1"] = 0, ["z"] = 2, ["name"] = "default:wood" }, { ["x"] = 4, ["meta"] = { ["fields"] = { ["owner_info"] = "return { [\"y\"] = 75, [\"x\"] = 656, [\"z\"] = -779 }" }, ["inventory"] = {  } }, ["param2"] = 1, ["y"] = 0, ["param1"] = 0, ["z"] = 3, ["name"] = "default:wood" }, { ["x"] = 4, ["meta"] = { ["fields"] = { ["owner_info"] = "return { [\"y\"] = 75, [\"x\"] = 656, [\"z\"] = -779 }" }, ["inventory"] = {  } }, ["param2"] = 1, ["y"] = 0, ["param1"] = 0, ["z"] = 4, ["name"] = "default:wood" }, { ["x"] = 4, ["meta"] = { ["fields"] = { ["owner_info"] = "return { [\"y\"] = 75, [\"x\"] = 656, [\"z\"] = -779 }" }, ["inventory"] = {  } }, ["param2"] = 1, ["y"] = 0, ["param1"] = 0, ["z"] = 5, ["name"] = "default:wood" }, { ["x"] = 4, ["meta"] = { ["fields"] = { ["owner_info"] = "return { [\"y\"] = 75, [\"x\"] = 656, [\"z\"] = -779 }" }, ["inventory"] = {  } }, ["param2"] = 1, ["y"] = 0, ["param1"] = 0, ["z"] = 6, ["name"] = "default:wood" }, { ["x"] = 4, ["meta"] = { ["fields"] = { ["owner_info"] = "return { [\"y\"] = 75, [\"x\"] = 656, [\"z\"] = -779 }" }, ["inventory"] = {  } }, ["param2"] = 1, ["y"] = 1, ["param1"] = 0, ["z"] = 1, ["name"] = "default:wood" }, { ["x"] = 4, ["meta"] = { ["fields"] = {  }, ["inventory"] = {  } }, ["param2"] = 2, ["y"] = 1, ["param1"] = 204, ["z"] = 2, ["name"] = "cottages:bench" }, { ["x"] = 4, ["meta"] = { ["fields"] = { ["src_totaltime"] = "0", ["src_time"] = "0", ["formspec"] = "size[8,8.5]bgcolor[#080808BB;true]background[5,5;1,1;gui_formbg.png;true]listcolors[#00000069;#5A5A5A;#141318;#30434C;#FFF]list[current_name;src;2.75,0.5;1,1;]list[current_name;fuel;2.75,2.5;1,1;]image[2.75,1.5;1,1;default_furnace_fire_bg.png]image[3.75,1.5;1,1;gui_furnace_arrow_bg.png^[transformR270]list[current_name;dst;4.75,0.96;2,2;]list[current_player;main;0,4.25;8,1;]list[current_player;main;0,5.5;8,3;8]image[0,4.25;1,1;gui_hb_bg.png]image[1,4.25;1,1;gui_hb_bg.png]image[2,4.25;1,1;gui_hb_bg.png]image[3,4.25;1,1;gui_hb_bg.png]image[4,4.25;1,1;gui_hb_bg.png]image[5,4.25;1,1;gui_hb_bg.png]image[6,4.25;1,1;gui_hb_bg.png]image[7,4.25;1,1;gui_hb_bg.png]", ["fuel_time"] = "0", ["fuel_totaltime"] = "0", ["owner_info"] = "return { [\"y\"] = 75, [\"x\"] = 656, [\"z\"] = -779 }", ["infotext"] = "Furnace out of fuel" }, ["inventory"] = { ["fuel"] = { "" }, ["dst"] = { "", "", "", "" }, ["src"] = { "" } } }, ["param2"] = 2, ["y"] = 1, ["param1"] = 0, ["z"] = 3, ["name"] = "default:furnace" }, { ["x"] = 4, ["meta"] = { ["fields"] = { ["owner_info"] = "return { [\"y\"] = 75, [\"x\"] = 656, [\"z\"] = -779 }" }, ["inventory"] = {  } }, ["param2"] = 1, ["y"] = 1, ["param1"] = 153, ["z"] = 5, ["name"] = "cottages:bed_head" }, { ["x"] = 4, ["meta"] = { ["fields"] = { ["owner_info"] = "return { [\"y\"] = 75, [\"x\"] = 656, [\"z\"] = -779 }" }, ["inventory"] = {  } }, ["param2"] = 1, ["y"] = 1, ["param1"] = 0, ["z"] = 6, ["name"] = "default:wood" }, { ["x"] = 4, ["meta"] = { ["fields"] = { ["owner_info"] = "return { [\"y\"] = 75, [\"x\"] = 656, [\"z\"] = -779 }" }, ["inventory"] = {  } }, ["param2"] = 4, ["y"] = 2, ["param1"] = 0, ["z"] = 0, ["name"] = "default:torch" }, { ["x"] = 4, ["meta"] = { ["fields"] = { ["owner_info"] = "return { [\"y\"] = 75, [\"x\"] = 656, [\"z\"] = -779 }" }, ["inventory"] = {  } }, ["param2"] = 1, ["y"] = 2, ["param1"] = 0, ["z"] = 1, ["name"] = "default:wood" }, { ["x"] = 4, ["meta"] = { ["fields"] = { ["owner_info"] = "return { [\"y\"] = 75, [\"x\"] = 656, [\"z\"] = -779 }" }, ["inventory"] = {  } }, ["param2"] = 5, ["y"] = 2, ["param1"] = 0, ["z"] = 2, ["name"] = "default:torch" }, { ["x"] = 4, ["meta"] = { ["fields"] = {  }, ["inventory"] = {  } }, ["param2"] = 2, ["y"] = 2, ["param1"] = 204, ["z"] = 3, ["name"] = "cottages:stovepipe" }, { ["x"] = 4, ["meta"] = { ["fields"] = { ["owner_info"] = "return { [\"y\"] = 75, [\"x\"] = 656, [\"z\"] = -779 }" }, ["inventory"] = {  } }, ["param2"] = 1, ["y"] = 2, ["param1"] = 170, ["z"] = 5, ["name"] = "cottages:bed_head" }, { ["x"] = 4, ["meta"] = { ["fields"] = { ["owner_info"] = "return { [\"y\"] = 75, [\"x\"] = 656, [\"z\"] = -779 }" }, ["inventory"] = {  } }, ["param2"] = 1, ["y"] = 2, ["param1"] = 0, ["z"] = 6, ["name"] = "default:wood" }, { ["x"] = 4, ["meta"] = { ["fields"] = {  }, ["inventory"] = {  } }, ["param2"] = 1, ["y"] = 3, ["param1"] = 0, ["z"] = 1, ["name"] = "default:wood" }, { ["x"] = 4, ["meta"] = { ["fields"] = {  }, ["inventory"] = {  } }, ["param2"] = 2, ["y"] = 3, ["param1"] = 187, ["z"] = 3, ["name"] = "cottages:stovepipe" }, { ["x"] = 4, ["meta"] = { ["fields"] = {  }, ["inventory"] = {  } }, ["param2"] = 1, ["y"] = 3, ["param1"] = 0, ["z"] = 6, ["name"] = "default:wood" }, { ["x"] = 4, ["meta"] = { ["fields"] = {  }, ["inventory"] = {  } }, ["param2"] = 0, ["y"] = 4, ["param1"] = 189, ["z"] = 0, ["name"] = "cottages:roof_wood" }, { ["x"] = 4, ["meta"] = { ["fields"] = {  }, ["inventory"] = {  } }, ["param2"] = 18, ["y"] = 4, ["param1"] = 0, ["z"] = 1, ["name"] = "default:tree" }, { ["x"] = 4, ["meta"] = { ["fields"] = { ["owner_info"] = "return { [\"y\"] = 75, [\"x\"] = 656, [\"z\"] = -779 }" }, ["inventory"] = {  } }, ["param2"] = 1, ["y"] = 4, ["param1"] = 0, ["z"] = 2, ["name"] = "default:wood" }, { ["x"] = 4, ["meta"] = { ["fields"] = {  }, ["inventory"] = {  } }, ["param2"] = 3, ["y"] = 4, ["param1"] = 0, ["z"] = 3, ["name"] = "default:wood" }, { ["x"] = 4, ["meta"] = { ["fields"] = { ["owner_info"] = "return { [\"y\"] = 75, [\"x\"] = 656, [\"z\"] = -779 }" }, ["inventory"] = {  } }, ["param2"] = 1, ["y"] = 4, ["param1"] = 0, ["z"] = 4, ["name"] = "default:wood" }, { ["x"] = 4, ["meta"] = { ["fields"] = { ["owner_info"] = "return { [\"y\"] = 75, [\"x\"] = 656, [\"z\"] = -779 }" }, ["inventory"] = {  } }, ["param2"] = 1, ["y"] = 4, ["param1"] = 0, ["z"] = 5, ["name"] = "default:wood" }, { ["x"] = 4, ["meta"] = { ["fields"] = {  }, ["inventory"] = {  } }, ["param2"] = 18, ["y"] = 4, ["param1"] = 0, ["z"] = 6, ["name"] = "default:tree" }, { ["x"] = 4, ["meta"] = { ["fields"] = { ["owner_info"] = "return { [\"y\"] = 75, [\"x\"] = 656, [\"z\"] = -779 }" }, ["inventory"] = {  } }, ["param2"] = 2, ["y"] = 4, ["param1"] = 157, ["z"] = 7, ["name"] = "cottages:roof_wood" }, { ["x"] = 4, ["meta"] = { ["fields"] = { ["owner_info"] = "return { [\"y\"] = 75, [\"x\"] = 656, [\"z\"] = -779 }" }, ["inventory"] = {  } }, ["param2"] = 0, ["y"] = 5, ["param1"] = 157, ["z"] = 1, ["name"] = "cottages:roof_wood" }, { ["x"] = 4, ["meta"] = { ["fields"] = {  }, ["inventory"] = {  } }, ["param2"] = 2, ["y"] = 5, ["param1"] = 0, ["z"] = 2, ["name"] = "default:wood" }, { ["x"] = 4, ["meta"] = { ["fields"] = { ["owner_info"] = "return { [\"y\"] = 75, [\"x\"] = 656, [\"z\"] = -779 }" }, ["inventory"] = {  } }, ["param2"] = 3, ["y"] = 5, ["param1"] = 139, ["z"] = 3, ["name"] = "doors:door_wood_b_1" }, { ["x"] = 4, ["meta"] = { ["fields"] = { ["owner_info"] = "return { [\"y\"] = 75, [\"x\"] = 656, [\"z\"] = -779 }" }, ["inventory"] = {  } }, ["param2"] = 1, ["y"] = 5, ["param1"] = 0, ["z"] = 4, ["name"] = "default:wood" }, { ["x"] = 4, ["meta"] = { ["fields"] = { ["owner_info"] = "return { [\"y\"] = 75, [\"x\"] = 656, [\"z\"] = -779 }" }, ["inventory"] = {  } }, ["param2"] = 1, ["y"] = 5, ["param1"] = 0, ["z"] = 5, ["name"] = "default:wood" }, { ["x"] = 4, ["meta"] = { ["fields"] = { ["owner_info"] = "return { [\"y\"] = 75, [\"x\"] = 656, [\"z\"] = -779 }" }, ["inventory"] = {  } }, ["param2"] = 2, ["y"] = 5, ["param1"] = 141, ["z"] = 6, ["name"] = "cottages:roof_wood" }, { ["x"] = 4, ["meta"] = { ["fields"] = {  }, ["inventory"] = {  } }, ["param2"] = 0, ["y"] = 6, ["param1"] = 141, ["z"] = 2, ["name"] = "cottages:roof_connector_wood" }, { ["x"] = 4, ["meta"] = { ["fields"] = { ["owner_info"] = "return { [\"y\"] = 75, [\"x\"] = 656, [\"z\"] = -779 }" }, ["inventory"] = {  } }, ["param2"] = 3, ["y"] = 6, ["param1"] = 124, ["z"] = 3, ["name"] = "doors:door_wood_t_1" }, { ["x"] = 4, ["meta"] = { ["fields"] = { ["owner_info"] = "return { [\"y\"] = 75, [\"x\"] = 656, [\"z\"] = -779 }" }, ["inventory"] = {  } }, ["param2"] = 1, ["y"] = 6, ["param1"] = 0, ["z"] = 4, ["name"] = "default:wood" }, { ["x"] = 4, ["meta"] = { ["fields"] = {  }, ["inventory"] = {  } }, ["param2"] = 2, ["y"] = 6, ["param1"] = 141, ["z"] = 5, ["name"] = "cottages:roof_connector_wood" }, { ["x"] = 4, ["meta"] = { ["fields"] = { ["owner_info"] = "return { [\"y\"] = 75, [\"x\"] = 656, [\"z\"] = -779 }" }, ["inventory"] = {  } }, ["param2"] = 0, ["y"] = 7, ["param1"] = 109, ["z"] = 3, ["name"] = "cottages:roof_wood" }, { ["x"] = 4, ["meta"] = { ["fields"] = { ["owner_info"] = "return { [\"y\"] = 75, [\"x\"] = 656, [\"z\"] = -779 }" }, ["inventory"] = {  } }, ["param2"] = 2, ["y"] = 7, ["param1"] = 109, ["z"] = 4, ["name"] = "cottages:roof_wood" }, { ["x"] = 5, ["meta"] = { ["fields"] = { ["owner_info"] = "return { [\"y\"] = 75, [\"x\"] = 656, [\"z\"] = -779 }" }, ["inventory"] = {  } }, ["param2"] = 1, ["y"] = 0, ["param1"] = 173, ["z"] = 0, ["name"] = "stairs:slab_wood" }, { ["x"] = 5, ["meta"] = { ["fields"] = { ["owner_info"] = "return { [\"y\"] = 75, [\"x\"] = 656, [\"z\"] = -779 }" }, ["inventory"] = {  } }, ["param2"] = 1, ["y"] = 0, ["param1"] = 0, ["z"] = 1, ["name"] = "default:wood" }, { ["x"] = 5, ["meta"] = { ["fields"] = { ["owner_info"] = "return { [\"y\"] = 75, [\"x\"] = 656, [\"z\"] = -779 }" }, ["inventory"] = {  } }, ["param2"] = 1, ["y"] = 0, ["param1"] = 0, ["z"] = 2, ["name"] = "default:wood" }, { ["x"] = 5, ["meta"] = { ["fields"] = { ["owner_info"] = "return { [\"y\"] = 75, [\"x\"] = 656, [\"z\"] = -779 }" }, ["inventory"] = {  } }, ["param2"] = 1, ["y"] = 0, ["param1"] = 0, ["z"] = 3, ["name"] = "default:wood" }, { ["x"] = 5, ["meta"] = { ["fields"] = { ["owner_info"] = "return { [\"y\"] = 75, [\"x\"] = 656, [\"z\"] = -779 }" }, ["inventory"] = {  } }, ["param2"] = 1, ["y"] = 0, ["param1"] = 0, ["z"] = 4, ["name"] = "default:wood" }, { ["x"] = 5, ["meta"] = { ["fields"] = { ["owner_info"] = "return { [\"y\"] = 75, [\"x\"] = 656, [\"z\"] = -779 }" }, ["inventory"] = {  } }, ["param2"] = 1, ["y"] = 0, ["param1"] = 0, ["z"] = 5, ["name"] = "default:wood" }, { ["x"] = 5, ["meta"] = { ["fields"] = { ["owner_info"] = "return { [\"y\"] = 75, [\"x\"] = 656, [\"z\"] = -779 }" }, ["inventory"] = {  } }, ["param2"] = 1, ["y"] = 0, ["param1"] = 0, ["z"] = 6, ["name"] = "default:wood" }, { ["x"] = 5, ["meta"] = { ["fields"] = { ["owner_info"] = "return { [\"y\"] = 75, [\"x\"] = 656, [\"z\"] = -779 }" }, ["inventory"] = {  } }, ["param2"] = 0, ["y"] = 1, ["param1"] = 172, ["z"] = 1, ["name"] = "doors:door_wood_b_1" }, { ["x"] = 5, ["meta"] = { ["fields"] = { ["owner_info"] = "return { [\"y\"] = 75, [\"x\"] = 656, [\"z\"] = -779 }" }, ["inventory"] = {  } }, ["param2"] = 4, ["y"] = 1, ["param1"] = 153, ["z"] = 4, ["name"] = "default:ladder" }, { ["x"] = 5, ["meta"] = { ["fields"] = { ["owner_info"] = "return { [\"y\"] = 75, [\"x\"] = 656, [\"z\"] = -779 }" }, ["inventory"] = {  } }, ["param2"] = 3, ["y"] = 1, ["param1"] = 136, ["z"] = 5, ["name"] = "cottages:bed_head" }, { ["x"] = 5, ["meta"] = { ["fields"] = { ["owner_info"] = "return { [\"y\"] = 75, [\"x\"] = 656, [\"z\"] = -779 }" }, ["inventory"] = {  } }, ["param2"] = 1, ["y"] = 1, ["param1"] = 0, ["z"] = 6, ["name"] = "default:wood" }, { ["x"] = 5, ["meta"] = { ["fields"] = { ["owner_info"] = "return { [\"y\"] = 75, [\"x\"] = 656, [\"z\"] = -779 }" }, ["inventory"] = {  } }, ["param2"] = 0, ["y"] = 2, ["param1"] = 188, ["z"] = 1, ["name"] = "doors:door_wood_t_1" }, { ["x"] = 5, ["meta"] = { ["fields"] = { ["owner_info"] = "return { [\"y\"] = 75, [\"x\"] = 656, [\"z\"] = -779 }" }, ["inventory"] = {  } }, ["param2"] = 4, ["y"] = 2, ["param1"] = 170, ["z"] = 4, ["name"] = "default:ladder" }, { ["x"] = 5, ["meta"] = { ["fields"] = { ["owner_info"] = "return { [\"y\"] = 75, [\"x\"] = 656, [\"z\"] = -779 }" }, ["inventory"] = {  } }, ["param2"] = 3, ["y"] = 2, ["param1"] = 153, ["z"] = 5, ["name"] = "cottages:bed_head" }, { ["x"] = 5, ["meta"] = { ["fields"] = { ["owner_info"] = "return { [\"y\"] = 75, [\"x\"] = 656, [\"z\"] = -779 }" }, ["inventory"] = {  } }, ["param2"] = 1, ["y"] = 2, ["param1"] = 0, ["z"] = 6, ["name"] = "default:wood" }, { ["x"] = 5, ["meta"] = { ["fields"] = {  }, ["inventory"] = {  } }, ["param2"] = 1, ["y"] = 3, ["param1"] = 0, ["z"] = 1, ["name"] = "default:wood" }, { ["x"] = 5, ["meta"] = { ["fields"] = {  }, ["inventory"] = {  } }, ["param2"] = 1, ["y"] = 3, ["param1"] = 0, ["z"] = 6, ["name"] = "default:wood" }, { ["x"] = 5, ["meta"] = { ["fields"] = {  }, ["inventory"] = {  } }, ["param2"] = 0, ["y"] = 4, ["param1"] = 173, ["z"] = 0, ["name"] = "cottages:roof_wood" }, { ["x"] = 5, ["meta"] = { ["fields"] = {  }, ["inventory"] = {  } }, ["param2"] = 18, ["y"] = 4, ["param1"] = 0, ["z"] = 1, ["name"] = "default:tree" }, { ["x"] = 5, ["meta"] = { ["fields"] = { ["owner_info"] = "return { [\"y\"] = 75, [\"x\"] = 656, [\"z\"] = -779 }" }, ["inventory"] = {  } }, ["param2"] = 1, ["y"] = 4, ["param1"] = 0, ["z"] = 2, ["name"] = "default:wood" }, { ["x"] = 5, ["meta"] = { ["fields"] = { ["owner_info"] = "return { [\"y\"] = 75, [\"x\"] = 656, [\"z\"] = -779 }" }, ["inventory"] = {  } }, ["param2"] = 1, ["y"] = 4, ["param1"] = 0, ["z"] = 3, ["name"] = "default:wood" }, { ["x"] = 5, ["meta"] = { ["fields"] = { ["owner_info"] = "return { [\"y\"] = 75, [\"x\"] = 656, [\"z\"] = -779 }" }, ["inventory"] = {  } }, ["param2"] = 1, ["y"] = 4, ["param1"] = 0, ["z"] = 4, ["name"] = "default:wood" }, { ["x"] = 5, ["meta"] = { ["fields"] = { ["owner_info"] = "return { [\"y\"] = 75, [\"x\"] = 656, [\"z\"] = -779 }" }, ["inventory"] = {  } }, ["param2"] = 1, ["y"] = 4, ["param1"] = 0, ["z"] = 5, ["name"] = "default:wood" }, { ["x"] = 5, ["meta"] = { ["fields"] = {  }, ["inventory"] = {  } }, ["param2"] = 18, ["y"] = 4, ["param1"] = 0, ["z"] = 6, ["name"] = "default:tree" }, { ["x"] = 5, ["meta"] = { ["fields"] = { ["owner_info"] = "return { [\"y\"] = 75, [\"x\"] = 656, [\"z\"] = -779 }" }, ["inventory"] = {  } }, ["param2"] = 2, ["y"] = 4, ["param1"] = 157, ["z"] = 7, ["name"] = "cottages:roof_wood" }, { ["x"] = 5, ["meta"] = { ["fields"] = { ["owner_info"] = "return { [\"y\"] = 75, [\"x\"] = 656, [\"z\"] = -779 }" }, ["inventory"] = {  } }, ["param2"] = 0, ["y"] = 5, ["param1"] = 141, ["z"] = 1, ["name"] = "cottages:roof_wood" }, { ["x"] = 5, ["meta"] = { ["fields"] = { ["infotext"] = "Chest", ["owner_info"] = "return { [\"y\"] = 75, [\"x\"] = 656, [\"z\"] = -779 }", ["formspec"] = "size[8,9]list[current_name;main;0,0;8,4;]list[current_player;main;0,5;8,4;]" }, ["inventory"] = { ["main"] = { "", "", "", "", "", "", "", "default:paper 4", "farming:string 3", "", "", "default:coal_lump 11", "", "", "", "", "", "", "", "farming:string 2", "", "", "", "", "", "", "default:paper 3", "", "", "", "", "" } } }, ["param2"] = 2, ["y"] = 5, ["param1"] = 0, ["z"] = 2, ["name"] = "default:chest" }, { ["x"] = 5, ["meta"] = { ["fields"] = { ["owner_info"] = "return { [\"y\"] = 75, [\"x\"] = 656, [\"z\"] = -779 }" }, ["inventory"] = {  } }, ["param2"] = 3, ["y"] = 5, ["param1"] = 139, ["z"] = 4, ["name"] = "cottages:bench" }, { ["x"] = 5, ["meta"] = { ["fields"] = { ["infotext"] = "Chest", ["owner_info"] = "return { [\"y\"] = 75, [\"x\"] = 656, [\"z\"] = -779 }", ["formspec"] = "size[8,9]list[current_name;main;0,0;8,4;]list[current_player;main;0,5;8,4;]" }, ["inventory"] = { ["main"] = { "", "", "", "", "default:book", "", "", "", "", "", "", "", "", "", "", "", "", "", "", "wool:white", "", "", "", "", "", "", "", "default:paper", "", "", "", "default:paper 4" } } }, ["param2"] = 0, ["y"] = 5, ["param1"] = 0, ["z"] = 5, ["name"] = "default:chest" }, { ["x"] = 5, ["meta"] = { ["fields"] = { ["owner_info"] = "return { [\"y\"] = 75, [\"x\"] = 656, [\"z\"] = -779 }" }, ["inventory"] = {  } }, ["param2"] = 2, ["y"] = 5, ["param1"] = 141, ["z"] = 6, ["name"] = "cottages:roof_wood" }, { ["x"] = 5, ["meta"] = { ["fields"] = { ["owner_info"] = "return { [\"y\"] = 75, [\"x\"] = 656, [\"z\"] = -779 }" }, ["inventory"] = {  } }, ["param2"] = 0, ["y"] = 6, ["param1"] = 141, ["z"] = 2, ["name"] = "cottages:roof_wood" }, { ["x"] = 5, ["meta"] = { ["fields"] = { ["owner_info"] = "return { [\"y\"] = 75, [\"x\"] = 656, [\"z\"] = -779 }" }, ["inventory"] = {  } }, ["param2"] = 2, ["y"] = 6, ["param1"] = 141, ["z"] = 5, ["name"] = "cottages:roof_wood" }, { ["x"] = 5, ["meta"] = { ["fields"] = { ["owner_info"] = "return { [\"y\"] = 75, [\"x\"] = 656, [\"z\"] = -779 }" }, ["inventory"] = {  } }, ["param2"] = 0, ["y"] = 7, ["param1"] = 109, ["z"] = 3, ["name"] = "cottages:roof_wood" }, { ["x"] = 5, ["meta"] = { ["fields"] = { ["owner_info"] = "return { [\"y\"] = 75, [\"x\"] = 656, [\"z\"] = -779 }" }, ["inventory"] = {  } }, ["param2"] = 2, ["y"] = 7, ["param1"] = 109, ["z"] = 4, ["name"] = "cottages:roof_wood" }, { ["x"] = 6, ["meta"] = { ["fields"] = { ["owner_info"] = "return { [\"y\"] = 75, [\"x\"] = 656, [\"z\"] = -779 }" }, ["inventory"] = {  } }, ["param2"] = 1, ["y"] = 0, ["param1"] = 189, ["z"] = 0, ["name"] = "stairs:slab_wood" }, { ["x"] = 6, ["meta"] = { ["fields"] = { ["owner_info"] = "return { [\"y\"] = 75, [\"x\"] = 656, [\"z\"] = -779 }" }, ["inventory"] = {  } }, ["param2"] = 1, ["y"] = 0, ["param1"] = 0, ["z"] = 1, ["name"] = "default:wood" }, { ["x"] = 6, ["meta"] = { ["fields"] = { ["owner_info"] = "return { [\"y\"] = 75, [\"x\"] = 656, [\"z\"] = -779 }" }, ["inventory"] = {  } }, ["param2"] = 1, ["y"] = 0, ["param1"] = 0, ["z"] = 2, ["name"] = "default:wood" }, { ["x"] = 6, ["meta"] = { ["fields"] = { ["owner_info"] = "return { [\"y\"] = 75, [\"x\"] = 656, [\"z\"] = -779 }" }, ["inventory"] = {  } }, ["param2"] = 1, ["y"] = 0, ["param1"] = 0, ["z"] = 3, ["name"] = "default:wood" }, { ["x"] = 6, ["meta"] = { ["fields"] = { ["owner_info"] = "return { [\"y\"] = 75, [\"x\"] = 656, [\"z\"] = -779 }" }, ["inventory"] = {  } }, ["param2"] = 1, ["y"] = 0, ["param1"] = 0, ["z"] = 4, ["name"] = "default:wood" }, { ["x"] = 6, ["meta"] = { ["fields"] = { ["owner_info"] = "return { [\"y\"] = 75, [\"x\"] = 656, [\"z\"] = -779 }" }, ["inventory"] = {  } }, ["param2"] = 1, ["y"] = 0, ["param1"] = 0, ["z"] = 5, ["name"] = "default:wood" }, { ["x"] = 6, ["meta"] = { ["fields"] = { ["owner_info"] = "return { [\"y\"] = 75, [\"x\"] = 656, [\"z\"] = -779 }" }, ["inventory"] = {  } }, ["param2"] = 1, ["y"] = 0, ["param1"] = 0, ["z"] = 6, ["name"] = "default:wood" }, { ["x"] = 6, ["meta"] = { ["fields"] = { ["owner_info"] = "return { [\"y\"] = 75, [\"x\"] = 656, [\"z\"] = -779 }" }, ["inventory"] = {  } }, ["param2"] = 1, ["y"] = 1, ["param1"] = 0, ["z"] = 1, ["name"] = "default:wood" }, { ["x"] = 6, ["meta"] = { ["fields"] = { ["infotext"] = "Chest", ["owner_info"] = "return { [\"y\"] = 75, [\"x\"] = 656, [\"z\"] = -779 }", ["formspec"] = "size[8,9]list[current_name;main;0,0;8,4;]list[current_player;main;0,5;8,4;]" }, ["inventory"] = { ["main"] = { "", "", "", "", "", "farming:string 4", "", "", "", "vessels:drinking_glass 2", "default:book", "", "default:mese_crystal_fragment 3", "", "", "", "", "", "", "", "", "", "", "", "default:coal_lump 22", "", "", "", "default:book", "", "", "" } } }, ["param2"] = 2, ["y"] = 1, ["param1"] = 0, ["z"] = 2, ["name"] = "default:chest" }, { ["x"] = 6, ["meta"] = { ["fields"] = { ["owner_info"] = "return { [\"y\"] = 75, [\"x\"] = 656, [\"z\"] = -779 }" }, ["inventory"] = {  } }, ["param2"] = 3, ["y"] = 1, ["param1"] = 137, ["z"] = 5, ["name"] = "cottages:bed_foot" }, { ["x"] = 6, ["meta"] = { ["fields"] = { ["owner_info"] = "return { [\"y\"] = 75, [\"x\"] = 656, [\"z\"] = -779 }" }, ["inventory"] = {  } }, ["param2"] = 1, ["y"] = 1, ["param1"] = 0, ["z"] = 6, ["name"] = "default:wood" }, { ["x"] = 6, ["meta"] = { ["fields"] = { ["owner_info"] = "return { [\"y\"] = 75, [\"x\"] = 656, [\"z\"] = -779 }" }, ["inventory"] = {  } }, ["param2"] = 5, ["y"] = 1, ["param1"] = 0, ["z"] = 7, ["name"] = "default:torch" }, { ["x"] = 6, ["meta"] = { ["fields"] = { ["owner_info"] = "return { [\"y\"] = 75, [\"x\"] = 656, [\"z\"] = -779 }" }, ["inventory"] = {  } }, ["param2"] = 4, ["y"] = 2, ["param1"] = 0, ["z"] = 0, ["name"] = "default:torch" }, { ["x"] = 6, ["meta"] = { ["fields"] = { ["owner_info"] = "return { [\"y\"] = 75, [\"x\"] = 656, [\"z\"] = -779 }" }, ["inventory"] = {  } }, ["param2"] = 1, ["y"] = 2, ["param1"] = 0, ["z"] = 1, ["name"] = "default:wood" }, { ["x"] = 6, ["meta"] = { ["fields"] = { ["infotext"] = "Chest", ["owner_info"] = "return { [\"y\"] = 75, [\"x\"] = 656, [\"z\"] = -779 }", ["formspec"] = "size[8,9]list[current_name;main;0,0;8,4;]list[current_player;main;0,5;8,4;]" }, ["inventory"] = { ["main"] = { "", "", "default:steel_ingot", "", "", "", "", "", "", "", "wool:white 6", "", "", "", "", "", "", "", "", "default:apple 6", "default:coal_lump 5", "", "", "", "", "", "", "", "", "default:stick 36", "", "" } } }, ["param2"] = 2, ["y"] = 2, ["param1"] = 0, ["z"] = 2, ["name"] = "default:chest" }, { ["x"] = 6, ["meta"] = { ["fields"] = { ["owner_info"] = "return { [\"y\"] = 75, [\"x\"] = 656, [\"z\"] = -779 }" }, ["inventory"] = {  } }, ["param2"] = 3, ["y"] = 2, ["param1"] = 154, ["z"] = 5, ["name"] = "cottages:bed_foot" }, { ["x"] = 6, ["meta"] = { ["fields"] = { ["owner_info"] = "return { [\"y\"] = 75, [\"x\"] = 656, [\"z\"] = -779 }" }, ["inventory"] = {  } }, ["param2"] = 1, ["y"] = 2, ["param1"] = 0, ["z"] = 6, ["name"] = "default:wood" }, { ["x"] = 6, ["meta"] = { ["fields"] = {  }, ["inventory"] = {  } }, ["param2"] = 1, ["y"] = 3, ["param1"] = 0, ["z"] = 1, ["name"] = "default:wood" }, { ["x"] = 6, ["meta"] = { ["fields"] = {  }, ["inventory"] = {  } }, ["param2"] = 1, ["y"] = 3, ["param1"] = 0, ["z"] = 6, ["name"] = "default:wood" }, { ["x"] = 6, ["meta"] = { ["fields"] = {  }, ["inventory"] = {  } }, ["param2"] = 0, ["y"] = 4, ["param1"] = 189, ["z"] = 0, ["name"] = "cottages:roof_wood" }, { ["x"] = 6, ["meta"] = { ["fields"] = {  }, ["inventory"] = {  } }, ["param2"] = 18, ["y"] = 4, ["param1"] = 0, ["z"] = 1, ["name"] = "default:tree" }, { ["x"] = 6, ["meta"] = { ["fields"] = { ["owner_info"] = "return { [\"y\"] = 75, [\"x\"] = 656, [\"z\"] = -779 }" }, ["inventory"] = {  } }, ["param2"] = 1, ["y"] = 4, ["param1"] = 0, ["z"] = 2, ["name"] = "default:wood" }, { ["x"] = 6, ["meta"] = { ["fields"] = { ["owner_info"] = "return { [\"y\"] = 75, [\"x\"] = 656, [\"z\"] = -779 }" }, ["inventory"] = {  } }, ["param2"] = 1, ["y"] = 4, ["param1"] = 0, ["z"] = 3, ["name"] = "default:wood" }, { ["x"] = 6, ["meta"] = { ["fields"] = { ["owner_info"] = "return { [\"y\"] = 75, [\"x\"] = 656, [\"z\"] = -779 }" }, ["inventory"] = {  } }, ["param2"] = 1, ["y"] = 4, ["param1"] = 0, ["z"] = 4, ["name"] = "default:wood" }, { ["x"] = 6, ["meta"] = { ["fields"] = { ["owner_info"] = "return { [\"y\"] = 75, [\"x\"] = 656, [\"z\"] = -779 }" }, ["inventory"] = {  } }, ["param2"] = 1, ["y"] = 4, ["param1"] = 0, ["z"] = 5, ["name"] = "default:wood" }, { ["x"] = 6, ["meta"] = { ["fields"] = {  }, ["inventory"] = {  } }, ["param2"] = 18, ["y"] = 4, ["param1"] = 0, ["z"] = 6, ["name"] = "default:tree" }, { ["x"] = 6, ["meta"] = { ["fields"] = { ["owner_info"] = "return { [\"y\"] = 75, [\"x\"] = 656, [\"z\"] = -779 }" }, ["inventory"] = {  } }, ["param2"] = 2, ["y"] = 4, ["param1"] = 173, ["z"] = 7, ["name"] = "cottages:roof_wood" }, { ["x"] = 6, ["meta"] = { ["fields"] = { ["owner_info"] = "return { [\"y\"] = 75, [\"x\"] = 656, [\"z\"] = -779 }" }, ["inventory"] = {  } }, ["param2"] = 0, ["y"] = 5, ["param1"] = 157, ["z"] = 1, ["name"] = "cottages:roof_wood" }, { ["x"] = 6, ["meta"] = { ["fields"] = { ["infotext"] = "Chest", ["owner_info"] = "return { [\"y\"] = 75, [\"x\"] = 656, [\"z\"] = -779 }", ["formspec"] = "size[8,9]list[current_name;main;0,0;8,4;]list[current_player;main;0,5;8,4;]" }, ["inventory"] = { ["main"] = { "", "", "", "default:paper 2", "", "", "", "", "farming:string 2", "", "", "", "", "default:apple 4", "", "", "", "", "", "", "", "", "", "", "default:steel_ingot 3", "", "", "", "", "", "default:torch 2", "" } } }, ["param2"] = 2, ["y"] = 5, ["param1"] = 0, ["z"] = 2, ["name"] = "default:chest" }, { ["x"] = 6, ["meta"] = { ["fields"] = { ["infotext"] = "Chest", ["owner_info"] = "return { [\"y\"] = 75, [\"x\"] = 656, [\"z\"] = -779 }", ["formspec"] = "size[8,9]list[current_name;main;0,0;8,4;]list[current_player;main;0,5;8,4;]" }, ["inventory"] = { ["main"] = { "farming:string", "", "", "", "", "", "", "", "", "", "", "", "", "", "", "", "", "", "", "", "", "", "", "default:axe_steel", "default:book", "", "", "", "default:paper 2", "", "", "" } } }, ["param2"] = 0, ["y"] = 5, ["param1"] = 0, ["z"] = 5, ["name"] = "default:chest" }, { ["x"] = 6, ["meta"] = { ["fields"] = { ["owner_info"] = "return { [\"y\"] = 75, [\"x\"] = 656, [\"z\"] = -779 }" }, ["inventory"] = {  } }, ["param2"] = 2, ["y"] = 5, ["param1"] = 157, ["z"] = 6, ["name"] = "cottages:roof_wood" }, { ["x"] = 6, ["meta"] = { ["fields"] = { ["owner_info"] = "return { [\"y\"] = 75, [\"x\"] = 656, [\"z\"] = -779 }" }, ["inventory"] = {  } }, ["param2"] = 0, ["y"] = 6, ["param1"] = 157, ["z"] = 2, ["name"] = "cottages:roof_wood" }, { ["x"] = 6, ["meta"] = { ["fields"] = { ["owner_info"] = "return { [\"y\"] = 75, [\"x\"] = 656, [\"z\"] = -779 }" }, ["inventory"] = {  } }, ["param2"] = 2, ["y"] = 6, ["param1"] = 157, ["z"] = 5, ["name"] = "cottages:roof_wood" }, { ["x"] = 6, ["meta"] = { ["fields"] = { ["owner_info"] = "return { [\"y\"] = 75, [\"x\"] = 656, [\"z\"] = -779 }" }, ["inventory"] = {  } }, ["param2"] = 0, ["y"] = 7, ["param1"] = 125, ["z"] = 3, ["name"] = "cottages:roof_wood" }, { ["x"] = 6, ["meta"] = { ["fields"] = { ["owner_info"] = "return { [\"y\"] = 75, [\"x\"] = 656, [\"z\"] = -779 }" }, ["inventory"] = {  } }, ["param2"] = 2, ["y"] = 7, ["param1"] = 125, ["z"] = 4, ["name"] = "cottages:roof_wood" }, { ["x"] = 7, ["meta"] = { ["fields"] = { ["owner_info"] = "return { [\"y\"] = 75, [\"x\"] = 656, [\"z\"] = -779 }" }, ["inventory"] = {  } }, ["param2"] = 0, ["y"] = 0, ["param1"] = 173, ["z"] = 0, ["name"] = "cottages:bench" }, { ["x"] = 7, ["meta"] = { ["fields"] = { ["owner_info"] = "return { [\"y\"] = 75, [\"x\"] = 656, [\"z\"] = -779 }" }, ["inventory"] = {  } }, ["param2"] = 1, ["y"] = 0, ["param1"] = 0, ["z"] = 1, ["name"] = "default:wood" }, { ["x"] = 7, ["meta"] = { ["fields"] = { ["owner_info"] = "return { [\"y\"] = 75, [\"x\"] = 656, [\"z\"] = -779 }" }, ["inventory"] = {  } }, ["param2"] = 1, ["y"] = 0, ["param1"] = 0, ["z"] = 2, ["name"] = "default:wood" }, { ["x"] = 7, ["meta"] = { ["fields"] = { ["owner_info"] = "return { [\"y\"] = 75, [\"x\"] = 656, [\"z\"] = -779 }" }, ["inventory"] = {  } }, ["param2"] = 1, ["y"] = 0, ["param1"] = 0, ["z"] = 3, ["name"] = "default:wood" }, { ["x"] = 7, ["meta"] = { ["fields"] = { ["owner_info"] = "return { [\"y\"] = 75, [\"x\"] = 656, [\"z\"] = -779 }" }, ["inventory"] = {  } }, ["param2"] = 1, ["y"] = 0, ["param1"] = 0, ["z"] = 4, ["name"] = "default:wood" }, { ["x"] = 7, ["meta"] = { ["fields"] = { ["owner_info"] = "return { [\"y\"] = 75, [\"x\"] = 656, [\"z\"] = -779 }" }, ["inventory"] = {  } }, ["param2"] = 1, ["y"] = 0, ["param1"] = 0, ["z"] = 5, ["name"] = "default:wood" }, { ["x"] = 7, ["meta"] = { ["fields"] = { ["owner_info"] = "return { [\"y\"] = 75, [\"x\"] = 656, [\"z\"] = -779 }" }, ["inventory"] = {  } }, ["param2"] = 1, ["y"] = 0, ["param1"] = 0, ["z"] = 6, ["name"] = "default:wood" }, { ["x"] = 7, ["meta"] = { ["fields"] = { ["owner_info"] = "return { [\"y\"] = 75, [\"x\"] = 656, [\"z\"] = -779 }" }, ["inventory"] = {  } }, ["param2"] = 1, ["y"] = 1, ["param1"] = 0, ["z"] = 1, ["name"] = "default:wood" }, { ["x"] = 7, ["meta"] = { ["fields"] = { ["infotext"] = "Chest", ["owner_info"] = "return { [\"y\"] = 75, [\"x\"] = 656, [\"z\"] = -779 }", ["formspec"] = "size[8,9]list[current_name;main;0,0;8,4;]list[current_player;main;0,5;8,4;]" }, ["inventory"] = { ["main"] = { "", "bucket:bucket_empty", "default:apple 2", "", "default:coal_lump 18", "default:paper 4", "", "", "", "", "default:axe_stone", "", "", "default:torch 9", "", "vessels:steel_bottle", "", "", "", "", "", "", "", "", "", "", "", "default:book", "", "", "", "" } } }, ["param2"] = 2, ["y"] = 1, ["param1"] = 0, ["z"] = 2, ["name"] = "default:chest" }, { ["x"] = 7, ["meta"] = { ["fields"] = { ["owner_info"] = "return { [\"y\"] = 75, [\"x\"] = 656, [\"z\"] = -779 }" }, ["inventory"] = {  } }, ["param2"] = 2, ["y"] = 1, ["param1"] = 137, ["z"] = 3, ["name"] = "default:ladder" }, { ["x"] = 7, ["meta"] = { ["fields"] = { ["owner_info"] = "return { [\"y\"] = 75, [\"x\"] = 656, [\"z\"] = -779 }" }, ["inventory"] = {  } }, ["param2"] = 0, ["y"] = 1, ["param1"] = 137, ["z"] = 4, ["name"] = "cottages:bed_foot" }, { ["x"] = 7, ["meta"] = { ["fields"] = { ["owner_info"] = "return { [\"y\"] = 75, [\"x\"] = 656, [\"z\"] = -779 }" }, ["inventory"] = {  } }, ["param2"] = 0, ["y"] = 1, ["param1"] = 154, ["z"] = 5, ["name"] = "cottages:bed_head" }, { ["x"] = 7, ["meta"] = { ["fields"] = { ["owner_info"] = "return { [\"y\"] = 75, [\"x\"] = 656, [\"z\"] = -779 }" }, ["inventory"] = {  } }, ["param2"] = 1, ["y"] = 1, ["param1"] = 0, ["z"] = 6, ["name"] = "default:wood" }, { ["x"] = 7, ["meta"] = { ["fields"] = {  }, ["inventory"] = {  } }, ["param2"] = 0, ["y"] = 2, ["param1"] = 205, ["z"] = 0, ["name"] = "cottages:window_shutter_open" }, { ["x"] = 7, ["meta"] = { ["fields"] = {  }, ["inventory"] = {  } }, ["param2"] = 0, ["y"] = 2, ["param1"] = 188, ["z"] = 1, ["name"] = "cottages:glass_pane" }, { ["x"] = 7, ["meta"] = { ["fields"] = { ["owner_info"] = "return { [\"y\"] = 75, [\"x\"] = 656, [\"z\"] = -779 }" }, ["inventory"] = {  } }, ["param2"] = 2, ["y"] = 2, ["param1"] = 154, ["z"] = 3, ["name"] = "default:ladder" }, { ["x"] = 7, ["meta"] = { ["fields"] = { ["owner_info"] = "return { [\"y\"] = 75, [\"x\"] = 656, [\"z\"] = -779 }" }, ["inventory"] = {  } }, ["param2"] = 0, ["y"] = 2, ["param1"] = 154, ["z"] = 4, ["name"] = "cottages:bed_foot" }, { ["x"] = 7, ["meta"] = { ["fields"] = { ["owner_info"] = "return { [\"y\"] = 75, [\"x\"] = 656, [\"z\"] = -779 }" }, ["inventory"] = {  } }, ["param2"] = 0, ["y"] = 2, ["param1"] = 171, ["z"] = 5, ["name"] = "cottages:bed_head" }, { ["x"] = 7, ["meta"] = { ["fields"] = { ["owner_info"] = "return { [\"y\"] = 75, [\"x\"] = 656, [\"z\"] = -779 }" }, ["inventory"] = {  } }, ["param2"] = 1, ["y"] = 2, ["param1"] = 0, ["z"] = 6, ["name"] = "default:wood" }, { ["x"] = 7, ["meta"] = { ["fields"] = {  }, ["inventory"] = {  } }, ["param2"] = 1, ["y"] = 3, ["param1"] = 0, ["z"] = 1, ["name"] = "default:wood" }, { ["x"] = 7, ["meta"] = { ["fields"] = { ["owner_info"] = "return { [\"y\"] = 75, [\"x\"] = 656, [\"z\"] = -779 }" }, ["inventory"] = {  } }, ["param2"] = 2, ["y"] = 3, ["param1"] = 137, ["z"] = 3, ["name"] = "default:ladder" }, { ["x"] = 7, ["meta"] = { ["fields"] = {  }, ["inventory"] = {  } }, ["param2"] = 1, ["y"] = 3, ["param1"] = 0, ["z"] = 6, ["name"] = "default:wood" }, { ["x"] = 7, ["meta"] = { ["fields"] = {  }, ["inventory"] = {  } }, ["param2"] = 0, ["y"] = 4, ["param1"] = 173, ["z"] = 0, ["name"] = "cottages:roof_wood" }, { ["x"] = 7, ["meta"] = { ["fields"] = {  }, ["inventory"] = {  } }, ["param2"] = 18, ["y"] = 4, ["param1"] = 0, ["z"] = 1, ["name"] = "default:tree" }, { ["x"] = 7, ["meta"] = { ["fields"] = { ["owner_info"] = "return { [\"y\"] = 75, [\"x\"] = 656, [\"z\"] = -779 }" }, ["inventory"] = {  } }, ["param2"] = 1, ["y"] = 4, ["param1"] = 0, ["z"] = 2, ["name"] = "default:wood" }, { ["x"] = 7, ["meta"] = { ["fields"] = { ["owner_info"] = "return { [\"y\"] = 75, [\"x\"] = 656, [\"z\"] = -779 }" }, ["inventory"] = {  } }, ["param2"] = 2, ["y"] = 4, ["param1"] = 138, ["z"] = 3, ["name"] = "default:ladder" }, { ["x"] = 7, ["meta"] = { ["fields"] = { ["owner_info"] = "return { [\"y\"] = 75, [\"x\"] = 656, [\"z\"] = -779 }" }, ["inventory"] = {  } }, ["param2"] = 1, ["y"] = 4, ["param1"] = 0, ["z"] = 4, ["name"] = "default:wood" }, { ["x"] = 7, ["meta"] = { ["fields"] = { ["owner_info"] = "return { [\"y\"] = 75, [\"x\"] = 656, [\"z\"] = -779 }" }, ["inventory"] = {  } }, ["param2"] = 1, ["y"] = 4, ["param1"] = 0, ["z"] = 5, ["name"] = "default:wood" }, { ["x"] = 7, ["meta"] = { ["fields"] = {  }, ["inventory"] = {  } }, ["param2"] = 18, ["y"] = 4, ["param1"] = 0, ["z"] = 6, ["name"] = "default:tree" }, { ["x"] = 7, ["meta"] = { ["fields"] = { ["owner_info"] = "return { [\"y\"] = 75, [\"x\"] = 656, [\"z\"] = -779 }" }, ["inventory"] = {  } }, ["param2"] = 2, ["y"] = 4, ["param1"] = 157, ["z"] = 7, ["name"] = "cottages:roof_wood" }, { ["x"] = 7, ["meta"] = { ["fields"] = { ["owner_info"] = "return { [\"y\"] = 75, [\"x\"] = 656, [\"z\"] = -779 }" }, ["inventory"] = {  } }, ["param2"] = 0, ["y"] = 5, ["param1"] = 173, ["z"] = 1, ["name"] = "cottages:roof_wood" }, { ["x"] = 7, ["meta"] = { ["fields"] = { ["infotext"] = "Chest", ["owner_info"] = "return { [\"y\"] = 75, [\"x\"] = 656, [\"z\"] = -779 }", ["formspec"] = "size[8,9]list[current_name;main;0,0;8,4;]list[current_player;main;0,5;8,4;]" }, ["inventory"] = { ["main"] = { "", "", "", "", "", "", "default:coal_lump 9", "", "", "", "", "default:paper", "", "", "", "", "", "", "", "", "default:torch 9", "farming:string 5", "", "default:paper 6", "", "", "", "default:book", "", "", "", "" } } }, ["param2"] = 2, ["y"] = 5, ["param1"] = 0, ["z"] = 2, ["name"] = "default:chest" }, { ["x"] = 7, ["meta"] = { ["fields"] = { ["owner_info"] = "return { [\"y\"] = 75, [\"x\"] = 656, [\"z\"] = -779 }" }, ["inventory"] = {  } }, ["param2"] = 2, ["y"] = 5, ["param1"] = 155, ["z"] = 3, ["name"] = "default:ladder" }, { ["x"] = 7, ["meta"] = { ["fields"] = { ["owner_info"] = "return { [\"y\"] = 75, [\"x\"] = 656, [\"z\"] = -779 }" }, ["inventory"] = {  } }, ["param2"] = 1, ["y"] = 5, ["param1"] = 171, ["z"] = 4, ["name"] = "cottages:bench" }, { ["x"] = 7, ["meta"] = { ["fields"] = { ["infotext"] = "Chest", ["owner_info"] = "return { [\"y\"] = 75, [\"x\"] = 656, [\"z\"] = -779 }", ["formspec"] = "size[8,9]list[current_name;main;0,0;8,4;]list[current_player;main;0,5;8,4;]" }, ["inventory"] = { ["main"] = { "", "", "", "", "", "", "", "", "", "wool:white 2", "default:coal_lump 10", "", "", "", "default:torch 9", "", "", "", "", "", "", "default:apple 6", "", "default:paper 4", "default:stick 28", "", "", "default:book", "", "default:pick_steel", "", "" } } }, ["param2"] = 0, ["y"] = 5, ["param1"] = 0, ["z"] = 5, ["name"] = "default:chest" }, { ["x"] = 7, ["meta"] = { ["fields"] = { ["owner_info"] = "return { [\"y\"] = 75, [\"x\"] = 656, [\"z\"] = -779 }" }, ["inventory"] = {  } }, ["param2"] = 2, ["y"] = 5, ["param1"] = 173, ["z"] = 6, ["name"] = "cottages:roof_wood" }, { ["x"] = 7, ["meta"] = { ["fields"] = { ["owner_info"] = "return { [\"y\"] = 75, [\"x\"] = 656, [\"z\"] = -779 }" }, ["inventory"] = {  } }, ["param2"] = 0, ["y"] = 6, ["param1"] = 173, ["z"] = 2, ["name"] = "cottages:roof_wood" }, { ["x"] = 7, ["meta"] = { ["fields"] = { ["owner_info"] = "return { [\"y\"] = 75, [\"x\"] = 656, [\"z\"] = -779 }" }, ["inventory"] = {  } }, ["param2"] = 2, ["y"] = 6, ["param1"] = 156, ["z"] = 3, ["name"] = "default:ladder" }, { ["x"] = 7, ["meta"] = { ["fields"] = { ["owner_info"] = "return { [\"y\"] = 75, [\"x\"] = 656, [\"z\"] = -779 }" }, ["inventory"] = {  } }, ["param2"] = 2, ["y"] = 6, ["param1"] = 173, ["z"] = 5, ["name"] = "cottages:roof_wood" }, { ["x"] = 7, ["meta"] = { ["fields"] = { ["owner_info"] = "return { [\"y\"] = 75, [\"x\"] = 656, [\"z\"] = -779 }" }, ["inventory"] = {  } }, ["param2"] = 0, ["y"] = 7, ["param1"] = 141, ["z"] = 3, ["name"] = "cottages:roof_wood" }, { ["x"] = 7, ["meta"] = { ["fields"] = { ["owner_info"] = "return { [\"y\"] = 75, [\"x\"] = 656, [\"z\"] = -779 }" }, ["inventory"] = {  } }, ["param2"] = 2, ["y"] = 7, ["param1"] = 141, ["z"] = 4, ["name"] = "cottages:roof_wood" }, { ["x"] = 8, ["meta"] = { ["fields"] = { ["owner_info"] = "return { [\"y\"] = 75, [\"x\"] = 656, [\"z\"] = -779 }" }, ["inventory"] = {  } }, ["param2"] = 0, ["y"] = 0, ["param1"] = 157, ["z"] = 0, ["name"] = "cottages:bench" }, { ["x"] = 8, ["meta"] = { ["fields"] = { ["owner_info"] = "return { [\"y\"] = 75, [\"x\"] = 656, [\"z\"] = -779 }" }, ["inventory"] = {  } }, ["param2"] = 1, ["y"] = 0, ["param1"] = 0, ["z"] = 1, ["name"] = "default:tree" }, { ["x"] = 8, ["meta"] = { ["fields"] = { ["owner_info"] = "return { [\"y\"] = 75, [\"x\"] = 656, [\"z\"] = -779 }" }, ["inventory"] = {  } }, ["param2"] = 1, ["y"] = 0, ["param1"] = 0, ["z"] = 2, ["name"] = "default:wood" }, { ["x"] = 8, ["meta"] = { ["fields"] = { ["owner_info"] = "return { [\"y\"] = 75, [\"x\"] = 656, [\"z\"] = -779 }" }, ["inventory"] = {  } }, ["param2"] = 1, ["y"] = 0, ["param1"] = 0, ["z"] = 3, ["name"] = "default:wood" }, { ["x"] = 8, ["meta"] = { ["fields"] = { ["owner_info"] = "return { [\"y\"] = 75, [\"x\"] = 656, [\"z\"] = -779 }" }, ["inventory"] = {  } }, ["param2"] = 1, ["y"] = 0, ["param1"] = 0, ["z"] = 4, ["name"] = "default:wood" }, { ["x"] = 8, ["meta"] = { ["fields"] = { ["owner_info"] = "return { [\"y\"] = 75, [\"x\"] = 656, [\"z\"] = -779 }" }, ["inventory"] = {  } }, ["param2"] = 1, ["y"] = 0, ["param1"] = 0, ["z"] = 5, ["name"] = "default:wood" }, { ["x"] = 8, ["meta"] = { ["fields"] = { ["owner_info"] = "return { [\"y\"] = 75, [\"x\"] = 656, [\"z\"] = -779 }" }, ["inventory"] = {  } }, ["param2"] = 1, ["y"] = 0, ["param1"] = 0, ["z"] = 6, ["name"] = "default:tree" }, { ["x"] = 8, ["meta"] = { ["fields"] = { ["owner_info"] = "return { [\"y\"] = 75, [\"x\"] = 656, [\"z\"] = -779 }" }, ["inventory"] = {  } }, ["param2"] = 1, ["y"] = 1, ["param1"] = 0, ["z"] = 1, ["name"] = "default:tree" }, { ["x"] = 8, ["meta"] = { ["fields"] = { ["owner_info"] = "return { [\"y\"] = 75, [\"x\"] = 656, [\"z\"] = -779 }" }, ["inventory"] = {  } }, ["param2"] = 1, ["y"] = 1, ["param1"] = 0, ["z"] = 2, ["name"] = "default:wood" }, { ["x"] = 8, ["meta"] = { ["fields"] = { ["owner_info"] = "return { [\"y\"] = 75, [\"x\"] = 656, [\"z\"] = -779 }" }, ["inventory"] = {  } }, ["param2"] = 1, ["y"] = 1, ["param1"] = 0, ["z"] = 3, ["name"] = "default:wood" }, { ["x"] = 8, ["meta"] = { ["fields"] = { ["owner_info"] = "return { [\"y\"] = 75, [\"x\"] = 656, [\"z\"] = -779 }" }, ["inventory"] = {  } }, ["param2"] = 1, ["y"] = 1, ["param1"] = 0, ["z"] = 4, ["name"] = "default:wood" }, { ["x"] = 8, ["meta"] = { ["fields"] = { ["owner_info"] = "return { [\"y\"] = 75, [\"x\"] = 656, [\"z\"] = -779 }" }, ["inventory"] = {  } }, ["param2"] = 1, ["y"] = 1, ["param1"] = 0, ["z"] = 5, ["name"] = "default:wood" }, { ["x"] = 8, ["meta"] = { ["fields"] = { ["owner_info"] = "return { [\"y\"] = 75, [\"x\"] = 656, [\"z\"] = -779 }" }, ["inventory"] = {  } }, ["param2"] = 1, ["y"] = 1, ["param1"] = 0, ["z"] = 6, ["name"] = "default:tree" }, { ["x"] = 8, ["meta"] = { ["fields"] = { ["owner_info"] = "return { [\"y\"] = 75, [\"x\"] = 656, [\"z\"] = -779 }" }, ["inventory"] = {  } }, ["param2"] = 1, ["y"] = 2, ["param1"] = 0, ["z"] = 1, ["name"] = "default:tree" }, { ["x"] = 8, ["meta"] = { ["fields"] = {  }, ["inventory"] = {  } }, ["param2"] = 3, ["y"] = 2, ["param1"] = 188, ["z"] = 2, ["name"] = "cottages:glass_pane" }, { ["x"] = 8, ["meta"] = { ["fields"] = { ["owner_info"] = "return { [\"y\"] = 75, [\"x\"] = 656, [\"z\"] = -779 }" }, ["inventory"] = {  } }, ["param2"] = 1, ["y"] = 2, ["param1"] = 0, ["z"] = 3, ["name"] = "default:wood" }, { ["x"] = 8, ["meta"] = { ["fields"] = { ["owner_info"] = "return { [\"y\"] = 75, [\"x\"] = 656, [\"z\"] = -779 }" }, ["inventory"] = {  } }, ["param2"] = 1, ["y"] = 2, ["param1"] = 0, ["z"] = 4, ["name"] = "default:wood" }, { ["x"] = 8, ["meta"] = { ["fields"] = {  }, ["inventory"] = {  } }, ["param2"] = 3, ["y"] = 2, ["param1"] = 188, ["z"] = 5, ["name"] = "cottages:glass_pane" }, { ["x"] = 8, ["meta"] = { ["fields"] = { ["owner_info"] = "return { [\"y\"] = 75, [\"x\"] = 656, [\"z\"] = -779 }" }, ["inventory"] = {  } }, ["param2"] = 1, ["y"] = 2, ["param1"] = 0, ["z"] = 6, ["name"] = "default:tree" }, { ["x"] = 8, ["meta"] = { ["fields"] = {  }, ["inventory"] = {  } }, ["param2"] = 1, ["y"] = 3, ["param1"] = 0, ["z"] = 1, ["name"] = "default:tree" }, { ["x"] = 8, ["meta"] = { ["fields"] = { ["owner_info"] = "return { [\"y\"] = 75, [\"x\"] = 656, [\"z\"] = -779 }" }, ["inventory"] = {  } }, ["param2"] = 1, ["y"] = 3, ["param1"] = 0, ["z"] = 2, ["name"] = "default:wood" }, { ["x"] = 8, ["meta"] = { ["fields"] = { ["owner_info"] = "return { [\"y\"] = 75, [\"x\"] = 656, [\"z\"] = -779 }" }, ["inventory"] = {  } }, ["param2"] = 1, ["y"] = 3, ["param1"] = 0, ["z"] = 3, ["name"] = "default:wood" }, { ["x"] = 8, ["meta"] = { ["fields"] = { ["owner_info"] = "return { [\"y\"] = 75, [\"x\"] = 656, [\"z\"] = -779 }" }, ["inventory"] = {  } }, ["param2"] = 1, ["y"] = 3, ["param1"] = 0, ["z"] = 4, ["name"] = "default:wood" }, { ["x"] = 8, ["meta"] = { ["fields"] = { ["owner_info"] = "return { [\"y\"] = 75, [\"x\"] = 656, [\"z\"] = -779 }" }, ["inventory"] = {  } }, ["param2"] = 1, ["y"] = 3, ["param1"] = 0, ["z"] = 5, ["name"] = "default:wood" }, { ["x"] = 8, ["meta"] = { ["fields"] = {  }, ["inventory"] = {  } }, ["param2"] = 1, ["y"] = 3, ["param1"] = 0, ["z"] = 6, ["name"] = "default:tree" }, { ["x"] = 8, ["meta"] = { ["fields"] = {  }, ["inventory"] = {  } }, ["param2"] = 0, ["y"] = 4, ["param1"] = 173, ["z"] = 0, ["name"] = "cottages:roof_wood" }, { ["x"] = 8, ["meta"] = { ["fields"] = {  }, ["inventory"] = {  } }, ["param2"] = 18, ["y"] = 4, ["param1"] = 0, ["z"] = 1, ["name"] = "default:tree" }, { ["x"] = 8, ["meta"] = { ["fields"] = { ["owner_info"] = "return { [\"y\"] = 75, [\"x\"] = 656, [\"z\"] = -779 }" }, ["inventory"] = {  } }, ["param2"] = 1, ["y"] = 4, ["param1"] = 0, ["z"] = 2, ["name"] = "default:wood" }, { ["x"] = 8, ["meta"] = { ["fields"] = { ["owner_info"] = "return { [\"y\"] = 75, [\"x\"] = 656, [\"z\"] = -779 }" }, ["inventory"] = {  } }, ["param2"] = 1, ["y"] = 4, ["param1"] = 0, ["z"] = 3, ["name"] = "default:wood" }, { ["x"] = 8, ["meta"] = { ["fields"] = { ["owner_info"] = "return { [\"y\"] = 75, [\"x\"] = 656, [\"z\"] = -779 }" }, ["inventory"] = {  } }, ["param2"] = 1, ["y"] = 4, ["param1"] = 0, ["z"] = 4, ["name"] = "default:wood" }, { ["x"] = 8, ["meta"] = { ["fields"] = { ["owner_info"] = "return { [\"y\"] = 75, [\"x\"] = 656, [\"z\"] = -779 }" }, ["inventory"] = {  } }, ["param2"] = 1, ["y"] = 4, ["param1"] = 0, ["z"] = 5, ["name"] = "default:wood" }, { ["x"] = 8, ["meta"] = { ["fields"] = {  }, ["inventory"] = {  } }, ["param2"] = 18, ["y"] = 4, ["param1"] = 0, ["z"] = 6, ["name"] = "default:tree" }, { ["x"] = 8, ["meta"] = { ["fields"] = { ["owner_info"] = "return { [\"y\"] = 75, [\"x\"] = 656, [\"z\"] = -779 }" }, ["inventory"] = {  } }, ["param2"] = 2, ["y"] = 4, ["param1"] = 173, ["z"] = 7, ["name"] = "cottages:roof_wood" }, { ["x"] = 8, ["meta"] = { ["fields"] = { ["owner_info"] = "return { [\"y\"] = 75, [\"x\"] = 656, [\"z\"] = -779 }" }, ["inventory"] = {  } }, ["param2"] = 0, ["y"] = 5, ["param1"] = 189, ["z"] = 1, ["name"] = "cottages:roof_connector_wood" }, { ["x"] = 8, ["meta"] = { ["fields"] = { ["owner_info"] = "return { [\"y\"] = 75, [\"x\"] = 656, [\"z\"] = -779 }" }, ["inventory"] = {  } }, ["param2"] = 1, ["y"] = 5, ["param1"] = 0, ["z"] = 2, ["name"] = "default:wood" }, { ["x"] = 8, ["meta"] = { ["fields"] = { ["owner_info"] = "return { [\"y\"] = 75, [\"x\"] = 656, [\"z\"] = -779 }" }, ["inventory"] = {  } }, ["param2"] = 1, ["y"] = 5, ["param1"] = 0, ["z"] = 3, ["name"] = "default:wood" }, { ["x"] = 8, ["meta"] = { ["fields"] = {  }, ["inventory"] = {  } }, ["param2"] = 3, ["y"] = 5, ["param1"] = 188, ["z"] = 4, ["name"] = "cottages:glass_pane" }, { ["x"] = 8, ["meta"] = { ["fields"] = { ["owner_info"] = "return { [\"y\"] = 75, [\"x\"] = 656, [\"z\"] = -779 }" }, ["inventory"] = {  } }, ["param2"] = 1, ["y"] = 5, ["param1"] = 0, ["z"] = 5, ["name"] = "default:wood" }, { ["x"] = 8, ["meta"] = { ["fields"] = { ["owner_info"] = "return { [\"y\"] = 75, [\"x\"] = 656, [\"z\"] = -779 }" }, ["inventory"] = {  } }, ["param2"] = 2, ["y"] = 5, ["param1"] = 189, ["z"] = 6, ["name"] = "cottages:roof_connector_wood" }, { ["x"] = 8, ["meta"] = { ["fields"] = { ["owner_info"] = "return { [\"y\"] = 75, [\"x\"] = 656, [\"z\"] = -779 }" }, ["inventory"] = {  } }, ["param2"] = 0, ["y"] = 6, ["param1"] = 189, ["z"] = 2, ["name"] = "cottages:roof_connector_wood" }, { ["x"] = 8, ["meta"] = { ["fields"] = { ["owner_info"] = "return { [\"y\"] = 75, [\"x\"] = 656, [\"z\"] = -779 }" }, ["inventory"] = {  } }, ["param2"] = 1, ["y"] = 6, ["param1"] = 0, ["z"] = 3, ["name"] = "default:wood" }, { ["x"] = 8, ["meta"] = { ["fields"] = {  }, ["inventory"] = {  } }, ["param2"] = 3, ["y"] = 6, ["param1"] = 172, ["z"] = 4, ["name"] = "cottages:glass_pane" }, { ["x"] = 8, ["meta"] = { ["fields"] = { ["owner_info"] = "return { [\"y\"] = 75, [\"x\"] = 656, [\"z\"] = -779 }" }, ["inventory"] = {  } }, ["param2"] = 2, ["y"] = 6, ["param1"] = 189, ["z"] = 5, ["name"] = "cottages:roof_connector_wood" }, { ["x"] = 8, ["meta"] = { ["fields"] = { ["owner_info"] = "return { [\"y\"] = 75, [\"x\"] = 656, [\"z\"] = -779 }" }, ["inventory"] = {  } }, ["param2"] = 0, ["y"] = 7, ["param1"] = 157, ["z"] = 3, ["name"] = "cottages:roof_connector_wood" }, { ["x"] = 8, ["meta"] = { ["fields"] = { ["owner_info"] = "return { [\"y\"] = 75, [\"x\"] = 656, [\"z\"] = -779 }" }, ["inventory"] = {  } }, ["param2"] = 2, ["y"] = 7, ["param1"] = 157, ["z"] = 4, ["name"] = "cottages:roof_connector_wood" }, { ["x"] = 9, ["meta"] = { ["fields"] = { ["owner_info"] = "return { [\"y\"] = 75, [\"x\"] = 656, [\"z\"] = -779 }" }, ["inventory"] = {  } }, ["param2"] = 3, ["y"] = 0, ["param1"] = 205, ["z"] = 2, ["name"] = "cottages:bench" }, { ["x"] = 9, ["meta"] = { ["fields"] = { ["owner_info"] = "return { [\"y\"] = 75, [\"x\"] = 656, [\"z\"] = -779 }" }, ["inventory"] = {  } }, ["param2"] = 3, ["y"] = 0, ["param1"] = 189, ["z"] = 3, ["name"] = "cottages:bench" }, { ["x"] = 9, ["meta"] = { ["fields"] = { ["owner_info"] = "return { [\"y\"] = 75, [\"x\"] = 656, [\"z\"] = -779 }" }, ["inventory"] = {  } }, ["param2"] = 3, ["y"] = 0, ["param1"] = 189, ["z"] = 4, ["name"] = "cottages:bench" }, { ["x"] = 9, ["meta"] = { ["fields"] = { ["owner_info"] = "return { [\"y\"] = 75, [\"x\"] = 656, [\"z\"] = -779 }" }, ["inventory"] = {  } }, ["param2"] = 3, ["y"] = 0, ["param1"] = 205, ["z"] = 5, ["name"] = "cottages:bench" }, { ["x"] = 9, ["meta"] = { ["fields"] = { ["owner_info"] = "return { [\"y\"] = 75, [\"x\"] = 656, [\"z\"] = -779 }" }, ["inventory"] = {  } }, ["param2"] = 3, ["y"] = 1, ["param1"] = 0, ["z"] = 2, ["name"] = "default:torch" }, { ["x"] = 9, ["meta"] = { ["fields"] = { ["owner_info"] = "return { [\"y\"] = 75, [\"x\"] = 656, [\"z\"] = -779 }" }, ["inventory"] = {  } }, ["param2"] = 3, ["y"] = 1, ["param1"] = 0, ["z"] = 5, ["name"] = "default:torch" }, { ["x"] = 9, ["meta"] = { ["fields"] = {  }, ["inventory"] = {  } }, ["param2"] = 3, ["y"] = 2, ["param1"] = 205, ["z"] = 2, ["name"] = "cottages:window_shutter_open" }, { ["x"] = 9, ["meta"] = { ["fields"] = {  }, ["inventory"] = {  } }, ["param2"] = 3, ["y"] = 2, ["param1"] = 205, ["z"] = 5, ["name"] = "cottages:window_shutter_open" }, { ["x"] = 9, ["meta"] = { ["fields"] = {  }, ["inventory"] = {  } }, ["param2"] = 3, ["y"] = 3, ["param1"] = 0, ["z"] = 1, ["name"] = "default:torch" }, { ["x"] = 9, ["meta"] = { ["fields"] = {  }, ["inventory"] = {  } }, ["param2"] = 3, ["y"] = 3, ["param1"] = 0, ["z"] = 6, ["name"] = "default:torch" }, { ["x"] = 9, ["meta"] = { ["fields"] = {  }, ["inventory"] = {  } }, ["param2"] = 0, ["y"] = 4, ["param1"] = 189, ["z"] = 0, ["name"] = "cottages:roof_wood" }, { ["x"] = 9, ["meta"] = { ["fields"] = {  }, ["inventory"] = {  } }, ["param2"] = 18, ["y"] = 4, ["param1"] = 0, ["z"] = 1, ["name"] = "default:tree" }, { ["x"] = 9, ["meta"] = { ["fields"] = {  }, ["inventory"] = {  } }, ["param2"] = 18, ["y"] = 4, ["param1"] = 0, ["z"] = 6, ["name"] = "default:tree" }, { ["x"] = 9, ["meta"] = { ["fields"] = { ["owner_info"] = "return { [\"y\"] = 75, [\"x\"] = 656, [\"z\"] = -779 }" }, ["inventory"] = {  } }, ["param2"] = 2, ["y"] = 4, ["param1"] = 189, ["z"] = 7, ["name"] = "cottages:roof_wood" }, { ["x"] = 9, ["meta"] = { ["fields"] = { ["owner_info"] = "return { [\"y\"] = 75, [\"x\"] = 656, [\"z\"] = -779 }" }, ["inventory"] = {  } }, ["param2"] = 0, ["y"] = 5, ["param1"] = 205, ["z"] = 1, ["name"] = "cottages:roof_wood" }, { ["x"] = 9, ["meta"] = { ["fields"] = { ["owner_info"] = "return { [\"y\"] = 75, [\"x\"] = 656, [\"z\"] = -779 }" }, ["inventory"] = {  } }, ["param2"] = 3, ["y"] = 5, ["param1"] = 0, ["z"] = 2, ["name"] = "default:torch" }, { ["x"] = 9, ["meta"] = { ["fields"] = {  }, ["inventory"] = {  } }, ["param2"] = 3, ["y"] = 5, ["param1"] = 205, ["z"] = 4, ["name"] = "cottages:window_shutter_open" }, { ["x"] = 9, ["meta"] = { ["fields"] = { ["owner_info"] = "return { [\"y\"] = 75, [\"x\"] = 656, [\"z\"] = -779 }" }, ["inventory"] = {  } }, ["param2"] = 3, ["y"] = 5, ["param1"] = 0, ["z"] = 5, ["name"] = "default:torch" }, { ["x"] = 9, ["meta"] = { ["fields"] = { ["owner_info"] = "return { [\"y\"] = 75, [\"x\"] = 656, [\"z\"] = -779 }" }, ["inventory"] = {  } }, ["param2"] = 2, ["y"] = 5, ["param1"] = 205, ["z"] = 6, ["name"] = "cottages:roof_wood" }, { ["x"] = 9, ["meta"] = { ["fields"] = { ["owner_info"] = "return { [\"y\"] = 75, [\"x\"] = 656, [\"z\"] = -779 }" }, ["inventory"] = {  } }, ["param2"] = 0, ["y"] = 6, ["param1"] = 205, ["z"] = 2, ["name"] = "cottages:roof_wood" }, { ["x"] = 9, ["meta"] = { ["fields"] = {  }, ["inventory"] = {  } }, ["param2"] = 3, ["y"] = 6, ["param1"] = 189, ["z"] = 4, ["name"] = "cottages:window_shutter_open" }, { ["x"] = 9, ["meta"] = { ["fields"] = { ["owner_info"] = "return { [\"y\"] = 75, [\"x\"] = 656, [\"z\"] = -779 }" }, ["inventory"] = {  } }, ["param2"] = 2, ["y"] = 6, ["param1"] = 205, ["z"] = 5, ["name"] = "cottages:roof_wood" }, { ["x"] = 9, ["meta"] = { ["fields"] = { ["owner_info"] = "return { [\"y\"] = 75, [\"x\"] = 656, [\"z\"] = -779 }" }, ["inventory"] = {  } }, ["param2"] = 0, ["y"] = 7, ["param1"] = 173, ["z"] = 3, ["name"] = "cottages:roof_wood" }, { ["x"] = 9, ["meta"] = { ["fields"] = { ["owner_info"] = "return { [\"y\"] = 75, [\"x\"] = 656, [\"z\"] = -779 }" }, ["inventory"] = {  } }, ["param2"] = 2, ["y"] = 7, ["param1"] = 173, ["z"] = 4, ["name"] = "cottages:roof_wood" } }