return { { ["x"] = 0, ["meta"] = { ["fields"] = { ["owner_info"] = "return { [\"y\"] = 2, [\"x\"] = 340, [\"z\"] = 1095 }" }, ["inventory"] = {  } }, ["param2"] = 2, ["y"] = 2, ["param1"] = 15, ["z"] = 7, ["name"] = "default:torch" }, { ["x"] = 0, ["meta"] = { ["fields"] = { ["owner_info"] = "return { [\"y\"] = 2, [\"x\"] = 340, [\"z\"] = 1095 }" }, ["inventory"] = {  } }, ["param2"] = 0, ["y"] = 4, ["param1"] = 15, ["z"] = 1, ["name"] = "default:torch" }, { ["x"] = 0, ["meta"] = { ["fields"] = { ["owner_info"] = "return { [\"y\"] = 2, [\"x\"] = 340, [\"z\"] = 1095 }" }, ["inventory"] = {  } }, ["param2"] = 0, ["y"] = 5, ["param1"] = 207, ["z"] = 1, ["name"] = "default:fence_wood" }, { ["x"] = 1, ["meta"] = { ["fields"] = { ["owner_info"] = "return { [\"y\"] = 2, [\"x\"] = 340, [\"z\"] = 1095 }" }, ["inventory"] = {  } }, ["param2"] = 0, ["y"] = 0, ["param1"] = 0, ["z"] = 1, ["name"] = "default:stone" }, { ["x"] = 1, ["meta"] = { ["fields"] = { ["owner_info"] = "return { [\"y\"] = 2, [\"x\"] = 340, [\"z\"] = 1095 }" }, ["inventory"] = {  } }, ["param2"] = 0, ["y"] = 0, ["param1"] = 0, ["z"] = 2, ["name"] = "default:stone" }, { ["x"] = 1, ["meta"] = { ["fields"] = { ["owner_info"] = "return { [\"y\"] = 2, [\"x\"] = 340, [\"z\"] = 1095 }" }, ["inventory"] = {  } }, ["param2"] = 0, ["y"] = 0, ["param1"] = 0, ["z"] = 3, ["name"] = "default:stone" }, { ["x"] = 1, ["meta"] = { ["fields"] = { ["owner_info"] = "return { [\"y\"] = 2, [\"x\"] = 340, [\"z\"] = 1095 }" }, ["inventory"] = {  } }, ["param2"] = 0, ["y"] = 0, ["param1"] = 0, ["z"] = 4, ["name"] = "default:stone" }, { ["x"] = 1, ["meta"] = { ["fields"] = { ["owner_info"] = "return { [\"y\"] = 2, [\"x\"] = 340, [\"z\"] = 1095 }" }, ["inventory"] = {  } }, ["param2"] = 0, ["y"] = 0, ["param1"] = 0, ["z"] = 5, ["name"] = "default:stone" }, { ["x"] = 1, ["meta"] = { ["fields"] = { ["owner_info"] = "return { [\"y\"] = 2, [\"x\"] = 340, [\"z\"] = 1095 }" }, ["inventory"] = {  } }, ["param2"] = 0, ["y"] = 0, ["param1"] = 0, ["z"] = 6, ["name"] = "default:stone" }, { ["x"] = 1, ["meta"] = { ["fields"] = { ["owner_info"] = "return { [\"y\"] = 2, [\"x\"] = 340, [\"z\"] = 1095 }" }, ["inventory"] = {  } }, ["param2"] = 0, ["y"] = 0, ["param1"] = 0, ["z"] = 7, ["name"] = "default:stone" }, { ["x"] = 1, ["meta"] = { ["fields"] = { ["owner_info"] = "return { [\"y\"] = 2, [\"x\"] = 340, [\"z\"] = 1095 }" }, ["inventory"] = {  } }, ["param2"] = 0, ["y"] = 0, ["param1"] = 0, ["z"] = 8, ["name"] = "default:stone" }, { ["x"] = 1, ["meta"] = { ["fields"] = { ["owner_info"] = "return { [\"y\"] = 2, [\"x\"] = 340, [\"z\"] = 1095 }" }, ["inventory"] = {  } }, ["param2"] = 0, ["y"] = 1, ["param1"] = 0, ["z"] = 1, ["name"] = "default:brick" }, { ["x"] = 1, ["meta"] = { ["fields"] = { ["owner_info"] = "return { [\"y\"] = 2, [\"x\"] = 340, [\"z\"] = 1095 }" }, ["inventory"] = {  } }, ["param2"] = 0, ["y"] = 1, ["param1"] = 0, ["z"] = 2, ["name"] = "default:brick" }, { ["x"] = 1, ["meta"] = { ["fields"] = { ["owner_info"] = "return { [\"y\"] = 2, [\"x\"] = 340, [\"z\"] = 1095 }" }, ["inventory"] = {  } }, ["param2"] = 0, ["y"] = 1, ["param1"] = 0, ["z"] = 3, ["name"] = "default:brick" }, { ["x"] = 1, ["meta"] = { ["fields"] = { ["owner_info"] = "return { [\"y\"] = 2, [\"x\"] = 340, [\"z\"] = 1095 }" }, ["inventory"] = {  } }, ["param2"] = 0, ["y"] = 1, ["param1"] = 0, ["z"] = 4, ["name"] = "default:brick" }, { ["x"] = 1, ["meta"] = { ["fields"] = { ["owner_info"] = "return { [\"y\"] = 2, [\"x\"] = 340, [\"z\"] = 1095 }" }, ["inventory"] = {  } }, ["param2"] = 0, ["y"] = 1, ["param1"] = 0, ["z"] = 5, ["name"] = "default:brick" }, { ["x"] = 1, ["meta"] = { ["fields"] = { ["owner_info"] = "return { [\"y\"] = 2, [\"x\"] = 340, [\"z\"] = 1095 }" }, ["inventory"] = {  } }, ["param2"] = 0, ["y"] = 1, ["param1"] = 0, ["z"] = 6, ["name"] = "default:brick" }, { ["x"] = 1, ["meta"] = { ["fields"] = { ["owner_info"] = "return { [\"y\"] = 2, [\"x\"] = 340, [\"z\"] = 1095 }" }, ["inventory"] = {  } }, ["param2"] = 0, ["y"] = 1, ["param1"] = 0, ["z"] = 7, ["name"] = "default:brick" }, { ["x"] = 1, ["meta"] = { ["fields"] = { ["owner_info"] = "return { [\"y\"] = 2, [\"x\"] = 340, [\"z\"] = 1095 }" }, ["inventory"] = {  } }, ["param2"] = 0, ["y"] = 1, ["param1"] = 0, ["z"] = 8, ["name"] = "default:brick" }, { ["x"] = 1, ["meta"] = { ["fields"] = { ["owner_info"] = "return { [\"y\"] = 2, [\"x\"] = 340, [\"z\"] = 1095 }" }, ["inventory"] = {  } }, ["param2"] = 0, ["y"] = 2, ["param1"] = 0, ["z"] = 1, ["name"] = "default:cobble" }, { ["x"] = 1, ["meta"] = { ["fields"] = { ["owner_info"] = "return { [\"y\"] = 2, [\"x\"] = 340, [\"z\"] = 1095 }" }, ["inventory"] = {  } }, ["param2"] = 3, ["y"] = 2, ["param1"] = 189, ["z"] = 2, ["name"] = "stairs:slab_cobble" }, { ["x"] = 1, ["meta"] = { ["fields"] = { ["owner_info"] = "return { [\"y\"] = 2, [\"x\"] = 340, [\"z\"] = 1095 }" }, ["inventory"] = {  } }, ["param2"] = 3, ["y"] = 2, ["param1"] = 173, ["z"] = 3, ["name"] = "stairs:slab_cobble" }, { ["x"] = 1, ["meta"] = { ["fields"] = { ["owner_info"] = "return { [\"y\"] = 2, [\"x\"] = 340, [\"z\"] = 1095 }" }, ["inventory"] = {  } }, ["param2"] = 3, ["y"] = 2, ["param1"] = 157, ["z"] = 4, ["name"] = "stairs:slab_cobble" }, { ["x"] = 1, ["meta"] = { ["fields"] = { ["owner_info"] = "return { [\"y\"] = 2, [\"x\"] = 340, [\"z\"] = 1095 }" }, ["inventory"] = {  } }, ["param2"] = 0, ["y"] = 2, ["param1"] = 0, ["z"] = 5, ["name"] = "default:brick" }, { ["x"] = 1, ["meta"] = { ["fields"] = { ["owner_info"] = "return { [\"y\"] = 2, [\"x\"] = 340, [\"z\"] = 1095 }" }, ["inventory"] = {  } }, ["param2"] = 0, ["y"] = 2, ["param1"] = 0, ["z"] = 6, ["name"] = "default:brick" }, { ["x"] = 1, ["meta"] = { ["fields"] = { ["owner_info"] = "return { [\"y\"] = 2, [\"x\"] = 340, [\"z\"] = 1095 }" }, ["inventory"] = {  } }, ["param2"] = 0, ["y"] = 2, ["param1"] = 0, ["z"] = 7, ["name"] = "default:brick" }, { ["x"] = 1, ["meta"] = { ["fields"] = { ["owner_info"] = "return { [\"y\"] = 2, [\"x\"] = 340, [\"z\"] = 1095 }" }, ["inventory"] = {  } }, ["param2"] = 0, ["y"] = 2, ["param1"] = 0, ["z"] = 8, ["name"] = "default:brick" }, { ["x"] = 1, ["meta"] = { ["fields"] = { ["owner_info"] = "return { [\"y\"] = 2, [\"x\"] = 340, [\"z\"] = 1095 }" }, ["inventory"] = {  } }, ["param2"] = 0, ["y"] = 3, ["param1"] = 191, ["z"] = 1, ["name"] = "default:fence_wood" }, { ["x"] = 1, ["meta"] = { ["fields"] = { ["owner_info"] = "return { [\"y\"] = 2, [\"x\"] = 340, [\"z\"] = 1095 }" }, ["inventory"] = {  } }, ["param2"] = 3, ["y"] = 3, ["param1"] = 157, ["z"] = 5, ["name"] = "stairs:slab_cobble" }, { ["x"] = 1, ["meta"] = { ["fields"] = { ["owner_info"] = "return { [\"y\"] = 2, [\"x\"] = 340, [\"z\"] = 1095 }" }, ["inventory"] = {  } }, ["param2"] = 3, ["y"] = 3, ["param1"] = 173, ["z"] = 6, ["name"] = "stairs:slab_cobble" }, { ["x"] = 1, ["meta"] = { ["fields"] = { ["owner_info"] = "return { [\"y\"] = 2, [\"x\"] = 340, [\"z\"] = 1095 }" }, ["inventory"] = {  } }, ["param2"] = 3, ["y"] = 3, ["param1"] = 189, ["z"] = 7, ["name"] = "stairs:slab_cobble" }, { ["x"] = 1, ["meta"] = { ["fields"] = { ["owner_info"] = "return { [\"y\"] = 2, [\"x\"] = 340, [\"z\"] = 1095 }" }, ["inventory"] = {  } }, ["param2"] = 3, ["y"] = 3, ["param1"] = 173, ["z"] = 8, ["name"] = "stairs:slab_cobble" }, { ["x"] = 1, ["meta"] = { ["fields"] = { ["owner_info"] = "return { [\"y\"] = 2, [\"x\"] = 340, [\"z\"] = 1095 }" }, ["inventory"] = {  } }, ["param2"] = 0, ["y"] = 4, ["param1"] = 15, ["z"] = 0, ["name"] = "default:torch" }, { ["x"] = 1, ["meta"] = { ["fields"] = { ["owner_info"] = "return { [\"y\"] = 2, [\"x\"] = 340, [\"z\"] = 1095 }" }, ["inventory"] = {  } }, ["param2"] = 0, ["y"] = 4, ["param1"] = 207, ["z"] = 1, ["name"] = "default:fence_wood" }, { ["x"] = 1, ["meta"] = { ["fields"] = { ["owner_info"] = "return { [\"y\"] = 2, [\"x\"] = 340, [\"z\"] = 1095 }" }, ["inventory"] = {  } }, ["param2"] = 0, ["y"] = 4, ["param1"] = 15, ["z"] = 2, ["name"] = "default:torch" }, { ["x"] = 1, ["meta"] = { ["fields"] = { ["owner_info"] = "return { [\"y\"] = 2, [\"x\"] = 340, [\"z\"] = 1095 }" }, ["inventory"] = {  } }, ["param2"] = 0, ["y"] = 5, ["param1"] = 207, ["z"] = 0, ["name"] = "default:fence_wood" }, { ["x"] = 1, ["meta"] = { ["fields"] = { ["owner_info"] = "return { [\"y\"] = 2, [\"x\"] = 340, [\"z\"] = 1095 }" }, ["inventory"] = {  } }, ["param2"] = 0, ["y"] = 5, ["param1"] = 191, ["z"] = 1, ["name"] = "default:fence_wood" }, { ["x"] = 1, ["meta"] = { ["fields"] = { ["owner_info"] = "return { [\"y\"] = 2, [\"x\"] = 340, [\"z\"] = 1095 }" }, ["inventory"] = {  } }, ["param2"] = 0, ["y"] = 5, ["param1"] = 207, ["z"] = 2, ["name"] = "default:fence_wood" }, { ["x"] = 2, ["meta"] = { ["fields"] = {  }, ["inventory"] = {  } }, ["param2"] = 0, ["y"] = 0, ["param1"] = 141, ["z"] = 0, ["name"] = "stairs:slab_stone" }, { ["x"] = 2, ["meta"] = { ["fields"] = { ["owner_info"] = "return { [\"y\"] = 2, [\"x\"] = 340, [\"z\"] = 1095 }" }, ["inventory"] = {  } }, ["param2"] = 0, ["y"] = 0, ["param1"] = 0, ["z"] = 1, ["name"] = "default:stone" }, { ["x"] = 2, ["meta"] = { ["fields"] = { ["owner_info"] = "return { [\"y\"] = 2, [\"x\"] = 340, [\"z\"] = 1095 }" }, ["inventory"] = {  } }, ["param2"] = 0, ["y"] = 0, ["param1"] = 0, ["z"] = 2, ["name"] = "default:stone" }, { ["x"] = 2, ["meta"] = { ["fields"] = { ["owner_info"] = "return { [\"y\"] = 2, [\"x\"] = 340, [\"z\"] = 1095 }" }, ["inventory"] = {  } }, ["param2"] = 0, ["y"] = 0, ["param1"] = 0, ["z"] = 3, ["name"] = "default:stone" }, { ["x"] = 2, ["meta"] = { ["fields"] = { ["owner_info"] = "return { [\"y\"] = 2, [\"x\"] = 340, [\"z\"] = 1095 }" }, ["inventory"] = {  } }, ["param2"] = 0, ["y"] = 0, ["param1"] = 0, ["z"] = 4, ["name"] = "default:stone" }, { ["x"] = 2, ["meta"] = { ["fields"] = { ["owner_info"] = "return { [\"y\"] = 2, [\"x\"] = 340, [\"z\"] = 1095 }" }, ["inventory"] = {  } }, ["param2"] = 0, ["y"] = 0, ["param1"] = 0, ["z"] = 5, ["name"] = "default:stone" }, { ["x"] = 2, ["meta"] = { ["fields"] = { ["owner_info"] = "return { [\"y\"] = 2, [\"x\"] = 340, [\"z\"] = 1095 }" }, ["inventory"] = {  } }, ["param2"] = 0, ["y"] = 0, ["param1"] = 0, ["z"] = 6, ["name"] = "default:stone" }, { ["x"] = 2, ["meta"] = { ["fields"] = { ["owner_info"] = "return { [\"y\"] = 2, [\"x\"] = 340, [\"z\"] = 1095 }" }, ["inventory"] = {  } }, ["param2"] = 0, ["y"] = 0, ["param1"] = 0, ["z"] = 7, ["name"] = "default:stone" }, { ["x"] = 2, ["meta"] = { ["fields"] = { ["owner_info"] = "return { [\"y\"] = 2, [\"x\"] = 340, [\"z\"] = 1095 }" }, ["inventory"] = {  } }, ["param2"] = 0, ["y"] = 0, ["param1"] = 0, ["z"] = 8, ["name"] = "default:stone" }, { ["x"] = 2, ["meta"] = { ["fields"] = { ["owner_info"] = "return { [\"y\"] = 2, [\"x\"] = 340, [\"z\"] = 1095 }" }, ["inventory"] = {  } }, ["param2"] = 0, ["y"] = 1, ["param1"] = 0, ["z"] = 1, ["name"] = "default:brick" }, { ["x"] = 2, ["meta"] = { ["fields"] = { ["owner_info"] = "return { [\"y\"] = 2, [\"x\"] = 340, [\"z\"] = 1095 }" }, ["inventory"] = {  } }, ["param2"] = 0, ["y"] = 1, ["param1"] = 0, ["z"] = 2, ["name"] = "default:desert_sand" }, { ["x"] = 2, ["meta"] = { ["fields"] = { ["owner_info"] = "return { [\"y\"] = 2, [\"x\"] = 340, [\"z\"] = 1095 }" }, ["inventory"] = {  } }, ["param2"] = 0, ["y"] = 1, ["param1"] = 0, ["z"] = 3, ["name"] = "default:desert_sand" }, { ["x"] = 2, ["meta"] = { ["fields"] = {  }, ["inventory"] = {  } }, ["param2"] = 0, ["y"] = 1, ["param1"] = 0, ["z"] = 4, ["name"] = "default:desert_sand" }, { ["x"] = 2, ["meta"] = { ["fields"] = { ["owner_info"] = "return { [\"y\"] = 2, [\"x\"] = 340, [\"z\"] = 1095 }" }, ["inventory"] = {  } }, ["param2"] = 0, ["y"] = 1, ["param1"] = 0, ["z"] = 5, ["name"] = "default:clay" }, { ["x"] = 2, ["meta"] = { ["fields"] = { ["owner_info"] = "return { [\"y\"] = 2, [\"x\"] = 340, [\"z\"] = 1095 }" }, ["inventory"] = {  } }, ["param2"] = 0, ["y"] = 1, ["param1"] = 0, ["z"] = 6, ["name"] = "default:clay" }, { ["x"] = 2, ["meta"] = { ["fields"] = { ["owner_info"] = "return { [\"y\"] = 2, [\"x\"] = 340, [\"z\"] = 1095 }" }, ["inventory"] = {  } }, ["param2"] = 0, ["y"] = 1, ["param1"] = 0, ["z"] = 7, ["name"] = "default:clay" }, { ["x"] = 2, ["meta"] = { ["fields"] = { ["owner_info"] = "return { [\"y\"] = 2, [\"x\"] = 340, [\"z\"] = 1095 }" }, ["inventory"] = {  } }, ["param2"] = 0, ["y"] = 1, ["param1"] = 0, ["z"] = 8, ["name"] = "default:brick" }, { ["x"] = 2, ["meta"] = { ["fields"] = { ["owner_info"] = "return { [\"y\"] = 2, [\"x\"] = 340, [\"z\"] = 1095 }" }, ["inventory"] = {  } }, ["param2"] = 3, ["y"] = 2, ["param1"] = 189, ["z"] = 1, ["name"] = "stairs:slab_cobble" }, { ["x"] = 2, ["meta"] = { ["fields"] = {  }, ["inventory"] = {  } }, ["param2"] = 0, ["y"] = 2, ["param1"] = 0, ["z"] = 3, ["name"] = "default:desert_sand" }, { ["x"] = 2, ["meta"] = { ["fields"] = { ["owner_info"] = "return { [\"y\"] = 2, [\"x\"] = 340, [\"z\"] = 1095 }" }, ["inventory"] = {  } }, ["param2"] = 0, ["y"] = 2, ["param1"] = 0, ["z"] = 6, ["name"] = "default:clay" }, { ["x"] = 2, ["meta"] = { ["fields"] = { ["owner_info"] = "return { [\"y\"] = 2, [\"x\"] = 340, [\"z\"] = 1095 }" }, ["inventory"] = {  } }, ["param2"] = 0, ["y"] = 2, ["param1"] = 0, ["z"] = 7, ["name"] = "default:clay" }, { ["x"] = 2, ["meta"] = { ["fields"] = { ["owner_info"] = "return { [\"y\"] = 2, [\"x\"] = 340, [\"z\"] = 1095 }" }, ["inventory"] = {  } }, ["param2"] = 0, ["y"] = 2, ["param1"] = 0, ["z"] = 8, ["name"] = "default:brick" }, { ["x"] = 2, ["meta"] = { ["fields"] = { ["owner_info"] = "return { [\"y\"] = 2, [\"x\"] = 340, [\"z\"] = 1095 }" }, ["inventory"] = {  } }, ["param2"] = 5, ["y"] = 2, ["param1"] = 15, ["z"] = 9, ["name"] = "default:torch" }, { ["x"] = 2, ["meta"] = { ["fields"] = { ["owner_info"] = "return { [\"y\"] = 2, [\"x\"] = 340, [\"z\"] = 1095 }" }, ["inventory"] = {  } }, ["param2"] = 0, ["y"] = 3, ["param1"] = 0, ["z"] = 7, ["name"] = "default:clay" }, { ["x"] = 2, ["meta"] = { ["fields"] = { ["owner_info"] = "return { [\"y\"] = 2, [\"x\"] = 340, [\"z\"] = 1095 }" }, ["inventory"] = {  } }, ["param2"] = 3, ["y"] = 3, ["param1"] = 189, ["z"] = 8, ["name"] = "stairs:slab_cobble" }, { ["x"] = 2, ["meta"] = { ["fields"] = { ["owner_info"] = "return { [\"y\"] = 2, [\"x\"] = 340, [\"z\"] = 1095 }" }, ["inventory"] = {  } }, ["param2"] = 0, ["y"] = 4, ["param1"] = 15, ["z"] = 1, ["name"] = "default:torch" }, { ["x"] = 2, ["meta"] = { ["fields"] = { ["owner_info"] = "return { [\"y\"] = 2, [\"x\"] = 340, [\"z\"] = 1095 }" }, ["inventory"] = {  } }, ["param2"] = 0, ["y"] = 5, ["param1"] = 207, ["z"] = 1, ["name"] = "default:fence_wood" }, { ["x"] = 3, ["meta"] = { ["fields"] = {  }, ["inventory"] = {  } }, ["param2"] = 0, ["y"] = 0, ["param1"] = 157, ["z"] = 0, ["name"] = "stairs:slab_stone" }, { ["x"] = 3, ["meta"] = { ["fields"] = { ["owner_info"] = "return { [\"y\"] = 2, [\"x\"] = 340, [\"z\"] = 1095 }" }, ["inventory"] = {  } }, ["param2"] = 0, ["y"] = 0, ["param1"] = 0, ["z"] = 1, ["name"] = "default:stone" }, { ["x"] = 3, ["meta"] = { ["fields"] = { ["owner_info"] = "return { [\"y\"] = 2, [\"x\"] = 340, [\"z\"] = 1095 }" }, ["inventory"] = {  } }, ["param2"] = 0, ["y"] = 0, ["param1"] = 0, ["z"] = 2, ["name"] = "default:stone" }, { ["x"] = 3, ["meta"] = { ["fields"] = { ["owner_info"] = "return { [\"y\"] = 2, [\"x\"] = 340, [\"z\"] = 1095 }" }, ["inventory"] = {  } }, ["param2"] = 0, ["y"] = 0, ["param1"] = 0, ["z"] = 3, ["name"] = "default:stone" }, { ["x"] = 3, ["meta"] = { ["fields"] = { ["owner_info"] = "return { [\"y\"] = 2, [\"x\"] = 340, [\"z\"] = 1095 }" }, ["inventory"] = {  } }, ["param2"] = 0, ["y"] = 0, ["param1"] = 0, ["z"] = 4, ["name"] = "default:stone" }, { ["x"] = 3, ["meta"] = { ["fields"] = { ["owner_info"] = "return { [\"y\"] = 2, [\"x\"] = 340, [\"z\"] = 1095 }" }, ["inventory"] = {  } }, ["param2"] = 0, ["y"] = 0, ["param1"] = 0, ["z"] = 5, ["name"] = "default:stone" }, { ["x"] = 3, ["meta"] = { ["fields"] = { ["owner_info"] = "return { [\"y\"] = 2, [\"x\"] = 340, [\"z\"] = 1095 }" }, ["inventory"] = {  } }, ["param2"] = 0, ["y"] = 0, ["param1"] = 0, ["z"] = 6, ["name"] = "default:stone" }, { ["x"] = 3, ["meta"] = { ["fields"] = { ["owner_info"] = "return { [\"y\"] = 2, [\"x\"] = 340, [\"z\"] = 1095 }" }, ["inventory"] = {  } }, ["param2"] = 0, ["y"] = 0, ["param1"] = 0, ["z"] = 7, ["name"] = "default:stone" }, { ["x"] = 3, ["meta"] = { ["fields"] = { ["owner_info"] = "return { [\"y\"] = 2, [\"x\"] = 340, [\"z\"] = 1095 }" }, ["inventory"] = {  } }, ["param2"] = 0, ["y"] = 0, ["param1"] = 0, ["z"] = 8, ["name"] = "default:stone" }, { ["x"] = 3, ["meta"] = { ["fields"] = { ["owner_info"] = "return { [\"y\"] = 2, [\"x\"] = 340, [\"z\"] = 1095 }" }, ["inventory"] = {  } }, ["param2"] = 0, ["y"] = 1, ["param1"] = 0, ["z"] = 6, ["name"] = "default:clay" }, { ["x"] = 3, ["meta"] = { ["fields"] = { ["owner_info"] = "return { [\"y\"] = 2, [\"x\"] = 340, [\"z\"] = 1095 }" }, ["inventory"] = {  } }, ["param2"] = 0, ["y"] = 1, ["param1"] = 0, ["z"] = 7, ["name"] = "default:clay" }, { ["x"] = 3, ["meta"] = { ["fields"] = { ["owner_info"] = "return { [\"y\"] = 2, [\"x\"] = 340, [\"z\"] = 1095 }" }, ["inventory"] = {  } }, ["param2"] = 0, ["y"] = 1, ["param1"] = 0, ["z"] = 8, ["name"] = "default:brick" }, { ["x"] = 3, ["meta"] = { ["fields"] = { ["owner_info"] = "return { [\"y\"] = 2, [\"x\"] = 340, [\"z\"] = 1095 }" }, ["inventory"] = {  } }, ["param2"] = 0, ["y"] = 2, ["param1"] = 0, ["z"] = 7, ["name"] = "default:clay" }, { ["x"] = 3, ["meta"] = { ["fields"] = { ["owner_info"] = "return { [\"y\"] = 2, [\"x\"] = 340, [\"z\"] = 1095 }" }, ["inventory"] = {  } }, ["param2"] = 0, ["y"] = 2, ["param1"] = 0, ["z"] = 8, ["name"] = "default:brick" }, { ["x"] = 3, ["meta"] = { ["fields"] = { ["owner_info"] = "return { [\"y\"] = 2, [\"x\"] = 340, [\"z\"] = 1095 }" }, ["inventory"] = {  } }, ["param2"] = 3, ["y"] = 3, ["param1"] = 173, ["z"] = 8, ["name"] = "stairs:slab_cobble" }, { ["x"] = 4, ["meta"] = { ["fields"] = {  }, ["inventory"] = {  } }, ["param2"] = 0, ["y"] = 0, ["param1"] = 173, ["z"] = 0, ["name"] = "stairs:slab_stone" }, { ["x"] = 4, ["meta"] = { ["fields"] = { ["owner_info"] = "return { [\"y\"] = 2, [\"x\"] = 340, [\"z\"] = 1095 }" }, ["inventory"] = {  } }, ["param2"] = 0, ["y"] = 0, ["param1"] = 0, ["z"] = 1, ["name"] = "default:stone" }, { ["x"] = 4, ["meta"] = { ["fields"] = { ["owner_info"] = "return { [\"y\"] = 2, [\"x\"] = 340, [\"z\"] = 1095 }" }, ["inventory"] = {  } }, ["param2"] = 0, ["y"] = 0, ["param1"] = 0, ["z"] = 2, ["name"] = "default:stone" }, { ["x"] = 4, ["meta"] = { ["fields"] = { ["owner_info"] = "return { [\"y\"] = 2, [\"x\"] = 340, [\"z\"] = 1095 }" }, ["inventory"] = {  } }, ["param2"] = 0, ["y"] = 0, ["param1"] = 0, ["z"] = 3, ["name"] = "default:stone" }, { ["x"] = 4, ["meta"] = { ["fields"] = { ["owner_info"] = "return { [\"y\"] = 2, [\"x\"] = 340, [\"z\"] = 1095 }" }, ["inventory"] = {  } }, ["param2"] = 0, ["y"] = 0, ["param1"] = 0, ["z"] = 4, ["name"] = "default:stone" }, { ["x"] = 4, ["meta"] = { ["fields"] = { ["owner_info"] = "return { [\"y\"] = 2, [\"x\"] = 340, [\"z\"] = 1095 }" }, ["inventory"] = {  } }, ["param2"] = 0, ["y"] = 0, ["param1"] = 0, ["z"] = 5, ["name"] = "default:stone" }, { ["x"] = 4, ["meta"] = { ["fields"] = { ["owner_info"] = "return { [\"y\"] = 2, [\"x\"] = 340, [\"z\"] = 1095 }" }, ["inventory"] = {  } }, ["param2"] = 0, ["y"] = 0, ["param1"] = 0, ["z"] = 6, ["name"] = "default:stone" }, { ["x"] = 4, ["meta"] = { ["fields"] = { ["owner_info"] = "return { [\"y\"] = 2, [\"x\"] = 340, [\"z\"] = 1095 }" }, ["inventory"] = {  } }, ["param2"] = 0, ["y"] = 0, ["param1"] = 0, ["z"] = 7, ["name"] = "default:stone" }, { ["x"] = 4, ["meta"] = { ["fields"] = { ["owner_info"] = "return { [\"y\"] = 2, [\"x\"] = 340, [\"z\"] = 1095 }" }, ["inventory"] = {  } }, ["param2"] = 0, ["y"] = 0, ["param1"] = 0, ["z"] = 8, ["name"] = "default:stone" }, { ["x"] = 4, ["meta"] = { ["fields"] = { ["src_totaltime"] = "0", ["src_time"] = "0", ["formspec"] = "size[8,8.5]bgcolor[#080808BB;true]background[5,5;1,1;gui_formbg.png;true]listcolors[#00000069;#5A5A5A;#141318;#30434C;#FFF]list[current_name;src;2.75,0.5;1,1;]list[current_name;fuel;2.75,2.5;1,1;]image[2.75,1.5;1,1;default_furnace_fire_bg.png]image[3.75,1.5;1,1;gui_furnace_arrow_bg.png^[transformR270]list[current_name;dst;4.75,0.96;2,2;]list[current_player;main;0,4.25;8,1;]list[current_player;main;0,5.5;8,3;8]image[0,4.25;1,1;gui_hb_bg.png]image[1,4.25;1,1;gui_hb_bg.png]image[2,4.25;1,1;gui_hb_bg.png]image[3,4.25;1,1;gui_hb_bg.png]image[4,4.25;1,1;gui_hb_bg.png]image[5,4.25;1,1;gui_hb_bg.png]image[6,4.25;1,1;gui_hb_bg.png]image[7,4.25;1,1;gui_hb_bg.png]", ["fuel_time"] = "0", ["fuel_totaltime"] = "0", ["owner_info"] = "return { [\"y\"] = 2, [\"x\"] = 340, [\"z\"] = 1095 }", ["infotext"] = "Furnace out of fuel" }, ["inventory"] = { ["fuel"] = { "" }, ["dst"] = { "", "", "", "" }, ["src"] = { "" } } }, ["param2"] = 0, ["y"] = 1, ["param1"] = 0, ["z"] = 7, ["name"] = "default:furnace" }, { ["x"] = 4, ["meta"] = { ["fields"] = { ["owner_info"] = "return { [\"y\"] = 2, [\"x\"] = 340, [\"z\"] = 1095 }" }, ["inventory"] = {  } }, ["param2"] = 0, ["y"] = 1, ["param1"] = 0, ["z"] = 8, ["name"] = "default:brick" }, { ["x"] = 4, ["meta"] = { ["fields"] = { ["owner_info"] = "return { [\"y\"] = 2, [\"x\"] = 340, [\"z\"] = 1095 }" }, ["inventory"] = {  } }, ["param2"] = 0, ["y"] = 2, ["param1"] = 0, ["z"] = 8, ["name"] = "default:brick" }, { ["x"] = 4, ["meta"] = { ["fields"] = {  }, ["inventory"] = {  } }, ["param2"] = 1, ["y"] = 3, ["param1"] = 189, ["z"] = 0, ["name"] = "stairs:stair_stone" }, { ["x"] = 4, ["meta"] = { ["fields"] = {  }, ["inventory"] = {  } }, ["param2"] = 1, ["y"] = 3, ["param1"] = 173, ["z"] = 1, ["name"] = "stairs:stair_stone" }, { ["x"] = 4, ["meta"] = { ["fields"] = {  }, ["inventory"] = {  } }, ["param2"] = 1, ["y"] = 3, ["param1"] = 157, ["z"] = 2, ["name"] = "stairs:stair_stone" }, { ["x"] = 4, ["meta"] = { ["fields"] = {  }, ["inventory"] = {  } }, ["param2"] = 1, ["y"] = 3, ["param1"] = 141, ["z"] = 3, ["name"] = "stairs:stair_stone" }, { ["x"] = 4, ["meta"] = { ["fields"] = {  }, ["inventory"] = {  } }, ["param2"] = 1, ["y"] = 3, ["param1"] = 157, ["z"] = 4, ["name"] = "stairs:stair_stone" }, { ["x"] = 4, ["meta"] = { ["fields"] = {  }, ["inventory"] = {  } }, ["param2"] = 1, ["y"] = 3, ["param1"] = 157, ["z"] = 5, ["name"] = "stairs:stair_stone" }, { ["x"] = 4, ["meta"] = { ["fields"] = {  }, ["inventory"] = {  } }, ["param2"] = 1, ["y"] = 3, ["param1"] = 173, ["z"] = 6, ["name"] = "stairs:stair_stone" }, { ["x"] = 4, ["meta"] = { ["fields"] = { ["owner_info"] = "return { [\"y\"] = 2, [\"x\"] = 340, [\"z\"] = 1095 }" }, ["inventory"] = {  } }, ["param2"] = 3, ["y"] = 3, ["param1"] = 157, ["z"] = 8, ["name"] = "stairs:slab_cobble" }, { ["x"] = 5, ["meta"] = { ["fields"] = {  }, ["inventory"] = {  } }, ["param2"] = 0, ["y"] = 0, ["param1"] = 189, ["z"] = 0, ["name"] = "stairs:slab_stone" }, { ["x"] = 5, ["meta"] = { ["fields"] = { ["owner_info"] = "return { [\"y\"] = 2, [\"x\"] = 340, [\"z\"] = 1095 }" }, ["inventory"] = {  } }, ["param2"] = 0, ["y"] = 0, ["param1"] = 0, ["z"] = 1, ["name"] = "default:stone" }, { ["x"] = 5, ["meta"] = { ["fields"] = { ["owner_info"] = "return { [\"y\"] = 2, [\"x\"] = 340, [\"z\"] = 1095 }" }, ["inventory"] = {  } }, ["param2"] = 0, ["y"] = 0, ["param1"] = 0, ["z"] = 2, ["name"] = "default:stone" }, { ["x"] = 5, ["meta"] = { ["fields"] = { ["owner_info"] = "return { [\"y\"] = 2, [\"x\"] = 340, [\"z\"] = 1095 }" }, ["inventory"] = {  } }, ["param2"] = 0, ["y"] = 0, ["param1"] = 0, ["z"] = 3, ["name"] = "default:stone" }, { ["x"] = 5, ["meta"] = { ["fields"] = { ["owner_info"] = "return { [\"y\"] = 2, [\"x\"] = 340, [\"z\"] = 1095 }" }, ["inventory"] = {  } }, ["param2"] = 0, ["y"] = 0, ["param1"] = 0, ["z"] = 4, ["name"] = "default:stone" }, { ["x"] = 5, ["meta"] = { ["fields"] = { ["owner_info"] = "return { [\"y\"] = 2, [\"x\"] = 340, [\"z\"] = 1095 }" }, ["inventory"] = {  } }, ["param2"] = 0, ["y"] = 0, ["param1"] = 0, ["z"] = 5, ["name"] = "default:stone" }, { ["x"] = 5, ["meta"] = { ["fields"] = { ["owner_info"] = "return { [\"y\"] = 2, [\"x\"] = 340, [\"z\"] = 1095 }" }, ["inventory"] = {  } }, ["param2"] = 0, ["y"] = 0, ["param1"] = 0, ["z"] = 6, ["name"] = "default:stone" }, { ["x"] = 5, ["meta"] = { ["fields"] = { ["owner_info"] = "return { [\"y\"] = 2, [\"x\"] = 340, [\"z\"] = 1095 }" }, ["inventory"] = {  } }, ["param2"] = 0, ["y"] = 0, ["param1"] = 0, ["z"] = 7, ["name"] = "default:stone" }, { ["x"] = 5, ["meta"] = { ["fields"] = { ["owner_info"] = "return { [\"y\"] = 2, [\"x\"] = 340, [\"z\"] = 1095 }" }, ["inventory"] = {  } }, ["param2"] = 0, ["y"] = 0, ["param1"] = 0, ["z"] = 8, ["name"] = "default:stone" }, { ["x"] = 5, ["meta"] = { ["fields"] = { ["owner_info"] = "return { [\"y\"] = 2, [\"x\"] = 340, [\"z\"] = 1095 }" }, ["inventory"] = {  } }, ["param2"] = 0, ["y"] = 1, ["param1"] = 0, ["z"] = 1, ["name"] = "default:brick" }, { ["x"] = 5, ["meta"] = { ["fields"] = { ["owner_info"] = "return { [\"y\"] = 2, [\"x\"] = 340, [\"z\"] = 1095 }" }, ["inventory"] = {  } }, ["param2"] = 1, ["y"] = 1, ["param1"] = 172, ["z"] = 2, ["name"] = "doors:door_wood_b_1" }, { ["x"] = 5, ["meta"] = { ["fields"] = { ["owner_info"] = "return { [\"y\"] = 2, [\"x\"] = 340, [\"z\"] = 1095 }" }, ["inventory"] = {  } }, ["param2"] = 0, ["y"] = 1, ["param1"] = 0, ["z"] = 3, ["name"] = "default:brick" }, { ["x"] = 5, ["meta"] = { ["fields"] = { ["owner_info"] = "return { [\"y\"] = 2, [\"x\"] = 340, [\"z\"] = 1095 }" }, ["inventory"] = {  } }, ["param2"] = 0, ["y"] = 1, ["param1"] = 0, ["z"] = 4, ["name"] = "default:brick" }, { ["x"] = 5, ["meta"] = { ["fields"] = { ["owner_info"] = "return { [\"y\"] = 2, [\"x\"] = 340, [\"z\"] = 1095 }" }, ["inventory"] = {  } }, ["param2"] = 0, ["y"] = 1, ["param1"] = 0, ["z"] = 5, ["name"] = "default:brick" }, { ["x"] = 5, ["meta"] = { ["fields"] = { ["owner_info"] = "return { [\"y\"] = 2, [\"x\"] = 340, [\"z\"] = 1095 }" }, ["inventory"] = {  } }, ["param2"] = 0, ["y"] = 1, ["param1"] = 0, ["z"] = 7, ["name"] = "default:sand" }, { ["x"] = 5, ["meta"] = { ["fields"] = { ["owner_info"] = "return { [\"y\"] = 2, [\"x\"] = 340, [\"z\"] = 1095 }" }, ["inventory"] = {  } }, ["param2"] = 0, ["y"] = 1, ["param1"] = 0, ["z"] = 8, ["name"] = "default:brick" }, { ["x"] = 5, ["meta"] = { ["fields"] = { ["owner_info"] = "return { [\"y\"] = 2, [\"x\"] = 340, [\"z\"] = 1095 }" }, ["inventory"] = {  } }, ["param2"] = 4, ["y"] = 2, ["param1"] = 0, ["z"] = 0, ["name"] = "default:torch" }, { ["x"] = 5, ["meta"] = { ["fields"] = { ["owner_info"] = "return { [\"y\"] = 2, [\"x\"] = 340, [\"z\"] = 1095 }" }, ["inventory"] = {  } }, ["param2"] = 0, ["y"] = 2, ["param1"] = 0, ["z"] = 1, ["name"] = "default:brick" }, { ["x"] = 5, ["meta"] = { ["fields"] = { ["owner_info"] = "return { [\"y\"] = 2, [\"x\"] = 340, [\"z\"] = 1095 }" }, ["inventory"] = {  } }, ["param2"] = 1, ["y"] = 2, ["param1"] = 188, ["z"] = 2, ["name"] = "doors:door_wood_t_1" }, { ["x"] = 5, ["meta"] = { ["fields"] = { ["owner_info"] = "return { [\"y\"] = 2, [\"x\"] = 340, [\"z\"] = 1095 }" }, ["inventory"] = {  } }, ["param2"] = 0, ["y"] = 2, ["param1"] = 0, ["z"] = 3, ["name"] = "default:brick" }, { ["x"] = 5, ["meta"] = { ["fields"] = { ["owner_info"] = "return { [\"y\"] = 2, [\"x\"] = 340, [\"z\"] = 1095 }" }, ["inventory"] = {  } }, ["param2"] = 0, ["y"] = 2, ["param1"] = 188, ["z"] = 4, ["name"] = "default:glass" }, { ["x"] = 5, ["meta"] = { ["fields"] = { ["owner_info"] = "return { [\"y\"] = 2, [\"x\"] = 340, [\"z\"] = 1095 }" }, ["inventory"] = {  } }, ["param2"] = 0, ["y"] = 2, ["param1"] = 0, ["z"] = 5, ["name"] = "default:brick" }, { ["x"] = 5, ["meta"] = { ["fields"] = { ["owner_info"] = "return { [\"y\"] = 2, [\"x\"] = 340, [\"z\"] = 1095 }" }, ["inventory"] = {  } }, ["param2"] = 0, ["y"] = 2, ["param1"] = 0, ["z"] = 8, ["name"] = "default:brick" }, { ["x"] = 5, ["meta"] = { ["fields"] = { ["owner_info"] = "return { [\"y\"] = 2, [\"x\"] = 340, [\"z\"] = 1095 }" }, ["inventory"] = {  } }, ["param2"] = 0, ["y"] = 3, ["param1"] = 0, ["z"] = 1, ["name"] = "default:brick" }, { ["x"] = 5, ["meta"] = { ["fields"] = { ["owner_info"] = "return { [\"y\"] = 2, [\"x\"] = 340, [\"z\"] = 1095 }" }, ["inventory"] = {  } }, ["param2"] = 0, ["y"] = 3, ["param1"] = 0, ["z"] = 2, ["name"] = "default:brick" }, { ["x"] = 5, ["meta"] = { ["fields"] = { ["owner_info"] = "return { [\"y\"] = 2, [\"x\"] = 340, [\"z\"] = 1095 }" }, ["inventory"] = {  } }, ["param2"] = 0, ["y"] = 3, ["param1"] = 0, ["z"] = 3, ["name"] = "default:brick" }, { ["x"] = 5, ["meta"] = { ["fields"] = { ["owner_info"] = "return { [\"y\"] = 2, [\"x\"] = 340, [\"z\"] = 1095 }" }, ["inventory"] = {  } }, ["param2"] = 0, ["y"] = 3, ["param1"] = 0, ["z"] = 4, ["name"] = "default:brick" }, { ["x"] = 5, ["meta"] = { ["fields"] = { ["owner_info"] = "return { [\"y\"] = 2, [\"x\"] = 340, [\"z\"] = 1095 }" }, ["inventory"] = {  } }, ["param2"] = 0, ["y"] = 3, ["param1"] = 0, ["z"] = 5, ["name"] = "default:brick" }, { ["x"] = 5, ["meta"] = { ["fields"] = {  }, ["inventory"] = {  } }, ["param2"] = 3, ["y"] = 3, ["param1"] = 157, ["z"] = 8, ["name"] = "stairs:slab_cobble" }, { ["x"] = 5, ["meta"] = { ["fields"] = {  }, ["inventory"] = {  } }, ["param2"] = 1, ["y"] = 4, ["param1"] = 189, ["z"] = 0, ["name"] = "stairs:stair_stone" }, { ["x"] = 5, ["meta"] = { ["fields"] = {  }, ["inventory"] = {  } }, ["param2"] = 1, ["y"] = 4, ["param1"] = 173, ["z"] = 1, ["name"] = "stairs:stair_stone" }, { ["x"] = 5, ["meta"] = { ["fields"] = {  }, ["inventory"] = {  } }, ["param2"] = 1, ["y"] = 4, ["param1"] = 189, ["z"] = 2, ["name"] = "stairs:stair_stone" }, { ["x"] = 5, ["meta"] = { ["fields"] = {  }, ["inventory"] = {  } }, ["param2"] = 1, ["y"] = 4, ["param1"] = 173, ["z"] = 3, ["name"] = "stairs:stair_stone" }, { ["x"] = 5, ["meta"] = { ["fields"] = {  }, ["inventory"] = {  } }, ["param2"] = 1, ["y"] = 4, ["param1"] = 189, ["z"] = 4, ["name"] = "stairs:stair_stone" }, { ["x"] = 5, ["meta"] = { ["fields"] = {  }, ["inventory"] = {  } }, ["param2"] = 1, ["y"] = 4, ["param1"] = 189, ["z"] = 5, ["name"] = "stairs:stair_stone" }, { ["x"] = 5, ["meta"] = { ["fields"] = {  }, ["inventory"] = {  } }, ["param2"] = 1, ["y"] = 4, ["param1"] = 205, ["z"] = 6, ["name"] = "stairs:stair_stone" }, { ["x"] = 6, ["meta"] = { ["fields"] = { ["owner_info"] = "return { [\"y\"] = 2, [\"x\"] = 340, [\"z\"] = 1095 }" }, ["inventory"] = {  } }, ["param2"] = 0, ["y"] = 0, ["param1"] = 0, ["z"] = 1, ["name"] = "default:stone" }, { ["x"] = 6, ["meta"] = { ["fields"] = { ["owner_info"] = "return { [\"y\"] = 2, [\"x\"] = 340, [\"z\"] = 1095 }" }, ["inventory"] = {  } }, ["param2"] = 0, ["y"] = 0, ["param1"] = 0, ["z"] = 2, ["name"] = "default:stone" }, { ["x"] = 6, ["meta"] = { ["fields"] = { ["owner_info"] = "return { [\"y\"] = 2, [\"x\"] = 340, [\"z\"] = 1095 }" }, ["inventory"] = {  } }, ["param2"] = 0, ["y"] = 0, ["param1"] = 0, ["z"] = 3, ["name"] = "default:stone" }, { ["x"] = 6, ["meta"] = { ["fields"] = { ["owner_info"] = "return { [\"y\"] = 2, [\"x\"] = 340, [\"z\"] = 1095 }" }, ["inventory"] = {  } }, ["param2"] = 0, ["y"] = 0, ["param1"] = 0, ["z"] = 4, ["name"] = "default:stone" }, { ["x"] = 6, ["meta"] = { ["fields"] = { ["owner_info"] = "return { [\"y\"] = 2, [\"x\"] = 340, [\"z\"] = 1095 }" }, ["inventory"] = {  } }, ["param2"] = 0, ["y"] = 0, ["param1"] = 0, ["z"] = 5, ["name"] = "default:stone" }, { ["x"] = 6, ["meta"] = { ["fields"] = { ["owner_info"] = "return { [\"y\"] = 2, [\"x\"] = 340, [\"z\"] = 1095 }" }, ["inventory"] = {  } }, ["param2"] = 0, ["y"] = 0, ["param1"] = 0, ["z"] = 6, ["name"] = "default:stone" }, { ["x"] = 6, ["meta"] = { ["fields"] = { ["owner_info"] = "return { [\"y\"] = 2, [\"x\"] = 340, [\"z\"] = 1095 }" }, ["inventory"] = {  } }, ["param2"] = 0, ["y"] = 0, ["param1"] = 0, ["z"] = 7, ["name"] = "default:stone" }, { ["x"] = 6, ["meta"] = { ["fields"] = { ["owner_info"] = "return { [\"y\"] = 2, [\"x\"] = 340, [\"z\"] = 1095 }" }, ["inventory"] = {  } }, ["param2"] = 0, ["y"] = 0, ["param1"] = 0, ["z"] = 8, ["name"] = "default:stone" }, { ["x"] = 6, ["meta"] = { ["fields"] = { ["owner_info"] = "return { [\"y\"] = 2, [\"x\"] = 340, [\"z\"] = 1095 }" }, ["inventory"] = {  } }, ["param2"] = 0, ["y"] = 1, ["param1"] = 0, ["z"] = 1, ["name"] = "default:brick" }, { ["x"] = 6, ["meta"] = { ["fields"] = { ["infotext"] = "Chest", ["owner_info"] = "return { [\"y\"] = 2, [\"x\"] = 340, [\"z\"] = 1095 }", ["formspec"] = "size[8,9]bgcolor[#080808BB;true]background[5,5;1,1;gui_formbg.png;true]listcolors[#00000069;#5A5A5A;#141318;#30434C;#FFF]list[current_name;main;0,0.3;8,4;]list[current_player;main;0,4.85;8,1;]list[current_player;main;0,6.08;8,3;8]image[0,4.85;1,1;gui_hb_bg.png]image[1,4.85;1,1;gui_hb_bg.png]image[2,4.85;1,1;gui_hb_bg.png]image[3,4.85;1,1;gui_hb_bg.png]image[4,4.85;1,1;gui_hb_bg.png]image[5,4.85;1,1;gui_hb_bg.png]image[6,4.85;1,1;gui_hb_bg.png]image[7,4.85;1,1;gui_hb_bg.png]" }, ["inventory"] = { ["main"] = { "", "", "", "", "", "default:paper 4", "default:paper", "", "", "", "default:torch 5", "default:coal_lump 8", "", "", "", "", "default:book", "", "", "", "", "", "", "", "", "", "", "", "", "", "", "" } } }, ["param2"] = 2, ["y"] = 1, ["param1"] = 0, ["z"] = 3, ["name"] = "default:chest" }, { ["x"] = 6, ["meta"] = { ["fields"] = {  }, ["inventory"] = {  } }, ["param2"] = 0, ["y"] = 1, ["param1"] = 187, ["z"] = 4, ["name"] = "stairs:slab_stone" }, { ["x"] = 6, ["meta"] = { ["fields"] = { ["owner_info"] = "return { [\"y\"] = 2, [\"x\"] = 340, [\"z\"] = 1095 }" }, ["inventory"] = {  } }, ["param2"] = 0, ["y"] = 1, ["param1"] = 0, ["z"] = 5, ["name"] = "default:brick" }, { ["x"] = 6, ["meta"] = { ["fields"] = { ["owner_info"] = "return { [\"y\"] = 2, [\"x\"] = 340, [\"z\"] = 1095 }" }, ["inventory"] = {  } }, ["param2"] = 0, ["y"] = 1, ["param1"] = 0, ["z"] = 6, ["name"] = "default:sand" }, { ["x"] = 6, ["meta"] = { ["fields"] = { ["owner_info"] = "return { [\"y\"] = 2, [\"x\"] = 340, [\"z\"] = 1095 }" }, ["inventory"] = {  } }, ["param2"] = 0, ["y"] = 1, ["param1"] = 0, ["z"] = 7, ["name"] = "default:sand" }, { ["x"] = 6, ["meta"] = { ["fields"] = { ["owner_info"] = "return { [\"y\"] = 2, [\"x\"] = 340, [\"z\"] = 1095 }" }, ["inventory"] = {  } }, ["param2"] = 0, ["y"] = 1, ["param1"] = 0, ["z"] = 8, ["name"] = "default:brick" }, { ["x"] = 6, ["meta"] = { ["fields"] = { ["owner_info"] = "return { [\"y\"] = 2, [\"x\"] = 340, [\"z\"] = 1095 }" }, ["inventory"] = {  } }, ["param2"] = 0, ["y"] = 2, ["param1"] = 188, ["z"] = 1, ["name"] = "default:glass" }, { ["x"] = 6, ["meta"] = { ["fields"] = {  }, ["inventory"] = {  } }, ["param2"] = 0, ["y"] = 2, ["param1"] = 187, ["z"] = 3, ["name"] = "stairs:slab_stone" }, { ["x"] = 6, ["meta"] = { ["fields"] = { ["owner_info"] = "return { [\"y\"] = 2, [\"x\"] = 340, [\"z\"] = 1095 }" }, ["inventory"] = {  } }, ["param2"] = 0, ["y"] = 2, ["param1"] = 187, ["z"] = 5, ["name"] = "default:glass" }, { ["x"] = 6, ["meta"] = { ["fields"] = { ["owner_info"] = "return { [\"y\"] = 2, [\"x\"] = 340, [\"z\"] = 1095 }" }, ["inventory"] = {  } }, ["param2"] = 0, ["y"] = 2, ["param1"] = 0, ["z"] = 7, ["name"] = "default:sand" }, { ["x"] = 6, ["meta"] = { ["fields"] = { ["owner_info"] = "return { [\"y\"] = 2, [\"x\"] = 340, [\"z\"] = 1095 }" }, ["inventory"] = {  } }, ["param2"] = 0, ["y"] = 2, ["param1"] = 0, ["z"] = 8, ["name"] = "default:brick" }, { ["x"] = 6, ["meta"] = { ["fields"] = { ["owner_info"] = "return { [\"y\"] = 2, [\"x\"] = 340, [\"z\"] = 1095 }" }, ["inventory"] = {  } }, ["param2"] = 0, ["y"] = 3, ["param1"] = 0, ["z"] = 1, ["name"] = "default:brick" }, { ["x"] = 6, ["meta"] = { ["fields"] = { ["owner_info"] = "return { [\"y\"] = 2, [\"x\"] = 340, [\"z\"] = 1095 }" }, ["inventory"] = {  } }, ["param2"] = 3, ["y"] = 3, ["param1"] = 0, ["z"] = 2, ["name"] = "default:torch" }, { ["x"] = 6, ["meta"] = { ["fields"] = { ["owner_info"] = "return { [\"y\"] = 2, [\"x\"] = 340, [\"z\"] = 1095 }" }, ["inventory"] = {  } }, ["param2"] = 3, ["y"] = 3, ["param1"] = 0, ["z"] = 4, ["name"] = "default:torch" }, { ["x"] = 6, ["meta"] = { ["fields"] = { ["owner_info"] = "return { [\"y\"] = 2, [\"x\"] = 340, [\"z\"] = 1095 }" }, ["inventory"] = {  } }, ["param2"] = 0, ["y"] = 3, ["param1"] = 0, ["z"] = 5, ["name"] = "default:brick" }, { ["x"] = 6, ["meta"] = { ["fields"] = { ["owner_info"] = "return { [\"y\"] = 2, [\"x\"] = 340, [\"z\"] = 1095 }" }, ["inventory"] = {  } }, ["param2"] = 0, ["y"] = 3, ["param1"] = 0, ["z"] = 7, ["name"] = "default:sand" }, { ["x"] = 6, ["meta"] = { ["fields"] = { ["owner_info"] = "return { [\"y\"] = 2, [\"x\"] = 340, [\"z\"] = 1095 }" }, ["inventory"] = {  } }, ["param2"] = 3, ["y"] = 3, ["param1"] = 173, ["z"] = 8, ["name"] = "stairs:slab_cobble" }, { ["x"] = 6, ["meta"] = { ["fields"] = { ["owner_info"] = "return { [\"y\"] = 2, [\"x\"] = 340, [\"z\"] = 1095 }" }, ["inventory"] = {  } }, ["param2"] = 0, ["y"] = 4, ["param1"] = 0, ["z"] = 1, ["name"] = "default:brick" }, { ["x"] = 6, ["meta"] = { ["fields"] = { ["owner_info"] = "return { [\"y\"] = 2, [\"x\"] = 340, [\"z\"] = 1095 }" }, ["inventory"] = {  } }, ["param2"] = 0, ["y"] = 4, ["param1"] = 0, ["z"] = 5, ["name"] = "default:brick" }, { ["x"] = 6, ["meta"] = { ["fields"] = { ["owner_info"] = "return { [\"y\"] = 2, [\"x\"] = 340, [\"z\"] = 1095 }" }, ["inventory"] = {  } }, ["param2"] = 5, ["y"] = 4, ["param1"] = 0, ["z"] = 6, ["name"] = "default:torch" }, { ["x"] = 6, ["meta"] = { ["fields"] = {  }, ["inventory"] = {  } }, ["param2"] = 0, ["y"] = 5, ["param1"] = 157, ["z"] = 0, ["name"] = "stairs:slab_stone" }, { ["x"] = 6, ["meta"] = { ["fields"] = {  }, ["inventory"] = {  } }, ["param2"] = 0, ["y"] = 5, ["param1"] = 173, ["z"] = 1, ["name"] = "stairs:slab_stone" }, { ["x"] = 6, ["meta"] = { ["fields"] = {  }, ["inventory"] = {  } }, ["param2"] = 0, ["y"] = 5, ["param1"] = 189, ["z"] = 2, ["name"] = "stairs:slab_stone" }, { ["x"] = 6, ["meta"] = { ["fields"] = {  }, ["inventory"] = {  } }, ["param2"] = 0, ["y"] = 5, ["param1"] = 173, ["z"] = 3, ["name"] = "stairs:slab_stone" }, { ["x"] = 6, ["meta"] = { ["fields"] = {  }, ["inventory"] = {  } }, ["param2"] = 0, ["y"] = 5, ["param1"] = 189, ["z"] = 4, ["name"] = "stairs:slab_stone" }, { ["x"] = 6, ["meta"] = { ["fields"] = {  }, ["inventory"] = {  } }, ["param2"] = 0, ["y"] = 5, ["param1"] = 189, ["z"] = 5, ["name"] = "stairs:slab_stone" }, { ["x"] = 6, ["meta"] = { ["fields"] = {  }, ["inventory"] = {  } }, ["param2"] = 0, ["y"] = 5, ["param1"] = 205, ["z"] = 6, ["name"] = "stairs:slab_stone" }, { ["x"] = 7, ["meta"] = { ["fields"] = { ["owner_info"] = "return { [\"y\"] = 2, [\"x\"] = 340, [\"z\"] = 1095 }" }, ["inventory"] = {  } }, ["param2"] = 0, ["y"] = 0, ["param1"] = 0, ["z"] = 1, ["name"] = "default:stone" }, { ["x"] = 7, ["meta"] = { ["fields"] = { ["owner_info"] = "return { [\"y\"] = 2, [\"x\"] = 340, [\"z\"] = 1095 }" }, ["inventory"] = {  } }, ["param2"] = 0, ["y"] = 0, ["param1"] = 0, ["z"] = 2, ["name"] = "default:stone" }, { ["x"] = 7, ["meta"] = { ["fields"] = { ["owner_info"] = "return { [\"y\"] = 2, [\"x\"] = 340, [\"z\"] = 1095 }" }, ["inventory"] = {  } }, ["param2"] = 0, ["y"] = 0, ["param1"] = 0, ["z"] = 3, ["name"] = "default:stone" }, { ["x"] = 7, ["meta"] = { ["fields"] = { ["owner_info"] = "return { [\"y\"] = 2, [\"x\"] = 340, [\"z\"] = 1095 }" }, ["inventory"] = {  } }, ["param2"] = 0, ["y"] = 0, ["param1"] = 0, ["z"] = 4, ["name"] = "default:stone" }, { ["x"] = 7, ["meta"] = { ["fields"] = { ["owner_info"] = "return { [\"y\"] = 2, [\"x\"] = 340, [\"z\"] = 1095 }" }, ["inventory"] = {  } }, ["param2"] = 0, ["y"] = 0, ["param1"] = 0, ["z"] = 5, ["name"] = "default:stone" }, { ["x"] = 7, ["meta"] = { ["fields"] = { ["owner_info"] = "return { [\"y\"] = 2, [\"x\"] = 340, [\"z\"] = 1095 }" }, ["inventory"] = {  } }, ["param2"] = 0, ["y"] = 0, ["param1"] = 0, ["z"] = 6, ["name"] = "default:stone" }, { ["x"] = 7, ["meta"] = { ["fields"] = { ["owner_info"] = "return { [\"y\"] = 2, [\"x\"] = 340, [\"z\"] = 1095 }" }, ["inventory"] = {  } }, ["param2"] = 0, ["y"] = 0, ["param1"] = 0, ["z"] = 7, ["name"] = "default:stone" }, { ["x"] = 7, ["meta"] = { ["fields"] = { ["owner_info"] = "return { [\"y\"] = 2, [\"x\"] = 340, [\"z\"] = 1095 }" }, ["inventory"] = {  } }, ["param2"] = 0, ["y"] = 0, ["param1"] = 0, ["z"] = 8, ["name"] = "default:stone" }, { ["x"] = 7, ["meta"] = { ["fields"] = { ["owner_info"] = "return { [\"y\"] = 2, [\"x\"] = 340, [\"z\"] = 1095 }" }, ["inventory"] = {  } }, ["param2"] = 0, ["y"] = 1, ["param1"] = 0, ["z"] = 1, ["name"] = "default:brick" }, { ["x"] = 7, ["meta"] = { ["fields"] = { ["owner_info"] = "return { [\"y\"] = 2, [\"x\"] = 340, [\"z\"] = 1095 }" }, ["inventory"] = {  } }, ["param2"] = 0, ["y"] = 1, ["param1"] = 0, ["z"] = 5, ["name"] = "default:brick" }, { ["x"] = 7, ["meta"] = { ["fields"] = { ["owner_info"] = "return { [\"y\"] = 2, [\"x\"] = 340, [\"z\"] = 1095 }" }, ["inventory"] = {  } }, ["param2"] = 0, ["y"] = 1, ["param1"] = 0, ["z"] = 6, ["name"] = "default:sand" }, { ["x"] = 7, ["meta"] = { ["fields"] = { ["owner_info"] = "return { [\"y\"] = 2, [\"x\"] = 340, [\"z\"] = 1095 }" }, ["inventory"] = {  } }, ["param2"] = 0, ["y"] = 1, ["param1"] = 0, ["z"] = 7, ["name"] = "default:sand" }, { ["x"] = 7, ["meta"] = { ["fields"] = { ["owner_info"] = "return { [\"y\"] = 2, [\"x\"] = 340, [\"z\"] = 1095 }" }, ["inventory"] = {  } }, ["param2"] = 0, ["y"] = 1, ["param1"] = 0, ["z"] = 8, ["name"] = "default:brick" }, { ["x"] = 7, ["meta"] = { ["fields"] = { ["owner_info"] = "return { [\"y\"] = 2, [\"x\"] = 340, [\"z\"] = 1095 }" }, ["inventory"] = {  } }, ["param2"] = 0, ["y"] = 2, ["param1"] = 188, ["z"] = 1, ["name"] = "default:glass" }, { ["x"] = 7, ["meta"] = { ["fields"] = { ["owner_info"] = "return { [\"y\"] = 2, [\"x\"] = 340, [\"z\"] = 1095 }" }, ["inventory"] = {  } }, ["param2"] = 0, ["y"] = 2, ["param1"] = 187, ["z"] = 5, ["name"] = "default:glass" }, { ["x"] = 7, ["meta"] = { ["fields"] = { ["owner_info"] = "return { [\"y\"] = 2, [\"x\"] = 340, [\"z\"] = 1095 }" }, ["inventory"] = {  } }, ["param2"] = 0, ["y"] = 2, ["param1"] = 0, ["z"] = 6, ["name"] = "default:sand" }, { ["x"] = 7, ["meta"] = { ["fields"] = { ["owner_info"] = "return { [\"y\"] = 2, [\"x\"] = 340, [\"z\"] = 1095 }" }, ["inventory"] = {  } }, ["param2"] = 0, ["y"] = 2, ["param1"] = 0, ["z"] = 7, ["name"] = "default:sand" }, { ["x"] = 7, ["meta"] = { ["fields"] = { ["owner_info"] = "return { [\"y\"] = 2, [\"x\"] = 340, [\"z\"] = 1095 }" }, ["inventory"] = {  } }, ["param2"] = 0, ["y"] = 2, ["param1"] = 0, ["z"] = 8, ["name"] = "default:brick" }, { ["x"] = 7, ["meta"] = { ["fields"] = { ["owner_info"] = "return { [\"y\"] = 2, [\"x\"] = 340, [\"z\"] = 1095 }" }, ["inventory"] = {  } }, ["param2"] = 5, ["y"] = 2, ["param1"] = 15, ["z"] = 9, ["name"] = "default:torch" }, { ["x"] = 7, ["meta"] = { ["fields"] = { ["owner_info"] = "return { [\"y\"] = 2, [\"x\"] = 340, [\"z\"] = 1095 }" }, ["inventory"] = {  } }, ["param2"] = 0, ["y"] = 3, ["param1"] = 0, ["z"] = 1, ["name"] = "default:brick" }, { ["x"] = 7, ["meta"] = { ["fields"] = {  }, ["inventory"] = {  } }, ["param2"] = 2, ["y"] = 3, ["param1"] = 0, ["z"] = 2, ["name"] = "default:torch" }, { ["x"] = 7, ["meta"] = { ["fields"] = {  }, ["inventory"] = {  } }, ["param2"] = 2, ["y"] = 3, ["param1"] = 0, ["z"] = 4, ["name"] = "default:torch" }, { ["x"] = 7, ["meta"] = { ["fields"] = { ["owner_info"] = "return { [\"y\"] = 2, [\"x\"] = 340, [\"z\"] = 1095 }" }, ["inventory"] = {  } }, ["param2"] = 0, ["y"] = 3, ["param1"] = 0, ["z"] = 5, ["name"] = "default:brick" }, { ["x"] = 7, ["meta"] = { ["fields"] = { ["owner_info"] = "return { [\"y\"] = 2, [\"x\"] = 340, [\"z\"] = 1095 }" }, ["inventory"] = {  } }, ["param2"] = 0, ["y"] = 3, ["param1"] = 0, ["z"] = 7, ["name"] = "default:sand" }, { ["x"] = 7, ["meta"] = { ["fields"] = { ["owner_info"] = "return { [\"y\"] = 2, [\"x\"] = 340, [\"z\"] = 1095 }" }, ["inventory"] = {  } }, ["param2"] = 3, ["y"] = 3, ["param1"] = 189, ["z"] = 8, ["name"] = "stairs:slab_cobble" }, { ["x"] = 7, ["meta"] = { ["fields"] = {  }, ["inventory"] = {  } }, ["param2"] = 3, ["y"] = 4, ["param1"] = 173, ["z"] = 0, ["name"] = "stairs:stair_stone" }, { ["x"] = 7, ["meta"] = { ["fields"] = {  }, ["inventory"] = {  } }, ["param2"] = 3, ["y"] = 4, ["param1"] = 189, ["z"] = 1, ["name"] = "stairs:stair_stone" }, { ["x"] = 7, ["meta"] = { ["fields"] = {  }, ["inventory"] = {  } }, ["param2"] = 3, ["y"] = 4, ["param1"] = 205, ["z"] = 2, ["name"] = "stairs:stair_stone" }, { ["x"] = 7, ["meta"] = { ["fields"] = {  }, ["inventory"] = {  } }, ["param2"] = 3, ["y"] = 4, ["param1"] = 189, ["z"] = 3, ["name"] = "stairs:stair_stone" }, { ["x"] = 7, ["meta"] = { ["fields"] = {  }, ["inventory"] = {  } }, ["param2"] = 3, ["y"] = 4, ["param1"] = 205, ["z"] = 4, ["name"] = "stairs:stair_stone" }, { ["x"] = 7, ["meta"] = { ["fields"] = {  }, ["inventory"] = {  } }, ["param2"] = 3, ["y"] = 4, ["param1"] = 189, ["z"] = 5, ["name"] = "stairs:stair_stone" }, { ["x"] = 7, ["meta"] = { ["fields"] = {  }, ["inventory"] = {  } }, ["param2"] = 3, ["y"] = 4, ["param1"] = 205, ["z"] = 6, ["name"] = "stairs:stair_stone" }, { ["x"] = 8, ["meta"] = { ["fields"] = { ["owner_info"] = "return { [\"y\"] = 2, [\"x\"] = 340, [\"z\"] = 1095 }" }, ["inventory"] = {  } }, ["param2"] = 0, ["y"] = 0, ["param1"] = 0, ["z"] = 1, ["name"] = "default:stone" }, { ["x"] = 8, ["meta"] = { ["fields"] = { ["owner_info"] = "return { [\"y\"] = 2, [\"x\"] = 340, [\"z\"] = 1095 }" }, ["inventory"] = {  } }, ["param2"] = 0, ["y"] = 0, ["param1"] = 0, ["z"] = 2, ["name"] = "default:stone" }, { ["x"] = 8, ["meta"] = { ["fields"] = { ["owner_info"] = "return { [\"y\"] = 2, [\"x\"] = 340, [\"z\"] = 1095 }" }, ["inventory"] = {  } }, ["param2"] = 0, ["y"] = 0, ["param1"] = 0, ["z"] = 3, ["name"] = "default:stone" }, { ["x"] = 8, ["meta"] = { ["fields"] = { ["owner_info"] = "return { [\"y\"] = 2, [\"x\"] = 340, [\"z\"] = 1095 }" }, ["inventory"] = {  } }, ["param2"] = 0, ["y"] = 0, ["param1"] = 0, ["z"] = 4, ["name"] = "default:stone" }, { ["x"] = 8, ["meta"] = { ["fields"] = { ["owner_info"] = "return { [\"y\"] = 2, [\"x\"] = 340, [\"z\"] = 1095 }" }, ["inventory"] = {  } }, ["param2"] = 0, ["y"] = 0, ["param1"] = 0, ["z"] = 5, ["name"] = "default:stone" }, { ["x"] = 8, ["meta"] = { ["fields"] = { ["owner_info"] = "return { [\"y\"] = 2, [\"x\"] = 340, [\"z\"] = 1095 }" }, ["inventory"] = {  } }, ["param2"] = 0, ["y"] = 0, ["param1"] = 0, ["z"] = 6, ["name"] = "default:stone" }, { ["x"] = 8, ["meta"] = { ["fields"] = { ["owner_info"] = "return { [\"y\"] = 2, [\"x\"] = 340, [\"z\"] = 1095 }" }, ["inventory"] = {  } }, ["param2"] = 0, ["y"] = 0, ["param1"] = 0, ["z"] = 7, ["name"] = "default:stone" }, { ["x"] = 8, ["meta"] = { ["fields"] = { ["owner_info"] = "return { [\"y\"] = 2, [\"x\"] = 340, [\"z\"] = 1095 }" }, ["inventory"] = {  } }, ["param2"] = 0, ["y"] = 0, ["param1"] = 0, ["z"] = 8, ["name"] = "default:stone" }, { ["x"] = 8, ["meta"] = { ["fields"] = { ["owner_info"] = "return { [\"y\"] = 2, [\"x\"] = 340, [\"z\"] = 1095 }" }, ["inventory"] = {  } }, ["param2"] = 0, ["y"] = 1, ["param1"] = 0, ["z"] = 1, ["name"] = "default:brick" }, { ["x"] = 8, ["meta"] = { ["fields"] = { ["owner_info"] = "return { [\"y\"] = 2, [\"x\"] = 340, [\"z\"] = 1095 }" }, ["inventory"] = {  } }, ["param2"] = 0, ["y"] = 1, ["param1"] = 0, ["z"] = 2, ["name"] = "default:brick" }, { ["x"] = 8, ["meta"] = { ["fields"] = { ["owner_info"] = "return { [\"y\"] = 2, [\"x\"] = 340, [\"z\"] = 1095 }" }, ["inventory"] = {  } }, ["param2"] = 0, ["y"] = 1, ["param1"] = 0, ["z"] = 3, ["name"] = "default:brick" }, { ["x"] = 8, ["meta"] = { ["fields"] = { ["owner_info"] = "return { [\"y\"] = 2, [\"x\"] = 340, [\"z\"] = 1095 }" }, ["inventory"] = {  } }, ["param2"] = 0, ["y"] = 1, ["param1"] = 0, ["z"] = 4, ["name"] = "default:brick" }, { ["x"] = 8, ["meta"] = { ["fields"] = { ["owner_info"] = "return { [\"y\"] = 2, [\"x\"] = 340, [\"z\"] = 1095 }" }, ["inventory"] = {  } }, ["param2"] = 0, ["y"] = 1, ["param1"] = 0, ["z"] = 5, ["name"] = "default:brick" }, { ["x"] = 8, ["meta"] = { ["fields"] = { ["owner_info"] = "return { [\"y\"] = 2, [\"x\"] = 340, [\"z\"] = 1095 }" }, ["inventory"] = {  } }, ["param2"] = 0, ["y"] = 1, ["param1"] = 0, ["z"] = 6, ["name"] = "default:brick" }, { ["x"] = 8, ["meta"] = { ["fields"] = { ["owner_info"] = "return { [\"y\"] = 2, [\"x\"] = 340, [\"z\"] = 1095 }" }, ["inventory"] = {  } }, ["param2"] = 0, ["y"] = 1, ["param1"] = 0, ["z"] = 7, ["name"] = "default:brick" }, { ["x"] = 8, ["meta"] = { ["fields"] = { ["owner_info"] = "return { [\"y\"] = 2, [\"x\"] = 340, [\"z\"] = 1095 }" }, ["inventory"] = {  } }, ["param2"] = 0, ["y"] = 1, ["param1"] = 0, ["z"] = 8, ["name"] = "default:brick" }, { ["x"] = 8, ["meta"] = { ["fields"] = { ["owner_info"] = "return { [\"y\"] = 2, [\"x\"] = 340, [\"z\"] = 1095 }" }, ["inventory"] = {  } }, ["param2"] = 4, ["y"] = 2, ["param1"] = 0, ["z"] = 0, ["name"] = "default:torch" }, { ["x"] = 8, ["meta"] = { ["fields"] = { ["owner_info"] = "return { [\"y\"] = 2, [\"x\"] = 340, [\"z\"] = 1095 }" }, ["inventory"] = {  } }, ["param2"] = 0, ["y"] = 2, ["param1"] = 0, ["z"] = 1, ["name"] = "default:brick" }, { ["x"] = 8, ["meta"] = { ["fields"] = { ["owner_info"] = "return { [\"y\"] = 2, [\"x\"] = 340, [\"z\"] = 1095 }" }, ["inventory"] = {  } }, ["param2"] = 0, ["y"] = 2, ["param1"] = 189, ["z"] = 2, ["name"] = "default:glass" }, { ["x"] = 8, ["meta"] = { ["fields"] = { ["owner_info"] = "return { [\"y\"] = 2, [\"x\"] = 340, [\"z\"] = 1095 }" }, ["inventory"] = {  } }, ["param2"] = 0, ["y"] = 2, ["param1"] = 173, ["z"] = 3, ["name"] = "default:glass" }, { ["x"] = 8, ["meta"] = { ["fields"] = { ["owner_info"] = "return { [\"y\"] = 2, [\"x\"] = 340, [\"z\"] = 1095 }" }, ["inventory"] = {  } }, ["param2"] = 0, ["y"] = 2, ["param1"] = 0, ["z"] = 4, ["name"] = "default:brick" }, { ["x"] = 8, ["meta"] = { ["fields"] = { ["owner_info"] = "return { [\"y\"] = 2, [\"x\"] = 340, [\"z\"] = 1095 }" }, ["inventory"] = {  } }, ["param2"] = 0, ["y"] = 2, ["param1"] = 0, ["z"] = 5, ["name"] = "default:brick" }, { ["x"] = 8, ["meta"] = { ["fields"] = { ["owner_info"] = "return { [\"y\"] = 2, [\"x\"] = 340, [\"z\"] = 1095 }" }, ["inventory"] = {  } }, ["param2"] = 0, ["y"] = 2, ["param1"] = 0, ["z"] = 6, ["name"] = "default:brick" }, { ["x"] = 8, ["meta"] = { ["fields"] = { ["owner_info"] = "return { [\"y\"] = 2, [\"x\"] = 340, [\"z\"] = 1095 }" }, ["inventory"] = {  } }, ["param2"] = 0, ["y"] = 2, ["param1"] = 0, ["z"] = 7, ["name"] = "default:brick" }, { ["x"] = 8, ["meta"] = { ["fields"] = { ["owner_info"] = "return { [\"y\"] = 2, [\"x\"] = 340, [\"z\"] = 1095 }" }, ["inventory"] = {  } }, ["param2"] = 0, ["y"] = 2, ["param1"] = 0, ["z"] = 8, ["name"] = "default:brick" }, { ["x"] = 8, ["meta"] = { ["fields"] = {  }, ["inventory"] = {  } }, ["param2"] = 3, ["y"] = 3, ["param1"] = 205, ["z"] = 0, ["name"] = "stairs:stair_stone" }, { ["x"] = 8, ["meta"] = { ["fields"] = {  }, ["inventory"] = {  } }, ["param2"] = 3, ["y"] = 3, ["param1"] = 189, ["z"] = 1, ["name"] = "stairs:stair_stone" }, { ["x"] = 8, ["meta"] = { ["fields"] = {  }, ["inventory"] = {  } }, ["param2"] = 3, ["y"] = 3, ["param1"] = 205, ["z"] = 2, ["name"] = "stairs:stair_stone" }, { ["x"] = 8, ["meta"] = { ["fields"] = {  }, ["inventory"] = {  } }, ["param2"] = 3, ["y"] = 3, ["param1"] = 189, ["z"] = 3, ["name"] = "stairs:stair_stone" }, { ["x"] = 8, ["meta"] = { ["fields"] = {  }, ["inventory"] = {  } }, ["param2"] = 3, ["y"] = 3, ["param1"] = 205, ["z"] = 4, ["name"] = "stairs:stair_stone" }, { ["x"] = 8, ["meta"] = { ["fields"] = {  }, ["inventory"] = {  } }, ["param2"] = 3, ["y"] = 3, ["param1"] = 189, ["z"] = 5, ["name"] = "stairs:stair_stone" }, { ["x"] = 8, ["meta"] = { ["fields"] = {  }, ["inventory"] = {  } }, ["param2"] = 3, ["y"] = 3, ["param1"] = 173, ["z"] = 6, ["name"] = "stairs:stair_stone" }, { ["x"] = 8, ["meta"] = { ["fields"] = { ["owner_info"] = "return { [\"y\"] = 2, [\"x\"] = 340, [\"z\"] = 1095 }" }, ["inventory"] = {  } }, ["param2"] = 3, ["y"] = 3, ["param1"] = 173, ["z"] = 7, ["name"] = "stairs:slab_cobble" }, { ["x"] = 8, ["meta"] = { ["fields"] = { ["owner_info"] = "return { [\"y\"] = 2, [\"x\"] = 340, [\"z\"] = 1095 }" }, ["inventory"] = {  } }, ["param2"] = 3, ["y"] = 3, ["param1"] = 173, ["z"] = 8, ["name"] = "stairs:slab_cobble" }, { ["x"] = 9, ["meta"] = { ["fields"] = { ["owner_info"] = "return { [\"y\"] = 2, [\"x\"] = 340, [\"z\"] = 1095 }" }, ["inventory"] = {  } }, ["param2"] = 3, ["y"] = 1, ["param1"] = 15, ["z"] = 2, ["name"] = "default:torch" }, { ["x"] = 9, ["meta"] = { ["fields"] = { ["owner_info"] = "return { [\"y\"] = 2, [\"x\"] = 340, [\"z\"] = 1095 }" }, ["inventory"] = {  } }, ["param2"] = 3, ["y"] = 1, ["param1"] = 15, ["z"] = 7, ["name"] = "default:torch" } }