return { { ["x"] = 0, ["meta"] = { ["fields"] = { ["owner_info"] = "return { [\"y\"] = 2, [\"x\"] = 343, [\"z\"] = 1108 }" }, ["inventory"] = {  } }, ["param2"] = 2, ["y"] = 2, ["param1"] = 0, ["z"] = 6, ["name"] = "default:torch" }, { ["x"] = 0, ["meta"] = { ["fields"] = { ["owner_info"] = "return { [\"y\"] = 2, [\"x\"] = 343, [\"z\"] = 1108 }" }, ["inventory"] = {  } }, ["param2"] = 2, ["y"] = 2, ["param1"] = 0, ["z"] = 8, ["name"] = "default:torch" }, { ["x"] = 0, ["meta"] = { ["fields"] = { ["owner_info"] = "return { [\"y\"] = 2, [\"x\"] = 343, [\"z\"] = 1108 }" }, ["inventory"] = {  } }, ["param2"] = 2, ["y"] = 5, ["param1"] = 0, ["z"] = 6, ["name"] = "default:torch" }, { ["x"] = 0, ["meta"] = { ["fields"] = { ["owner_info"] = "return { [\"y\"] = 2, [\"x\"] = 343, [\"z\"] = 1108 }" }, ["inventory"] = {  } }, ["param2"] = 2, ["y"] = 5, ["param1"] = 0, ["z"] = 8, ["name"] = "default:torch" }, { ["x"] = 0, ["meta"] = { ["fields"] = {  }, ["inventory"] = {  } }, ["param2"] = 0, ["y"] = 7, ["param1"] = 173, ["z"] = 5, ["name"] = "stairs:slab_stone" }, { ["x"] = 0, ["meta"] = { ["fields"] = {  }, ["inventory"] = {  } }, ["param2"] = 0, ["y"] = 7, ["param1"] = 189, ["z"] = 6, ["name"] = "stairs:slab_stone" }, { ["x"] = 0, ["meta"] = { ["fields"] = {  }, ["inventory"] = {  } }, ["param2"] = 0, ["y"] = 7, ["param1"] = 173, ["z"] = 7, ["name"] = "stairs:slab_stone" }, { ["x"] = 0, ["meta"] = { ["fields"] = {  }, ["inventory"] = {  } }, ["param2"] = 0, ["y"] = 7, ["param1"] = 189, ["z"] = 8, ["name"] = "stairs:slab_stone" }, { ["x"] = 0, ["meta"] = { ["fields"] = {  }, ["inventory"] = {  } }, ["param2"] = 0, ["y"] = 7, ["param1"] = 173, ["z"] = 9, ["name"] = "stairs:slab_stone" }, { ["x"] = 1, ["meta"] = { ["fields"] = { ["owner_info"] = "return { [\"y\"] = 2, [\"x\"] = 343, [\"z\"] = 1108 }" }, ["inventory"] = {  } }, ["param2"] = 9, ["y"] = 0, ["param1"] = 173, ["z"] = 1, ["name"] = "default:fence_wood" }, { ["x"] = 1, ["meta"] = { ["fields"] = { ["owner_info"] = "return { [\"y\"] = 2, [\"x\"] = 343, [\"z\"] = 1108 }" }, ["inventory"] = {  } }, ["param2"] = 9, ["y"] = 0, ["param1"] = 0, ["z"] = 6, ["name"] = "default:brick" }, { ["x"] = 1, ["meta"] = { ["fields"] = { ["owner_info"] = "return { [\"y\"] = 2, [\"x\"] = 343, [\"z\"] = 1108 }" }, ["inventory"] = {  } }, ["param2"] = 9, ["y"] = 0, ["param1"] = 0, ["z"] = 7, ["name"] = "default:brick" }, { ["x"] = 1, ["meta"] = { ["fields"] = { ["owner_info"] = "return { [\"y\"] = 2, [\"x\"] = 343, [\"z\"] = 1108 }" }, ["inventory"] = {  } }, ["param2"] = 9, ["y"] = 0, ["param1"] = 0, ["z"] = 8, ["name"] = "default:brick" }, { ["x"] = 1, ["meta"] = { ["fields"] = { ["owner_info"] = "return { [\"y\"] = 2, [\"x\"] = 343, [\"z\"] = 1108 }" }, ["inventory"] = {  } }, ["param2"] = 9, ["y"] = 1, ["param1"] = 189, ["z"] = 1, ["name"] = "default:fence_wood" }, { ["x"] = 1, ["meta"] = { ["fields"] = { ["owner_info"] = "return { [\"y\"] = 2, [\"x\"] = 343, [\"z\"] = 1108 }" }, ["inventory"] = {  } }, ["param2"] = 9, ["y"] = 1, ["param1"] = 0, ["z"] = 5, ["name"] = "default:brick" }, { ["x"] = 1, ["meta"] = { ["fields"] = { ["owner_info"] = "return { [\"y\"] = 2, [\"x\"] = 343, [\"z\"] = 1108 }" }, ["inventory"] = {  } }, ["param2"] = 9, ["y"] = 1, ["param1"] = 0, ["z"] = 6, ["name"] = "default:brick" }, { ["x"] = 1, ["meta"] = { ["fields"] = { ["owner_info"] = "return { [\"y\"] = 2, [\"x\"] = 343, [\"z\"] = 1108 }" }, ["inventory"] = {  } }, ["param2"] = 9, ["y"] = 1, ["param1"] = 0, ["z"] = 7, ["name"] = "default:brick" }, { ["x"] = 1, ["meta"] = { ["fields"] = { ["owner_info"] = "return { [\"y\"] = 2, [\"x\"] = 343, [\"z\"] = 1108 }" }, ["inventory"] = {  } }, ["param2"] = 9, ["y"] = 1, ["param1"] = 0, ["z"] = 8, ["name"] = "default:brick" }, { ["x"] = 1, ["meta"] = { ["fields"] = { ["owner_info"] = "return { [\"y\"] = 2, [\"x\"] = 343, [\"z\"] = 1108 }" }, ["inventory"] = {  } }, ["param2"] = 0, ["y"] = 1, ["param1"] = 0, ["z"] = 9, ["name"] = "default:brick" }, { ["x"] = 1, ["meta"] = { ["fields"] = { ["owner_info"] = "return { [\"y\"] = 2, [\"x\"] = 343, [\"z\"] = 1108 }" }, ["inventory"] = {  } }, ["param2"] = 9, ["y"] = 2, ["param1"] = 205, ["z"] = 1, ["name"] = "default:fence_wood" }, { ["x"] = 1, ["meta"] = { ["fields"] = { ["owner_info"] = "return { [\"y\"] = 2, [\"x\"] = 343, [\"z\"] = 1108 }" }, ["inventory"] = {  } }, ["param2"] = 9, ["y"] = 2, ["param1"] = 0, ["z"] = 5, ["name"] = "default:brick" }, { ["x"] = 1, ["meta"] = { ["fields"] = { ["owner_info"] = "return { [\"y\"] = 2, [\"x\"] = 343, [\"z\"] = 1108 }" }, ["inventory"] = {  } }, ["param2"] = 9, ["y"] = 2, ["param1"] = 0, ["z"] = 6, ["name"] = "default:brick" }, { ["x"] = 1, ["meta"] = { ["fields"] = { ["owner_info"] = "return { [\"y\"] = 2, [\"x\"] = 343, [\"z\"] = 1108 }" }, ["inventory"] = {  } }, ["param2"] = 9, ["y"] = 2, ["param1"] = 0, ["z"] = 7, ["name"] = "default:brick" }, { ["x"] = 1, ["meta"] = { ["fields"] = { ["owner_info"] = "return { [\"y\"] = 2, [\"x\"] = 343, [\"z\"] = 1108 }" }, ["inventory"] = {  } }, ["param2"] = 9, ["y"] = 2, ["param1"] = 0, ["z"] = 8, ["name"] = "default:brick" }, { ["x"] = 1, ["meta"] = { ["fields"] = { ["owner_info"] = "return { [\"y\"] = 2, [\"x\"] = 343, [\"z\"] = 1108 }" }, ["inventory"] = {  } }, ["param2"] = 9, ["y"] = 2, ["param1"] = 0, ["z"] = 9, ["name"] = "default:brick" }, { ["x"] = 1, ["meta"] = { ["fields"] = { ["owner_info"] = "return { [\"y\"] = 2, [\"x\"] = 343, [\"z\"] = 1108 }" }, ["inventory"] = {  } }, ["param2"] = 9, ["y"] = 3, ["param1"] = 0, ["z"] = 1, ["name"] = "default:brick" }, { ["x"] = 1, ["meta"] = { ["fields"] = { ["owner_info"] = "return { [\"y\"] = 2, [\"x\"] = 343, [\"z\"] = 1108 }" }, ["inventory"] = {  } }, ["param2"] = 9, ["y"] = 3, ["param1"] = 0, ["z"] = 2, ["name"] = "default:brick" }, { ["x"] = 1, ["meta"] = { ["fields"] = { ["owner_info"] = "return { [\"y\"] = 2, [\"x\"] = 343, [\"z\"] = 1108 }" }, ["inventory"] = {  } }, ["param2"] = 9, ["y"] = 3, ["param1"] = 0, ["z"] = 3, ["name"] = "default:brick" }, { ["x"] = 1, ["meta"] = { ["fields"] = { ["owner_info"] = "return { [\"y\"] = 2, [\"x\"] = 343, [\"z\"] = 1108 }" }, ["inventory"] = {  } }, ["param2"] = 9, ["y"] = 3, ["param1"] = 0, ["z"] = 4, ["name"] = "default:brick" }, { ["x"] = 1, ["meta"] = { ["fields"] = { ["owner_info"] = "return { [\"y\"] = 2, [\"x\"] = 343, [\"z\"] = 1108 }" }, ["inventory"] = {  } }, ["param2"] = 9, ["y"] = 3, ["param1"] = 0, ["z"] = 5, ["name"] = "default:brick" }, { ["x"] = 1, ["meta"] = { ["fields"] = { ["owner_info"] = "return { [\"y\"] = 2, [\"x\"] = 343, [\"z\"] = 1108 }" }, ["inventory"] = {  } }, ["param2"] = 9, ["y"] = 3, ["param1"] = 0, ["z"] = 6, ["name"] = "default:brick" }, { ["x"] = 1, ["meta"] = { ["fields"] = { ["owner_info"] = "return { [\"y\"] = 2, [\"x\"] = 343, [\"z\"] = 1108 }" }, ["inventory"] = {  } }, ["param2"] = 9, ["y"] = 3, ["param1"] = 0, ["z"] = 7, ["name"] = "default:brick" }, { ["x"] = 1, ["meta"] = { ["fields"] = { ["owner_info"] = "return { [\"y\"] = 2, [\"x\"] = 343, [\"z\"] = 1108 }" }, ["inventory"] = {  } }, ["param2"] = 9, ["y"] = 3, ["param1"] = 0, ["z"] = 8, ["name"] = "default:brick" }, { ["x"] = 1, ["meta"] = { ["fields"] = { ["owner_info"] = "return { [\"y\"] = 2, [\"x\"] = 343, [\"z\"] = 1108 }" }, ["inventory"] = {  } }, ["param2"] = 9, ["y"] = 3, ["param1"] = 0, ["z"] = 9, ["name"] = "default:brick" }, { ["x"] = 1, ["meta"] = { ["fields"] = { ["owner_info"] = "return { [\"y\"] = 2, [\"x\"] = 343, [\"z\"] = 1108 }" }, ["inventory"] = {  } }, ["param2"] = 9, ["y"] = 4, ["param1"] = 0, ["z"] = 1, ["name"] = "default:brick" }, { ["x"] = 1, ["meta"] = { ["fields"] = { ["owner_info"] = "return { [\"y\"] = 2, [\"x\"] = 343, [\"z\"] = 1108 }" }, ["inventory"] = {  } }, ["param2"] = 9, ["y"] = 4, ["param1"] = 191, ["z"] = 2, ["name"] = "default:fence_wood" }, { ["x"] = 1, ["meta"] = { ["fields"] = { ["owner_info"] = "return { [\"y\"] = 2, [\"x\"] = 343, [\"z\"] = 1108 }" }, ["inventory"] = {  } }, ["param2"] = 9, ["y"] = 4, ["param1"] = 175, ["z"] = 3, ["name"] = "default:fence_wood" }, { ["x"] = 1, ["meta"] = { ["fields"] = { ["owner_info"] = "return { [\"y\"] = 2, [\"x\"] = 343, [\"z\"] = 1108 }" }, ["inventory"] = {  } }, ["param2"] = 9, ["y"] = 4, ["param1"] = 157, ["z"] = 4, ["name"] = "default:fence_wood" }, { ["x"] = 1, ["meta"] = { ["fields"] = { ["owner_info"] = "return { [\"y\"] = 2, [\"x\"] = 343, [\"z\"] = 1108 }" }, ["inventory"] = {  } }, ["param2"] = 9, ["y"] = 4, ["param1"] = 0, ["z"] = 5, ["name"] = "default:brick" }, { ["x"] = 1, ["meta"] = { ["fields"] = { ["owner_info"] = "return { [\"y\"] = 2, [\"x\"] = 343, [\"z\"] = 1108 }" }, ["inventory"] = {  } }, ["param2"] = 9, ["y"] = 4, ["param1"] = 0, ["z"] = 6, ["name"] = "default:brick" }, { ["x"] = 1, ["meta"] = { ["fields"] = { ["owner_info"] = "return { [\"y\"] = 2, [\"x\"] = 343, [\"z\"] = 1108 }" }, ["inventory"] = {  } }, ["param2"] = 9, ["y"] = 4, ["param1"] = 172, ["z"] = 7, ["name"] = "default:glass" }, { ["x"] = 1, ["meta"] = { ["fields"] = { ["owner_info"] = "return { [\"y\"] = 2, [\"x\"] = 343, [\"z\"] = 1108 }" }, ["inventory"] = {  } }, ["param2"] = 9, ["y"] = 4, ["param1"] = 0, ["z"] = 8, ["name"] = "default:brick" }, { ["x"] = 1, ["meta"] = { ["fields"] = { ["owner_info"] = "return { [\"y\"] = 2, [\"x\"] = 343, [\"z\"] = 1108 }" }, ["inventory"] = {  } }, ["param2"] = 0, ["y"] = 4, ["param1"] = 0, ["z"] = 9, ["name"] = "default:brick" }, { ["x"] = 1, ["meta"] = { ["fields"] = { ["owner_info"] = "return { [\"y\"] = 2, [\"x\"] = 343, [\"z\"] = 1108 }" }, ["inventory"] = {  } }, ["param2"] = 2, ["y"] = 5, ["param1"] = 15, ["z"] = 1, ["name"] = "default:torch" }, { ["x"] = 1, ["meta"] = { ["fields"] = { ["owner_info"] = "return { [\"y\"] = 2, [\"x\"] = 343, [\"z\"] = 1108 }" }, ["inventory"] = {  } }, ["param2"] = 9, ["y"] = 5, ["param1"] = 0, ["z"] = 6, ["name"] = "default:brick" }, { ["x"] = 1, ["meta"] = { ["fields"] = { ["owner_info"] = "return { [\"y\"] = 2, [\"x\"] = 343, [\"z\"] = 1108 }" }, ["inventory"] = {  } }, ["param2"] = 9, ["y"] = 5, ["param1"] = 188, ["z"] = 7, ["name"] = "default:glass" }, { ["x"] = 1, ["meta"] = { ["fields"] = { ["owner_info"] = "return { [\"y\"] = 2, [\"x\"] = 343, [\"z\"] = 1108 }" }, ["inventory"] = {  } }, ["param2"] = 9, ["y"] = 5, ["param1"] = 0, ["z"] = 8, ["name"] = "default:brick" }, { ["x"] = 1, ["meta"] = { ["fields"] = { ["owner_info"] = "return { [\"y\"] = 2, [\"x\"] = 343, [\"z\"] = 1108 }" }, ["inventory"] = {  } }, ["param2"] = 9, ["y"] = 6, ["param1"] = 0, ["z"] = 6, ["name"] = "default:brick" }, { ["x"] = 1, ["meta"] = { ["fields"] = { ["owner_info"] = "return { [\"y\"] = 2, [\"x\"] = 343, [\"z\"] = 1108 }" }, ["inventory"] = {  } }, ["param2"] = 9, ["y"] = 6, ["param1"] = 0, ["z"] = 7, ["name"] = "default:brick" }, { ["x"] = 1, ["meta"] = { ["fields"] = { ["owner_info"] = "return { [\"y\"] = 2, [\"x\"] = 343, [\"z\"] = 1108 }" }, ["inventory"] = {  } }, ["param2"] = 9, ["y"] = 6, ["param1"] = 0, ["z"] = 8, ["name"] = "default:brick" }, { ["x"] = 1, ["meta"] = { ["fields"] = {  }, ["inventory"] = {  } }, ["param2"] = 0, ["y"] = 7, ["param1"] = 141, ["z"] = 4, ["name"] = "stairs:slab_stone" }, { ["x"] = 1, ["meta"] = { ["fields"] = {  }, ["inventory"] = {  } }, ["param2"] = 0, ["y"] = 7, ["param1"] = 157, ["z"] = 5, ["name"] = "stairs:slab_stone" }, { ["x"] = 1, ["meta"] = { ["fields"] = {  }, ["inventory"] = {  } }, ["param2"] = 0, ["y"] = 7, ["param1"] = 173, ["z"] = 6, ["name"] = "stairs:slab_stone" }, { ["x"] = 1, ["meta"] = { ["fields"] = {  }, ["inventory"] = {  } }, ["param2"] = 0, ["y"] = 7, ["param1"] = 157, ["z"] = 7, ["name"] = "stairs:slab_stone" }, { ["x"] = 1, ["meta"] = { ["fields"] = {  }, ["inventory"] = {  } }, ["param2"] = 0, ["y"] = 7, ["param1"] = 173, ["z"] = 8, ["name"] = "stairs:slab_stone" }, { ["x"] = 1, ["meta"] = { ["fields"] = {  }, ["inventory"] = {  } }, ["param2"] = 0, ["y"] = 7, ["param1"] = 157, ["z"] = 9, ["name"] = "stairs:slab_stone" }, { ["x"] = 1, ["meta"] = { ["fields"] = {  }, ["inventory"] = {  } }, ["param2"] = 0, ["y"] = 7, ["param1"] = 157, ["z"] = 10, ["name"] = "stairs:slab_stone" }, { ["x"] = 2, ["meta"] = { ["fields"] = { ["owner_info"] = "return { [\"y\"] = 2, [\"x\"] = 343, [\"z\"] = 1108 }" }, ["inventory"] = {  } }, ["param2"] = 0, ["y"] = 0, ["param1"] = 0, ["z"] = 0, ["name"] = "default:sand" }, { ["x"] = 2, ["meta"] = { ["fields"] = { ["owner_info"] = "return { [\"y\"] = 2, [\"x\"] = 343, [\"z\"] = 1108 }" }, ["inventory"] = {  } }, ["param2"] = 0, ["y"] = 0, ["param1"] = 0, ["z"] = 1, ["name"] = "default:sand" }, { ["x"] = 2, ["meta"] = { ["fields"] = { ["owner_info"] = "return { [\"y\"] = 2, [\"x\"] = 343, [\"z\"] = 1108 }" }, ["inventory"] = {  } }, ["param2"] = 4, ["y"] = 0, ["param1"] = 172, ["z"] = 4, ["name"] = "default:ladder" }, { ["x"] = 2, ["meta"] = { ["fields"] = { ["owner_info"] = "return { [\"y\"] = 2, [\"x\"] = 343, [\"z\"] = 1108 }" }, ["inventory"] = {  } }, ["param2"] = 9, ["y"] = 0, ["param1"] = 0, ["z"] = 5, ["name"] = "default:brick" }, { ["x"] = 2, ["meta"] = { ["fields"] = { ["owner_info"] = "return { [\"y\"] = 2, [\"x\"] = 343, [\"z\"] = 1108 }" }, ["inventory"] = {  } }, ["param2"] = 9, ["y"] = 0, ["param1"] = 0, ["z"] = 6, ["name"] = "default:brick" }, { ["x"] = 2, ["meta"] = { ["fields"] = { ["owner_info"] = "return { [\"y\"] = 2, [\"x\"] = 343, [\"z\"] = 1108 }" }, ["inventory"] = {  } }, ["param2"] = 9, ["y"] = 0, ["param1"] = 0, ["z"] = 7, ["name"] = "default:brick" }, { ["x"] = 2, ["meta"] = { ["fields"] = { ["owner_info"] = "return { [\"y\"] = 2, [\"x\"] = 343, [\"z\"] = 1108 }" }, ["inventory"] = {  } }, ["param2"] = 9, ["y"] = 0, ["param1"] = 0, ["z"] = 8, ["name"] = "default:brick" }, { ["x"] = 2, ["meta"] = { ["fields"] = { ["owner_info"] = "return { [\"y\"] = 2, [\"x\"] = 343, [\"z\"] = 1108 }" }, ["inventory"] = {  } }, ["param2"] = 9, ["y"] = 0, ["param1"] = 0, ["z"] = 9, ["name"] = "default:brick" }, { ["x"] = 2, ["meta"] = { ["fields"] = { ["owner_info"] = "return { [\"y\"] = 2, [\"x\"] = 343, [\"z\"] = 1108 }" }, ["inventory"] = {  } }, ["param2"] = 1, ["y"] = 1, ["param1"] = 15, ["z"] = 0, ["name"] = "default:torch" }, { ["x"] = 2, ["meta"] = { ["fields"] = { ["owner_info"] = "return { [\"y\"] = 2, [\"x\"] = 343, [\"z\"] = 1108 }" }, ["inventory"] = {  } }, ["param2"] = 4, ["y"] = 1, ["param1"] = 188, ["z"] = 4, ["name"] = "default:ladder" }, { ["x"] = 2, ["meta"] = { ["fields"] = { ["owner_info"] = "return { [\"y\"] = 2, [\"x\"] = 343, [\"z\"] = 1108 }" }, ["inventory"] = {  } }, ["param2"] = 9, ["y"] = 1, ["param1"] = 0, ["z"] = 5, ["name"] = "default:brick" }, { ["x"] = 2, ["meta"] = { ["fields"] = { ["src_totaltime"] = "0", ["src_time"] = "0", ["formspec"] = "size[8,8.5]bgcolor[#080808BB;true]background[5,5;1,1;gui_formbg.png;true]listcolors[#00000069;#5A5A5A;#141318;#30434C;#FFF]list[current_name;src;2.75,0.5;1,1;]list[current_name;fuel;2.75,2.5;1,1;]image[2.75,1.5;1,1;default_furnace_fire_bg.png]image[3.75,1.5;1,1;gui_furnace_arrow_bg.png^[transformR270]list[current_name;dst;4.75,0.96;2,2;]list[current_player;main;0,4.25;8,1;]list[current_player;main;0,5.5;8,3;8]image[0,4.25;1,1;gui_hb_bg.png]image[1,4.25;1,1;gui_hb_bg.png]image[2,4.25;1,1;gui_hb_bg.png]image[3,4.25;1,1;gui_hb_bg.png]image[4,4.25;1,1;gui_hb_bg.png]image[5,4.25;1,1;gui_hb_bg.png]image[6,4.25;1,1;gui_hb_bg.png]image[7,4.25;1,1;gui_hb_bg.png]", ["fuel_time"] = "0", ["fuel_totaltime"] = "0", ["owner_info"] = "return { [\"y\"] = 2, [\"x\"] = 343, [\"z\"] = 1108 }", ["infotext"] = "Furnace out of fuel" }, ["inventory"] = { ["fuel"] = { "" }, ["dst"] = { "", "", "", "" }, ["src"] = { "" } } }, ["param2"] = 3, ["y"] = 1, ["param1"] = 0, ["z"] = 6, ["name"] = "default:furnace" }, { ["x"] = 2, ["meta"] = { ["fields"] = { ["src_totaltime"] = "0", ["src_time"] = "0", ["formspec"] = "size[8,8.5]bgcolor[#080808BB;true]background[5,5;1,1;gui_formbg.png;true]listcolors[#00000069;#5A5A5A;#141318;#30434C;#FFF]list[current_name;src;2.75,0.5;1,1;]list[current_name;fuel;2.75,2.5;1,1;]image[2.75,1.5;1,1;default_furnace_fire_bg.png]image[3.75,1.5;1,1;gui_furnace_arrow_bg.png^[transformR270]list[current_name;dst;4.75,0.96;2,2;]list[current_player;main;0,4.25;8,1;]list[current_player;main;0,5.5;8,3;8]image[0,4.25;1,1;gui_hb_bg.png]image[1,4.25;1,1;gui_hb_bg.png]image[2,4.25;1,1;gui_hb_bg.png]image[3,4.25;1,1;gui_hb_bg.png]image[4,4.25;1,1;gui_hb_bg.png]image[5,4.25;1,1;gui_hb_bg.png]image[6,4.25;1,1;gui_hb_bg.png]image[7,4.25;1,1;gui_hb_bg.png]", ["fuel_time"] = "0", ["fuel_totaltime"] = "0", ["owner_info"] = "return { [\"y\"] = 2, [\"x\"] = 343, [\"z\"] = 1108 }", ["infotext"] = "Furnace out of fuel" }, ["inventory"] = { ["fuel"] = { "" }, ["dst"] = { "", "", "", "" }, ["src"] = { "" } } }, ["param2"] = 3, ["y"] = 1, ["param1"] = 0, ["z"] = 7, ["name"] = "default:furnace" }, { ["x"] = 2, ["meta"] = { ["fields"] = { ["src_totaltime"] = "0", ["src_time"] = "0", ["formspec"] = "size[8,8.5]bgcolor[#080808BB;true]background[5,5;1,1;gui_formbg.png;true]listcolors[#00000069;#5A5A5A;#141318;#30434C;#FFF]list[current_name;src;2.75,0.5;1,1;]list[current_name;fuel;2.75,2.5;1,1;]image[2.75,1.5;1,1;default_furnace_fire_bg.png]image[3.75,1.5;1,1;gui_furnace_arrow_bg.png^[transformR270]list[current_name;dst;4.75,0.96;2,2;]list[current_player;main;0,4.25;8,1;]list[current_player;main;0,5.5;8,3;8]image[0,4.25;1,1;gui_hb_bg.png]image[1,4.25;1,1;gui_hb_bg.png]image[2,4.25;1,1;gui_hb_bg.png]image[3,4.25;1,1;gui_hb_bg.png]image[4,4.25;1,1;gui_hb_bg.png]image[5,4.25;1,1;gui_hb_bg.png]image[6,4.25;1,1;gui_hb_bg.png]image[7,4.25;1,1;gui_hb_bg.png]", ["fuel_time"] = "0", ["fuel_totaltime"] = "0", ["owner_info"] = "return { [\"y\"] = 2, [\"x\"] = 343, [\"z\"] = 1108 }", ["infotext"] = "Furnace out of fuel" }, ["inventory"] = { ["fuel"] = { "" }, ["dst"] = { "", "", "", "" }, ["src"] = { "" } } }, ["param2"] = 3, ["y"] = 1, ["param1"] = 0, ["z"] = 8, ["name"] = "default:furnace" }, { ["x"] = 2, ["meta"] = { ["fields"] = { ["owner_info"] = "return { [\"y\"] = 2, [\"x\"] = 343, [\"z\"] = 1108 }" }, ["inventory"] = {  } }, ["param2"] = 9, ["y"] = 1, ["param1"] = 0, ["z"] = 9, ["name"] = "default:brick" }, { ["x"] = 2, ["meta"] = { ["fields"] = { ["owner_info"] = "return { [\"y\"] = 2, [\"x\"] = 343, [\"z\"] = 1108 }" }, ["inventory"] = {  } }, ["param2"] = 0, ["y"] = 2, ["param1"] = 0, ["z"] = 1, ["name"] = "default:torch" }, { ["x"] = 2, ["meta"] = { ["fields"] = { ["owner_info"] = "return { [\"y\"] = 2, [\"x\"] = 343, [\"z\"] = 1108 }" }, ["inventory"] = {  } }, ["param2"] = 4, ["y"] = 2, ["param1"] = 204, ["z"] = 4, ["name"] = "default:ladder" }, { ["x"] = 2, ["meta"] = { ["fields"] = { ["owner_info"] = "return { [\"y\"] = 2, [\"x\"] = 343, [\"z\"] = 1108 }" }, ["inventory"] = {  } }, ["param2"] = 9, ["y"] = 2, ["param1"] = 0, ["z"] = 5, ["name"] = "default:brick" }, { ["x"] = 2, ["meta"] = { ["fields"] = { ["src_totaltime"] = "0", ["src_time"] = "0", ["formspec"] = "size[8,8.5]bgcolor[#080808BB;true]background[5,5;1,1;gui_formbg.png;true]listcolors[#00000069;#5A5A5A;#141318;#30434C;#FFF]list[current_name;src;2.75,0.5;1,1;]list[current_name;fuel;2.75,2.5;1,1;]image[2.75,1.5;1,1;default_furnace_fire_bg.png]image[3.75,1.5;1,1;gui_furnace_arrow_bg.png^[transformR270]list[current_name;dst;4.75,0.96;2,2;]list[current_player;main;0,4.25;8,1;]list[current_player;main;0,5.5;8,3;8]image[0,4.25;1,1;gui_hb_bg.png]image[1,4.25;1,1;gui_hb_bg.png]image[2,4.25;1,1;gui_hb_bg.png]image[3,4.25;1,1;gui_hb_bg.png]image[4,4.25;1,1;gui_hb_bg.png]image[5,4.25;1,1;gui_hb_bg.png]image[6,4.25;1,1;gui_hb_bg.png]image[7,4.25;1,1;gui_hb_bg.png]", ["fuel_time"] = "0", ["fuel_totaltime"] = "0", ["owner_info"] = "return { [\"y\"] = 2, [\"x\"] = 343, [\"z\"] = 1108 }", ["infotext"] = "Furnace out of fuel" }, ["inventory"] = { ["fuel"] = { "" }, ["dst"] = { "", "", "", "" }, ["src"] = { "" } } }, ["param2"] = 3, ["y"] = 2, ["param1"] = 0, ["z"] = 6, ["name"] = "default:furnace" }, { ["x"] = 2, ["meta"] = { ["fields"] = { ["src_totaltime"] = "0", ["src_time"] = "0", ["formspec"] = "size[8,8.5]bgcolor[#080808BB;true]background[5,5;1,1;gui_formbg.png;true]listcolors[#00000069;#5A5A5A;#141318;#30434C;#FFF]list[current_name;src;2.75,0.5;1,1;]list[current_name;fuel;2.75,2.5;1,1;]image[2.75,1.5;1,1;default_furnace_fire_bg.png]image[3.75,1.5;1,1;gui_furnace_arrow_bg.png^[transformR270]list[current_name;dst;4.75,0.96;2,2;]list[current_player;main;0,4.25;8,1;]list[current_player;main;0,5.5;8,3;8]image[0,4.25;1,1;gui_hb_bg.png]image[1,4.25;1,1;gui_hb_bg.png]image[2,4.25;1,1;gui_hb_bg.png]image[3,4.25;1,1;gui_hb_bg.png]image[4,4.25;1,1;gui_hb_bg.png]image[5,4.25;1,1;gui_hb_bg.png]image[6,4.25;1,1;gui_hb_bg.png]image[7,4.25;1,1;gui_hb_bg.png]", ["fuel_time"] = "0", ["fuel_totaltime"] = "0", ["owner_info"] = "return { [\"y\"] = 2, [\"x\"] = 343, [\"z\"] = 1108 }", ["infotext"] = "Furnace out of fuel" }, ["inventory"] = { ["fuel"] = { "" }, ["dst"] = { "", "", "", "" }, ["src"] = { "" } } }, ["param2"] = 3, ["y"] = 2, ["param1"] = 0, ["z"] = 7, ["name"] = "default:furnace" }, { ["x"] = 2, ["meta"] = { ["fields"] = { ["src_totaltime"] = "0", ["src_time"] = "0", ["formspec"] = "size[8,8.5]bgcolor[#080808BB;true]background[5,5;1,1;gui_formbg.png;true]listcolors[#00000069;#5A5A5A;#141318;#30434C;#FFF]list[current_name;src;2.75,0.5;1,1;]list[current_name;fuel;2.75,2.5;1,1;]image[2.75,1.5;1,1;default_furnace_fire_bg.png]image[3.75,1.5;1,1;gui_furnace_arrow_bg.png^[transformR270]list[current_name;dst;4.75,0.96;2,2;]list[current_player;main;0,4.25;8,1;]list[current_player;main;0,5.5;8,3;8]image[0,4.25;1,1;gui_hb_bg.png]image[1,4.25;1,1;gui_hb_bg.png]image[2,4.25;1,1;gui_hb_bg.png]image[3,4.25;1,1;gui_hb_bg.png]image[4,4.25;1,1;gui_hb_bg.png]image[5,4.25;1,1;gui_hb_bg.png]image[6,4.25;1,1;gui_hb_bg.png]image[7,4.25;1,1;gui_hb_bg.png]", ["fuel_time"] = "0", ["fuel_totaltime"] = "0", ["owner_info"] = "return { [\"y\"] = 2, [\"x\"] = 343, [\"z\"] = 1108 }", ["infotext"] = "Furnace out of fuel" }, ["inventory"] = { ["fuel"] = { "" }, ["dst"] = { "", "", "", "" }, ["src"] = { "" } } }, ["param2"] = 3, ["y"] = 2, ["param1"] = 0, ["z"] = 8, ["name"] = "default:furnace" }, { ["x"] = 2, ["meta"] = { ["fields"] = { ["owner_info"] = "return { [\"y\"] = 2, [\"x\"] = 343, [\"z\"] = 1108 }" }, ["inventory"] = {  } }, ["param2"] = 9, ["y"] = 2, ["param1"] = 0, ["z"] = 9, ["name"] = "default:brick" }, { ["x"] = 2, ["meta"] = { ["fields"] = { ["owner_info"] = "return { [\"y\"] = 2, [\"x\"] = 343, [\"z\"] = 1108 }" }, ["inventory"] = {  } }, ["param2"] = 5, ["y"] = 2, ["param1"] = 0, ["z"] = 10, ["name"] = "default:torch" }, { ["x"] = 2, ["meta"] = { ["fields"] = { ["owner_info"] = "return { [\"y\"] = 2, [\"x\"] = 343, [\"z\"] = 1108 }" }, ["inventory"] = {  } }, ["param2"] = 9, ["y"] = 3, ["param1"] = 0, ["z"] = 1, ["name"] = "default:brick" }, { ["x"] = 2, ["meta"] = { ["fields"] = { ["owner_info"] = "return { [\"y\"] = 2, [\"x\"] = 343, [\"z\"] = 1108 }" }, ["inventory"] = {  } }, ["param2"] = 0, ["y"] = 3, ["param1"] = 189, ["z"] = 2, ["name"] = "stairs:slab_brick" }, { ["x"] = 2, ["meta"] = { ["fields"] = { ["owner_info"] = "return { [\"y\"] = 2, [\"x\"] = 343, [\"z\"] = 1108 }" }, ["inventory"] = {  } }, ["param2"] = 0, ["y"] = 3, ["param1"] = 173, ["z"] = 3, ["name"] = "stairs:slab_brick" }, { ["x"] = 2, ["meta"] = { ["fields"] = { ["owner_info"] = "return { [\"y\"] = 2, [\"x\"] = 343, [\"z\"] = 1108 }" }, ["inventory"] = {  } }, ["param2"] = 4, ["y"] = 3, ["param1"] = 188, ["z"] = 4, ["name"] = "default:ladder" }, { ["x"] = 2, ["meta"] = { ["fields"] = { ["owner_info"] = "return { [\"y\"] = 2, [\"x\"] = 343, [\"z\"] = 1108 }" }, ["inventory"] = {  } }, ["param2"] = 9, ["y"] = 3, ["param1"] = 0, ["z"] = 5, ["name"] = "default:brick" }, { ["x"] = 2, ["meta"] = { ["fields"] = { ["owner_info"] = "return { [\"y\"] = 2, [\"x\"] = 343, [\"z\"] = 1108 }" }, ["inventory"] = {  } }, ["param2"] = 0, ["y"] = 3, ["param1"] = 0, ["z"] = 6, ["name"] = "default:wood" }, { ["x"] = 2, ["meta"] = { ["fields"] = { ["owner_info"] = "return { [\"y\"] = 2, [\"x\"] = 343, [\"z\"] = 1108 }" }, ["inventory"] = {  } }, ["param2"] = 0, ["y"] = 3, ["param1"] = 0, ["z"] = 7, ["name"] = "default:wood" }, { ["x"] = 2, ["meta"] = { ["fields"] = { ["owner_info"] = "return { [\"y\"] = 2, [\"x\"] = 343, [\"z\"] = 1108 }" }, ["inventory"] = {  } }, ["param2"] = 0, ["y"] = 3, ["param1"] = 0, ["z"] = 8, ["name"] = "default:wood" }, { ["x"] = 2, ["meta"] = { ["fields"] = { ["owner_info"] = "return { [\"y\"] = 2, [\"x\"] = 343, [\"z\"] = 1108 }" }, ["inventory"] = {  } }, ["param2"] = 9, ["y"] = 3, ["param1"] = 0, ["z"] = 9, ["name"] = "default:brick" }, { ["x"] = 2, ["meta"] = { ["fields"] = { ["owner_info"] = "return { [\"y\"] = 2, [\"x\"] = 343, [\"z\"] = 1108 }" }, ["inventory"] = {  } }, ["param2"] = 9, ["y"] = 4, ["param1"] = 191, ["z"] = 1, ["name"] = "default:fence_wood" }, { ["x"] = 2, ["meta"] = { ["fields"] = { ["owner_info"] = "return { [\"y\"] = 2, [\"x\"] = 343, [\"z\"] = 1108 }" }, ["inventory"] = {  } }, ["param2"] = 4, ["y"] = 4, ["param1"] = 173, ["z"] = 4, ["name"] = "default:ladder" }, { ["x"] = 2, ["meta"] = { ["fields"] = { ["owner_info"] = "return { [\"y\"] = 2, [\"x\"] = 343, [\"z\"] = 1108 }" }, ["inventory"] = {  } }, ["param2"] = 9, ["y"] = 4, ["param1"] = 0, ["z"] = 5, ["name"] = "default:brick" }, { ["x"] = 2, ["meta"] = { ["fields"] = { ["owner_info"] = "return { [\"y\"] = 2, [\"x\"] = 343, [\"z\"] = 1108 }", ["formspec"] = "size[8,7;]bgcolor[#080808BB;true]background[5,5;1,1;gui_formbg.png;true]listcolors[#00000069;#5A5A5A;#141318;#30434C;#FFF]list[context;books;0,0.3;8,2;]list[current_player;main;0,2.85;8,1;]list[current_player;main;0,4.08;8,3;8]image[0,2.85;1,1;gui_hb_bg.png]image[1,2.85;1,1;gui_hb_bg.png]image[2,2.85;1,1;gui_hb_bg.png]image[3,2.85;1,1;gui_hb_bg.png]image[4,2.85;1,1;gui_hb_bg.png]image[5,2.85;1,1;gui_hb_bg.png]image[6,2.85;1,1;gui_hb_bg.png]image[7,2.85;1,1;gui_hb_bg.png]" }, ["inventory"] = { ["books"] = { "", "", "", "", "", "", "", "", "", "", "", "", "", "", "", "" } } }, ["param2"] = 0, ["y"] = 4, ["param1"] = 204, ["z"] = 6, ["name"] = "default:bookshelf" }, { ["x"] = 2, ["meta"] = { ["fields"] = { ["owner_info"] = "return { [\"y\"] = 2, [\"x\"] = 343, [\"z\"] = 1108 }" }, ["inventory"] = {  } }, ["param2"] = 3, ["y"] = 4, ["param1"] = 187, ["z"] = 8, ["name"] = "cottages:bed_head" }, { ["x"] = 2, ["meta"] = { ["fields"] = { ["owner_info"] = "return { [\"y\"] = 2, [\"x\"] = 343, [\"z\"] = 1108 }" }, ["inventory"] = {  } }, ["param2"] = 9, ["y"] = 4, ["param1"] = 0, ["z"] = 9, ["name"] = "default:brick" }, { ["x"] = 2, ["meta"] = { ["fields"] = { ["owner_info"] = "return { [\"y\"] = 2, [\"x\"] = 343, [\"z\"] = 1108 }" }, ["inventory"] = {  } }, ["param2"] = 4, ["y"] = 5, ["param1"] = 157, ["z"] = 4, ["name"] = "default:ladder" }, { ["x"] = 2, ["meta"] = { ["fields"] = { ["owner_info"] = "return { [\"y\"] = 2, [\"x\"] = 343, [\"z\"] = 1108 }" }, ["inventory"] = {  } }, ["param2"] = 9, ["y"] = 5, ["param1"] = 0, ["z"] = 5, ["name"] = "default:brick" }, { ["x"] = 2, ["meta"] = { ["fields"] = { ["owner_info"] = "return { [\"y\"] = 2, [\"x\"] = 343, [\"z\"] = 1108 }" }, ["inventory"] = {  } }, ["param2"] = 1, ["y"] = 5, ["param1"] = 0, ["z"] = 6, ["name"] = "default:torch" }, { ["x"] = 2, ["meta"] = { ["fields"] = { ["owner_info"] = "return { [\"y\"] = 2, [\"x\"] = 343, [\"z\"] = 1108 }" }, ["inventory"] = {  } }, ["param2"] = 9, ["y"] = 5, ["param1"] = 0, ["z"] = 9, ["name"] = "default:brick" }, { ["x"] = 2, ["meta"] = { ["fields"] = { ["owner_info"] = "return { [\"y\"] = 2, [\"x\"] = 343, [\"z\"] = 1108 }" }, ["inventory"] = {  } }, ["param2"] = 4, ["y"] = 6, ["param1"] = 141, ["z"] = 4, ["name"] = "default:ladder" }, { ["x"] = 2, ["meta"] = { ["fields"] = { ["owner_info"] = "return { [\"y\"] = 2, [\"x\"] = 343, [\"z\"] = 1108 }" }, ["inventory"] = {  } }, ["param2"] = 9, ["y"] = 6, ["param1"] = 0, ["z"] = 5, ["name"] = "default:brick" }, { ["x"] = 2, ["meta"] = { ["fields"] = { ["owner_info"] = "return { [\"y\"] = 2, [\"x\"] = 343, [\"z\"] = 1108 }" }, ["inventory"] = {  } }, ["param2"] = 4, ["y"] = 6, ["param1"] = 0, ["z"] = 8, ["name"] = "default:torch" }, { ["x"] = 2, ["meta"] = { ["fields"] = { ["owner_info"] = "return { [\"y\"] = 2, [\"x\"] = 343, [\"z\"] = 1108 }" }, ["inventory"] = {  } }, ["param2"] = 9, ["y"] = 6, ["param1"] = 0, ["z"] = 9, ["name"] = "default:brick" }, { ["x"] = 2, ["meta"] = { ["fields"] = {  }, ["inventory"] = {  } }, ["param2"] = 0, ["y"] = 7, ["param1"] = 125, ["z"] = 4, ["name"] = "stairs:slab_stone" }, { ["x"] = 2, ["meta"] = { ["fields"] = {  }, ["inventory"] = {  } }, ["param2"] = 0, ["y"] = 7, ["param1"] = 141, ["z"] = 5, ["name"] = "stairs:slab_stone" }, { ["x"] = 2, ["meta"] = { ["fields"] = { ["owner_info"] = "return { [\"y\"] = 2, [\"x\"] = 343, [\"z\"] = 1108 }" }, ["inventory"] = {  } }, ["param2"] = 9, ["y"] = 7, ["param1"] = 0, ["z"] = 6, ["name"] = "default:stone" }, { ["x"] = 2, ["meta"] = { ["fields"] = { ["owner_info"] = "return { [\"y\"] = 2, [\"x\"] = 343, [\"z\"] = 1108 }" }, ["inventory"] = {  } }, ["param2"] = 9, ["y"] = 7, ["param1"] = 0, ["z"] = 7, ["name"] = "default:stone" }, { ["x"] = 2, ["meta"] = { ["fields"] = { ["owner_info"] = "return { [\"y\"] = 2, [\"x\"] = 343, [\"z\"] = 1108 }" }, ["inventory"] = {  } }, ["param2"] = 9, ["y"] = 7, ["param1"] = 0, ["z"] = 8, ["name"] = "default:stone" }, { ["x"] = 2, ["meta"] = { ["fields"] = {  }, ["inventory"] = {  } }, ["param2"] = 0, ["y"] = 7, ["param1"] = 157, ["z"] = 9, ["name"] = "stairs:slab_stone" }, { ["x"] = 2, ["meta"] = { ["fields"] = {  }, ["inventory"] = {  } }, ["param2"] = 0, ["y"] = 7, ["param1"] = 173, ["z"] = 10, ["name"] = "stairs:slab_stone" }, { ["x"] = 3, ["meta"] = { ["fields"] = { ["owner_info"] = "return { [\"y\"] = 2, [\"x\"] = 343, [\"z\"] = 1108 }" }, ["inventory"] = {  } }, ["param2"] = 0, ["y"] = 0, ["param1"] = 187, ["z"] = 4, ["name"] = "stairs:slab_brick" }, { ["x"] = 3, ["meta"] = { ["fields"] = { ["owner_info"] = "return { [\"y\"] = 2, [\"x\"] = 343, [\"z\"] = 1108 }" }, ["inventory"] = {  } }, ["param2"] = 9, ["y"] = 0, ["param1"] = 0, ["z"] = 5, ["name"] = "default:brick" }, { ["x"] = 3, ["meta"] = { ["fields"] = { ["owner_info"] = "return { [\"y\"] = 2, [\"x\"] = 343, [\"z\"] = 1108 }" }, ["inventory"] = {  } }, ["param2"] = 9, ["y"] = 0, ["param1"] = 0, ["z"] = 6, ["name"] = "default:brick" }, { ["x"] = 3, ["meta"] = { ["fields"] = { ["owner_info"] = "return { [\"y\"] = 2, [\"x\"] = 343, [\"z\"] = 1108 }" }, ["inventory"] = {  } }, ["param2"] = 9, ["y"] = 0, ["param1"] = 0, ["z"] = 7, ["name"] = "default:brick" }, { ["x"] = 3, ["meta"] = { ["fields"] = { ["owner_info"] = "return { [\"y\"] = 2, [\"x\"] = 343, [\"z\"] = 1108 }" }, ["inventory"] = {  } }, ["param2"] = 9, ["y"] = 0, ["param1"] = 0, ["z"] = 8, ["name"] = "default:brick" }, { ["x"] = 3, ["meta"] = { ["fields"] = { ["owner_info"] = "return { [\"y\"] = 2, [\"x\"] = 343, [\"z\"] = 1108 }" }, ["inventory"] = {  } }, ["param2"] = 9, ["y"] = 0, ["param1"] = 0, ["z"] = 9, ["name"] = "default:brick" }, { ["x"] = 3, ["meta"] = { ["fields"] = { ["owner_info"] = "return { [\"y\"] = 2, [\"x\"] = 343, [\"z\"] = 1108 }" }, ["inventory"] = {  } }, ["param2"] = 9, ["y"] = 1, ["param1"] = 0, ["z"] = 5, ["name"] = "default:brick" }, { ["x"] = 3, ["meta"] = { ["fields"] = { ["owner_info"] = "return { [\"y\"] = 2, [\"x\"] = 343, [\"z\"] = 1108 }" }, ["inventory"] = {  } }, ["param2"] = 9, ["y"] = 1, ["param1"] = 0, ["z"] = 9, ["name"] = "default:brick" }, { ["x"] = 3, ["meta"] = { ["fields"] = { ["owner_info"] = "return { [\"y\"] = 2, [\"x\"] = 343, [\"z\"] = 1108 }" }, ["inventory"] = {  } }, ["param2"] = 4, ["y"] = 2, ["param1"] = 0, ["z"] = 4, ["name"] = "default:torch" }, { ["x"] = 3, ["meta"] = { ["fields"] = { ["owner_info"] = "return { [\"y\"] = 2, [\"x\"] = 343, [\"z\"] = 1108 }" }, ["inventory"] = {  } }, ["param2"] = 9, ["y"] = 2, ["param1"] = 0, ["z"] = 5, ["name"] = "default:brick" }, { ["x"] = 3, ["meta"] = { ["fields"] = { ["owner_info"] = "return { [\"y\"] = 2, [\"x\"] = 343, [\"z\"] = 1108 }" }, ["inventory"] = {  } }, ["param2"] = 5, ["y"] = 2, ["param1"] = 0, ["z"] = 6, ["name"] = "default:torch" }, { ["x"] = 3, ["meta"] = { ["fields"] = { ["owner_info"] = "return { [\"y\"] = 2, [\"x\"] = 343, [\"z\"] = 1108 }" }, ["inventory"] = {  } }, ["param2"] = 4, ["y"] = 2, ["param1"] = 0, ["z"] = 8, ["name"] = "default:torch" }, { ["x"] = 3, ["meta"] = { ["fields"] = { ["owner_info"] = "return { [\"y\"] = 2, [\"x\"] = 343, [\"z\"] = 1108 }" }, ["inventory"] = {  } }, ["param2"] = 9, ["y"] = 2, ["param1"] = 0, ["z"] = 9, ["name"] = "default:brick" }, { ["x"] = 3, ["meta"] = { ["fields"] = { ["owner_info"] = "return { [\"y\"] = 2, [\"x\"] = 343, [\"z\"] = 1108 }" }, ["inventory"] = {  } }, ["param2"] = 9, ["y"] = 3, ["param1"] = 0, ["z"] = 1, ["name"] = "default:brick" }, { ["x"] = 3, ["meta"] = { ["fields"] = { ["owner_info"] = "return { [\"y\"] = 2, [\"x\"] = 343, [\"z\"] = 1108 }" }, ["inventory"] = {  } }, ["param2"] = 0, ["y"] = 3, ["param1"] = 173, ["z"] = 2, ["name"] = "stairs:slab_brick" }, { ["x"] = 3, ["meta"] = { ["fields"] = { ["owner_info"] = "return { [\"y\"] = 2, [\"x\"] = 343, [\"z\"] = 1108 }" }, ["inventory"] = {  } }, ["param2"] = 0, ["y"] = 3, ["param1"] = 189, ["z"] = 3, ["name"] = "stairs:slab_brick" }, { ["x"] = 3, ["meta"] = { ["fields"] = { ["owner_info"] = "return { [\"y\"] = 2, [\"x\"] = 343, [\"z\"] = 1108 }" }, ["inventory"] = {  } }, ["param2"] = 0, ["y"] = 3, ["param1"] = 204, ["z"] = 4, ["name"] = "stairs:slab_brick" }, { ["x"] = 3, ["meta"] = { ["fields"] = { ["owner_info"] = "return { [\"y\"] = 2, [\"x\"] = 343, [\"z\"] = 1108 }" }, ["inventory"] = {  } }, ["param2"] = 9, ["y"] = 3, ["param1"] = 0, ["z"] = 5, ["name"] = "default:brick" }, { ["x"] = 3, ["meta"] = { ["fields"] = { ["owner_info"] = "return { [\"y\"] = 2, [\"x\"] = 343, [\"z\"] = 1108 }" }, ["inventory"] = {  } }, ["param2"] = 0, ["y"] = 3, ["param1"] = 0, ["z"] = 6, ["name"] = "default:wood" }, { ["x"] = 3, ["meta"] = { ["fields"] = { ["owner_info"] = "return { [\"y\"] = 2, [\"x\"] = 343, [\"z\"] = 1108 }" }, ["inventory"] = {  } }, ["param2"] = 0, ["y"] = 3, ["param1"] = 0, ["z"] = 7, ["name"] = "default:wood" }, { ["x"] = 3, ["meta"] = { ["fields"] = { ["owner_info"] = "return { [\"y\"] = 2, [\"x\"] = 343, [\"z\"] = 1108 }" }, ["inventory"] = {  } }, ["param2"] = 0, ["y"] = 3, ["param1"] = 0, ["z"] = 8, ["name"] = "default:wood" }, { ["x"] = 3, ["meta"] = { ["fields"] = { ["owner_info"] = "return { [\"y\"] = 2, [\"x\"] = 343, [\"z\"] = 1108 }" }, ["inventory"] = {  } }, ["param2"] = 9, ["y"] = 3, ["param1"] = 0, ["z"] = 9, ["name"] = "default:brick" }, { ["x"] = 3, ["meta"] = { ["fields"] = { ["owner_info"] = "return { [\"y\"] = 2, [\"x\"] = 343, [\"z\"] = 1108 }" }, ["inventory"] = {  } }, ["param2"] = 9, ["y"] = 4, ["param1"] = 175, ["z"] = 1, ["name"] = "default:fence_wood" }, { ["x"] = 3, ["meta"] = { ["fields"] = { ["owner_info"] = "return { [\"y\"] = 2, [\"x\"] = 343, [\"z\"] = 1108 }" }, ["inventory"] = {  } }, ["param2"] = 0, ["y"] = 4, ["param1"] = 172, ["z"] = 5, ["name"] = "doors:door_wood_b_1" }, { ["x"] = 3, ["meta"] = { ["fields"] = { ["owner_info"] = "return { [\"y\"] = 2, [\"x\"] = 343, [\"z\"] = 1108 }" }, ["inventory"] = {  } }, ["param2"] = 3, ["y"] = 4, ["param1"] = 170, ["z"] = 8, ["name"] = "cottages:bed_foot" }, { ["x"] = 3, ["meta"] = { ["fields"] = { ["owner_info"] = "return { [\"y\"] = 2, [\"x\"] = 343, [\"z\"] = 1108 }" }, ["inventory"] = {  } }, ["param2"] = 9, ["y"] = 4, ["param1"] = 0, ["z"] = 9, ["name"] = "default:brick" }, { ["x"] = 3, ["meta"] = { ["fields"] = { ["owner_info"] = "return { [\"y\"] = 2, [\"x\"] = 343, [\"z\"] = 1108 }" }, ["inventory"] = {  } }, ["param2"] = 0, ["y"] = 5, ["param1"] = 188, ["z"] = 5, ["name"] = "doors:door_wood_t_1" }, { ["x"] = 3, ["meta"] = { ["fields"] = { ["owner_info"] = "return { [\"y\"] = 2, [\"x\"] = 343, [\"z\"] = 1108 }" }, ["inventory"] = {  } }, ["param2"] = 9, ["y"] = 5, ["param1"] = 0, ["z"] = 9, ["name"] = "default:brick" }, { ["x"] = 3, ["meta"] = { ["fields"] = { ["owner_info"] = "return { [\"y\"] = 2, [\"x\"] = 343, [\"z\"] = 1108 }" }, ["inventory"] = {  } }, ["param2"] = 5, ["y"] = 5, ["param1"] = 0, ["z"] = 10, ["name"] = "default:torch" }, { ["x"] = 3, ["meta"] = { ["fields"] = { ["owner_info"] = "return { [\"y\"] = 2, [\"x\"] = 343, [\"z\"] = 1108 }" }, ["inventory"] = {  } }, ["param2"] = 9, ["y"] = 6, ["param1"] = 0, ["z"] = 5, ["name"] = "default:brick" }, { ["x"] = 3, ["meta"] = { ["fields"] = { ["owner_info"] = "return { [\"y\"] = 2, [\"x\"] = 343, [\"z\"] = 1108 }" }, ["inventory"] = {  } }, ["param2"] = 9, ["y"] = 6, ["param1"] = 0, ["z"] = 9, ["name"] = "default:brick" }, { ["x"] = 3, ["meta"] = { ["fields"] = {  }, ["inventory"] = {  } }, ["param2"] = 0, ["y"] = 7, ["param1"] = 141, ["z"] = 4, ["name"] = "stairs:slab_stone" }, { ["x"] = 3, ["meta"] = { ["fields"] = {  }, ["inventory"] = {  } }, ["param2"] = 0, ["y"] = 7, ["param1"] = 125, ["z"] = 5, ["name"] = "stairs:slab_stone" }, { ["x"] = 3, ["meta"] = { ["fields"] = { ["owner_info"] = "return { [\"y\"] = 2, [\"x\"] = 343, [\"z\"] = 1108 }" }, ["inventory"] = {  } }, ["param2"] = 9, ["y"] = 7, ["param1"] = 0, ["z"] = 6, ["name"] = "default:stone" }, { ["x"] = 3, ["meta"] = { ["fields"] = { ["owner_info"] = "return { [\"y\"] = 2, [\"x\"] = 343, [\"z\"] = 1108 }" }, ["inventory"] = {  } }, ["param2"] = 9, ["y"] = 7, ["param1"] = 0, ["z"] = 8, ["name"] = "default:stone" }, { ["x"] = 3, ["meta"] = { ["fields"] = {  }, ["inventory"] = {  } }, ["param2"] = 0, ["y"] = 7, ["param1"] = 173, ["z"] = 9, ["name"] = "stairs:slab_stone" }, { ["x"] = 3, ["meta"] = { ["fields"] = {  }, ["inventory"] = {  } }, ["param2"] = 0, ["y"] = 7, ["param1"] = 189, ["z"] = 10, ["name"] = "stairs:slab_stone" }, { ["x"] = 3, ["meta"] = { ["fields"] = {  }, ["inventory"] = {  } }, ["param2"] = 0, ["y"] = 8, ["param1"] = 157, ["z"] = 7, ["name"] = "stairs:slab_stone" }, { ["x"] = 4, ["meta"] = { ["fields"] = { ["owner_info"] = "return { [\"y\"] = 2, [\"x\"] = 343, [\"z\"] = 1108 }" }, ["inventory"] = {  } }, ["param2"] = 0, ["y"] = 0, ["param1"] = 170, ["z"] = 4, ["name"] = "stairs:slab_brick" }, { ["x"] = 4, ["meta"] = { ["fields"] = { ["owner_info"] = "return { [\"y\"] = 2, [\"x\"] = 343, [\"z\"] = 1108 }" }, ["inventory"] = {  } }, ["param2"] = 9, ["y"] = 0, ["param1"] = 0, ["z"] = 5, ["name"] = "default:brick" }, { ["x"] = 4, ["meta"] = { ["fields"] = { ["owner_info"] = "return { [\"y\"] = 2, [\"x\"] = 343, [\"z\"] = 1108 }" }, ["inventory"] = {  } }, ["param2"] = 9, ["y"] = 0, ["param1"] = 0, ["z"] = 6, ["name"] = "default:brick" }, { ["x"] = 4, ["meta"] = { ["fields"] = { ["owner_info"] = "return { [\"y\"] = 2, [\"x\"] = 343, [\"z\"] = 1108 }" }, ["inventory"] = {  } }, ["param2"] = 9, ["y"] = 0, ["param1"] = 0, ["z"] = 7, ["name"] = "default:brick" }, { ["x"] = 4, ["meta"] = { ["fields"] = { ["owner_info"] = "return { [\"y\"] = 2, [\"x\"] = 343, [\"z\"] = 1108 }" }, ["inventory"] = {  } }, ["param2"] = 9, ["y"] = 0, ["param1"] = 0, ["z"] = 8, ["name"] = "default:brick" }, { ["x"] = 4, ["meta"] = { ["fields"] = { ["owner_info"] = "return { [\"y\"] = 2, [\"x\"] = 343, [\"z\"] = 1108 }" }, ["inventory"] = {  } }, ["param2"] = 9, ["y"] = 0, ["param1"] = 0, ["z"] = 9, ["name"] = "default:brick" }, { ["x"] = 4, ["meta"] = { ["fields"] = { ["owner_info"] = "return { [\"y\"] = 2, [\"x\"] = 343, [\"z\"] = 1108 }" }, ["inventory"] = {  } }, ["param2"] = 0, ["y"] = 1, ["param1"] = 170, ["z"] = 5, ["name"] = "doors:door_wood_b_1" }, { ["x"] = 4, ["meta"] = { ["fields"] = { ["owner_info"] = "return { [\"y\"] = 2, [\"x\"] = 343, [\"z\"] = 1108 }" }, ["inventory"] = {  } }, ["param2"] = 9, ["y"] = 1, ["param1"] = 0, ["z"] = 9, ["name"] = "default:brick" }, { ["x"] = 4, ["meta"] = { ["fields"] = { ["owner_info"] = "return { [\"y\"] = 2, [\"x\"] = 343, [\"z\"] = 1108 }" }, ["inventory"] = {  } }, ["param2"] = 0, ["y"] = 2, ["param1"] = 187, ["z"] = 5, ["name"] = "doors:door_wood_t_1" }, { ["x"] = 4, ["meta"] = { ["fields"] = { ["owner_info"] = "return { [\"y\"] = 2, [\"x\"] = 343, [\"z\"] = 1108 }" }, ["inventory"] = {  } }, ["param2"] = 9, ["y"] = 2, ["param1"] = 0, ["z"] = 9, ["name"] = "default:brick" }, { ["x"] = 4, ["meta"] = { ["fields"] = { ["owner_info"] = "return { [\"y\"] = 2, [\"x\"] = 343, [\"z\"] = 1108 }" }, ["inventory"] = {  } }, ["param2"] = 9, ["y"] = 3, ["param1"] = 0, ["z"] = 1, ["name"] = "default:brick" }, { ["x"] = 4, ["meta"] = { ["fields"] = { ["owner_info"] = "return { [\"y\"] = 2, [\"x\"] = 343, [\"z\"] = 1108 }" }, ["inventory"] = {  } }, ["param2"] = 9, ["y"] = 3, ["param1"] = 0, ["z"] = 2, ["name"] = "default:brick" }, { ["x"] = 4, ["meta"] = { ["fields"] = { ["owner_info"] = "return { [\"y\"] = 2, [\"x\"] = 343, [\"z\"] = 1108 }" }, ["inventory"] = {  } }, ["param2"] = 0, ["y"] = 3, ["param1"] = 173, ["z"] = 3, ["name"] = "stairs:slab_brick" }, { ["x"] = 4, ["meta"] = { ["fields"] = { ["owner_info"] = "return { [\"y\"] = 2, [\"x\"] = 343, [\"z\"] = 1108 }" }, ["inventory"] = {  } }, ["param2"] = 9, ["y"] = 3, ["param1"] = 0, ["z"] = 4, ["name"] = "default:brick" }, { ["x"] = 4, ["meta"] = { ["fields"] = { ["owner_info"] = "return { [\"y\"] = 2, [\"x\"] = 343, [\"z\"] = 1108 }" }, ["inventory"] = {  } }, ["param2"] = 9, ["y"] = 3, ["param1"] = 0, ["z"] = 5, ["name"] = "default:brick" }, { ["x"] = 4, ["meta"] = { ["fields"] = { ["owner_info"] = "return { [\"y\"] = 2, [\"x\"] = 343, [\"z\"] = 1108 }" }, ["inventory"] = {  } }, ["param2"] = 0, ["y"] = 3, ["param1"] = 0, ["z"] = 6, ["name"] = "default:wood" }, { ["x"] = 4, ["meta"] = { ["fields"] = { ["owner_info"] = "return { [\"y\"] = 2, [\"x\"] = 343, [\"z\"] = 1108 }" }, ["inventory"] = {  } }, ["param2"] = 0, ["y"] = 3, ["param1"] = 0, ["z"] = 7, ["name"] = "default:wood" }, { ["x"] = 4, ["meta"] = { ["fields"] = { ["owner_info"] = "return { [\"y\"] = 2, [\"x\"] = 343, [\"z\"] = 1108 }" }, ["inventory"] = {  } }, ["param2"] = 0, ["y"] = 3, ["param1"] = 0, ["z"] = 8, ["name"] = "default:wood" }, { ["x"] = 4, ["meta"] = { ["fields"] = { ["owner_info"] = "return { [\"y\"] = 2, [\"x\"] = 343, [\"z\"] = 1108 }" }, ["inventory"] = {  } }, ["param2"] = 9, ["y"] = 3, ["param1"] = 0, ["z"] = 9, ["name"] = "default:brick" }, { ["x"] = 4, ["meta"] = { ["fields"] = { ["owner_info"] = "return { [\"y\"] = 2, [\"x\"] = 343, [\"z\"] = 1108 }" }, ["inventory"] = {  } }, ["param2"] = 5, ["y"] = 3, ["param1"] = 0, ["z"] = 10, ["name"] = "default:torch" }, { ["x"] = 4, ["meta"] = { ["fields"] = { ["owner_info"] = "return { [\"y\"] = 2, [\"x\"] = 343, [\"z\"] = 1108 }" }, ["inventory"] = {  } }, ["param2"] = 9, ["y"] = 4, ["param1"] = 159, ["z"] = 1, ["name"] = "default:fence_wood" }, { ["x"] = 4, ["meta"] = { ["fields"] = { ["owner_info"] = "return { [\"y\"] = 2, [\"x\"] = 343, [\"z\"] = 1108 }" }, ["inventory"] = {  } }, ["param2"] = 2, ["y"] = 4, ["param1"] = 141, ["z"] = 2, ["name"] = "cottages:bench" }, { ["x"] = 4, ["meta"] = { ["fields"] = { ["owner_info"] = "return { [\"y\"] = 2, [\"x\"] = 343, [\"z\"] = 1108 }" }, ["inventory"] = {  } }, ["param2"] = 0, ["y"] = 4, ["param1"] = 173, ["z"] = 4, ["name"] = "cottages:bench" }, { ["x"] = 4, ["meta"] = { ["fields"] = { ["owner_info"] = "return { [\"y\"] = 2, [\"x\"] = 343, [\"z\"] = 1108 }" }, ["inventory"] = {  } }, ["param2"] = 9, ["y"] = 4, ["param1"] = 156, ["z"] = 5, ["name"] = "default:glass" }, { ["x"] = 4, ["meta"] = { ["fields"] = { ["owner_info"] = "return { [\"y\"] = 2, [\"x\"] = 343, [\"z\"] = 1108 }" }, ["inventory"] = {  } }, ["param2"] = 2, ["y"] = 4, ["param1"] = 171, ["z"] = 6, ["name"] = "cottages:bench" }, { ["x"] = 4, ["meta"] = { ["fields"] = { ["infotext"] = "Chest", ["owner_info"] = "return { [\"y\"] = 2, [\"x\"] = 343, [\"z\"] = 1108 }", ["formspec"] = "size[8,9]bgcolor[#080808BB;true]background[5,5;1,1;gui_formbg.png;true]listcolors[#00000069;#5A5A5A;#141318;#30434C;#FFF]list[current_name;main;0,0.3;8,4;]list[current_player;main;0,4.85;8,1;]list[current_player;main;0,6.08;8,3;8]image[0,4.85;1,1;gui_hb_bg.png]image[1,4.85;1,1;gui_hb_bg.png]image[2,4.85;1,1;gui_hb_bg.png]image[3,4.85;1,1;gui_hb_bg.png]image[4,4.85;1,1;gui_hb_bg.png]image[5,4.85;1,1;gui_hb_bg.png]image[6,4.85;1,1;gui_hb_bg.png]image[7,4.85;1,1;gui_hb_bg.png]" }, ["inventory"] = { ["main"] = { "", "", "default:coal_lump 7", "default:paper 6", "", "", "", "", "", "", "", "", "", "", "", "", "wool:white 6", "", "default:apple 5", "", "", "", "", "", "", "", "default:book", "", "", "", "", "" } } }, ["param2"] = 0, ["y"] = 4, ["param1"] = 0, ["z"] = 8, ["name"] = "default:chest" }, { ["x"] = 4, ["meta"] = { ["fields"] = { ["owner_info"] = "return { [\"y\"] = 2, [\"x\"] = 343, [\"z\"] = 1108 }" }, ["inventory"] = {  } }, ["param2"] = 9, ["y"] = 4, ["param1"] = 0, ["z"] = 9, ["name"] = "default:brick" }, { ["x"] = 4, ["meta"] = { ["fields"] = { ["owner_info"] = "return { [\"y\"] = 2, [\"x\"] = 343, [\"z\"] = 1108 }" }, ["inventory"] = {  } }, ["param2"] = 9, ["y"] = 5, ["param1"] = 172, ["z"] = 5, ["name"] = "default:glass" }, { ["x"] = 4, ["meta"] = { ["fields"] = { ["infotext"] = "Chest", ["owner_info"] = "return { [\"y\"] = 2, [\"x\"] = 343, [\"z\"] = 1108 }", ["formspec"] = "size[8,9]bgcolor[#080808BB;true]background[5,5;1,1;gui_formbg.png;true]listcolors[#00000069;#5A5A5A;#141318;#30434C;#FFF]list[current_name;main;0,0.3;8,4;]list[current_player;main;0,4.85;8,1;]list[current_player;main;0,6.08;8,3;8]image[0,4.85;1,1;gui_hb_bg.png]image[1,4.85;1,1;gui_hb_bg.png]image[2,4.85;1,1;gui_hb_bg.png]image[3,4.85;1,1;gui_hb_bg.png]image[4,4.85;1,1;gui_hb_bg.png]image[5,4.85;1,1;gui_hb_bg.png]image[6,4.85;1,1;gui_hb_bg.png]image[7,4.85;1,1;gui_hb_bg.png]" }, ["inventory"] = { ["main"] = { "", "", "", "", "default:paper", "", "default:book", "", "", "", "", "default:stick 19", "wool:white 4", "", "", "", "", "", "", "", "", "farming:string 3", "", "default:paper 2", "", "", "vessels:drinking_glass", "", "", "", "", "" } } }, ["param2"] = 0, ["y"] = 5, ["param1"] = 0, ["z"] = 8, ["name"] = "default:chest" }, { ["x"] = 4, ["meta"] = { ["fields"] = { ["owner_info"] = "return { [\"y\"] = 2, [\"x\"] = 343, [\"z\"] = 1108 }" }, ["inventory"] = {  } }, ["param2"] = 9, ["y"] = 5, ["param1"] = 0, ["z"] = 9, ["name"] = "default:brick" }, { ["x"] = 4, ["meta"] = { ["fields"] = { ["owner_info"] = "return { [\"y\"] = 2, [\"x\"] = 343, [\"z\"] = 1108 }" }, ["inventory"] = {  } }, ["param2"] = 9, ["y"] = 6, ["param1"] = 0, ["z"] = 5, ["name"] = "default:brick" }, { ["x"] = 4, ["meta"] = { ["fields"] = { ["owner_info"] = "return { [\"y\"] = 2, [\"x\"] = 343, [\"z\"] = 1108 }" }, ["inventory"] = {  } }, ["param2"] = 9, ["y"] = 6, ["param1"] = 0, ["z"] = 9, ["name"] = "default:brick" }, { ["x"] = 4, ["meta"] = { ["fields"] = {  }, ["inventory"] = {  } }, ["param2"] = 0, ["y"] = 7, ["param1"] = 125, ["z"] = 4, ["name"] = "stairs:slab_stone" }, { ["x"] = 4, ["meta"] = { ["fields"] = {  }, ["inventory"] = {  } }, ["param2"] = 0, ["y"] = 7, ["param1"] = 109, ["z"] = 5, ["name"] = "stairs:slab_stone" }, { ["x"] = 4, ["meta"] = { ["fields"] = { ["owner_info"] = "return { [\"y\"] = 2, [\"x\"] = 343, [\"z\"] = 1108 }" }, ["inventory"] = {  } }, ["param2"] = 9, ["y"] = 7, ["param1"] = 0, ["z"] = 6, ["name"] = "default:stone" }, { ["x"] = 4, ["meta"] = { ["fields"] = { ["owner_info"] = "return { [\"y\"] = 2, [\"x\"] = 343, [\"z\"] = 1108 }" }, ["inventory"] = {  } }, ["param2"] = 9, ["y"] = 7, ["param1"] = 0, ["z"] = 8, ["name"] = "default:stone" }, { ["x"] = 4, ["meta"] = { ["fields"] = {  }, ["inventory"] = {  } }, ["param2"] = 0, ["y"] = 7, ["param1"] = 157, ["z"] = 9, ["name"] = "stairs:slab_stone" }, { ["x"] = 4, ["meta"] = { ["fields"] = {  }, ["inventory"] = {  } }, ["param2"] = 0, ["y"] = 7, ["param1"] = 173, ["z"] = 10, ["name"] = "stairs:slab_stone" }, { ["x"] = 4, ["meta"] = { ["fields"] = {  }, ["inventory"] = {  } }, ["param2"] = 0, ["y"] = 8, ["param1"] = 141, ["z"] = 7, ["name"] = "stairs:slab_stone" }, { ["x"] = 5, ["meta"] = { ["fields"] = { ["owner_info"] = "return { [\"y\"] = 2, [\"x\"] = 343, [\"z\"] = 1108 }" }, ["inventory"] = {  } }, ["param2"] = 0, ["y"] = 0, ["param1"] = 0, ["z"] = 1, ["name"] = "default:clay" }, { ["x"] = 5, ["meta"] = { ["fields"] = { ["owner_info"] = "return { [\"y\"] = 2, [\"x\"] = 343, [\"z\"] = 1108 }" }, ["inventory"] = {  } }, ["param2"] = 0, ["y"] = 0, ["param1"] = 187, ["z"] = 4, ["name"] = "stairs:slab_brick" }, { ["x"] = 5, ["meta"] = { ["fields"] = { ["owner_info"] = "return { [\"y\"] = 2, [\"x\"] = 343, [\"z\"] = 1108 }" }, ["inventory"] = {  } }, ["param2"] = 9, ["y"] = 0, ["param1"] = 0, ["z"] = 5, ["name"] = "default:brick" }, { ["x"] = 5, ["meta"] = { ["fields"] = { ["owner_info"] = "return { [\"y\"] = 2, [\"x\"] = 343, [\"z\"] = 1108 }" }, ["inventory"] = {  } }, ["param2"] = 9, ["y"] = 0, ["param1"] = 0, ["z"] = 6, ["name"] = "default:brick" }, { ["x"] = 5, ["meta"] = { ["fields"] = { ["owner_info"] = "return { [\"y\"] = 2, [\"x\"] = 343, [\"z\"] = 1108 }" }, ["inventory"] = {  } }, ["param2"] = 9, ["y"] = 0, ["param1"] = 0, ["z"] = 7, ["name"] = "default:brick" }, { ["x"] = 5, ["meta"] = { ["fields"] = { ["owner_info"] = "return { [\"y\"] = 2, [\"x\"] = 343, [\"z\"] = 1108 }" }, ["inventory"] = {  } }, ["param2"] = 9, ["y"] = 0, ["param1"] = 0, ["z"] = 8, ["name"] = "default:brick" }, { ["x"] = 5, ["meta"] = { ["fields"] = { ["owner_info"] = "return { [\"y\"] = 2, [\"x\"] = 343, [\"z\"] = 1108 }" }, ["inventory"] = {  } }, ["param2"] = 9, ["y"] = 0, ["param1"] = 0, ["z"] = 9, ["name"] = "default:brick" }, { ["x"] = 5, ["meta"] = { ["fields"] = { ["owner_info"] = "return { [\"y\"] = 2, [\"x\"] = 343, [\"z\"] = 1108 }" }, ["inventory"] = {  } }, ["param2"] = 9, ["y"] = 1, ["param1"] = 0, ["z"] = 5, ["name"] = "default:brick" }, { ["x"] = 5, ["meta"] = { ["fields"] = { ["owner_info"] = "return { [\"y\"] = 2, [\"x\"] = 343, [\"z\"] = 1108 }" }, ["inventory"] = {  } }, ["param2"] = 9, ["y"] = 1, ["param1"] = 0, ["z"] = 9, ["name"] = "default:brick" }, { ["x"] = 5, ["meta"] = { ["fields"] = { ["owner_info"] = "return { [\"y\"] = 2, [\"x\"] = 343, [\"z\"] = 1108 }" }, ["inventory"] = {  } }, ["param2"] = 4, ["y"] = 2, ["param1"] = 0, ["z"] = 4, ["name"] = "default:torch" }, { ["x"] = 5, ["meta"] = { ["fields"] = { ["owner_info"] = "return { [\"y\"] = 2, [\"x\"] = 343, [\"z\"] = 1108 }" }, ["inventory"] = {  } }, ["param2"] = 9, ["y"] = 2, ["param1"] = 0, ["z"] = 5, ["name"] = "default:brick" }, { ["x"] = 5, ["meta"] = { ["fields"] = { ["owner_info"] = "return { [\"y\"] = 2, [\"x\"] = 343, [\"z\"] = 1108 }" }, ["inventory"] = {  } }, ["param2"] = 5, ["y"] = 2, ["param1"] = 0, ["z"] = 6, ["name"] = "default:torch" }, { ["x"] = 5, ["meta"] = { ["fields"] = { ["owner_info"] = "return { [\"y\"] = 2, [\"x\"] = 343, [\"z\"] = 1108 }" }, ["inventory"] = {  } }, ["param2"] = 4, ["y"] = 2, ["param1"] = 0, ["z"] = 8, ["name"] = "default:torch" }, { ["x"] = 5, ["meta"] = { ["fields"] = { ["owner_info"] = "return { [\"y\"] = 2, [\"x\"] = 343, [\"z\"] = 1108 }" }, ["inventory"] = {  } }, ["param2"] = 9, ["y"] = 2, ["param1"] = 0, ["z"] = 9, ["name"] = "default:brick" }, { ["x"] = 5, ["meta"] = { ["fields"] = { ["owner_info"] = "return { [\"y\"] = 2, [\"x\"] = 343, [\"z\"] = 1108 }" }, ["inventory"] = {  } }, ["param2"] = 9, ["y"] = 3, ["param1"] = 0, ["z"] = 1, ["name"] = "default:brick" }, { ["x"] = 5, ["meta"] = { ["fields"] = { ["owner_info"] = "return { [\"y\"] = 2, [\"x\"] = 343, [\"z\"] = 1108 }" }, ["inventory"] = {  } }, ["param2"] = 9, ["y"] = 3, ["param1"] = 0, ["z"] = 2, ["name"] = "default:brick" }, { ["x"] = 5, ["meta"] = { ["fields"] = { ["owner_info"] = "return { [\"y\"] = 2, [\"x\"] = 343, [\"z\"] = 1108 }" }, ["inventory"] = {  } }, ["param2"] = 0, ["y"] = 3, ["param1"] = 189, ["z"] = 3, ["name"] = "stairs:slab_brick" }, { ["x"] = 5, ["meta"] = { ["fields"] = { ["owner_info"] = "return { [\"y\"] = 2, [\"x\"] = 343, [\"z\"] = 1108 }" }, ["inventory"] = {  } }, ["param2"] = 9, ["y"] = 3, ["param1"] = 0, ["z"] = 4, ["name"] = "default:brick" }, { ["x"] = 5, ["meta"] = { ["fields"] = { ["owner_info"] = "return { [\"y\"] = 2, [\"x\"] = 343, [\"z\"] = 1108 }" }, ["inventory"] = {  } }, ["param2"] = 9, ["y"] = 3, ["param1"] = 0, ["z"] = 5, ["name"] = "default:brick" }, { ["x"] = 5, ["meta"] = { ["fields"] = { ["owner_info"] = "return { [\"y\"] = 2, [\"x\"] = 343, [\"z\"] = 1108 }" }, ["inventory"] = {  } }, ["param2"] = 0, ["y"] = 3, ["param1"] = 0, ["z"] = 6, ["name"] = "default:wood" }, { ["x"] = 5, ["meta"] = { ["fields"] = { ["owner_info"] = "return { [\"y\"] = 2, [\"x\"] = 343, [\"z\"] = 1108 }" }, ["inventory"] = {  } }, ["param2"] = 0, ["y"] = 3, ["param1"] = 0, ["z"] = 7, ["name"] = "default:wood" }, { ["x"] = 5, ["meta"] = { ["fields"] = { ["owner_info"] = "return { [\"y\"] = 2, [\"x\"] = 343, [\"z\"] = 1108 }" }, ["inventory"] = {  } }, ["param2"] = 0, ["y"] = 3, ["param1"] = 0, ["z"] = 8, ["name"] = "default:wood" }, { ["x"] = 5, ["meta"] = { ["fields"] = { ["owner_info"] = "return { [\"y\"] = 2, [\"x\"] = 343, [\"z\"] = 1108 }" }, ["inventory"] = {  } }, ["param2"] = 9, ["y"] = 3, ["param1"] = 0, ["z"] = 9, ["name"] = "default:brick" }, { ["x"] = 5, ["meta"] = { ["fields"] = { ["owner_info"] = "return { [\"y\"] = 2, [\"x\"] = 343, [\"z\"] = 1108 }" }, ["inventory"] = {  } }, ["param2"] = 9, ["y"] = 4, ["param1"] = 175, ["z"] = 1, ["name"] = "default:fence_wood" }, { ["x"] = 5, ["meta"] = { ["fields"] = { ["owner_info"] = "return { [\"y\"] = 2, [\"x\"] = 343, [\"z\"] = 1108 }" }, ["inventory"] = {  } }, ["param2"] = 2, ["y"] = 4, ["param1"] = 157, ["z"] = 2, ["name"] = "cottages:bench" }, { ["x"] = 5, ["meta"] = { ["fields"] = { ["owner_info"] = "return { [\"y\"] = 2, [\"x\"] = 343, [\"z\"] = 1108 }" }, ["inventory"] = {  } }, ["param2"] = 0, ["y"] = 4, ["param1"] = 157, ["z"] = 4, ["name"] = "cottages:bench" }, { ["x"] = 5, ["meta"] = { ["fields"] = { ["owner_info"] = "return { [\"y\"] = 2, [\"x\"] = 343, [\"z\"] = 1108 }" }, ["inventory"] = {  } }, ["param2"] = 9, ["y"] = 4, ["param1"] = 172, ["z"] = 5, ["name"] = "default:glass" }, { ["x"] = 5, ["meta"] = { ["fields"] = { ["owner_info"] = "return { [\"y\"] = 2, [\"x\"] = 343, [\"z\"] = 1108 }" }, ["inventory"] = {  } }, ["param2"] = 2, ["y"] = 4, ["param1"] = 187, ["z"] = 6, ["name"] = "cottages:bench" }, { ["x"] = 5, ["meta"] = { ["fields"] = { ["owner_info"] = "return { [\"y\"] = 2, [\"x\"] = 343, [\"z\"] = 1108 }" }, ["inventory"] = {  } }, ["param2"] = 1, ["y"] = 4, ["param1"] = 170, ["z"] = 8, ["name"] = "cottages:bed_foot" }, { ["x"] = 5, ["meta"] = { ["fields"] = { ["owner_info"] = "return { [\"y\"] = 2, [\"x\"] = 343, [\"z\"] = 1108 }" }, ["inventory"] = {  } }, ["param2"] = 9, ["y"] = 4, ["param1"] = 0, ["z"] = 9, ["name"] = "default:brick" }, { ["x"] = 5, ["meta"] = { ["fields"] = { ["owner_info"] = "return { [\"y\"] = 2, [\"x\"] = 343, [\"z\"] = 1108 }" }, ["inventory"] = {  } }, ["param2"] = 9, ["y"] = 5, ["param1"] = 188, ["z"] = 5, ["name"] = "default:glass" }, { ["x"] = 5, ["meta"] = { ["fields"] = { ["owner_info"] = "return { [\"y\"] = 2, [\"x\"] = 343, [\"z\"] = 1108 }" }, ["inventory"] = {  } }, ["param2"] = 9, ["y"] = 5, ["param1"] = 0, ["z"] = 9, ["name"] = "default:brick" }, { ["x"] = 5, ["meta"] = { ["fields"] = { ["owner_info"] = "return { [\"y\"] = 2, [\"x\"] = 343, [\"z\"] = 1108 }" }, ["inventory"] = {  } }, ["param2"] = 5, ["y"] = 5, ["param1"] = 0, ["z"] = 10, ["name"] = "default:torch" }, { ["x"] = 5, ["meta"] = { ["fields"] = { ["owner_info"] = "return { [\"y\"] = 2, [\"x\"] = 343, [\"z\"] = 1108 }" }, ["inventory"] = {  } }, ["param2"] = 9, ["y"] = 6, ["param1"] = 0, ["z"] = 5, ["name"] = "default:brick" }, { ["x"] = 5, ["meta"] = { ["fields"] = { ["owner_info"] = "return { [\"y\"] = 2, [\"x\"] = 343, [\"z\"] = 1108 }" }, ["inventory"] = {  } }, ["param2"] = 9, ["y"] = 6, ["param1"] = 0, ["z"] = 9, ["name"] = "default:brick" }, { ["x"] = 5, ["meta"] = { ["fields"] = {  }, ["inventory"] = {  } }, ["param2"] = 0, ["y"] = 7, ["param1"] = 141, ["z"] = 4, ["name"] = "stairs:slab_stone" }, { ["x"] = 5, ["meta"] = { ["fields"] = {  }, ["inventory"] = {  } }, ["param2"] = 0, ["y"] = 7, ["param1"] = 125, ["z"] = 5, ["name"] = "stairs:slab_stone" }, { ["x"] = 5, ["meta"] = { ["fields"] = { ["owner_info"] = "return { [\"y\"] = 2, [\"x\"] = 343, [\"z\"] = 1108 }" }, ["inventory"] = {  } }, ["param2"] = 9, ["y"] = 7, ["param1"] = 0, ["z"] = 6, ["name"] = "default:stone" }, { ["x"] = 5, ["meta"] = { ["fields"] = { ["owner_info"] = "return { [\"y\"] = 2, [\"x\"] = 343, [\"z\"] = 1108 }" }, ["inventory"] = {  } }, ["param2"] = 9, ["y"] = 7, ["param1"] = 0, ["z"] = 8, ["name"] = "default:stone" }, { ["x"] = 5, ["meta"] = { ["fields"] = {  }, ["inventory"] = {  } }, ["param2"] = 0, ["y"] = 7, ["param1"] = 173, ["z"] = 9, ["name"] = "stairs:slab_stone" }, { ["x"] = 5, ["meta"] = { ["fields"] = {  }, ["inventory"] = {  } }, ["param2"] = 0, ["y"] = 7, ["param1"] = 189, ["z"] = 10, ["name"] = "stairs:slab_stone" }, { ["x"] = 5, ["meta"] = { ["fields"] = {  }, ["inventory"] = {  } }, ["param2"] = 0, ["y"] = 8, ["param1"] = 157, ["z"] = 7, ["name"] = "stairs:slab_stone" }, { ["x"] = 6, ["meta"] = { ["fields"] = { ["owner_info"] = "return { [\"y\"] = 2, [\"x\"] = 343, [\"z\"] = 1108 }" }, ["inventory"] = {  } }, ["param2"] = 0, ["y"] = 0, ["param1"] = 0, ["z"] = 0, ["name"] = "default:clay" }, { ["x"] = 6, ["meta"] = { ["fields"] = { ["owner_info"] = "return { [\"y\"] = 2, [\"x\"] = 343, [\"z\"] = 1108 }" }, ["inventory"] = {  } }, ["param2"] = 0, ["y"] = 0, ["param1"] = 0, ["z"] = 1, ["name"] = "default:clay" }, { ["x"] = 6, ["meta"] = { ["fields"] = { ["owner_info"] = "return { [\"y\"] = 2, [\"x\"] = 343, [\"z\"] = 1108 }" }, ["inventory"] = {  } }, ["param2"] = 9, ["y"] = 0, ["param1"] = 0, ["z"] = 5, ["name"] = "default:brick" }, { ["x"] = 6, ["meta"] = { ["fields"] = { ["owner_info"] = "return { [\"y\"] = 2, [\"x\"] = 343, [\"z\"] = 1108 }" }, ["inventory"] = {  } }, ["param2"] = 9, ["y"] = 0, ["param1"] = 0, ["z"] = 6, ["name"] = "default:brick" }, { ["x"] = 6, ["meta"] = { ["fields"] = { ["owner_info"] = "return { [\"y\"] = 2, [\"x\"] = 343, [\"z\"] = 1108 }" }, ["inventory"] = {  } }, ["param2"] = 9, ["y"] = 0, ["param1"] = 0, ["z"] = 7, ["name"] = "default:brick" }, { ["x"] = 6, ["meta"] = { ["fields"] = { ["owner_info"] = "return { [\"y\"] = 2, [\"x\"] = 343, [\"z\"] = 1108 }" }, ["inventory"] = {  } }, ["param2"] = 9, ["y"] = 0, ["param1"] = 0, ["z"] = 8, ["name"] = "default:brick" }, { ["x"] = 6, ["meta"] = { ["fields"] = { ["owner_info"] = "return { [\"y\"] = 2, [\"x\"] = 343, [\"z\"] = 1108 }" }, ["inventory"] = {  } }, ["param2"] = 9, ["y"] = 0, ["param1"] = 0, ["z"] = 9, ["name"] = "default:brick" }, { ["x"] = 6, ["meta"] = { ["fields"] = { ["owner_info"] = "return { [\"y\"] = 2, [\"x\"] = 343, [\"z\"] = 1108 }" }, ["inventory"] = {  } }, ["param2"] = 0, ["y"] = 1, ["param1"] = 0, ["z"] = 1, ["name"] = "default:clay" }, { ["x"] = 6, ["meta"] = { ["fields"] = { ["owner_info"] = "return { [\"y\"] = 2, [\"x\"] = 343, [\"z\"] = 1108 }" }, ["inventory"] = {  } }, ["param2"] = 9, ["y"] = 1, ["param1"] = 0, ["z"] = 5, ["name"] = "default:brick" }, { ["x"] = 6, ["meta"] = { ["fields"] = { ["infotext"] = "Chest", ["owner_info"] = "return { [\"y\"] = 2, [\"x\"] = 343, [\"z\"] = 1108 }", ["formspec"] = "size[8,9]bgcolor[#080808BB;true]background[5,5;1,1;gui_formbg.png;true]listcolors[#00000069;#5A5A5A;#141318;#30434C;#FFF]list[current_name;main;0,0.3;8,4;]list[current_player;main;0,4.85;8,1;]list[current_player;main;0,6.08;8,3;8]image[0,4.85;1,1;gui_hb_bg.png]image[1,4.85;1,1;gui_hb_bg.png]image[2,4.85;1,1;gui_hb_bg.png]image[3,4.85;1,1;gui_hb_bg.png]image[4,4.85;1,1;gui_hb_bg.png]image[5,4.85;1,1;gui_hb_bg.png]image[6,4.85;1,1;gui_hb_bg.png]image[7,4.85;1,1;gui_hb_bg.png]" }, ["inventory"] = { ["main"] = { "", "", "", "wool:white 6", "", "", "", "", "", "default:paper 6", "vessels:glass_bottle 2", "", "", "", "default:torch 9", "", "", "", "", "", "", "", "", "default:paper 6", "", "", "", "vessels:drinking_glass 2", "default:paper 3", "", "default:pick_stone", "" } } }, ["param2"] = 1, ["y"] = 1, ["param1"] = 0, ["z"] = 6, ["name"] = "default:chest" }, { ["x"] = 6, ["meta"] = { ["fields"] = { ["infotext"] = "Chest", ["owner_info"] = "return { [\"y\"] = 2, [\"x\"] = 343, [\"z\"] = 1108 }", ["formspec"] = "size[8,9]bgcolor[#080808BB;true]background[5,5;1,1;gui_formbg.png;true]listcolors[#00000069;#5A5A5A;#141318;#30434C;#FFF]list[current_name;main;0,0.3;8,4;]list[current_player;main;0,4.85;8,1;]list[current_player;main;0,6.08;8,3;8]image[0,4.85;1,1;gui_hb_bg.png]image[1,4.85;1,1;gui_hb_bg.png]image[2,4.85;1,1;gui_hb_bg.png]image[3,4.85;1,1;gui_hb_bg.png]image[4,4.85;1,1;gui_hb_bg.png]image[5,4.85;1,1;gui_hb_bg.png]image[6,4.85;1,1;gui_hb_bg.png]image[7,4.85;1,1;gui_hb_bg.png]" }, ["inventory"] = { ["main"] = { "", "", "", "", "", "", "", "default:torch 8", "default:coal_lump 2", "default:steel_ingot 4", "farming:string 3", "", "", "", "", "", "", "default:paper 6", "", "", "", "", "", "", "", "", "", "", "default:apple 3", "", "", "" } } }, ["param2"] = 1, ["y"] = 1, ["param1"] = 0, ["z"] = 7, ["name"] = "default:chest" }, { ["x"] = 6, ["meta"] = { ["fields"] = { ["infotext"] = "Chest", ["owner_info"] = "return { [\"y\"] = 2, [\"x\"] = 343, [\"z\"] = 1108 }", ["formspec"] = "size[8,9]bgcolor[#080808BB;true]background[5,5;1,1;gui_formbg.png;true]listcolors[#00000069;#5A5A5A;#141318;#30434C;#FFF]list[current_name;main;0,0.3;8,4;]list[current_player;main;0,4.85;8,1;]list[current_player;main;0,6.08;8,3;8]image[0,4.85;1,1;gui_hb_bg.png]image[1,4.85;1,1;gui_hb_bg.png]image[2,4.85;1,1;gui_hb_bg.png]image[3,4.85;1,1;gui_hb_bg.png]image[4,4.85;1,1;gui_hb_bg.png]image[5,4.85;1,1;gui_hb_bg.png]image[6,4.85;1,1;gui_hb_bg.png]image[7,4.85;1,1;gui_hb_bg.png]" }, ["inventory"] = { ["main"] = { "", "", "", "", "default:shovel_stone", "", "", "", "", "default:ladder", "", "", "", "", "", "", "", "", "", "", "", "", "farming:string 3", "", "", "", "", "", "", "", "farming:string 2", "" } } }, ["param2"] = 1, ["y"] = 1, ["param1"] = 0, ["z"] = 8, ["name"] = "default:chest" }, { ["x"] = 6, ["meta"] = { ["fields"] = { ["owner_info"] = "return { [\"y\"] = 2, [\"x\"] = 343, [\"z\"] = 1108 }" }, ["inventory"] = {  } }, ["param2"] = 9, ["y"] = 1, ["param1"] = 0, ["z"] = 9, ["name"] = "default:brick" }, { ["x"] = 6, ["meta"] = { ["fields"] = { ["owner_info"] = "return { [\"y\"] = 2, [\"x\"] = 343, [\"z\"] = 1108 }" }, ["inventory"] = {  } }, ["param2"] = 0, ["y"] = 2, ["param1"] = 0, ["z"] = 1, ["name"] = "default:torch" }, { ["x"] = 6, ["meta"] = { ["fields"] = { ["owner_info"] = "return { [\"y\"] = 2, [\"x\"] = 343, [\"z\"] = 1108 }" }, ["inventory"] = {  } }, ["param2"] = 0, ["y"] = 2, ["param1"] = 0, ["z"] = 5, ["name"] = "default:brick" }, { ["x"] = 6, ["meta"] = { ["fields"] = { ["infotext"] = "Chest", ["owner_info"] = "return { [\"y\"] = 2, [\"x\"] = 343, [\"z\"] = 1108 }", ["formspec"] = "size[8,9]bgcolor[#080808BB;true]background[5,5;1,1;gui_formbg.png;true]listcolors[#00000069;#5A5A5A;#141318;#30434C;#FFF]list[current_name;main;0,0.3;8,4;]list[current_player;main;0,4.85;8,1;]list[current_player;main;0,6.08;8,3;8]image[0,4.85;1,1;gui_hb_bg.png]image[1,4.85;1,1;gui_hb_bg.png]image[2,4.85;1,1;gui_hb_bg.png]image[3,4.85;1,1;gui_hb_bg.png]image[4,4.85;1,1;gui_hb_bg.png]image[5,4.85;1,1;gui_hb_bg.png]image[6,4.85;1,1;gui_hb_bg.png]image[7,4.85;1,1;gui_hb_bg.png]" }, ["inventory"] = { ["main"] = { "", "", "", "", "", "", "", "", "", "", "", "", "", "", "", "default:apple 7", "", "", "", "default:paper 6", "wool:white 3", "", "", "", "", "", "farming:string 2", "", "default:book", "", "", "" } } }, ["param2"] = 1, ["y"] = 2, ["param1"] = 0, ["z"] = 6, ["name"] = "default:chest" }, { ["x"] = 6, ["meta"] = { ["fields"] = { ["infotext"] = "Chest", ["owner_info"] = "return { [\"y\"] = 2, [\"x\"] = 343, [\"z\"] = 1108 }", ["formspec"] = "size[8,9]bgcolor[#080808BB;true]background[5,5;1,1;gui_formbg.png;true]listcolors[#00000069;#5A5A5A;#141318;#30434C;#FFF]list[current_name;main;0,0.3;8,4;]list[current_player;main;0,4.85;8,1;]list[current_player;main;0,6.08;8,3;8]image[0,4.85;1,1;gui_hb_bg.png]image[1,4.85;1,1;gui_hb_bg.png]image[2,4.85;1,1;gui_hb_bg.png]image[3,4.85;1,1;gui_hb_bg.png]image[4,4.85;1,1;gui_hb_bg.png]image[5,4.85;1,1;gui_hb_bg.png]image[6,4.85;1,1;gui_hb_bg.png]image[7,4.85;1,1;gui_hb_bg.png]" }, ["inventory"] = { ["main"] = { "wool:white 3", "", "", "", "default:apple 2", "", "", "", "", "default:apple 5", "default:torch 4", "", "", "", "", "default:stick 32", "", "", "", "", "", "", "", "", "default:ladder", "default:paper 6", "", "", "", "", "", "" } } }, ["param2"] = 1, ["y"] = 2, ["param1"] = 0, ["z"] = 7, ["name"] = "default:chest" }, { ["x"] = 6, ["meta"] = { ["fields"] = { ["infotext"] = "Chest", ["owner_info"] = "return { [\"y\"] = 2, [\"x\"] = 343, [\"z\"] = 1108 }", ["formspec"] = "size[8,9]bgcolor[#080808BB;true]background[5,5;1,1;gui_formbg.png;true]listcolors[#00000069;#5A5A5A;#141318;#30434C;#FFF]list[current_name;main;0,0.3;8,4;]list[current_player;main;0,4.85;8,1;]list[current_player;main;0,6.08;8,3;8]image[0,4.85;1,1;gui_hb_bg.png]image[1,4.85;1,1;gui_hb_bg.png]image[2,4.85;1,1;gui_hb_bg.png]image[3,4.85;1,1;gui_hb_bg.png]image[4,4.85;1,1;gui_hb_bg.png]image[5,4.85;1,1;gui_hb_bg.png]image[6,4.85;1,1;gui_hb_bg.png]image[7,4.85;1,1;gui_hb_bg.png]" }, ["inventory"] = { ["main"] = { "default:book", "", "", "", "", "", "", "", "", "default:paper 2", "", "", "", "", "", "", "", "", "farming:string 4", "", "", "", "", "", "", "default:steel_ingot 2", "bucket:bucket_empty 3", "", "", "", "", "" } } }, ["param2"] = 1, ["y"] = 2, ["param1"] = 0, ["z"] = 8, ["name"] = "default:chest" }, { ["x"] = 6, ["meta"] = { ["fields"] = { ["owner_info"] = "return { [\"y\"] = 2, [\"x\"] = 343, [\"z\"] = 1108 }" }, ["inventory"] = {  } }, ["param2"] = 9, ["y"] = 2, ["param1"] = 0, ["z"] = 9, ["name"] = "default:brick" }, { ["x"] = 6, ["meta"] = { ["fields"] = { ["owner_info"] = "return { [\"y\"] = 2, [\"x\"] = 343, [\"z\"] = 1108 }" }, ["inventory"] = {  } }, ["param2"] = 5, ["y"] = 2, ["param1"] = 0, ["z"] = 10, ["name"] = "default:torch" }, { ["x"] = 6, ["meta"] = { ["fields"] = { ["owner_info"] = "return { [\"y\"] = 2, [\"x\"] = 343, [\"z\"] = 1108 }" }, ["inventory"] = {  } }, ["param2"] = 9, ["y"] = 3, ["param1"] = 0, ["z"] = 1, ["name"] = "default:brick" }, { ["x"] = 6, ["meta"] = { ["fields"] = { ["owner_info"] = "return { [\"y\"] = 2, [\"x\"] = 343, [\"z\"] = 1108 }" }, ["inventory"] = {  } }, ["param2"] = 9, ["y"] = 3, ["param1"] = 0, ["z"] = 2, ["name"] = "default:brick" }, { ["x"] = 6, ["meta"] = { ["fields"] = { ["owner_info"] = "return { [\"y\"] = 2, [\"x\"] = 343, [\"z\"] = 1108 }" }, ["inventory"] = {  } }, ["param2"] = 0, ["y"] = 3, ["param1"] = 173, ["z"] = 3, ["name"] = "stairs:slab_brick" }, { ["x"] = 6, ["meta"] = { ["fields"] = { ["owner_info"] = "return { [\"y\"] = 2, [\"x\"] = 343, [\"z\"] = 1108 }" }, ["inventory"] = {  } }, ["param2"] = 9, ["y"] = 3, ["param1"] = 0, ["z"] = 4, ["name"] = "default:brick" }, { ["x"] = 6, ["meta"] = { ["fields"] = { ["owner_info"] = "return { [\"y\"] = 2, [\"x\"] = 343, [\"z\"] = 1108 }" }, ["inventory"] = {  } }, ["param2"] = 9, ["y"] = 3, ["param1"] = 0, ["z"] = 5, ["name"] = "default:brick" }, { ["x"] = 6, ["meta"] = { ["fields"] = { ["owner_info"] = "return { [\"y\"] = 2, [\"x\"] = 343, [\"z\"] = 1108 }" }, ["inventory"] = {  } }, ["param2"] = 0, ["y"] = 3, ["param1"] = 0, ["z"] = 6, ["name"] = "default:wood" }, { ["x"] = 6, ["meta"] = { ["fields"] = { ["owner_info"] = "return { [\"y\"] = 2, [\"x\"] = 343, [\"z\"] = 1108 }" }, ["inventory"] = {  } }, ["param2"] = 0, ["y"] = 3, ["param1"] = 0, ["z"] = 7, ["name"] = "default:wood" }, { ["x"] = 6, ["meta"] = { ["fields"] = { ["owner_info"] = "return { [\"y\"] = 2, [\"x\"] = 343, [\"z\"] = 1108 }" }, ["inventory"] = {  } }, ["param2"] = 0, ["y"] = 3, ["param1"] = 0, ["z"] = 8, ["name"] = "default:wood" }, { ["x"] = 6, ["meta"] = { ["fields"] = { ["owner_info"] = "return { [\"y\"] = 2, [\"x\"] = 343, [\"z\"] = 1108 }" }, ["inventory"] = {  } }, ["param2"] = 9, ["y"] = 3, ["param1"] = 0, ["z"] = 9, ["name"] = "default:brick" }, { ["x"] = 6, ["meta"] = { ["fields"] = { ["owner_info"] = "return { [\"y\"] = 2, [\"x\"] = 343, [\"z\"] = 1108 }" }, ["inventory"] = {  } }, ["param2"] = 9, ["y"] = 4, ["param1"] = 191, ["z"] = 1, ["name"] = "default:fence_wood" }, { ["x"] = 6, ["meta"] = { ["fields"] = { ["owner_info"] = "return { [\"y\"] = 2, [\"x\"] = 343, [\"z\"] = 1108 }" }, ["inventory"] = {  } }, ["param2"] = 2, ["y"] = 4, ["param1"] = 173, ["z"] = 2, ["name"] = "cottages:bench" }, { ["x"] = 6, ["meta"] = { ["fields"] = { ["owner_info"] = "return { [\"y\"] = 2, [\"x\"] = 343, [\"z\"] = 1108 }" }, ["inventory"] = {  } }, ["param2"] = 0, ["y"] = 4, ["param1"] = 141, ["z"] = 4, ["name"] = "cottages:bench" }, { ["x"] = 6, ["meta"] = { ["fields"] = { ["owner_info"] = "return { [\"y\"] = 2, [\"x\"] = 343, [\"z\"] = 1108 }" }, ["inventory"] = {  } }, ["param2"] = 9, ["y"] = 4, ["param1"] = 0, ["z"] = 5, ["name"] = "default:brick" }, { ["x"] = 6, ["meta"] = { ["fields"] = { ["owner_info"] = "return { [\"y\"] = 2, [\"x\"] = 343, [\"z\"] = 1108 }", ["formspec"] = "size[8,7;]bgcolor[#080808BB;true]background[5,5;1,1;gui_formbg.png;true]listcolors[#00000069;#5A5A5A;#141318;#30434C;#FFF]list[context;books;0,0.3;8,2;]list[current_player;main;0,2.85;8,1;]list[current_player;main;0,4.08;8,3;8]image[0,2.85;1,1;gui_hb_bg.png]image[1,2.85;1,1;gui_hb_bg.png]image[2,2.85;1,1;gui_hb_bg.png]image[3,2.85;1,1;gui_hb_bg.png]image[4,2.85;1,1;gui_hb_bg.png]image[5,2.85;1,1;gui_hb_bg.png]image[6,2.85;1,1;gui_hb_bg.png]image[7,2.85;1,1;gui_hb_bg.png]" }, ["inventory"] = { ["books"] = { "", "", "", "", "", "", "", "", "", "", "", "", "", "", "", "" } } }, ["param2"] = 0, ["y"] = 4, ["param1"] = 204, ["z"] = 6, ["name"] = "default:bookshelf" }, { ["x"] = 6, ["meta"] = { ["fields"] = { ["owner_info"] = "return { [\"y\"] = 2, [\"x\"] = 343, [\"z\"] = 1108 }" }, ["inventory"] = {  } }, ["param2"] = 1, ["y"] = 4, ["param1"] = 187, ["z"] = 8, ["name"] = "cottages:bed_head" }, { ["x"] = 6, ["meta"] = { ["fields"] = { ["owner_info"] = "return { [\"y\"] = 2, [\"x\"] = 343, [\"z\"] = 1108 }" }, ["inventory"] = {  } }, ["param2"] = 9, ["y"] = 4, ["param1"] = 0, ["z"] = 9, ["name"] = "default:brick" }, { ["x"] = 6, ["meta"] = { ["fields"] = { ["owner_info"] = "return { [\"y\"] = 2, [\"x\"] = 343, [\"z\"] = 1108 }" }, ["inventory"] = {  } }, ["param2"] = 9, ["y"] = 5, ["param1"] = 0, ["z"] = 5, ["name"] = "default:brick" }, { ["x"] = 6, ["meta"] = { ["fields"] = { ["owner_info"] = "return { [\"y\"] = 2, [\"x\"] = 343, [\"z\"] = 1108 }" }, ["inventory"] = {  } }, ["param2"] = 1, ["y"] = 5, ["param1"] = 0, ["z"] = 6, ["name"] = "default:torch" }, { ["x"] = 6, ["meta"] = { ["fields"] = { ["owner_info"] = "return { [\"y\"] = 2, [\"x\"] = 343, [\"z\"] = 1108 }" }, ["inventory"] = {  } }, ["param2"] = 9, ["y"] = 5, ["param1"] = 0, ["z"] = 9, ["name"] = "default:brick" }, { ["x"] = 6, ["meta"] = { ["fields"] = { ["owner_info"] = "return { [\"y\"] = 2, [\"x\"] = 343, [\"z\"] = 1108 }" }, ["inventory"] = {  } }, ["param2"] = 9, ["y"] = 6, ["param1"] = 0, ["z"] = 5, ["name"] = "default:brick" }, { ["x"] = 6, ["meta"] = { ["fields"] = { ["owner_info"] = "return { [\"y\"] = 2, [\"x\"] = 343, [\"z\"] = 1108 }" }, ["inventory"] = {  } }, ["param2"] = 4, ["y"] = 6, ["param1"] = 0, ["z"] = 8, ["name"] = "default:torch" }, { ["x"] = 6, ["meta"] = { ["fields"] = { ["owner_info"] = "return { [\"y\"] = 2, [\"x\"] = 343, [\"z\"] = 1108 }" }, ["inventory"] = {  } }, ["param2"] = 9, ["y"] = 6, ["param1"] = 0, ["z"] = 9, ["name"] = "default:brick" }, { ["x"] = 6, ["meta"] = { ["fields"] = {  }, ["inventory"] = {  } }, ["param2"] = 0, ["y"] = 7, ["param1"] = 125, ["z"] = 4, ["name"] = "stairs:slab_stone" }, { ["x"] = 6, ["meta"] = { ["fields"] = {  }, ["inventory"] = {  } }, ["param2"] = 0, ["y"] = 7, ["param1"] = 141, ["z"] = 5, ["name"] = "stairs:slab_stone" }, { ["x"] = 6, ["meta"] = { ["fields"] = { ["owner_info"] = "return { [\"y\"] = 2, [\"x\"] = 343, [\"z\"] = 1108 }" }, ["inventory"] = {  } }, ["param2"] = 9, ["y"] = 7, ["param1"] = 0, ["z"] = 6, ["name"] = "default:stone" }, { ["x"] = 6, ["meta"] = { ["fields"] = { ["owner_info"] = "return { [\"y\"] = 2, [\"x\"] = 343, [\"z\"] = 1108 }" }, ["inventory"] = {  } }, ["param2"] = 9, ["y"] = 7, ["param1"] = 0, ["z"] = 7, ["name"] = "default:stone" }, { ["x"] = 6, ["meta"] = { ["fields"] = { ["owner_info"] = "return { [\"y\"] = 2, [\"x\"] = 343, [\"z\"] = 1108 }" }, ["inventory"] = {  } }, ["param2"] = 9, ["y"] = 7, ["param1"] = 0, ["z"] = 8, ["name"] = "default:stone" }, { ["x"] = 6, ["meta"] = { ["fields"] = {  }, ["inventory"] = {  } }, ["param2"] = 0, ["y"] = 7, ["param1"] = 157, ["z"] = 9, ["name"] = "stairs:slab_stone" }, { ["x"] = 6, ["meta"] = { ["fields"] = {  }, ["inventory"] = {  } }, ["param2"] = 0, ["y"] = 7, ["param1"] = 173, ["z"] = 10, ["name"] = "stairs:slab_stone" }, { ["x"] = 7, ["meta"] = { ["fields"] = { ["owner_info"] = "return { [\"y\"] = 2, [\"x\"] = 343, [\"z\"] = 1108 }" }, ["inventory"] = {  } }, ["param2"] = 9, ["y"] = 0, ["param1"] = 173, ["z"] = 1, ["name"] = "default:fence_wood" }, { ["x"] = 7, ["meta"] = { ["fields"] = { ["owner_info"] = "return { [\"y\"] = 2, [\"x\"] = 343, [\"z\"] = 1108 }" }, ["inventory"] = {  } }, ["param2"] = 9, ["y"] = 0, ["param1"] = 0, ["z"] = 6, ["name"] = "default:brick" }, { ["x"] = 7, ["meta"] = { ["fields"] = { ["owner_info"] = "return { [\"y\"] = 2, [\"x\"] = 343, [\"z\"] = 1108 }" }, ["inventory"] = {  } }, ["param2"] = 9, ["y"] = 0, ["param1"] = 0, ["z"] = 7, ["name"] = "default:brick" }, { ["x"] = 7, ["meta"] = { ["fields"] = { ["owner_info"] = "return { [\"y\"] = 2, [\"x\"] = 343, [\"z\"] = 1108 }" }, ["inventory"] = {  } }, ["param2"] = 9, ["y"] = 0, ["param1"] = 0, ["z"] = 8, ["name"] = "default:brick" }, { ["x"] = 7, ["meta"] = { ["fields"] = { ["owner_info"] = "return { [\"y\"] = 2, [\"x\"] = 343, [\"z\"] = 1108 }" }, ["inventory"] = {  } }, ["param2"] = 9, ["y"] = 1, ["param1"] = 189, ["z"] = 1, ["name"] = "default:fence_wood" }, { ["x"] = 7, ["meta"] = { ["fields"] = { ["owner_info"] = "return { [\"y\"] = 2, [\"x\"] = 343, [\"z\"] = 1108 }" }, ["inventory"] = {  } }, ["param2"] = 9, ["y"] = 1, ["param1"] = 0, ["z"] = 5, ["name"] = "default:brick" }, { ["x"] = 7, ["meta"] = { ["fields"] = { ["owner_info"] = "return { [\"y\"] = 2, [\"x\"] = 343, [\"z\"] = 1108 }" }, ["inventory"] = {  } }, ["param2"] = 9, ["y"] = 1, ["param1"] = 0, ["z"] = 6, ["name"] = "default:brick" }, { ["x"] = 7, ["meta"] = { ["fields"] = { ["owner_info"] = "return { [\"y\"] = 2, [\"x\"] = 343, [\"z\"] = 1108 }" }, ["inventory"] = {  } }, ["param2"] = 9, ["y"] = 1, ["param1"] = 0, ["z"] = 7, ["name"] = "default:brick" }, { ["x"] = 7, ["meta"] = { ["fields"] = { ["owner_info"] = "return { [\"y\"] = 2, [\"x\"] = 343, [\"z\"] = 1108 }" }, ["inventory"] = {  } }, ["param2"] = 9, ["y"] = 1, ["param1"] = 0, ["z"] = 8, ["name"] = "default:brick" }, { ["x"] = 7, ["meta"] = { ["fields"] = { ["owner_info"] = "return { [\"y\"] = 2, [\"x\"] = 343, [\"z\"] = 1108 }" }, ["inventory"] = {  } }, ["param2"] = 0, ["y"] = 1, ["param1"] = 0, ["z"] = 9, ["name"] = "default:brick" }, { ["x"] = 7, ["meta"] = { ["fields"] = { ["owner_info"] = "return { [\"y\"] = 2, [\"x\"] = 343, [\"z\"] = 1108 }" }, ["inventory"] = {  } }, ["param2"] = 9, ["y"] = 2, ["param1"] = 205, ["z"] = 1, ["name"] = "default:fence_wood" }, { ["x"] = 7, ["meta"] = { ["fields"] = { ["owner_info"] = "return { [\"y\"] = 2, [\"x\"] = 343, [\"z\"] = 1108 }" }, ["inventory"] = {  } }, ["param2"] = 9, ["y"] = 2, ["param1"] = 0, ["z"] = 5, ["name"] = "default:brick" }, { ["x"] = 7, ["meta"] = { ["fields"] = { ["owner_info"] = "return { [\"y\"] = 2, [\"x\"] = 343, [\"z\"] = 1108 }" }, ["inventory"] = {  } }, ["param2"] = 9, ["y"] = 2, ["param1"] = 0, ["z"] = 6, ["name"] = "default:brick" }, { ["x"] = 7, ["meta"] = { ["fields"] = { ["owner_info"] = "return { [\"y\"] = 2, [\"x\"] = 343, [\"z\"] = 1108 }" }, ["inventory"] = {  } }, ["param2"] = 9, ["y"] = 2, ["param1"] = 0, ["z"] = 7, ["name"] = "default:brick" }, { ["x"] = 7, ["meta"] = { ["fields"] = { ["owner_info"] = "return { [\"y\"] = 2, [\"x\"] = 343, [\"z\"] = 1108 }" }, ["inventory"] = {  } }, ["param2"] = 9, ["y"] = 2, ["param1"] = 0, ["z"] = 8, ["name"] = "default:brick" }, { ["x"] = 7, ["meta"] = { ["fields"] = { ["owner_info"] = "return { [\"y\"] = 2, [\"x\"] = 343, [\"z\"] = 1108 }" }, ["inventory"] = {  } }, ["param2"] = 0, ["y"] = 2, ["param1"] = 0, ["z"] = 9, ["name"] = "default:brick" }, { ["x"] = 7, ["meta"] = { ["fields"] = { ["owner_info"] = "return { [\"y\"] = 2, [\"x\"] = 343, [\"z\"] = 1108 }" }, ["inventory"] = {  } }, ["param2"] = 9, ["y"] = 3, ["param1"] = 0, ["z"] = 1, ["name"] = "default:brick" }, { ["x"] = 7, ["meta"] = { ["fields"] = { ["owner_info"] = "return { [\"y\"] = 2, [\"x\"] = 343, [\"z\"] = 1108 }" }, ["inventory"] = {  } }, ["param2"] = 9, ["y"] = 3, ["param1"] = 0, ["z"] = 2, ["name"] = "default:brick" }, { ["x"] = 7, ["meta"] = { ["fields"] = { ["owner_info"] = "return { [\"y\"] = 2, [\"x\"] = 343, [\"z\"] = 1108 }" }, ["inventory"] = {  } }, ["param2"] = 9, ["y"] = 3, ["param1"] = 0, ["z"] = 3, ["name"] = "default:brick" }, { ["x"] = 7, ["meta"] = { ["fields"] = { ["owner_info"] = "return { [\"y\"] = 2, [\"x\"] = 343, [\"z\"] = 1108 }" }, ["inventory"] = {  } }, ["param2"] = 9, ["y"] = 3, ["param1"] = 0, ["z"] = 4, ["name"] = "default:brick" }, { ["x"] = 7, ["meta"] = { ["fields"] = { ["owner_info"] = "return { [\"y\"] = 2, [\"x\"] = 343, [\"z\"] = 1108 }" }, ["inventory"] = {  } }, ["param2"] = 9, ["y"] = 3, ["param1"] = 0, ["z"] = 5, ["name"] = "default:brick" }, { ["x"] = 7, ["meta"] = { ["fields"] = { ["owner_info"] = "return { [\"y\"] = 2, [\"x\"] = 343, [\"z\"] = 1108 }" }, ["inventory"] = {  } }, ["param2"] = 9, ["y"] = 3, ["param1"] = 0, ["z"] = 6, ["name"] = "default:brick" }, { ["x"] = 7, ["meta"] = { ["fields"] = { ["owner_info"] = "return { [\"y\"] = 2, [\"x\"] = 343, [\"z\"] = 1108 }" }, ["inventory"] = {  } }, ["param2"] = 9, ["y"] = 3, ["param1"] = 0, ["z"] = 7, ["name"] = "default:brick" }, { ["x"] = 7, ["meta"] = { ["fields"] = { ["owner_info"] = "return { [\"y\"] = 2, [\"x\"] = 343, [\"z\"] = 1108 }" }, ["inventory"] = {  } }, ["param2"] = 9, ["y"] = 3, ["param1"] = 0, ["z"] = 8, ["name"] = "default:brick" }, { ["x"] = 7, ["meta"] = { ["fields"] = { ["owner_info"] = "return { [\"y\"] = 2, [\"x\"] = 343, [\"z\"] = 1108 }" }, ["inventory"] = {  } }, ["param2"] = 0, ["y"] = 3, ["param1"] = 0, ["z"] = 9, ["name"] = "default:brick" }, { ["x"] = 7, ["meta"] = { ["fields"] = { ["owner_info"] = "return { [\"y\"] = 2, [\"x\"] = 343, [\"z\"] = 1108 }" }, ["inventory"] = {  } }, ["param2"] = 9, ["y"] = 4, ["param1"] = 0, ["z"] = 1, ["name"] = "default:brick" }, { ["x"] = 7, ["meta"] = { ["fields"] = { ["owner_info"] = "return { [\"y\"] = 2, [\"x\"] = 343, [\"z\"] = 1108 }" }, ["inventory"] = {  } }, ["param2"] = 9, ["y"] = 4, ["param1"] = 191, ["z"] = 2, ["name"] = "default:fence_wood" }, { ["x"] = 7, ["meta"] = { ["fields"] = { ["owner_info"] = "return { [\"y\"] = 2, [\"x\"] = 343, [\"z\"] = 1108 }" }, ["inventory"] = {  } }, ["param2"] = 9, ["y"] = 4, ["param1"] = 175, ["z"] = 3, ["name"] = "default:fence_wood" }, { ["x"] = 7, ["meta"] = { ["fields"] = { ["owner_info"] = "return { [\"y\"] = 2, [\"x\"] = 343, [\"z\"] = 1108 }" }, ["inventory"] = {  } }, ["param2"] = 9, ["y"] = 4, ["param1"] = 157, ["z"] = 4, ["name"] = "default:fence_wood" }, { ["x"] = 7, ["meta"] = { ["fields"] = { ["owner_info"] = "return { [\"y\"] = 2, [\"x\"] = 343, [\"z\"] = 1108 }" }, ["inventory"] = {  } }, ["param2"] = 9, ["y"] = 4, ["param1"] = 0, ["z"] = 5, ["name"] = "default:brick" }, { ["x"] = 7, ["meta"] = { ["fields"] = { ["owner_info"] = "return { [\"y\"] = 2, [\"x\"] = 343, [\"z\"] = 1108 }" }, ["inventory"] = {  } }, ["param2"] = 9, ["y"] = 4, ["param1"] = 0, ["z"] = 6, ["name"] = "default:brick" }, { ["x"] = 7, ["meta"] = { ["fields"] = { ["owner_info"] = "return { [\"y\"] = 2, [\"x\"] = 343, [\"z\"] = 1108 }" }, ["inventory"] = {  } }, ["param2"] = 9, ["y"] = 4, ["param1"] = 172, ["z"] = 7, ["name"] = "default:glass" }, { ["x"] = 7, ["meta"] = { ["fields"] = { ["owner_info"] = "return { [\"y\"] = 2, [\"x\"] = 343, [\"z\"] = 1108 }" }, ["inventory"] = {  } }, ["param2"] = 9, ["y"] = 4, ["param1"] = 0, ["z"] = 8, ["name"] = "default:brick" }, { ["x"] = 7, ["meta"] = { ["fields"] = { ["owner_info"] = "return { [\"y\"] = 2, [\"x\"] = 343, [\"z\"] = 1108 }" }, ["inventory"] = {  } }, ["param2"] = 0, ["y"] = 4, ["param1"] = 0, ["z"] = 9, ["name"] = "default:brick" }, { ["x"] = 7, ["meta"] = { ["fields"] = { ["owner_info"] = "return { [\"y\"] = 2, [\"x\"] = 343, [\"z\"] = 1108 }" }, ["inventory"] = {  } }, ["param2"] = 2, ["y"] = 5, ["param1"] = 15, ["z"] = 1, ["name"] = "default:torch" }, { ["x"] = 7, ["meta"] = { ["fields"] = { ["owner_info"] = "return { [\"y\"] = 2, [\"x\"] = 343, [\"z\"] = 1108 }" }, ["inventory"] = {  } }, ["param2"] = 9, ["y"] = 5, ["param1"] = 0, ["z"] = 6, ["name"] = "default:brick" }, { ["x"] = 7, ["meta"] = { ["fields"] = { ["owner_info"] = "return { [\"y\"] = 2, [\"x\"] = 343, [\"z\"] = 1108 }" }, ["inventory"] = {  } }, ["param2"] = 9, ["y"] = 5, ["param1"] = 188, ["z"] = 7, ["name"] = "default:glass" }, { ["x"] = 7, ["meta"] = { ["fields"] = { ["owner_info"] = "return { [\"y\"] = 2, [\"x\"] = 343, [\"z\"] = 1108 }" }, ["inventory"] = {  } }, ["param2"] = 9, ["y"] = 5, ["param1"] = 0, ["z"] = 8, ["name"] = "default:brick" }, { ["x"] = 7, ["meta"] = { ["fields"] = { ["owner_info"] = "return { [\"y\"] = 2, [\"x\"] = 343, [\"z\"] = 1108 }" }, ["inventory"] = {  } }, ["param2"] = 9, ["y"] = 6, ["param1"] = 0, ["z"] = 6, ["name"] = "default:brick" }, { ["x"] = 7, ["meta"] = { ["fields"] = { ["owner_info"] = "return { [\"y\"] = 2, [\"x\"] = 343, [\"z\"] = 1108 }" }, ["inventory"] = {  } }, ["param2"] = 9, ["y"] = 6, ["param1"] = 0, ["z"] = 7, ["name"] = "default:brick" }, { ["x"] = 7, ["meta"] = { ["fields"] = { ["owner_info"] = "return { [\"y\"] = 2, [\"x\"] = 343, [\"z\"] = 1108 }" }, ["inventory"] = {  } }, ["param2"] = 9, ["y"] = 6, ["param1"] = 0, ["z"] = 8, ["name"] = "default:brick" }, { ["x"] = 7, ["meta"] = { ["fields"] = {  }, ["inventory"] = {  } }, ["param2"] = 0, ["y"] = 7, ["param1"] = 141, ["z"] = 4, ["name"] = "stairs:slab_stone" }, { ["x"] = 7, ["meta"] = { ["fields"] = {  }, ["inventory"] = {  } }, ["param2"] = 0, ["y"] = 7, ["param1"] = 157, ["z"] = 5, ["name"] = "stairs:slab_stone" }, { ["x"] = 7, ["meta"] = { ["fields"] = {  }, ["inventory"] = {  } }, ["param2"] = 0, ["y"] = 7, ["param1"] = 173, ["z"] = 6, ["name"] = "stairs:slab_stone" }, { ["x"] = 7, ["meta"] = { ["fields"] = {  }, ["inventory"] = {  } }, ["param2"] = 0, ["y"] = 7, ["param1"] = 157, ["z"] = 7, ["name"] = "stairs:slab_stone" }, { ["x"] = 7, ["meta"] = { ["fields"] = {  }, ["inventory"] = {  } }, ["param2"] = 0, ["y"] = 7, ["param1"] = 173, ["z"] = 8, ["name"] = "stairs:slab_stone" }, { ["x"] = 7, ["meta"] = { ["fields"] = {  }, ["inventory"] = {  } }, ["param2"] = 0, ["y"] = 7, ["param1"] = 157, ["z"] = 9, ["name"] = "stairs:slab_stone" }, { ["x"] = 7, ["meta"] = { ["fields"] = {  }, ["inventory"] = {  } }, ["param2"] = 0, ["y"] = 7, ["param1"] = 157, ["z"] = 10, ["name"] = "stairs:slab_stone" }, { ["x"] = 8, ["meta"] = { ["fields"] = { ["owner_info"] = "return { [\"y\"] = 2, [\"x\"] = 343, [\"z\"] = 1108 }" }, ["inventory"] = {  } }, ["param2"] = 3, ["y"] = 2, ["param1"] = 0, ["z"] = 6, ["name"] = "default:torch" }, { ["x"] = 8, ["meta"] = { ["fields"] = { ["owner_info"] = "return { [\"y\"] = 2, [\"x\"] = 343, [\"z\"] = 1108 }" }, ["inventory"] = {  } }, ["param2"] = 3, ["y"] = 2, ["param1"] = 0, ["z"] = 8, ["name"] = "default:torch" }, { ["x"] = 8, ["meta"] = { ["fields"] = { ["owner_info"] = "return { [\"y\"] = 2, [\"x\"] = 343, [\"z\"] = 1108 }" }, ["inventory"] = {  } }, ["param2"] = 3, ["y"] = 5, ["param1"] = 0, ["z"] = 6, ["name"] = "default:torch" }, { ["x"] = 8, ["meta"] = { ["fields"] = { ["owner_info"] = "return { [\"y\"] = 2, [\"x\"] = 343, [\"z\"] = 1108 }" }, ["inventory"] = {  } }, ["param2"] = 3, ["y"] = 5, ["param1"] = 0, ["z"] = 8, ["name"] = "default:torch" }, { ["x"] = 8, ["meta"] = { ["fields"] = {  }, ["inventory"] = {  } }, ["param2"] = 0, ["y"] = 7, ["param1"] = 173, ["z"] = 5, ["name"] = "stairs:slab_stone" }, { ["x"] = 8, ["meta"] = { ["fields"] = {  }, ["inventory"] = {  } }, ["param2"] = 0, ["y"] = 7, ["param1"] = 189, ["z"] = 6, ["name"] = "stairs:slab_stone" }, { ["x"] = 8, ["meta"] = { ["fields"] = {  }, ["inventory"] = {  } }, ["param2"] = 0, ["y"] = 7, ["param1"] = 173, ["z"] = 7, ["name"] = "stairs:slab_stone" }, { ["x"] = 8, ["meta"] = { ["fields"] = {  }, ["inventory"] = {  } }, ["param2"] = 0, ["y"] = 7, ["param1"] = 189, ["z"] = 8, ["name"] = "stairs:slab_stone" }, { ["x"] = 8, ["meta"] = { ["fields"] = {  }, ["inventory"] = {  } }, ["param2"] = 0, ["y"] = 7, ["param1"] = 173, ["z"] = 9, ["name"] = "stairs:slab_stone" } }